#notes label(help) run me for the dreamfort walkthrough
Welcome to the Dreamfort Walkthrough!
It can be difficult applying a set of blueprints that you did not write yourself. This walkthrough will guide you through the high-level steps of building Dreamfort. Each level also has its own mini-walkthrough with specific steps for that level.
""
"The final fort will have a walled-in area on the surface for livestock, trading, and military. One z-level down is the farming level, with related workshops and vents up to the surface for miasma control. The farming level also has a miniature dining hall and dormitory for use until you get the services and housing levels set up."
""
"Beyond those two, the other layers can be built in any order, at any z-level, according to your preference and the layout peculiarities of your embark site:"
"- The industry level has a compact, but complete set of workshops and stockpiles (minus what is already provided on the farming level)."
"- The services level has dining, hospital, and justice services, including a well system. This level is 4 z-levels deep."
"- The guildhall level has many empty rooms for building libraries, temples, and guildhalls."
- The suites level has fancy rooms for your nobles.
- The apartments level(s) has small but well-furnished bedrooms for your other dwarves.
""
"Run each level's ""help"" blueprint (e.g. /surface_help) for more details, or run /checklist for a list of all commands you need to run, in order."
""
"Dreamfort has a central staircase-based design. For all Dreamfort levels, place the cursor on the center staircase tile when you apply the blueprints. The first surface blueprint will designate a column of staircases that you can use as a guide."
""
"Dreamfort blueprints take care of everything to get the fort up and running. You don't need to clear any trees or create any extra buildings or stockpiles (though of course you are free to do so). Blueprints that do require manual steps (like 'assign minecart to hauling route') will leave a message telling you so when you run them. Blueprints will also leave messages with hints when you might want to run ""quickfort orders"" to start manufacturing needed items."
""
"Dreamfort works best at an embark site that is flat and has at least one soil layer. New players should also avoid aquifers if they are not prepared to deal with them. Bring picks for mining, an axe for woodcutting, and an anvil for a forge."
""
"Directly after embark, apply /surface1 on the surface (see /surface_help for how to select a good spot) and /industry1 on a level least two z-levels underground (the z-level immediately below the surface is reserved for the farming level). The walkthroughs for those levels will guide you. Once you channel out parts of the surface with /surface3, you can start the farming sequence on the z-level below the surface with /farming1. You can start the services, guildhall, suites, and apartments sequences as your fort needs those levels."
""
"This .csv file is generated from source .xlsx files. If you want to look at how these blueprints are put together, it will be easier to look at the online spreadsheets than this giant .csv. You can view them at: https://drive.google.com/drive/folders/1iS90EEVqUkxTeZiiukVj1pLloZqabKuP"
You are welcome to copy those spreadsheets and make your own modifications!
"#dreamfort.csv is generated with the following command:
  for fname in dreamfort*.xlsx; do xlsx2csv -a -p '' $fname; done | sed 's/,*$//'"
#notes label(checklist)
Here is the recommended order for Dreamfort commands. See walkthroughs for details.
""
-- Find a good starting spot on the surface --
quickfort run library/dreamfort.csv -n /surface4
quickfort undo library/dreamfort.csv -n /surface4
""
"-- Surface, industry, and farming --"
quickfort run library/dreamfort.csv -n /surface1
quickfort run library/dreamfort.csv -n /industry1
quickfort run library/dreamfort.csv -n /surface2
quickfort orders library/dreamfort.csv -n /industry2
quickfort orders library/dreamfort.csv -n /farming2
quickfort orders library/dreamfort.csv -n /surface4
quickfort orders library/dreamfort.csv -n /surface5
quickfort orders library/dreamfort.csv -n /surface6
quickfort run library/dreamfort.csv -n /surface3
quickfort run library/dreamfort.csv -n /industry2
quickfort run library/dreamfort.csv -n /farming1
quickfort run library/dreamfort.csv -n /surface4
quickfort run library/dreamfort.csv -n /farming2
quickfort run library/dreamfort.csv -n /farming3
orders import automation
quickfort run library/dreamfort.csv -n /surface5
quickfort run library/dreamfort.csv -n /surface6
""
-- Everything else -- 
quickfort orders library/dreamfort.csv -n /services2
quickfort orders library/dreamfort.csv -n /guildhall2
quickfort orders library/dreamfort.csv -n /suites2
quickfort run library/dreamfort.csv -n /services1
quickfort run library/dreamfort.csv -n /services2
quickfort run library/dreamfort.csv -n /services3
quickfort run library/dreamfort.csv -n /guildhall1
quickfort run library/dreamfort.csv -n /guildhall2
quickfort run library/dreamfort.csv -n /suites1
quickfort run library/dreamfort.csv -n /suites2
quickfort run library/dreamfort.csv -n /apartments1_stack
""
-- Repeat for each apartments level --
quickfort orders library/dreamfort.csv -n /apartments2
quickfort run library/dreamfort.csv -n /apartments2
quickfort run library/dreamfort.csv -n /apartments3
burial -pets
#notes label(surface_help)
"Sets up a large, protected entrance to your fort in a flat area on the surface."
""
Features:
- A starting set of workshops and stockpiles (which you can later remove once you establish your permanent workshops and storage)
- Trade depot area
"- Walls, roof, and lever-controlled gates for security"
- Trap-filled hallways for invaders
- Livestock grazing area with nestbox zones and beehives
- A grid of 1x1 farm plots (meant to be managed with DFHack autofarm)
- An extra room near the entrance for a barracks (once you get your military going)
- Miasma vents for the farming level that is intended to be built in the layer directly beneath the surface
""
Manual steps you have to take:
- Assign grazing livestock to the large pasture and dogs to the pasture over the stairwell (DFHack's autonestbox can manage the nestbox zones)
- Connect levers to the gates
""
Be sure to choose an embark site that has an area flat enough to use these blueprints!
""
Surface Walkthrough:
"1) Choose a tile for your central staircase. The terrain around that tile should be perfectly flat. Trees are ok, but no slopes, rivers, or lakes. To be sure that the tile you've chosen is in a good spot, set the cursor over that tile and run ""quickfort run library/dreamfort.csv -n /surface4"". This will show you the eventual boundaries of the fort. Some wall segments might be missing due to existing trees, but that's ok. Make sure the area within the exterior wall is flat. Run ""quickfort undo library/dreamfort.csv -n /surface4"" to clean up."
""
"2) With the cursor on the chosen tile, run /surface1 to clear surrounding trees and set up your pastures. Remember to assign your dogs to the pasture around the staircase and your grazing animals to the large pasture. You can let your cats roam free."
""
"3) Once the trees have been cleared, run /surface2 to set up starting workshops/stockpiles and clear trees from a larger area. Run ""quickfort orders"" for /surface4, /surface5, and /surface6 to get a head start manufacturing items for those blueprints. If you want a consistent color for your walls and floors, remember to set the rock material in the buildingplan UI and in the manager orders for the blocks."
""
"4) Once the trees have been cleared from the larger area, run /surface3 to channel out the miasma vents for the farming level."
""
"5) When the channels have been dug, run /surface4 to build the protective walls and flooring. You can also start digging out the sub-surface farming level (/farming1) at this point. Although the vents will be covered with flooring, they will still work to prevent miasma."
""
"6) Once all the constructions are built, run /surface5 build gates, furniture, the trade depot, and traps."
""
"7) When at least the beehives are in place, run /surface6 to configure the hives and construct a roof."
"#meta label(surface1) start(staircase center)
message(Once the stairwell is mined out, you should start digging the industry level in a non-aquifer rock layer.
Once the area is clear of trees, continue with /surface2.) clear trees and set up pastures"
stair_guide/surface_stair_guide
clear_small/surface_clear_small
zones/surface_zones
name_zones/surface_name_zones
""
"#meta label(surface2) start(staircase center) message(This would be a good time to queue manager orders for /surface4, /surface5, and /surface6. If you want a consistent color for your walls, remember to set the rock material in the buildingplan UI and in the manager orders for blocks.
Once the whole area is clear of trees, continue with /surface3.) set up starting workshops/stockpiles and clear a larger area"
build_start/surface_build_start
place_start/surface_place_start
query_start/surface_query_start
clear/surface_clear
pick/surface_pick
""
"#meta label(surface3) start(staircase center) message(Once the channels are dug out, continue with /surface4. You can also start digging out the sub-surface farming level once the channels are done.) channel to prevent miasma in the sub-surface farming level"
dig/surface_channel
""
"#meta label(surface4) start(staircase center) message(Once floors and walls are built, continue with /surface5.) cover up the holes with flooring and build walls"
build_floors/surface_floors
build_walls/surface_walls
""
"#meta label(surface5) start(staircase center) message(Once buildings have been constructed, continue with /surface6) build gates, furniture, the trade depot, and traps"
build_bridges/surface_gates
build_buildings/surface_buildings
""
"#meta label(surface6) start(staircase center on ground level) message(The surface is secure! If you like, you can build a barracks in the empty entranceway room.) configure hives, build the roof"
query_buildings/surface_query_buildings
build_scaffolding/surface_scaffolding
#<
build_roof/surface_roof
build_roof2/surface_roof2
#dig label(surface_stair_guide) hidden() use the meta blueprints for normal application
j
#>
i
#>
i
#>
i7
#>
i7
#>
i7
#>
i7
#>
i7
#>
i7
#>
i7
#>
i7
#>
i7
#>
i7
#>
i7
#>
i7
#dig label(surface_clear_small) start(23; 25) hidden() use the meta blueprints for normal application


,,,,,,`,`,`,`,`,`,`,`,`,`,`,`,`,`,`,`,`,`,`,`,`,`,`,`,`,`,`,`,`,`,`,`,`
,,,,,,`,t,t,t,t,t,t,t,t,t,t,t,t,t,t,t,t,t,t,t,t,t,t,t,t,t,t,t,t,t,t,t,`
,,,,,,`,t,t,t,t,t,t,t,t,t,t,t,t,t,t,t,t,t,t,t,t,t,t,t,t,t,t,t,t,t,t,t,`
,,,,,,`,t,t,t,t,t,t,t,t,t,t,t,t,t,t,t,t,t,t,t,t,t,t,t,t,t,t,t,t,t,t,t,`
,,,,,,`,t,t,t,t,t,t,t,t,t,t,t,t,t,t,t,t,t,t,t,t,t,t,t,t,t,t,t,t,t,t,t,`
,,,,,,`,t,t,t,t,t,t,t,t,t,t,t,t,t,t,t,t,t,t,t,t,t,t,t,t,t,t,t,t,t,t,t,`
,,,,,,`,t,t,t,t,t,t,t,t,t,t,t,t,t,t,t,t,t,t,t,t,t,t,t,t,t,t,t,t,t,t,t,`
,,,,,,`,t,t,t,t,t,t,t,t,t,t,t,t,t,t,t,t,t,t,t,t,t,t,t,t,t,t,t,t,t,t,t,`
,,,,,,`,t,t,t,t,t,t,t,t,t,t,t,t,t,t,t,t,t,t,t,t,t,t,t,t,t,t,t,t,t,t,t,`
,,,,,,`,t,t,t,t,t,t,t,t,t,t,t,t,t,t,t,t,t,t,t,t,t,t,t,t,t,t,t,t,t,t,t,`
,,,,,,`,t,t,t,t,t,t,t,t,t,t,t,t,t,t,t,t,t,t,t,t,t,t,t,t,t,t,t,t,t,t,t,`
,,,,,,`,t,t,t,t,t,t,t,t,t,t,t,t,t,t,t,t,t,t,t,t,t,t,t,t,t,t,t,t,t,t,t,`
,,,,,,`,t,t,t,t,t,t,t,t,t,t,t,t,t,t,t,t,t,t,t,t,t,t,t,t,t,t,t,t,t,t,t,`
,,,,,,`,t,t,t,t,t,t,t,t,t,t,t,t,t,t,t,t,t,t,t,t,t,t,t,t,t,t,t,t,t,t,t,`
,,,,,,`,t,t,t,t,t,t,t,t,t,t,t,t,t,t,t,t,t,t,t,t,t,t,t,t,t,t,t,t,t,t,t,`
,,,,,,`,t,t,t,t,t,t,t,t,t,t,t,t,t,t,t,t,t,t,t,t,t,t,t,t,t,t,t,t,t,t,t,`
,,,,,,`,t,t,t,t,t,t,t,t,t,t,t,t,t,t,t,t,t,t,t,t,t,t,t,t,t,t,t,t,t,t,t,`
,,,,,,`,t,t,t,t,t,t,t,t,t,t,t,t,t,t,t,t,t,t,t,t,t,t,t,t,t,t,t,t,t,t,t,`
,,,,,,`,t,t,t,t,t,t,t,t,t,t,t,t,t,t,t,t,t,t,t,t,t,t,t,t,t,t,t,t,t,t,t,`
,,,,,,`,t,t,t,t,t,t,t,t,t,t,t,t,t,t,t,t,t,t,t,t,t,t,t,t,t,t,t,t,t,t,t,`
,,,,,,`,t,t,t,t,t,t,t,t,t,t,t,t,t,t,t,t,t,t,t,t,t,t,t,t,t,t,t,t,t,t,t,`
,,,,,,`,t,t,t,t,t,t,t,t,t,t,t,t,t,t,t,t,t,t,t,t,t,t,t,t,t,t,t,t,t,t,t,`
,,,,,,`,t,t,t,t,t,t,t,t,t,t,t,t,t,t,t,,t,t,t,t,t,t,t,t,t,t,t,t,t,t,t,`
,,,,,,`,t,t,t,t,t,t,t,t,t,t,t,t,t,t,t,t,t,t,t,t,t,t,t,t,t,t,t,t,t,t,t,`
,,,,,,`,t,t,t,t,t,t,t,t,t,t,t,t,t,t,t,t,t,t,t,t,t,t,t,t,t,t,t,t,t,t,t,`
,,,,,,`,`,`,`,`,`,`,`,`,`,,`,`,`,`,,`,,`,`,`,`,,`,`,`,`,`,`,`,`,`,`
,,,,,,`,`,`,`,`,`,`,`,`,`,,`,`,,,,,,,,`,`,,`,`,`,`,`,`,`,`,`,`
,,,,,,`,,,,,,,,,,,,`,,,,,,,,`,,,,,,,,,,,,`
,,,,,,`,,,,,,,,,,,,`,,,,,,,,`,,,,,,,,,,,,`
,,,,,,`,,,,,,,,,,,,,,,,,,,,,,,,,,,,,,,,`
,,,,,,`,,,,,,,,,,,,,,,,,,,,,,,,,,,,,,,,`
,,,,,,`,,,,,,,,,,,,,,,,,,,,,,,,,,,,,,,,`
,,,,,,`,,,,,,,,,,,,`,,,,,,,,`,,,,,,,,,,,,`
,,,,,,`,,,,,,,,,,,,`,,,,,,,,`,,,,,,,,,,,,`
,,,,,,`,`,`,`,`,`,`,`,`,`,`,`,`,,,,,,,,`,`,`,`,`,`,`,`,`,`,`,`,`
,,,,,,`,`,`,`,`,`,`,`,`,`,`,`,`,,,,,,,,`,`,`,`,`,`,`,`,`,`,`,`,`
,,,,,,,,,,,,,,,,,`,`,,,,,,,,`,`
,,,,,,,,,,,,,,,,,`,`,,,,,,,,`,`
,,,,,,,,,,,,,,,,,`,`,,,,,,,,`,`
,,,,,,`,`,`,`,`,`,`,`,`,`,`,`,`,,,,,,,,`,`,`,`,`,`,`,`,`,`,`,`,`
,,,,,,,,,,,,,,,,,,`,,,,,,,,`
,,,,,,,,,,,,,,,,,,`,`,`,`,`,`,`,`,`
,,,,,,,,,,,,,,,,,,,`,`,`,`,`,`,`
,,,,,,,,,,,,,,,,,,,`,`,`,`,`,`,`


#zone label(surface_zones) start(23; 25) hidden() message(remember to assign your dogs to the staircase pasture and your grazing animals to the large pasture) use the meta blueprints for normal application


,,,,,,`,`,`,`,`,`,`,`,`,`,`,`,`,`,`,`,`,`,`,`,`,`,`,`,`,`,`,`,`,`,`,`,`
,,,,,,`,gnm(31x17),,,,,,,,,,,,,,,,,,,,,,,,,,,,,,,`
,,,,,,`,,,,,,,,,,,,,,,,,,,,,,,,,,,,,,,,`
,,,,,,`,,,,,,,,,,,,,,,,,,,,,,,,,,,,,,,,`
,,,,,,`,,,,,,,,,,,,,,,,,,,,,,,,,,,,,,,,`
,,,,,,`,,,,,,,,,,,,,,,,,,,,,,,,,,,,,,,,`
,,,,,,`,,,,,,,,,,,,,,,,,,,,,,,,,,,,,,,,`
,,,,,,`,,,,,,,,,,,,,,,,,,,,,,,,,,,,,,,,`
,,,,,,`,,,,,,,,,,,,,,,,,,,,,,,,,,,,,,,,`
,,,,,,`,,,,,,,,,,,,,,,,,,,,,,,,,,,,,,,,`
,,,,,,`,,,,,,,,,,,,,,,,,,,,,,,,,,,,,,,,`
,,,,,,`,,,,,,,,,,,,,,,,,,,,,,,,,,,,,,,,`
,,,,,,`,,,,,,,,,,,,,,,,,,,,,,,,,,,,,,,,`
,,,,,,`,,,,,,,,,,,,,,,,,,,,,,,,,,,,,,,,`
,,,,,,`,,,,,,,,,,,,,,,,,,,,,,,,,,,,,,,,`
,,,,,,`,,,,,,,,,,,,,,,,,,,,,,,,,,,,,,,,`
,,,,,,`,,,,,,,,,,,,,,,,,,,,,,,,,,,,,,,,`
,,,,,,`,,,,,,,,,,,,,,,,,,,,,,,,,,,,,,,,`
,,,,,,`,n(1x1),n(1x1),n(1x1),n(1x1),n(1x1),n(1x1),n(1x1),n(1x1),n(1x1),n(1x1),n(1x1),n(1x1),,,,,,,,n(1x1),n(1x1),n(1x1),n(1x1),n(1x1),n(1x1),n(1x1),n(1x1),n(1x1),n(1x1),n(1x1),n(1x1),`
,,,,,,`,`,`,`,`,`,`,`,`,`,`,`,`,`,`,,`,,`,`,`,`,`,`,`,`,`,`,`,`,`,`,`
,,,,,,`,,,,,,,,,,,,,`,n(5x5),,,,,`,t(12x5),,,,,,,,,,,,`
,,,,,,`,,,,,,,,,,,,,,,`,`,`,,,,,,,,,,,,,,,`
,,,,,,`,,,,,,,,,,,,,`,,`,`,`,,`,,,,,,,,,,,,,`
,,,,,,`,,,,,,,,,,,,,,,`,`,`,,,,,,,,,,,,,,,`
,,,,,,`,,,,,,,,,,,,,`,,,,,,`,,,,,,,,,,,,,`
,,,,,,`,`,`,`,`,`,`,`,`,`,,`,`,`,`,,`,,`,`,`,`,,`,`,`,`,`,`,`,`,`,`
,,,,,,`,`,`,`,`,`,`,`,`,`,,`,`,,,,,,,,`,`,,`,`,`,`,`,`,`,`,`,`
,,,,,,`,,,,,,,,,,,,`,,,,,,,,`,,,,,,,,,,,,`
,,,,,,`,,,,,,,,,,,,`,,,,,,,,`,,,,,,,,,,,,`
,,,,,,`,,,,,,,,,,,,,,,,,,,,,,,,,,,,,,,,`
,,,,,,`,,,,,,,,,,,,,,,,,,,,,,,,,,,,,,,,`
,,,,,,`,,,,,,,,,,,,,,,,,,,,,,,,,,,,,,,,`
,,,,,,`,,,,,,,,,,,,`,,,,,,,,`,,,,,,,,,,,,`
,,,,,,`,,,,,,,,,,,,`,,,,,,,,`,,,,,,,,,,,,`
,,,,,,`,`,`,`,`,`,`,`,`,`,`,`,`,,,,,,,,`,`,`,`,`,`,`,`,`,`,`,`,`
,,,,,,`,`,`,`,`,`,`,`,`,`,`,`,`,,,,,,,,`,`,`,`,`,`,`,`,`,`,`,`,`
,,,,,,,,,,,,,,,,,`,`,,,,,,,,`,`
,,,,,,,,,,,,,,,,,`,`,,,,,,,,`,`
,,,,,,,,,,,,,,,,,`,`,,,,,,,,`,`
,,,,,,`,`,`,`,`,`,`,`,`,`,`,`,`,,,,,,,,`,`,`,`,`,`,`,`,`,`,`,`,`
,,,,,,,,,,,,,,,,,,`,,,,,,,,`
,,,,,,,,,,,,,,,,,,`,`,`,`,`,`,`,`,`
,,,,,,,,,,,,,,,,,,,`,`,`,`,`,`,`
,,,,,,,,,,,,,,,,,,,`,`,`,`,`,`,`



#query label(surface_name_zones) start(23; 25) hidden() use the meta blueprints for normal application


,,,,,,`,`,`,`,`,`,`,`,`,`,`,`,`,`,`,`,`,`,`,`,`,`,`,`,`,`,`,`,`,`,`,`,`
,,,,,,`,"{namezone name=""main pasture""}",,,,,,,,,,,,,,,,,,,,,,,,,,,,,,,`
,,,,,,`,,,,,,,,,,,,,,,,,,,,,,,,,,,,,,,,`
,,,,,,`,,,,,,,,,,,,,,,,,,,,,,,,,,,,,,,,`
,,,,,,`,,,,,,,,,,,,,,,,,,,,,,,,,,,,,,,,`
,,,,,,`,,,,,,,,,,,,,,,,,,,,,,,,,,,,,,,,`
,,,,,,`,,,,,,,,,,,,,,,,,,,,,,,,,,,,,,,,`
,,,,,,`,,,,,,,,,,,,,,,,,,,,,,,,,,,,,,,,`
,,,,,,`,,,,,,,,,,,,,,,,,,,,,,,,,,,,,,,,`
,,,,,,`,,,,,,,,,,,,,,,,,,,,,,,,,,,,,,,,`
,,,,,,`,,,,,,,,,,,,,,,,,,,,,,,,,,,,,,,,`
,,,,,,`,,,,,,,,,,,,,,,,,,,,,,,,,,,,,,,,`
,,,,,,`,,,,,,,,,,,,,,,,,,,,,,,,,,,,,,,,`
,,,,,,`,,,,,,,,,,,,,,,,,,,,,,,,,,,,,,,,`
,,,,,,`,,,,,,,,,,,,,,,,,,,,,,,,,,,,,,,,`
,,,,,,`,,,,,,,,,,,,,,,,,,,,,,,,,,,,,,,,`
,,,,,,`,,,,,,,,,,,,,,,,,,,,,,,,,,,,,,,,`
,,,,,,`,,,,,,,,,,,,,,,,,,,,,,,,,,,,,,,,`
,,,,,,`,"{namezone name=""nestbox1""}","{namezone name=""nestbox2""}","{namezone name=""nestbox3""}","{namezone name=""nestbox4""}","{namezone name=""nestbox5""}","{namezone name=""nestbox6""}","{namezone name=""nestbox7""}","{namezone name=""nestbox8""}","{namezone name=""nestbox9""}","{namezone name=""nestbox10""}","{namezone name=""nestbox11""}","{namezone name=""nestbox12""}",,,,,,,,"{namezone name=""nestbox13""}","{namezone name=""nestbox14""}","{namezone name=""nestbox15""}","{namezone name=""nestbox16""}","{namezone name=""nestbox17""}","{namezone name=""nestbox18""}","{namezone name=""nestbox19""}","{namezone name=""nestbox20""}","{namezone name=""nestbox21""}","{namezone name=""nestbox22""}","{namezone name=""nestbox23""}","{namezone name=""nestbox24""}",`
,,,,,,`,`,`,`,`,`,`,`,`,`,`,`,`,`,`,,`,,`,`,`,`,`,`,`,`,`,`,`,`,`,`,`
,,,,,,`,,,,,,,,,,,,,`,"{namezone name=""guard dogs""}",,,,,`,"{namezone name=""taming area""}",,,,,,,,,,,,`
,,,,,,`,,,,,,,,,,,,,,,`,`,`,,,,,,,,,,,,,,,`
,,,,,,`,,,,,,,,,,,,,`,,`,`,`,,`,,,,,,,,,,,,,`
,,,,,,`,,,,,,,,,,,,,,,`,`,`,,,,,,,,,,,,,,,`
,,,,,,`,,,,,,,,,,,,,`,,,,,,`,,,,,,,,,,,,,`
,,,,,,`,`,`,`,`,`,`,`,`,`,,`,`,`,`,,`,,`,`,`,`,,`,`,`,`,`,`,`,`,`,`
,,,,,,`,`,`,`,`,`,`,`,`,`,,`,`,,,,,,,,`,`,,`,`,`,`,`,`,`,`,`,`
,,,,,,`,,,,,,,,,,,,`,,,,,,,,`,,,,,,,,,,,,`
,,,,,,`,,,,,,,,,,,,`,,,,,,,,`,,,,,,,,,,,,`
,,,,,,`,,,,,,,,,,,,,,,,,,,,,,,,,,,,,,,,`
,,,,,,`,,,,,,,,,,,,,,,,,,,,,,,,,,,,,,,,`
,,,,,,`,,,,,,,,,,,,,,,,,,,,,,,,,,,,,,,,`
,,,,,,`,,,,,,,,,,,,`,,,,,,,,`,,,,,,,,,,,,`
,,,,,,`,,,,,,,,,,,,`,,,,,,,,`,,,,,,,,,,,,`
,,,,,,`,`,`,`,`,`,`,`,`,`,`,`,`,,,,,,,,`,`,`,`,`,`,`,`,`,`,`,`,`
,,,,,,`,`,`,`,`,`,`,`,`,`,`,`,`,,,,,,,,`,`,`,`,`,`,`,`,`,`,`,`,`
,,,,,,,,,,,,,,,,,`,`,,,,,,,,`,`
,,,,,,,,,,,,,,,,,`,`,,,,,,,,`,`
,,,,,,,,,,,,,,,,,`,`,,,,,,,,`,`
,,,,,,`,`,`,`,`,`,`,`,`,`,`,`,`,,,,,,,,`,`,`,`,`,`,`,`,`,`,`,`,`
,,,,,,,,,,,,,,,,,,`,,,,,,,,`
,,,,,,,,,,,,,,,,,,`,`,`,`,`,`,`,`,`
,,,,,,,,,,,,,,,,,,,`,`,`,`,`,`,`
,,,,,,,,,,,,,,,,,,,`,`,`,`,`,`,`



#build label(surface_build_start) start(23; 25) hidden() message(use autofarm to manage farm crop selection) use the meta blueprints for normal application


,,,,,,`,`,`,`,`,`,`,`,`,`,`,`,`,`,`,`,`,`,`,`,`,`,`,`,`,`,`,`,`,`,`,`,`
,,,,,,`,,,,,,,,,,,,,,,,,,,,,,,,,,,,,,,,`
,,,,,,`,,,,,,,,,,,,,,,,,,,,,,,,,,,,,,,,`
,,,,,,`,,,,,,,,,,,,,,,,,,,,,,,,,,,,,,,,`
,,,,,,`,,,,,,,,,,,,,,,,,,,,,,,,,,,,,,,,`
,,,,,,`,,,,,,,,,,,,,,,,,,,,,,,,,,,,,,,,`
,,,,,,`,,,,,,,,,,,,,,,,D,,,,,,,,,,,,,,,,`
,,,,,,`,,,,,,,,,,,,,,,,,,,,,,,,,,,,,,,,`
,,,,,,`,,,,,,,,,,,,,,,,,,,,,,,,,,,,,,,,`
,,,,,,`,,,,,,,,,,,,,,,,,,,,,,,,,,,,,,,,`
,,,,,,`,,,,,,,,,,,,,,,,,,,,,,,,,,,,,,,,`
,,,,,,`,,,,,,,,,,,,,,,,,,,,,,,,,,,,,,,,`
,,,,,,`,,,,,,,,,,,,,,,,,,,,,,,,,,,,,,,,`
,,,,,,`,,,,,,,,,,,,,,,,,,,,,,,,,,,,,,,,`
,,,,,,`,,,,,,,,,,,,,,,,,,,,,,,,,,,,,,,,`
,,,,,,`,,,,,,,,,,,,,,,,,,,,,,,,,,,,,,,,`
,,,,,,`,,,,,,,,,,wr,,,,wc,,,,wm,,,,wt,,,,,,,,,,`
,,,,,,`,,,,,,,,,,,,,,,,,,,,,,,,,,,,,,,,`
,,,,,,`,,,,,,,,,,,,,,,,,,,,,,,,,,,,,,,,`
,,,,,,`,`,`,`,`,`,`,`,`,`,`,`,`,`,`,,`,,`,`,`,`,`,`,`,`,`,`,`,`,`,`,`
,,,,,,`,p(1x1),p(1x1),p(1x1),p(1x1),p(1x1),p(1x1),p(1x1),p(1x1),p(1x1),p(1x1),p(1x1),p(1x1),`,,,,,,`,,,,,,,,,,,,,`
,,,,,,`,p(1x1),p(1x1),p(1x1),p(1x1),p(1x1),p(1x1),p(1x1),p(1x1),p(1x1),p(1x1),p(1x1),p(1x1),,,`,`,`,,,,,,,,,,,,,,,`
,,,,,,`,p(1x1),p(1x1),p(1x1),p(1x1),p(1x1),p(1x1),p(1x1),p(1x1),p(1x1),p(1x1),p(1x1),p(1x1),`,,`,`,`,,`,,,,,,,,,,,,,`
,,,,,,`,p(1x1),p(1x1),p(1x1),p(1x1),p(1x1),p(1x1),p(1x1),p(1x1),p(1x1),p(1x1),p(1x1),p(1x1),,,`,`,`,,,,,,,,,,,,,,,`
,,,,,,`,p(1x1),p(1x1),p(1x1),p(1x1),p(1x1),p(1x1),p(1x1),p(1x1),p(1x1),p(1x1),p(1x1),p(1x1),`,,,,,,`,,,,,,,,,,,,,`
,,,,,,`,`,`,`,`,`,`,`,`,`,,`,`,`,`,,`,,`,`,`,`,,`,`,`,`,`,`,`,`,`,`
,,,,,,`,`,`,`,`,`,`,`,`,`,,`,`,,,,,,,,`,`,,`,`,`,`,`,`,`,`,`,`
,,,,,,`,,,,,,,,,,,,`,,,,,,,,`,,,,,,,,,,,,`
,,,,,,`,,,,,,,,,,,,`,,,,,,,,`,,,,,,,,,,,,`
,,,,,,`,,,,,,,,,,,,,,,,,,,,,,,,,,,,,,,,`
,,,,,,`,,,,,,,,,,,,,,,,,,,,,,,,,,,,,,,,`
,,,,,,`,,,,,,,,,,,,,,,,,,,,,,,,,,,,,,,,`
,,,,,,`,,,,,,,,,,,,`,,,,,,,,`,,,,,,,,,,,,`
,,,,,,`,,,,,,,,,,,,`,,,,,,,,`,,,,,,,,,,,,`
,,,,,,`,`,`,`,`,`,`,`,`,`,`,`,`,,,,,,,,`,`,`,`,`,`,`,`,`,`,`,`,`
,,,,,,`,`,`,`,`,`,`,`,`,`,`,`,`,,,,,,,,`,`,`,`,`,`,`,`,`,`,`,`,`
,,,,,,,,,,,,,,,,,`,`,,,,,,,,`,`
,,,,,,,,,,,,,,,,,`,`,,,,,,,,`,`
,,,,,,,,,,,,,,,,,`,`,,,,,,,,`,`
,,,,,,`,`,`,`,`,`,`,`,`,`,`,`,`,,,,,,,,`,`,`,`,`,`,`,`,`,`,`,`,`
,,,,,,,,,,,,,,,,,,`,,,,,,,,`
,,,,,,,,,,,,,,,,,,`,`,`,`,`,`,`,`,`
,,,,,,,,,,,,,,,,,,,`,`,`,`,`,`,`
,,,,,,,,,,,,,,,,,,,`,`,`,`,`,`,`



#place label(surface_place_start) start(23; 25) hidden() use the meta blueprints for normal application


,,,,,,`,`,`,`,`,`,`,`,`,`,`,`,`,`,`,`,`,`,`,`,`,`,`,`,`,`,`,`,`,`,`,`,`
,,,,,,`,,,,,,,,,,,,,,,,,,,,,,,,,,,,,,,,`
,,,,,,`,,,,,,,,,,,,,,,,,,,,,,,,,,,,,,,,`
,,,,,,`,,,,,,,,,,,,,,,,,,,,,,,,,,,,,,,,`
,,,,,,`,,,,,,,,,,,,,,,,,,,,,,,,,,,,,,,,`
,,,,,,`,,,,,,,,,,,,,,,,,,,,,,,,,,,,,,,,`
,,,,,,`,,,,,,,,,,,,,,,,,,,,,,,,,,,,,,,,`
,,,,,,`,,,,,,,,,,,,,,,,,,,,,,,,,,,,,,,,`
,,,,,,`,,,,,,,,,,,,,,,,,,,,,,,,,,,,,,,,`
,,,,,,`,,,,,,,,,,,,,,,,,,,,,,,,,,,,,,,,`
,,,,,,`,,,,f(4x4),,,,w(4x4),,,,f(4x4),,,,,s(4x4),,,,gunbzSpd(4x4),,,,hl(4x4),,,,,,,`
,,,,,,`,,,,,,,,,,,,,,,,,,,,,,,,,,,,,,,,`
,,,,,,`,,,,,,,,,,,,,,,,,,,,,,,,,,,,,,,,`
,,,,,,`,,,,,,,,,,,,,,,,,,,,,,,,,,,,,,,,`
,,,,,,`,,,,,,,,,,,,,,,,,,,,,,,,,,,,,,,,`
,,,,,,`,,,,,,,,,,,,,,,,,,,,,,,,,,,,,,,,`
,,,,,,`,,,,,,,,,,,,,,,,,,,,,,,,,,,,,,,,`
,,,,,,`,,,,,,,,,,,,,,,,,,,,,,,,,,,,,,,,`
,,,,,,`,,,,,,,,,,,,,,,,,,,,,,,,,,,,,,,,`
,,,,,,`,`,`,`,`,`,`,`,`,`,`,`,`,`,`,,`,,`,`,`,`,`,`,`,`,`,`,`,`,`,`,`
,,,,,,`,,,,,,,,,,,,,`,,,,,,`,a(12x5),,,,,,,,,,,,`
,,,,,,`,,,,,,,,,,,,,,,`,`,`,,,,,,,,,,,,,,,`
,,,,,,`,,,,,,,,,,,,,`,,`,`,`,,`,,,,,,,,,,,,,`
,,,,,,`,,,,,,,,,,,,,,,`,`,`,,,,,,,,,,,,,,,`
,,,,,,`,,,,,,,,,,,,,`,,,,,,`,,,,,,,,,,,,,`
,,,,,,`,`,`,`,`,`,`,`,`,`,,`,`,`,`,,`,,`,`,`,`,,`,`,`,`,`,`,`,`,`,`
,,,,,,`,`,`,`,`,`,`,`,`,`,,`,`,,,,,,,,`,`,,`,`,`,`,`,`,`,`,`,`
,,,,,,`,,,,,,,,,,,,`,,,,,,,,`,,,,,,,,,,,,`
,,,,,,`,,,,,,,,,,,,`,,,,,,,,`,,,,,,,,,,,,`
,,,,,,`,,,,,,,,,,,,,,,,,,,,,,,,,,,,,,,,`
,,,,,,`,,,,,,,,,,,,,,,,,,,,,,,,,,,,,,,,`
,,,,,,`,,,,,,,,,,,,,,,,,,,,,,,,,,,,,,,,`
,,,,,,`,,,,,,,,,,,,`,,,,,,,,`,,,,,,,,,,,,`
,,,,,,`,,,,,,,,,,,,`,,,,,,,,`,,,,,,,,,,,,`
,,,,,,`,`,`,`,`,`,`,`,`,`,`,`,`,,,,,,,,`,`,`,`,`,`,`,`,`,`,`,`,`
,,,,,,`,`,`,`,`,`,`,`,`,`,`,`,`,,,,,,,,`,`,`,`,`,`,`,`,`,`,`,`,`
,,,,,,,,,,,,,,,,,`,`,,,,,,,,`,`
,,,,,,,,,,,,,,,,,`,`,,,,,,,,`,`
,,,,,,,,,,,,,,,,,`,`,,,,,,,,`,`
,,,,,,`,`,`,`,`,`,`,`,`,`,`,`,`,,,,,,,,`,`,`,`,`,`,`,`,`,`,`,`,`
,,,,,,,,,,,,,,,,,,`,,,,,,,,`
,,,,,,,,,,,,,,,,,,`,`,`,`,`,`,`,`,`
,,,,,,,,,,,,,,,,,,,`,`,`,`,`,`,`
,,,,,,,,,,,,,,,,,,,`,`,`,`,`,`,`



#query label(surface_query_start) start(23; 25) hidden() use the meta blueprints for normal application


,,,,,,`,`,`,`,`,`,`,`,`,`,`,`,`,`,`,`,`,`,`,`,`,`,`,`,`,`,`,`,`,`,`,`,`
,,,,,,`,,,,,,,,,,,,,,,,,,,,,,,,,,,,,,,,`
,,,,,,`,,,,,,,,,,,,,,,,,,,,,,,,,,,,,,,,`
,,,,,,`,,,,,,,,,,,,,,,,,,,,,,,,,,,,,,,,`
,,,,,,`,,,,,,,,,,,,,,,,,,,,,,,,,,,,,,,,`
,,,,,,`,,,,,,,,,,,,,,,,,,,,,,,,,,,,,,,,`
,,,,,,`,,,,,,,,,,,,,,,,,,,,,,,,,,,,,,,,`
,,,,,,`,,,,,,,,,,,,,,,,,,,,,,,,,,,,,,,,`
,,,,,,`,,,,,,,,,,,,,,,,,,,,,,,,,,,,,,,,`
,,,,,,`,,,,,,,,,,,,,,,,,,,,,,,,,,,,,,,,`
,,,,,,`,,,,"{givename name=""starting food""}",,,,"{givename name=""starting wood""}",,,,"{givename name=""starting booze""}",,,,,"{givename name=""starting stone""}",,,,"{givename name=""starting misc""}",,,,"{givename name=""starting textile""}",,,,,,,`
,,,,,,`,,,,forbidbooze,,,,,,,,booze,,,,,otherstone,,,,,,,,,,,,,,,`
,,,,,,`,,,,nocontainers,,,,,,,,,,,,,,,,,,,,,,,,,,,,`
,,,,,,`,,,,,,,,,,,,,,,,,,,,,,,,,,,,,,,,`
,,,,,,`,,,,,,,,,,,,,,,,,,,,,,,,,,,,,,,,`
,,,,,,`,,,,,,,,,,,,,,,,,,,,,,,,,,,,,,,,`
,,,,,,`,,,,,,,,,,,,,,,,,,,,,,,,,,,,,,,,`
,,,,,,`,,,,,,,,,,,,,,,,,,,,,,,,,,,,,,,,`
,,,,,,`,,,,,,,,,,,,,,,,,,,,,,,,,,,,,,,,`
,,,,,,`,`,`,`,`,`,`,`,`,`,`,`,`,`,`,,`,,`,`,`,`,`,`,`,`,`,`,`,`,`,`,`
,,,,,,`,,,,,,,,,,,,,`,,,,,,`,"{givename name=""prison/training area""}",,,,,,,,,,,,`
,,,,,,`,,,,,,,,,,,,,,,`,`,`,,,forbidcages,,,,,,,,,,,,`
,,,,,,`,,,,,,,,,,,,,`,,`,`,`,,`,forbidtraps,,,,,,,,,,,,`
,,,,,,`,,,,,,,,,,,,,,,`,`,`,,,,,,,,,,,,,,,`
,,,,,,`,,,,,,,,,,,,,`,,,,,,`,,,,,,,,,,,,,`
,,,,,,`,`,`,`,`,`,`,`,`,`,,`,`,`,`,,`,,`,`,`,`,,`,`,`,`,`,`,`,`,`,`
,,,,,,`,`,`,`,`,`,`,`,`,`,,`,`,,,,,,,,`,`,,`,`,`,`,`,`,`,`,`,`
,,,,,,`,,,,,,,,,,,,`,,,,,,,,`,,,,,,,,,,,,`
,,,,,,`,,,,,,,,,,,,`,,,,,,,,`,,,,,,,,,,,,`
,,,,,,`,,,,,,,,,,,,,,,,,,,,,,,,,,,,,,,,`
,,,,,,`,,,,,,,,,,,,,,,,,,,,,,,,,,,,,,,,`
,,,,,,`,,,,,,,,,,,,,,,,,,,,,,,,,,,,,,,,`
,,,,,,`,,,,,,,,,,,,`,,,,,,,,`,,,,,,,,,,,,`
,,,,,,`,,,,,,,,,,,,`,,,,,,,,`,,,,,,,,,,,,`
,,,,,,`,`,`,`,`,`,`,`,`,`,`,`,`,,,,,,,,`,`,`,`,`,`,`,`,`,`,`,`,`
,,,,,,`,`,`,`,`,`,`,`,`,`,`,`,`,,,,,,,,`,`,`,`,`,`,`,`,`,`,`,`,`
,,,,,,,,,,,,,,,,,`,`,,,,,,,,`,`
,,,,,,,,,,,,,,,,,`,`,,,,,,,,`,`
,,,,,,,,,,,,,,,,,`,`,,,,,,,,`,`
,,,,,,`,`,`,`,`,`,`,`,`,`,`,`,`,,,,,,,,`,`,`,`,`,`,`,`,`,`,`,`,`
,,,,,,,,,,,,,,,,,,`,,,,,,,,`
,,,,,,,,,,,,,,,,,,`,`,`,`,`,`,`,`,`
,,,,,,,,,,,,,,,,,,,`,`,`,`,`,`,`
,,,,,,,,,,,,,,,,,,,`,`,`,`,`,`,`



#dig label(surface_clear) start(23; 25) hidden() use the meta blueprints for normal application
t,t,t,t,t,t,t,t,t,t,t,t,t,t,t,t,t,t,t,t,t,t,t,t,t,t,t,t,t,t,t,t,t,t,t,t,t,t,t,t,t,t,t,t,t
t,t,t,t,t,t,t,t,t,t,t,t,t,t,t,t,t,t,t,t,t,t,t,t,t,t,t,t,t,t,t,t,t,t,t,t,t,t,t,t,t,t,t,t,t
t,t,t,t,t,t,t,t,t,t,t,t,t,t,t,t,t,t,t,t,t,t,t,t,t,t,t,t,t,t,t,t,t,t,t,t,t,t,t,t,t,t,t,t,t
t,t,t,t,t,t,t,t,t,t,t,t,t,t,t,t,t,t,t,t,t,t,t,t,t,t,t,t,t,t,t,t,t,t,t,t,t,t,t,t,t,t,t,t,t
t,t,t,t,t,t,t,t,t,t,t,t,t,t,t,t,t,t,t,t,t,t,t,t,t,t,t,t,t,t,t,t,t,t,t,t,t,t,t,t,t,t,t,t,t
t,t,t,t,t,t,t,t,t,t,t,t,t,t,t,t,t,t,t,t,t,t,t,t,t,t,t,t,t,t,t,t,t,t,t,t,t,t,t,t,t,t,t,t,t
t,t,t,t,t,t,t,t,t,t,t,t,t,t,t,t,t,t,t,t,t,t,t,t,t,t,t,t,t,t,t,t,t,t,t,t,t,t,t,t,t,t,t,t,t
t,t,t,t,t,t,t,t,t,t,t,t,t,t,t,t,t,t,t,t,t,t,t,t,t,t,t,t,t,t,t,t,t,t,t,t,t,t,t,t,t,t,t,t,t
t,t,t,t,t,t,t,t,t,t,t,t,t,t,t,t,t,t,t,t,t,t,t,t,t,t,t,t,t,t,t,t,t,t,t,t,t,t,t,t,t,t,t,t,t
t,t,t,t,t,t,t,t,t,t,t,t,t,t,t,t,t,t,t,t,t,t,t,t,t,t,t,t,t,t,t,t,t,t,t,t,t,t,t,t,t,t,t,t,t
t,t,t,t,t,t,t,t,t,t,t,t,t,t,t,t,t,t,t,t,t,t,t,t,t,t,t,t,t,t,t,t,t,t,t,t,t,t,t,t,t,t,t,t,t
t,t,t,t,t,t,t,t,t,t,t,t,t,t,t,t,t,t,t,t,t,t,t,t,t,t,t,t,t,t,t,t,t,t,t,t,t,t,t,t,t,t,t,t,t
t,t,t,t,t,t,t,t,t,t,t,t,t,t,t,t,t,t,t,t,t,t,t,t,t,t,t,t,t,t,t,t,t,t,t,t,t,t,t,t,t,t,t,t,t
t,t,t,t,t,t,t,t,t,t,t,t,t,t,t,t,t,t,t,t,t,t,t,t,t,t,t,t,t,t,t,t,t,t,t,t,t,t,t,t,t,t,t,t,t
t,t,t,t,t,t,t,t,t,t,t,t,t,t,t,t,t,t,t,t,t,t,t,t,t,t,t,t,t,t,t,t,t,t,t,t,t,t,t,t,t,t,t,t,t
t,t,t,t,t,t,t,t,t,t,t,t,t,t,t,t,t,t,t,t,t,t,t,t,t,t,t,t,t,t,t,t,t,t,t,t,t,t,t,t,t,t,t,t,t
t,t,t,t,t,t,t,t,t,t,t,t,t,t,t,t,t,t,t,t,t,t,t,t,t,t,t,t,t,t,t,t,t,t,t,t,t,t,t,t,t,t,t,t,t
t,t,t,t,t,t,t,t,t,t,t,t,t,t,t,t,t,t,t,t,t,t,t,t,t,t,t,t,t,t,t,t,t,t,t,t,t,t,t,t,t,t,t,t,t
t,t,t,t,t,t,t,t,t,t,t,t,t,t,t,t,t,t,t,t,t,t,t,t,t,t,t,t,t,t,t,t,t,t,t,t,t,t,t,t,t,t,t,t,t
t,t,t,t,t,t,t,t,t,t,t,t,t,t,t,t,t,t,t,t,t,t,t,t,t,t,t,t,t,t,t,t,t,t,t,t,t,t,t,t,t,t,t,t,t
t,t,t,t,t,t,t,t,t,t,t,t,t,t,t,t,t,t,t,t,t,t,t,t,t,t,t,t,t,t,t,t,t,t,t,t,t,t,t,t,t,t,t,t,t
t,t,t,t,t,t,t,t,t,t,t,t,t,t,t,t,t,t,t,t,t,t,t,t,t,t,t,t,t,t,t,t,t,t,t,t,t,t,t,t,t,t,t,t,t
t,t,t,t,t,t,t,t,t,t,t,t,t,t,t,t,t,t,t,t,t,t,t,t,t,t,t,t,t,t,t,t,t,t,t,t,t,t,t,t,t,t,t,t,t
t,t,t,t,t,t,t,t,t,t,t,t,t,t,t,t,t,t,t,t,t,t,t,t,t,t,t,t,t,t,t,t,t,t,t,t,t,t,t,t,t,t,t,t,t
t,t,t,t,t,t,t,t,t,t,t,t,t,t,t,t,t,t,t,t,t,t,`,t,t,t,t,t,t,t,t,t,t,t,t,t,t,t,t,t,t,t,t,t,t
t,t,t,t,t,t,t,t,t,t,t,t,t,t,t,t,t,t,t,t,t,t,t,t,t,t,t,t,t,t,t,t,t,t,t,t,t,t,t,t,t,t,t,t,t
t,t,t,t,t,t,t,t,t,t,t,t,t,t,t,t,t,t,t,t,t,t,t,t,t,t,t,t,t,t,t,t,t,t,t,t,t,t,t,t,t,t,t,t,t
t,t,t,t,t,t,t,t,t,t,t,t,t,t,t,t,t,t,t,t,t,t,t,t,t,t,t,t,t,t,t,t,t,t,t,t,t,t,t,t,t,t,t,t,t
t,t,t,t,t,t,t,t,t,t,t,t,t,t,t,t,t,t,t,t,t,t,t,t,t,t,t,t,t,t,t,t,t,t,t,t,t,t,t,t,t,t,t,t,t
t,t,t,t,t,t,t,t,t,t,t,t,t,t,t,t,t,t,t,t,t,t,t,t,t,t,t,t,t,t,t,t,t,t,t,t,t,t,t,t,t,t,t,t,t
t,t,t,t,t,t,t,t,t,t,t,t,t,t,t,t,t,t,t,t,t,t,t,t,t,t,t,t,t,t,t,t,t,t,t,t,t,t,t,t,t,t,t,t,t
t,t,t,t,t,t,t,t,t,t,t,t,t,t,t,t,t,t,t,t,t,t,t,t,t,t,t,t,t,t,t,t,t,t,t,t,t,t,t,t,t,t,t,t,t
t,t,t,t,t,t,t,t,t,t,t,t,t,t,t,t,t,t,t,t,t,t,t,t,t,t,t,t,t,t,t,t,t,t,t,t,t,t,t,t,t,t,t,t,t
t,t,t,t,t,t,t,t,t,t,t,t,t,t,t,t,t,t,t,t,t,t,t,t,t,t,t,t,t,t,t,t,t,t,t,t,t,t,t,t,t,t,t,t,t
t,t,t,t,t,t,t,t,t,t,t,t,t,t,t,t,t,t,t,t,t,t,t,t,t,t,t,t,t,t,t,t,t,t,t,t,t,t,t,t,t,t,t,t,t
t,t,t,t,t,t,t,t,t,t,t,t,t,t,t,t,t,t,t,t,t,t,t,t,t,t,t,t,t,t,t,t,t,t,t,t,t,t,t,t,t,t,t,t,t
t,t,t,t,t,t,t,t,t,t,t,t,t,t,t,t,t,t,t,t,t,t,t,t,t,t,t,t,t,t,t,t,t,t,t,t,t,t,t,t,t,t,t,t,t
t,t,t,t,t,t,t,t,t,t,t,t,t,t,t,t,t,t,t,t,t,t,t,t,t,t,t,t,t,t,t,t,t,t,t,t,t,t,t,t,t,t,t,t,t
t,t,t,t,t,t,t,t,t,t,t,t,t,t,t,t,t,t,t,t,t,t,t,t,t,t,t,t,t,t,t,t,t,t,t,t,t,t,t,t,t,t,t,t,t
t,t,t,t,t,t,t,t,t,t,t,t,t,t,t,t,t,t,t,t,t,t,t,t,t,t,t,t,t,t,t,t,t,t,t,t,t,t,t,t,t,t,t,t,t
t,t,t,t,t,t,t,t,t,t,t,t,t,t,t,t,t,t,t,t,t,t,t,t,t,t,t,t,t,t,t,t,t,t,t,t,t,t,t,t,t,t,t,t,t
t,t,t,t,t,t,t,t,t,t,t,t,t,t,t,t,t,t,t,t,t,t,t,t,t,t,t,t,t,t,t,t,t,t,t,t,t,t,t,t,t,t,t,t,t
t,t,t,t,t,t,t,t,t,t,t,t,t,t,t,t,t,t,t,t,t,t,t,t,t,t,t,t,t,t,t,t,t,t,t,t,t,t,t,t,t,t,t,t,t
t,t,t,t,t,t,t,t,t,t,t,t,t,t,t,t,t,t,t,t,t,t,t,t,t,t,t,t,t,t,t,t,t,t,t,t,t,t,t,t,t,t,t,t,t
t,t,t,t,t,t,t,t,t,t,t,t,t,t,t,t,t,t,t,t,t,t,t,t,t,t,t,t,t,t,t,t,t,t,t,t,t,t,t,t,t,t,t,t,t
t,t,t,t,t,t,t,t,t,t,t,t,t,t,t,t,t,t,t,t,t,t,t,t,t,t,t,t,t,t,t,t,t,t,t,t,t,t,t,t,t,t,t,t,t
t,t,t,t,t,t,t,t,t,t,t,t,t,t,t,t,t,t,t,t,t,t,t,t,t,t,t,t,t,t,t,t,t,t,t,t,t,t,t,t,t,t,t,t,t
t,t,t,t,t,t,t,t,t,t,t,t,t,t,t,t,t,t,t,t,t,t,t,t,t,t,t,t,t,t,t,t,t,t,t,t,t,t,t,t,t,t,t,t,t
t,t,t,t,t,t,t,t,t,t,t,t,t,t,t,t,t,t,t,t,t,t,t,t,t,t,t,t,t,t,t,t,t,t,t,t,t,t,t,t,t,t,t,t,t
#dig label(surface_pick) start(23; 25) hidden() use the meta blueprints for normal application
p,p,p,p,p,p,p,p,p,p,p,p,p,p,p,p,p,p,p,p,p,p,p,p,p,p,p,p,p,p,p,p,p,p,p,p,p,p,p,p,p,p,p,p,p
p,p,p,p,p,p,p,p,p,p,p,p,p,p,p,p,p,p,p,p,p,p,p,p,p,p,p,p,p,p,p,p,p,p,p,p,p,p,p,p,p,p,p,p,p
p,p,p,p,p,p,p,p,p,p,p,p,p,p,p,p,p,p,p,p,p,p,p,p,p,p,p,p,p,p,p,p,p,p,p,p,p,p,p,p,p,p,p,p,p
p,p,p,p,p,p,p,p,p,p,p,p,p,p,p,p,p,p,p,p,p,p,p,p,p,p,p,p,p,p,p,p,p,p,p,p,p,p,p,p,p,p,p,p,p
p,p,p,p,p,p,p,p,p,p,p,p,p,p,p,p,p,p,p,p,p,p,p,p,p,p,p,p,p,p,p,p,p,p,p,p,p,p,p,p,p,p,p,p,p
p,p,p,p,p,p,p,p,p,p,p,p,p,p,p,p,p,p,p,p,p,p,p,p,p,p,p,p,p,p,p,p,p,p,p,p,p,p,p,p,p,p,p,p,p
p,p,p,p,p,p,p,p,p,p,p,p,p,p,p,p,p,p,p,p,p,p,p,p,p,p,p,p,p,p,p,p,p,p,p,p,p,p,p,p,p,p,p,p,p
p,p,p,p,p,p,p,p,p,p,p,p,p,p,p,p,p,p,p,p,p,p,p,p,p,p,p,p,p,p,p,p,p,p,p,p,p,p,p,p,p,p,p,p,p
p,p,p,p,p,p,p,p,p,p,p,p,p,p,p,p,p,p,p,p,p,p,p,p,p,p,p,p,p,p,p,p,p,p,p,p,p,p,p,p,p,p,p,p,p
p,p,p,p,p,p,p,p,p,p,p,p,p,p,p,p,p,p,p,p,p,p,p,p,p,p,p,p,p,p,p,p,p,p,p,p,p,p,p,p,p,p,p,p,p
p,p,p,p,p,p,p,p,p,p,p,p,p,p,p,p,p,p,p,p,p,p,p,p,p,p,p,p,p,p,p,p,p,p,p,p,p,p,p,p,p,p,p,p,p
p,p,p,p,p,p,p,p,p,p,p,p,p,p,p,p,p,p,p,p,p,p,p,p,p,p,p,p,p,p,p,p,p,p,p,p,p,p,p,p,p,p,p,p,p
p,p,p,p,p,p,p,p,p,p,p,p,p,p,p,p,p,p,p,p,p,p,p,p,p,p,p,p,p,p,p,p,p,p,p,p,p,p,p,p,p,p,p,p,p
p,p,p,p,p,p,p,p,p,p,p,p,p,p,p,p,p,p,p,p,p,p,p,p,p,p,p,p,p,p,p,p,p,p,p,p,p,p,p,p,p,p,p,p,p
p,p,p,p,p,p,p,p,p,p,p,p,p,p,p,p,p,p,p,p,p,p,p,p,p,p,p,p,p,p,p,p,p,p,p,p,p,p,p,p,p,p,p,p,p
p,p,p,p,p,p,p,p,p,p,p,p,p,p,p,p,p,p,p,p,p,p,p,p,p,p,p,p,p,p,p,p,p,p,p,p,p,p,p,p,p,p,p,p,p
p,p,p,p,p,p,p,p,p,p,p,p,p,p,p,p,p,p,p,p,p,p,p,p,p,p,p,p,p,p,p,p,p,p,p,p,p,p,p,p,p,p,p,p,p
p,p,p,p,p,p,p,p,p,p,p,p,p,p,p,p,p,p,p,p,p,p,p,p,p,p,p,p,p,p,p,p,p,p,p,p,p,p,p,p,p,p,p,p,p
p,p,p,p,p,p,p,p,p,p,p,p,p,p,p,p,p,p,p,p,p,p,p,p,p,p,p,p,p,p,p,p,p,p,p,p,p,p,p,p,p,p,p,p,p
p,p,p,p,p,p,p,p,p,p,p,p,p,p,p,p,p,p,p,p,p,p,p,p,p,p,p,p,p,p,p,p,p,p,p,p,p,p,p,p,p,p,p,p,p
p,p,p,p,p,p,p,p,p,p,p,p,p,p,p,p,p,p,p,p,p,p,p,p,p,p,p,p,p,p,p,p,p,p,p,p,p,p,p,p,p,p,p,p,p
p,p,p,p,p,p,p,p,p,p,p,p,p,p,p,p,p,p,p,p,p,p,p,p,p,p,p,p,p,p,p,p,p,p,p,p,p,p,p,p,p,p,p,p,p
p,p,p,p,p,p,p,p,p,p,p,p,p,p,p,p,p,p,p,p,p,p,p,p,p,p,p,p,p,p,p,p,p,p,p,p,p,p,p,p,p,p,p,p,p
p,p,p,p,p,p,p,p,p,p,p,p,p,p,p,p,p,p,p,p,p,p,p,p,p,p,p,p,p,p,p,p,p,p,p,p,p,p,p,p,p,p,p,p,p
p,p,p,p,p,p,p,p,p,p,p,p,p,p,p,p,p,p,p,p,p,p,p,p,p,p,p,p,p,p,p,p,p,p,p,p,p,p,p,p,p,p,p,p,p
p,p,p,p,p,p,p,p,p,p,p,p,p,p,p,p,p,p,p,p,p,p,p,p,p,p,p,p,p,p,p,p,p,p,p,p,p,p,p,p,p,p,p,p,p
p,p,p,p,p,p,p,p,p,p,p,p,p,p,p,p,p,p,p,p,p,p,p,p,p,p,p,p,p,p,p,p,p,p,p,p,p,p,p,p,p,p,p,p,p
p,p,p,p,p,p,p,p,p,p,p,p,p,p,p,p,p,p,p,p,p,p,p,p,p,p,p,p,p,p,p,p,p,p,p,p,p,p,p,p,p,p,p,p,p
p,p,p,p,p,p,p,p,p,p,p,p,p,p,p,p,p,p,p,p,p,p,p,p,p,p,p,p,p,p,p,p,p,p,p,p,p,p,p,p,p,p,p,p,p
p,p,p,p,p,p,p,p,p,p,p,p,p,p,p,p,p,p,p,p,p,p,p,p,p,p,p,p,p,p,p,p,p,p,p,p,p,p,p,p,p,p,p,p,p
p,p,p,p,p,p,p,p,p,p,p,p,p,p,p,p,p,p,p,p,p,p,p,p,p,p,p,p,p,p,p,p,p,p,p,p,p,p,p,p,p,p,p,p,p
p,p,p,p,p,p,p,p,p,p,p,p,p,p,p,p,p,p,p,p,p,p,p,p,p,p,p,p,p,p,p,p,p,p,p,p,p,p,p,p,p,p,p,p,p
p,p,p,p,p,p,p,p,p,p,p,p,p,p,p,p,p,p,p,p,p,p,p,p,p,p,p,p,p,p,p,p,p,p,p,p,p,p,p,p,p,p,p,p,p
p,p,p,p,p,p,p,p,p,p,p,p,p,p,p,p,p,p,p,p,p,p,p,p,p,p,p,p,p,p,p,p,p,p,p,p,p,p,p,p,p,p,p,p,p
p,p,p,p,p,p,p,p,p,p,p,p,p,p,p,p,p,p,p,p,p,p,p,p,p,p,p,p,p,p,p,p,p,p,p,p,p,p,p,p,p,p,p,p,p
p,p,p,p,p,p,p,p,p,p,p,p,p,p,p,p,p,p,p,p,p,p,p,p,p,p,p,p,p,p,p,p,p,p,p,p,p,p,p,p,p,p,p,p,p
p,p,p,p,p,p,p,p,p,p,p,p,p,p,p,p,p,p,p,p,p,p,p,p,p,p,p,p,p,p,p,p,p,p,p,p,p,p,p,p,p,p,p,p,p
p,p,p,p,p,p,p,p,p,p,p,p,p,p,p,p,p,p,p,p,p,p,p,p,p,p,p,p,p,p,p,p,p,p,p,p,p,p,p,p,p,p,p,p,p
p,p,p,p,p,p,p,p,p,p,p,p,p,p,p,p,p,p,p,p,p,p,p,p,p,p,p,p,p,p,p,p,p,p,p,p,p,p,p,p,p,p,p,p,p
p,p,p,p,p,p,p,p,p,p,p,p,p,p,p,p,p,p,p,p,p,p,p,p,p,p,p,p,p,p,p,p,p,p,p,p,p,p,p,p,p,p,p,p,p
p,p,p,p,p,p,p,p,p,p,p,p,p,p,p,p,p,p,p,p,p,p,p,p,p,p,p,p,p,p,p,p,p,p,p,p,p,p,p,p,p,p,p,p,p
p,p,p,p,p,p,p,p,p,p,p,p,p,p,p,p,p,p,p,p,p,p,p,p,p,p,p,p,p,p,p,p,p,p,p,p,p,p,p,p,p,p,p,p,p
p,p,p,p,p,p,p,p,p,p,p,p,p,p,p,p,p,p,p,p,p,p,p,p,p,p,p,p,p,p,p,p,p,p,p,p,p,p,p,p,p,p,p,p,p
p,p,p,p,p,p,p,p,p,p,p,p,p,p,p,p,p,p,p,p,p,p,p,p,p,p,p,p,p,p,p,p,p,p,p,p,p,p,p,p,p,p,p,p,p
p,p,p,p,p,p,p,p,p,p,p,p,p,p,p,p,p,p,p,p,p,p,p,p,p,p,p,p,p,p,p,p,p,p,p,p,p,p,p,p,p,p,p,p,p
p,p,p,p,p,p,p,p,p,p,p,p,p,p,p,p,p,p,p,p,p,p,p,p,p,p,p,p,p,p,p,p,p,p,p,p,p,p,p,p,p,p,p,p,p
p,p,p,p,p,p,p,p,p,p,p,p,p,p,p,p,p,p,p,p,p,p,p,p,p,p,p,p,p,p,p,p,p,p,p,p,p,p,p,p,p,p,p,p,p
p,p,p,p,p,p,p,p,p,p,p,p,p,p,p,p,p,p,p,p,p,p,p,p,p,p,p,p,p,p,p,p,p,p,p,p,p,p,p,p,p,p,p,p,p
p,p,p,p,p,p,p,p,p,p,p,p,p,p,p,p,p,p,p,p,p,p,p,p,p,p,p,p,p,p,p,p,p,p,p,p,p,p,p,p,p,p,p,p,p
#dig label(surface_channel) start(23; 25) hidden() use the meta blueprints for normal application


,,,,,,`,`,`,`,`,`,`,`,`,`,`,`,`,`,`,`,`,`,`,`,`,`,`,`,`,`,`,`,`,`,`,`,`
,,,,,,`,,,,,,,,,,,,,,,,,,,,,,,,,,,,,,,,`
,,,,,,`,,,,,,,,,,,,,,,,,,,,,,,,,,,,,,,,`
,,,,,,`,,,,,,,,,,,,,,,,,,,,,,,,,,,,,,,,`
,,,,,,`,,,,,,,,,,,,,,,,,,,,,,,,,,,,,,,,`
,,,,,,`,,,,,,,,,,,,,,,,,,,,,,,,,,,,,,,,`
,,,,,,`,,,,,,,,,,,,,,,,,,,,,,,,,,,,,,,,`
,,,,,,`,,,,,,,,,,,,,,,,,,,,,,,,,,,,,,,,`
,,,,,,`,,,,,,,,,,,,,,,,,,,,,,,,,,,,,,,,`
,,,,,,`,,,,,,,,,,,,,,,,,,,,,,,,,,,,,,,,`
,,,,,,`,,,,,,,,,,,,,,,,,,,,,,,,,,,,,,,,`
,,,,,,`,,,,,,,,,,,,,,,,,,,,,,,,,,,,,,,,`
,,,,,,`,,,,,,,,,,,,,,,,,,,,,,,,,,,,,,,,`
,,,,,,`,,,,,,,,,,,,,,,,,,,,,,,,,,,,,,,,`
,,,,,,`,,,,,,,,,,,,,,,,,,,,,,,,,,,,,,,,`
,,,,,,`,,,,,,,,,,,,,,,,,,,,,,,,,,,,,,,,`
,,,,,,`,,,,,,,,,,,,,,,,,,,,,,,,,,,,,,,,`
,,,,,,`,,,,,,,,,,,,,,,,,,,,,,,,,,,,,,,,`
,,,,,,`,,,,,,,,,,,,,,,,,,,,h,,,,h,,,,,,,,`
,,,,,,`,`,`,`,`,`,`,`,`,`,`,`,`,`,`,,`,,`,`,`,`,`,`,`,`,`,`,`,`,`,`,`
,,,,,,`,,,,,,,,,,,,,`,,,,,,`,,,,,,,,,,,,,`
,,,,,,`,,,,,,,,,,,,,,,j,j,j,,,,,,,,,,,,,,,`
,,,,,,`,,,,,,,,,,,,,`,,j,j,j,,`,,,,,,,,,,,,,`
,,,,,,`,,,,,,,,,,,,,,,j,j,j,,,,,,,,,,,,,,,`
,,,,,,`,,,,,,,,,,,,,`,,,,,,`,,,,,,,,,,,,,`
,,,,,,`,`,`,`,`,`,`,`,`,`,,`,`,`,`,,`,,`,h,h,,`,`,`,h,`,`,`,`,`,`,`
,,,,,,`,`,`,`,`,`,`,`,`,`,,`,`,,,,,,,h,h,,h,`,`,h,`,h,`,`,`,`,`
,,,,,,`,,,,,,,,,,,,`,,,,,,,h,h,,,,,h,,`,,,,,`
,,,,,,`,,,,,,,,,,,,`,,,,,,,,`,,,,,,,`,,,,,`
,,,,,,`,,,,,,,,,,,,,,,,,,,h,h,h,h,h,h,h,h,h,h,h,h,h,h
,,,,,,`,,,,,,,,,,,,,,,,,,,h,h,h,h,h,h,h,h,h,h,h,h,h,h
,,,,,,`,,,,,,,,,,,,,,,,,,,h,h,h,h,h,h,h,h,h,h,h,h,h,h
,,,,,,`,,,,,,,,,,,,`,,,,,,,h,h,h,h,h,h,h,h,h,h,h,h,h,h
,,,,,,`,,,,,,,,,,,,`,,,,,,,h,h,h,h,h,h,h,h,h,h,h,h,h,h
,,,,,,`,`,`,`,`,`,`,`,`,`,`,`,`,,,h,h,h,,h,h,h,h,h,h,h,h,h,h,h,h,h,h
,,,,,,`,`,`,`,`,`,`,`,`,`,`,`,`,,,h,h,h,,h,h,h,h,h,h,h,h,h,h,h,h,h,h
,,,,,,,,,,,,,,,,,`,`,,,h,h,h,,h,h,h,h,h,h,h,h,h,h,h,h,h,h
,,,,,,,,,,,,,,,,,`,`,,,,,,,h,h,h,h,h,h,h,h,h,h,h,h,h,h
,,,,,,,,,,,,,,,,,`,`,,,,h,,,h,h,h,h,h,h,h,h,h,h,h,h,h,h
,,,,,,`,`,`,`,`,`,`,`,`,`,`,`,`,,,,,,,,`
,,,,,,,,,,,,,,,,,,`,,,,,,,,`
,,,,,,,,,,,,,,,,,,`,`,`,`,`,`,`,`,`
,,,,,,,,,,,,,,,,,,,`,`,`,`,`,`,`
,,,,,,,,,,,,,,,,,,,`,`,`,`,`,`,`



#build label(surface_floors) start(23; 25) hidden() use the meta blueprints for normal application


,,,,,,`,`,`,`,`,`,`,`,`,`,`,`,`,`,`,`,`,`,`,`,`,`,`,`,`,`,`,`,`,`,`,`,`
,,,,,,`,,,,,,,,,,,,,,,,,,,,,,,,,,,,,,,,`
,,,,,,`,,,,,,,,,,,,,,,,,,,,,,,,,,,,,,,,`
,,,,,,`,,,,,,,,,,,,,,,,,,,,,,,,,,,,,,,,`
,,,,,,`,,,,,,,,,,,,,,,,,,,,,,,,,,,,,,,,`
,,,,,,`,,,,,,,,,,,,,,,,,,,,,,,,,,,,,,,,`
,,,,,,`,,,,,,,,,,,,,,,,,,,,,,,,,,,,,,,,`
,,,,,,`,,,,,,,,,,,,,,,,,,,,,,,,,,,,,,,,`
,,,,,,`,,,,,,,,,,,,,,,,,,,,,,,,,,,,,,,,`
,,,,,,`,,,,,,,,,,,,,,,,,,,,,,,,,,,,,,,,`
,,,,,,`,,,,,,,,,,,,,,,,,,,,,,,,,,,,,,,,`
,,,,,,`,,,,,,,,,,,,,,,,,,,,,,,,,,,,,,,,`
,,,,,,`,,,,,,,,,,,,,,,,,,,,,,,,,,,,,,,,`
,,,,,,`,,,,,,,,,,,,,,,,,,,,,,,,,,,,,,,,`
,,,,,,`,,,,,,,,,,,,,,,,,,,,,,,,,,,,,,,,`
,,,,,,`,,,,,,,,,,,,,,,,,,,,,,,,,,,,,,,,`
,,,,,,`,,,,,,,,,,,,,,,,,,,,,,,,,,,,,,,,`
,,,,,,`,,,,,,,,,,,,,,,,,,,,,,,,,,,,,,,,`
,,,,,,`,,,,,,,,,,,,,,,,,,,,Cf,,,,Cf,,,,,,,,`
,,,,,,`,`,`,`,`,`,`,`,`,`,`,`,`,`,`,Cf,`,Cf,`,`,`,`,`,`,`,`,`,`,`,`,`,`,`
,,,,,,`,,,,,,,,,,,,,`,Cf,Cf,Cf,Cf,Cf,`,,,,,,,,,,,,,`
,,,,,,`,,,,,,,,,,,,,Cf,Cf,`,`,`,Cf,Cf,,,,,,,,,,,,,`
,,,,,,`,,,,,,,,,,,,,`,Cf,`,`,`,Cf,`,,,,,,,,,,,,,`
,,,,,,`,,,,,,,,,,,,,Cf,Cf,`,`,`,Cf,Cf,,,,,,,,,,,,,`
,,,,,,`,,,,,,,,,,,,,`,Cf,Cf,Cf,Cf,Cf,`,,,,,,,,,,,,,`
,,,,,,`,`,`,`,`,`,`,`,`,`,Cf,`,`,`,`,Cf,`,Cf,`,`,`,`,Cf,`,`,`,`,`,`,`,`,`,`
,,,,,,`,`,`,`,`,`,`,`,`,`,Cf,`,`,Cf,Cf,Cf,Cf,Cf,Cf,Cf,`,`,Cf,`,`,`,`,`,`,`,`,`,`
,,,,,,`,Cf,Cf,Cf,Cf,Cf,Cf,Cf,Cf,Cf,Cf,Cf,`,Cf,Cf,Cf,Cf,Cf,Cf,Cf,`,Cf,Cf,Cf,Cf,Cf,Cf,Cf,Cf,Cf,Cf,Cf,`
,,,,,,`,Cf,Cf,Cf,Cf,Cf,Cf,Cf,Cf,Cf,Cf,Cf,`,Cf,Cf,Cf,Cf,Cf,Cf,Cf,`,Cf,Cf,Cf,Cf,Cf,Cf,Cf,Cf,Cf,Cf,Cf,`
,,,,,,`,Cf,Cf,Cf,Cf,Cf,Cf,Cf,Cf,Cf,Cf,Cf,Cf,Cf,Cf,Cf,Cf,Cf,Cf,Cf,Cf,Cf,Cf,Cf,Cf,Cf,Cf,Cf,Cf,Cf,Cf,Cf,`
,,,,,,`,Cf,Cf,Cf,Cf,Cf,Cf,Cf,Cf,Cf,Cf,Cf,Cf,Cf,Cf,Cf,Cf,Cf,Cf,Cf,Cf,Cf,Cf,Cf,Cf,Cf,Cf,Cf,Cf,Cf,Cf,Cf,`
,,,,,,`,Cf,Cf,Cf,Cf,Cf,Cf,Cf,Cf,Cf,Cf,Cf,Cf,Cf,Cf,Cf,Cf,Cf,Cf,Cf,Cf,Cf,Cf,Cf,Cf,Cf,Cf,Cf,Cf,Cf,Cf,Cf,`
,,,,,,`,Cf,Cf,Cf,Cf,Cf,Cf,Cf,Cf,Cf,Cf,Cf,`,Cf,Cf,Cf,Cf,Cf,Cf,Cf,`,Cf,Cf,Cf,Cf,Cf,Cf,Cf,Cf,Cf,Cf,Cf,`
,,,,,,`,Cf,Cf,Cf,Cf,Cf,Cf,Cf,Cf,Cf,Cf,Cf,`,Cf,Cf,Cf,Cf,Cf,Cf,Cf,`,Cf,Cf,Cf,Cf,Cf,Cf,Cf,Cf,Cf,Cf,Cf,`
,,,,,,`,`,`,`,`,`,`,`,`,`,`,`,`,Cf,Cf,Cf,Cf,Cf,Cf,Cf,`,`,`,`,`,`,`,`,`,`,`,`,`
,,,,,,`,`,`,`,`,`,`,`,`,`,`,`,`,Cf,Cf,Cf,Cf,Cf,Cf,Cf,`,`,`,`,`,`,`,`,`,`,`,`,`
,,,,,,Cf,Cf,Cf,Cf,Cf,Cf,Cf,Cf,Cf,Cf,Cf,Cf,Cf,Cf,Cf,Cf,Cf,Cf,Cf,Cf,Cf,Cf,Cf,Cf,Cf,Cf,Cf,Cf,Cf,Cf,Cf,Cf,Cf
,,,,,,Cf,Cf,Cf,Cf,Cf,Cf,Cf,Cf,Cf,Cf,Cf,Cf,Cf,Cf,Cf,Cf,Cf,Cf,Cf,Cf,Cf,Cf,Cf,Cf,Cf,Cf,Cf,Cf,Cf,Cf,Cf,Cf,Cf
,,,,,,Cf,Cf,Cf,Cf,Cf,Cf,Cf,Cf,Cf,Cf,Cf,Cf,Cf,Cf,Cf,Cf,Cf,Cf,Cf,Cf,Cf,Cf,Cf,Cf,Cf,Cf,Cf,Cf,Cf,Cf,Cf,Cf,Cf
,,,,,,`,`,`,`,`,`,`,`,`,`,`,`,`,Cf,Cf,Cf,Cf,Cf,Cf,Cf,`,`,`,`,`,`,`,`,`,`,`,`,`
,,,,,,,,,,,,,,,,,,`,Cf,Cf,Cf,Cf,Cf,Cf,Cf,`
,,,,,,,,,,,,,,,,,,`,Cf,Cf,Cf,Cf,Cf,Cf,Cf,`





#build label(surface_walls) start(23; 25) hidden() use the meta blueprints for normal application


,,,,,,Cw,Cw,Cw,Cw,Cw,Cw,Cw,Cw,Cw,Cw,Cw,Cw,Cw,Cw,Cw,Cw,Cw,Cw,Cw,Cw,Cw,Cw,Cw,Cw,Cw,Cw,Cw,Cw,Cw,Cw,Cw,Cw,Cw
,,,,,,Cw,,,,,,,,,,,,,,,,,,,,,,,,,,,,,,,,Cw
,,,,,,Cw,,,,,,,,,,,,,,,,,,,,,,,,,,,,,,,,Cw
,,,,,,Cw,,,,,,,,,,,,,,,,,,,,,,,,,,,,,,,,Cw
,,,,,,Cw,,,,,,,,,,,,,,,,,,,,,,,,,,,,,,,,Cw
,,,,,,Cw,,,,,,,,,,,,,,,,,,,,,,,,,,,,,,,,Cw
,,,,,,Cw,,,,,,,,,,,,,,,,,,,,,,,,,,,,,,,,Cw
,,,,,,Cw,,,,,,,,,,,,,,,,,,,,,,,,,,,,,,,,Cw
,,,,,,Cw,,,,,,,,,,,,,,,,,,,,,,,,,,,,,,,,Cw
,,,,,,Cw,,,,,,,,,,,,,,,,,,,,,,,,,,,,,,,,Cw
,,,,,,Cw,,,,,,,,,,,,,,,,,,,,,,,,,,,,,,,,Cw
,,,,,,Cw,,,,,,,,,,,,,,,,,,,,,,,,,,,,,,,,Cw
,,,,,,Cw,,,,,,,,,,,,,,,,,,,,,,,,,,,,,,,,Cw
,,,,,,Cw,,,,,,,,,,,,,,,,,,,,,,,,,,,,,,,,Cw
,,,,,,Cw,,,,,,,,,,,,,,,,,,,,,,,,,,,,,,,,Cw
,,,,,,Cw,,,,,,,,,,,,,,,,,,,,,,,,,,,,,,,,Cw
,,,,,,Cw,,,,,,,,,,,,,,,,,,,,,,,,,,,,,,,,Cw
,,,,,,Cw,,,,,,,,,,,,,,,,,,,,,,,,,,,,,,,,Cw
,,,,,,Cw,,,,,,,,,,,,,,,,,,,,,,,,,,,,,,,,Cw
,,,,,,Cw,Cw,Cw,Cw,Cw,Cw,Cw,Cw,Cw,Cw,Cw,Cw,Cw,Cw,Cw,,Cw,,Cw,Cw,Cw,Cw,Cw,Cw,Cw,Cw,Cw,Cw,Cw,Cw,Cw,Cw,Cw
,,,,,,Cw,,,,,,,,,,,,,Cw,,,,,,Cw,,,,,,,,,,,,,Cw
,,,,,,Cw,,,,,,,,,,,,,,,`,`,`,,,,,,,,,,,,,,,Cw
,,,,,,Cw,,,,,,,,,,,,,Cw,,`,`,`,,Cw,,,,,,,,,,,,,Cw
,,,,,,Cw,,,,,,,,,,,,,,,`,`,`,,,,,,,,,,,,,,,Cw
,,,,,,Cw,,,,,,,,,,,,,Cw,,,,,,Cw,,,,,,,,,,,,,Cw
,,,,,,Cw,Cw,Cw,Cw,Cw,Cw,Cw,Cw,Cw,Cw,,Cw,Cw,Cw,Cw,,Cw,,Cw,Cw,Cw,Cw,,Cw,Cw,Cw,Cw,Cw,Cw,Cw,Cw,Cw,Cw
,,,,,,Cw,Cw,Cw,Cw,Cw,Cw,Cw,Cw,Cw,Cw,,Cw,Cw,,`,`,`,`,`,,Cw,Cw,,Cw,Cw,Cw,Cw,Cw,Cw,Cw,Cw,Cw,Cw
,,,,,,Cw,,,,,,,,,,,,Cw,,`,`,`,`,`,,Cw,,,,,,,,,,,,Cw
,,,,,,Cw,,,,,,,,,,,,Cw,,`,`,`,`,`,,Cw,,,,,,,,,,,,Cw
,,,,,,Cw,,,,,,,,,,,,`,`,,,,,,`,`,,,,,,,,,,,,Cw
,,,,,,Cw,,,,,,,,,,,,`,`,,,,,,`,`,,,,,,,,,,,,Cw
,,,,,,Cw,,,,,,,,,,,,`,`,,,,,,`,`,,,,,,,,,,,,Cw
,,,,,,Cw,,,,,,,,,,,,Cw,,,,,,,,Cw,,,,,,,,,,,,Cw
,,,,,,Cw,,,,,,,,,,,,Cw,,,,,,,,Cw,,,,,,,,,,,,Cw
,,,,,,Cw,Cw,Cw,Cw,Cw,Cw,Cw,Cw,Cw,Cw,Cw,Cw,Cw,,,,,,,,Cw,Cw,Cw,Cw,Cw,Cw,Cw,Cw,Cw,Cw,Cw,Cw,Cw
,,,,,,Cw,Cw,Cw,Cw,Cw,Cw,Cw,Cw,Cw,Cw,Cw,Cw,Cw,,,,,,,,Cw,Cw,Cw,Cw,Cw,Cw,Cw,Cw,Cw,Cw,Cw,Cw,Cw
,,,,,,`,`,,,,,,,,,,`,`,,,,,,,,`,`,,,,,,,,,,`,`
,,,,,,`,`,,,,,,,,,,`,`,,,,,,,,`,`,,,,,,,,,,`,`
,,,,,,`,`,,,,,,,,,,`,`,,,,,,,,`,`,,,,,,,,,,`,`
,,,,,,Cw,Cw,Cw,Cw,Cw,Cw,Cw,Cw,Cw,Cw,Cw,Cw,Cw,,,,,,,,Cw,Cw,Cw,Cw,Cw,Cw,Cw,Cw,Cw,Cw,Cw,Cw,Cw
,,,,,,,,,,,,,,,,,,Cw,,,,,,,,Cw
,,,,,,,,,,,,,,,,,,Cw,`,`,`,`,`,`,`,Cw
,,,,,,,,,,,,,,,,,,,`,`,`,`,`,`,`
,,,,,,,,,,,,,,,,,,,`,`,`,`,`,`,`



#build label(surface_gates) start(23; 25) hidden() use the meta blueprints for normal application


,,,,,,`,`,`,`,`,`,`,`,`,`,`,`,`,`,`,`,`,`,`,`,`,`,`,`,`,`,`,`,`,`,`,`,`
,,,,,,`,,,,,,,,,,,,,,,,,,,,,,,,,,,,,,,,`
,,,,,,`,,,,,,,,,,,,,,,,,,,,,,,,,,,,,,,,`
,,,,,,`,,,,,,,,,,,,,,,,,,,,,,,,,,,,,,,,`
,,,,,,`,,,,,,,,,,,,,,,,,,,,,,,,,,,,,,,,`
,,,,,,`,,,,,,,,,,,,,,,,,,,,,,,,,,,,,,,,`
,,,,,,`,,,,,,,,,,,,,,,,,,,,,,,,,,,,,,,,`
,,,,,,`,,,,,,,,,,,,,,,,,,,,,,,,,,,,,,,,`
,,,,,,`,,,,,,,,,,,,,,,,,,,,,,,,,,,,,,,,`
,,,,,,`,,,,,,,,,,,,,,,,,,,,,,,,,,,,,,,,`
,,,,,,`,,,,,,,,,,,,,,,,,,,,,,,,,,,,,,,,`
,,,,,,`,,,,,,,,,,,,,,,,,,,,,,,,,,,,,,,,`
,,,,,,`,,,,,,,,,,,,,,,,,,,,,,,,,,,,,,,,`
,,,,,,`,,,,,,,,,,,,,,,,,,,,,,,,,,,,,,,,`
,,,,,,`,,,,,,,,,,,,,,,,,,,,,,,,,,,,,,,,`
,,,,,,`,,,,,,,,,,,,,,,,,,,,,,,,,,,,,,,,`
,,,,,,`,,,,,,,,,,,,,,,,,,,,,,,,,,,,,,,,`
,,,,,,`,,,,,,,,,,,,,,,,,,,,,,,,,,,,,,,,`
,,,,,,`,,,,,,,,,,,,,,,,,,,,,,,,,,,,,,,,`
,,,,,,`,`,`,`,`,`,`,`,`,`,`,`,`,`,`,,`,,`,`,`,`,`,`,`,`,`,`,`,`,`,`,`
,,,,,,`,,,,,,,,,,,,,`,,,,,,`,,,,,,,,,,,,,`
,,,,,,`,,,,,,,,,,,,,,,`,`,`,,,,,,,,,,,,,,,`
,,,,,,`,,,,,,,,,,,,,`,,`,`,`,,`,,,,,,,,,,,,,`
,,,,,,`,,,,,,,,,,,,,,,`,`,`,,,,,,,,,,,,,,,`
,,,,,,`,,,,,,,,,,,,,`,,,,,,`,,,,,,,,,,,,,`
,,,,,,`,`,`,`,`,`,`,`,`,`,,`,`,`,`,,`,,`,`,`,`,,`,`,`,`,`,`,`,`,`,`
,,,,,,`,`,`,`,`,`,`,`,`,`,,`,`,,gw,gw,gw,gw,gw,,`,`,,`,`,`,`,`,`,`,`,`,`
,,,,,,`,,,,,,,,,,,,`,,gw,gw,gw,gw,gw,,`,,,,,,,,,,,,`
,,,,,,`,,,,,,,,,,,,`,,gw,gw,gw,gw,gw,,`,,,,,,,,,,,,`
,,,,,,`,,,,,,,,,,,,ga,ga,,,,,,gd,gd,,,,,,,,,,,,`
,,,,,,`,,,,,,,,,,,,ga,ga,,,,,,gd,gd,,,,,,,,,,,,`
,,,,,,`,,,,,,,,,,,,ga,ga,,,,,,gd,gd,,,,,,,,,,,,`
,,,,,,`,,,,,,,,,,,,`,,,,,,,,`,,,,,,,,,,,,`
,,,,,,`,,,,,,,,,,,,`,,,,,,,,`,,,,,,,,,,,,`
,,,,,,`,`,`,`,`,`,`,`,`,`,`,`,`,,,,,,,,`,`,`,`,`,`,`,`,`,`,`,`,`
,,,,,,`,`,`,`,`,`,`,`,`,`,`,`,`,,,,,,,,`,`,`,`,`,`,`,`,`,`,`,`,`
,,,,,,ga,ga,,,,,,,,,,gd,gd,,,,,,,,ga,ga,,,,,,,,,,gd,gd
,,,,,,ga,ga,,,,,,,,,,gd,gd,,,,,,,,ga,ga,,,,,,,,,,gd,gd
,,,,,,ga,ga,,,,,,,,,,gd,gd,,,,,,,,ga,ga,,,,,,,,,,gd,gd
,,,,,,`,`,`,`,`,`,`,`,`,`,`,`,`,,,,,,,,`,`,`,`,`,`,`,`,`,`,`,`,`
,,,,,,,,,,,,,,,,,,`,,,,,,,,`
,,,,,,,,,,,,,,,,,,`,gw,gw,gw,gw,gw,gw,gw,`
,,,,,,,,,,,,,,,,,,,gw,gw,gw,gw,gw,gw,gw
,,,,,,,,,,,,,,,,,,,gw,gw,gw,gw,gw,gw,gw



"#build label(surface_buildings) start(23; 25) hidden() message(Remember to connect the levers to the gates once they are built. Also, you can deconstruct the temporary trade depot in the pasture now.) use the meta blueprints for normal application"


,,,,,,`,`,`,`,`,`,`,`,`,`,`,`,`,`,`,`,`,`,`,`,`,`,`,`,`,`,`,`,`,`,`,`,`
,,,,,,`,,,,,,,,,,,,,,,,,,,,,,,,,,,,,,,,`
,,,,,,`,,,,,,,,,,,,,,,,,,,,,,,,,,,,,,,,`
,,,,,,`,,,,,,,,,,,,,,,,,,,,,,,,,,,,,,,,`
,,,,,,`,,,,,,,,,,,,,,,,,,,,,,,,,,,,,,,,`
,,,,,,`,,,,,,,,,,,,,,,,,,,,,,,,,,,,,,,,`
,,,,,,`,,,,,,,,,,,,,,,,,,,,,,,,,,,,,,,,`
,,,,,,`,,,,,,,,,,,,,,,,,,,,,,,,,,,,,,,,`
,,,,,,`,,,,,,,,,,,,,,,,,,,,,,,,,,,,,,,,`
,,,,,,`,,,,,,,,,,,,,,,,,,,,,,,,,,,,,,,,`
,,,,,,`,,,,,,,,,,,,,,,,,,,,,,,,,,,,,,,,`
,,,,,,`,,,,,,,,,,,,,,,,,,,,,,,,,,,,,,,,`
,,,,,,`,,,,,,,,,,,,,,,,,,,,,,,,,,,,,,,,`
,,,,,,`,~h,~h,,,,,,,,,,,,,,,,,,,,,,,,,,,,~h,~h,`
,,,,,,`,~h,~h,,,,,,,,,,,,,,,,,,,,,,,,,,,,~h,~h,`
,,,,,,`,~h,~h,,,,,,,,,,,,,,,,,,,,,,,,,,,,~h,~h,`
,,,,,,`,,,,,,,,,,,,,,,,,,,,,,,,,,,,,,,,`
,,,,,,`,,,,,,,,,,,,,,,,,,,,,,,,,,,,,,,,`
,,,,,,`,N,N,N,N,N,N,N,N,N,N,N,N,,,,,,,,N,N,N,N,N,N,N,N,N,N,N,N,`
,,,,,,`,`,`,`,`,`,`,`,`,`,`,`,`,`,`,d,`,d,`,`,`,`,`,`,`,`,`,`,`,`,`,`,`
,,,,,,`,,,,,,,,,,,,,`,Tl,,Tl,,Tl,`,,,,,,,,,,,,,`
,,,,,,`,,,,,,,,,,,,,d,,`,`,`,,d,,,,,,,,,,,,,`
,,,,,,`,,,,,,,,,,,,,`,,`,`,`,,`,,,,,,,,,,,,,`
,,,,,,`,,,,,,,,,,,,,d,,`,`,`,,d,,,,,,,,,,,,,`
,,,,,,`,,,,,,,,,,,,,`,Tl,Tl,Tl,Tl,Tl,`,,,,,,,,,,,,,`
,,,,,,`,`,`,`,`,`,`,`,`,`,d,`,`,`,`,d,`,d,`,`,`,`,d,`,`,`,`,`,`,`,`,`,`
,,,,,,`,`,`,`,`,`,`,`,`,`,d,`,`,,,,,,,,`,`,d,`,`,`,`,`,`,`,`,`,`
,,,,,,`,,,,,,,,,,,,`,,,,,,,,`,,,,,,,,,,,,`
,,,,,,`,,,,,,,,,,,,`,,,,,,,,`,,,,,,,,,,,,`
,,,,,,`,,,,,,,,,,,,,,,,,,,,,,,,,,,,,,,,`
,,,,,,`,,,,,,,,,D,,,,,,,,,,,,,,,,,,,,,,,`
,,,,,,`,,,,,,,,,,,,,,,,,,,,,,,,,,,,,,,,`
,,,,,,`,,,,,,,,,,,,`,,,,,,,,`,,,,,,,,,,,,`
,,,,,,`,,,,,,,,,,,,`,,,,,,,,`,,,,,,,,,,,,`
,,,,,,`,`,`,`,`,`,`,`,`,`,`,`,`,,,,,,,,`,`,`,`,`,`,`,`,`,`,`,`,`
,,,,,,`,`,`,`,`,`,`,`,`,`,`,`,`,,,,,,,,`,`,`,`,`,`,`,`,`,`,`,`,`
,,,,,,,,Tc,Tc,Tc,Tc,Tc,Tc,Tc,Tc,Tc,,,,,,,,,,,,Tc,Tc,Tc,Tc,Tc,Tc,Tc,Tc,Tc
,,,,,,,,Tc,Tc,Tc,Tc,Tc,Tc,Tc,Tc,Tc,,,,,,,,,,,,Tc,Tc,Tc,Tc,Tc,Tc,Tc,Tc,Tc
,,,,,,,,Tc,Tc,Tc,Tc,Tc,Tc,Tc,Tc,Tc,,,,,,,,,,,,Tc,Tc,Tc,Tc,Tc,Tc,Tc,Tc,Tc
,,,,,,`,`,`,`,`,`,`,`,`,`,`,`,`,,,,,,,,`,`,`,`,`,`,`,`,`,`,`,`,`
,,,,,,,,,,,,,,,,,,`,,,,,,,,`
,,,,,,,,,,,,,,,,Tc,Tc,`,,,,,,,,`,Tc,Tc
,,,,,,,,,,,,,,,,Tc,Tc,,,,,,,,,,Tc,Tc
,,,,,,,,,,,,,,,,Tc,Tc,,,,,,,,,,Tc,Tc
,,,,,,,,,,,,,,,,Tc,Tc,,,,,,,,,,Tc,Tc


#query label(surface_query_buildings) start(23; 25) hidden() use the meta blueprints for normal application


,,,,,,`,`,`,`,`,`,`,`,`,`,`,`,`,`,`,`,`,`,`,`,`,`,`,`,`,`,`,`,`,`,`,`,`
,,,,,,`,,,,,,,,,,,,,,,,,,,,,,,,,,,,,,,,`
,,,,,,`,,,,,,,,,,,,,,,,,,,,,,,,,,,,,,,,`
,,,,,,`,,,,,,,,,,,,,,,,,,,,,,,,,,,,,,,,`
,,,,,,`,,,,,,,,,,,,,,,,,,,,,,,,,,,,,,,,`
,,,,,,`,,,,,,,,,,,,,,,,,,,,,,,,,,,,,,,,`
,,,,,,`,,,,,,,,,,,,,,,,,,,,,,,,,,,,,,,,`
,,,,,,`,,,,,,,,,,,,,,,,,,,,,,,,,,,,,,,,`
,,,,,,`,,,,,,,,,,,,,,,,,,,,,,,,,,,,,,,,`
,,,,,,`,,,,,,,,,,,,,,,,,,,,,,,,,,,,,,,,`
,,,,,,`,,,,,,,,,,,,,,,,,,,,,,,,,,,,,,,,`
,,,,,,`,,,,,,,,,,,,,,,,,,,,,,,,,,,,,,,,`
,,,,,,`,,,,,,,,,,,,,,,,,,,,,,,,,,,,,,,,`
,,,,,,`,cg,cg,,,,,,,,,,,,,,,,,,,,,,,,,,,,cg,cg,`
,,,,,,`,c,c,,,,,,,,,,,,,,,,,,,,,,,,,,,,c,c,`
,,,,,,`,cg,cg,,,,,,,,,,,,,,,,,,,,,,,,,,,,cg,cg,`
,,,,,,`,,,,,,,,,,,,,,,,,,,,,,,,,,,,,,,,`
,,,,,,`,,,,,,,,,,,,,,,,,,,,,,,,,,,,,,,,`
,,,,,,`,,,,,,,,,,,,,,,,,,,,,,,,,,,,,,,,`
,,,,,,`,`,`,`,`,`,`,`,`,`,`,`,`,`,`,,`,,`,`,`,`,`,`,`,`,`,`,`,`,`,`,`
,,,,,,`,,,,,,,,,,,,,`,"{givename name=""trade depo gate""}",,"{givename name=""inner main gate""}",,"{givename name=""barracks gate""}",`,,,,,,,,,,,,,`
,,,,,,`,,,,,,,,,,,,,,,`,`,`,,,,,,,,,,,,,,,`
,,,,,,`,,,,,,,,,,,,,`,,`,`,`,,`,,,,,,,,,,,,,`
,,,,,,`,,,,,,,,,,,,,,,`,`,`,,,,,,,,,,,,,,,`
,,,,,,`,,,,,,,,,,,,,`,"{givename name=""left outer gate""}","{givename name=""left inner gate""}","{givename name=""outer main gate""}","{givename name=""right inner gate""}","{givename name=""right outer gate""}",`,,,,,,,,,,,,,`
,,,,,,`,`,`,`,`,`,`,`,`,`,,`,`,`,`,,`,,`,`,`,`,,`,`,`,`,`,`,`,`,`,`
,,,,,,`,`,`,`,`,`,`,`,`,`,,`,`,,,,,,,,`,`,,`,`,`,`,`,`,`,`,`,`
,,,,,,`,,,,,,,,,,,,`,,,,"{givename name=""inner main gate""}",,,,`,,,,,,,,,,,,`
,,,,,,`,,,,,,,,,,,,`,,,,,,,,`,,,,,,,,,,,,`
,,,,,,`,,,,,,,,,,,,,,,,,,,,,,,,,,,,,,,,`
,,,,,,`,,,,,,,,,,,,"{givename name=""trade depo gate""}",,,,,,,,"{givename name=""barracks gate""}",,,,,,,,,,,,`
,,,,,,`,,,,,,,,,,,,,,,,,,,,,,,,,,,,,,,,`
,,,,,,`,,,,,,,,,,,,`,,,,,,,,`,,,,,,,,,,,,`
,,,,,,`,,,,,,,,,,,,`,,,,,,,,`,,,,,,,,,,,,`
,,,,,,`,`,`,`,`,`,`,`,`,`,`,`,`,,,,,,,,`,`,`,`,`,`,`,`,`,`,`,`,`
,,,,,,`,`,`,`,`,`,`,`,`,`,`,`,`,,,,,,,,`,`,`,`,`,`,`,`,`,`,`,`,`

,,,,,,"{givename name=""left outer gate""}",,,,,,,,,,,,"{givename name=""left inner gate""}",,,,,,,,"{givename name=""right inner gate""}",,,,,,,,,,,,"{givename name=""right outer gate""}"

,,,,,,`,`,`,`,`,`,`,`,`,`,`,`,`,,,,,,,,`,`,`,`,`,`,`,`,`,`,`,`,`
,,,,,,,,,,,,,,,,,,`,,,,,,,,`
,,,,,,,,,,,,,,,,,,`,,,,,,,,`
,,,,,,,,,,,,,,,,,,,,,,"{givename name=""outer main gate""}"




#build label(surface_scaffolding) start(23; 25) hidden() use the meta blueprints for normal application


,,,,,,`,`,`,`,`,`,`,`,`,`,`,`,`,`,`,`,`,`,`,`,`,`,`,`,`,`,`,`,`,`,`,`,`
,,,,,,`,,,,,,,,,,,,,,,,,,,,,,,,,,,,,,,,`
,,,,,,`,,,,,,,,,,,,,,,,,,,,,,,,,,,,,,,,`
,,,,,,`,,,,,,,,,,,,,,,,,,,,,,,,,,,,,,,,`
,,,,,,`,,,,,,,,,,,,,,,,,,,,,,,,,,,,,,,,`
,,,,,,`,,,,,,,,,,,,,,,,,,,,,,,,,,,,,,,,`
,,,,,,`,,,,,,,,,,,,,,,,,,,,,,,,,,,,,,,,`
,,,,,,`,,,,,,,,,,,,,,,,,,,,,,,,,,,,,,,,`
,,,,,,`,,,,,,,,,,,,,,,,,,,,,,,,,,,,,,,,`
,,,,,,`,,,,,,,,,,,,,,,,,,,,,,,,,,,,,,,,`
,,,,,,`,,,,,,,,,,,,,,,,,,,,,,,,,,,,,,,,`
,,,,,,`,,,,,,,,,,,,,,,,,,,,,,,,,,,,,,,,`
,,,,,,`,,,,,,,,,,,,,,,,,,,,,,,,,,,,,,,,`
,,,,,,`,,,,,,,,,,,,,,,,,,,,,,,,,,,,,,,,`
,,,,,,`,,,,,,,,,,,,,,,,,,,,,,,,,,,,,,,,`
,,,,,,`,,,,,,,,,,,,,,,,,,,,,,,,,,,,,,,,`
,,,,,,`,,,,,,,,,,,,,,,,,,,,,,,,,,,,,,,,`
,,,,,,`,,,,,,,,,,,,,,,,,,,,,,,,,,,,,,,,`
,,,,,,`,,,,,,,,,,,,,,,,,,,,,,,,,,,,,,,,`
,,,,,,`,`,`,`,`,`,`,`,`,`,`,`,`,`,`,,`,,`,`,`,`,`,`,`,`,`,`,`,`,`,`,`
,,,,,,`,,,,,,,,,,,,,`,,,,,,`,,,,,,,,,,,,,`
,,,,,,`,,,,,,,,,,,,,,,`,`,`,,,,,,,,,,,,,,,`
,,,,,,`,,,,,,,,,,,,,`,,`,`,`,,`,,,,,,,,,,,,,`
,,,,,,`,,,,,,,,,,,,,,,`,`,`,,,,,,,,,,,,,,,`
,,,,,,`,,,,,,,,,,,,,`,,,,,,`,,,,,,,,,,,,,`
,,,,,,`,`,`,`,`,`,`,`,`,`,,`,`,`,`,,`,,`,`,`,`,,`,`,`,`,`,`,`,`,`,`
,,,,,,`,`,`,`,`,`,`,`,`,`,,`,`,,,,,,,,`,`,,`,`,`,`,`,`,`,`,`,`
,,,,,,`,,,,,,,,,,,,`,,,,,,,,`,,,,,,,,,,,,`
,,,,,,`,,,,,,,,,,,,`,,,,,,,,`,,,,,,,,,,,,`
,,,,,,`,,,,,,,,,,,,,,,,,,,,,,,,,,,,,,,,`
,,,,,,`,,,,,,,,,,,,,,,,,,,,,,,,,,,,,,,,`
,,,,,,`,,,,,,,,,,,,,,,,,,,,,,,,,,,,,,,,`
,,,,,,`,,,,,,,,,,,,`,,,,,,,,`,,,,,,,,,,,,`
,,,,,,`,,,,,,,,,,,,`,,,,,,,,`,,,,,,,,,,,,`
,,,,,,`,`,`,`,`,`,`,`,`,`,`,`,`,,,,,,,,`,`,`,`,`,`,`,`,`,`,`,`,`
,,,,,,`,`,`,`,`,`,`,`,`,`,`,`,`,,,,,,,,`,`,`,`,`,`,`,`,`,`,`,`,`



,,,,,,`,`,`,`,`,`,`,`,`,`,`,`,`,,,,,,,,`,`,`,`,`,`,`,`,`,`,`,`,`
,,,,,,,,,,,,,,,,,Cu,`,,,,,,,,`
,,,,,,,,,,,,,,,,,,`,,,,,,,,`





#build label(surface_roof) start(23; 25) hidden() use the meta blueprints for normal application


,,,,,,`,`,`,`,`,`,`,`,`,`,`,`,`,`,`,`,`,`,`,`,`,`,`,`,`,`,`,`,`,`,`,`,`
,,,,,,`,,,,,,,,,,,,,,,,,,,,,,,,,,,,,,,,`
,,,,,,`,,,,,,,,,,,,,,,,,,,,,,,,,,,,,,,,`
,,,,,,`,,,,,,,,,,,,,,,,,,,,,,,,,,,,,,,,`
,,,,,,`,,,,,,,,,,,,,,,,,,,,,,,,,,,,,,,,`
,,,,,,`,,,,,,,,,,,,,,,,,,,,,,,,,,,,,,,,`
,,,,,,`,,,,,,,,,,,,,,,,,,,,,,,,,,,,,,,,`
,,,,,,`,,,,,,,,,,,,,,,,,,,,,,,,,,,,,,,,`
,,,,,,`,,,,,,,,,,,,,,,,,,,,,,,,,,,,,,,,`
,,,,,,`,,,,,,,,,,,,,,,,,,,,,,,,,,,,,,,,`
,,,,,,`,,,,,,,,,,,,,,,,,,,,,,,,,,,,,,,,`
,,,,,,`,,,,,,,,,,,,,,,,,,,,,,,,,,,,,,,,`
,,,,,,`,,,,,,,,,,,,,,,,,,,,,,,,,,,,,,,,`
,,,,,,`,,,,,,,,,,,,,,,,,,,,,,,,,,,,,,,,`
,,,,,,`,,,,,,,,,,,,,,,,,,,,,,,,,,,,,,,,`
,,,,,,`,,,,,,,,,,,,,,,,,,,,,,,,,,,,,,,,`
,,,,,,`,,,,,,,,,,,,,,,,,,,,,,,,,,,,,,,,`
,,,,,,`,,,,,,,,,,,,,,,,,,,,,,,,,,,,,,,,`
,,,,,,`,,,,,,,,,,,,,,,,,,,,,,,,,,,,,,,,`
,,,,,,`,`,`,`,`,`,`,`,`,`,`,`,`,`,`,,`,,`,`,`,`,`,`,`,`,`,`,`,`,`,`,`
,,,,,,`,,,,,,,,,,,,,`,,,,,,`,,,,,,,,,,,,,`
,,,,,,`,,,,,,,,,,,,,,,,,,,,,,,,,,,,,,,,`
,,,,,,`,,,,,,,,,,,,,`,,,,,,`,,,,,,,,,,,,,`
,,,,,,`,,,,,,,,,,,,,,,,,,,,,,,,,,,,,,,,`
,,,,,,`,,,,,,,,,,,,,`,,,,,,`,,,,,,,,,,,,,`
,,,,,,`,`,`,`,`,`,`,`,`,`,Cf,`,`,`,`,Cf,`,Cf,`,`,`,`,Cf,`,`,`,`,`,`,`,`,`,`
,,,,,,`,`,`,`,`,`,`,`,`,`,Cf,`,`,Cf,Cf,Cf,Cf,Cf,Cf,Cf,`,`,Cf,`,`,`,`,`,`,`,`,`,`
,,,,,,`,Cf,Cf,Cf,Cf,Cf,Cf,Cf,Cf,Cf,Cf,Cf,`,Cf,Cf,Cf,Cf,Cf,Cf,Cf,`,Cf,Cf,Cf,Cf,Cf,Cf,Cf,Cf,Cf,Cf,Cf,`
,,,,,,`,Cf,Cf,Cf,Cf,Cf,Cf,Cf,Cf,Cf,Cf,Cf,`,Cf,Cf,Cf,Cf,Cf,Cf,Cf,`,Cf,Cf,Cf,Cf,Cf,Cf,Cf,Cf,Cf,Cf,Cf,`
,,,,,,`,Cf,Cf,Cf,Cf,Cf,Cf,Cf,Cf,Cf,Cf,Cf,Cf,Cf,Cf,Cf,Cf,Cf,Cf,Cf,Cf,Cf,Cf,Cf,Cf,Cf,Cf,Cf,Cf,Cf,Cf,Cf,`
,,,,,,`,Cf,Cf,Cf,Cf,Cf,Cf,Cf,Cf,Cf,Cf,Cf,Cf,Cf,Cf,Cf,Cf,Cf,Cf,Cf,Cf,Cf,Cf,Cf,Cf,Cf,Cf,Cf,Cf,Cf,Cf,Cf,`
,,,,,,`,Cf,Cf,Cf,Cf,Cf,Cf,Cf,Cf,Cf,Cf,Cf,Cf,Cf,Cf,Cf,Cf,Cf,Cf,Cf,Cf,Cf,Cf,Cf,Cf,Cf,Cf,Cf,Cf,Cf,Cf,Cf,`
,,,,,,`,Cf,Cf,Cf,Cf,Cf,Cf,Cf,Cf,Cf,Cf,Cf,`,Cf,Cf,Cf,Cf,Cf,Cf,Cf,`,Cf,Cf,Cf,Cf,Cf,Cf,Cf,Cf,Cf,Cf,Cf,`
,,,,,,`,Cf,Cf,Cf,Cf,Cf,Cf,Cf,Cf,Cf,Cf,Cf,`,Cf,Cf,Cf,Cf,Cf,Cf,Cf,`,Cf,Cf,Cf,Cf,Cf,Cf,Cf,Cf,Cf,Cf,Cf,`
,,,,,,`,`,`,`,`,`,`,`,`,`,`,`,`,Cf,Cf,Cf,Cf,Cf,Cf,Cf,`,`,`,`,`,`,`,`,`,`,`,`,`
,,,,,,`,`,`,`,`,`,`,`,`,`,`,`,`,Cf,Cf,Cf,Cf,Cf,Cf,Cf,`,`,`,`,`,`,`,`,`,`,`,`,`
,,,,,,,Cf,Cf,Cf,Cf,Cf,Cf,Cf,Cf,Cf,Cf,Cf,Cf,Cf,Cf,Cf,Cf,Cf,Cf,Cf,Cf,Cf,Cf,Cf,Cf,Cf,Cf,Cf,Cf,Cf,Cf,Cf
,,,,,,,Cf,Cf,Cf,Cf,Cf,Cf,Cf,Cf,Cf,Cf,Cf,Cf,Cf,Cf,Cf,Cf,Cf,Cf,Cf,Cf,Cf,Cf,Cf,Cf,Cf,Cf,Cf,Cf,Cf,Cf,Cf
,,,,,,,Cf,Cf,Cf,Cf,Cf,Cf,Cf,Cf,Cf,Cf,Cf,Cf,Cf,Cf,Cf,Cf,Cf,Cf,Cf,Cf,Cf,Cf,Cf,Cf,Cf,Cf,Cf,Cf,Cf,Cf,Cf
,,,,,,`,`,`,`,`,`,`,`,`,`,`,`,`,Cf,Cf,Cf,Cf,Cf,Cf,Cf,`,`,`,`,`,`,`,`,`,`,`,`,`
,,,,,,,,,,,,,,,,,Cd,`,Cf,Cf,Cf,Cf,Cf,Cf,Cf,`
,,,,,,,,,,,,,,,,,,`,Cf,Cf,Cf,Cf,Cf,Cf,Cf,`





#build label(surface_roof2) start(23; 25) hidden() use the meta blueprints for normal application
# this is split up into two blueprints to guarantee that buildingplan matches items to the lower tiles first

,,,,,,`,`,`,`,`,`,`,`,`,`,`,`,`,`,`,`,`,`,`,`,`,`,`,`,`,`,`,`,`,`,`,`,`
,,,,,,`,Cf,Cf,Cf,Cf,Cf,Cf,Cf,Cf,Cf,Cf,Cf,Cf,Cf,Cf,Cf,Cf,Cf,Cf,Cf,Cf,Cf,Cf,Cf,Cf,Cf,Cf,Cf,Cf,Cf,Cf,Cf,`
,,,,,,`,Cf,Cf,Cf,Cf,Cf,Cf,Cf,Cf,Cf,Cf,Cf,Cf,Cf,Cf,Cf,Cf,Cf,Cf,Cf,Cf,Cf,Cf,Cf,Cf,Cf,Cf,Cf,Cf,Cf,Cf,Cf,`
,,,,,,`,Cf,Cf,Cf,Cf,Cf,Cf,Cf,Cf,Cf,Cf,Cf,Cf,Cf,Cf,Cf,Cf,Cf,Cf,Cf,Cf,Cf,Cf,Cf,Cf,Cf,Cf,Cf,Cf,Cf,Cf,Cf,`
,,,,,,`,Cf,Cf,Cf,Cf,Cf,Cf,Cf,Cf,Cf,Cf,Cf,Cf,Cf,Cf,Cf,Cf,Cf,Cf,Cf,Cf,Cf,Cf,Cf,Cf,Cf,Cf,Cf,Cf,Cf,Cf,Cf,`
,,,,,,`,Cf,Cf,Cf,Cf,Cf,Cf,Cf,Cf,Cf,Cf,Cf,Cf,Cf,Cf,Cf,Cf,Cf,Cf,Cf,Cf,Cf,Cf,Cf,Cf,Cf,Cf,Cf,Cf,Cf,Cf,Cf,`
,,,,,,`,Cf,Cf,Cf,Cf,Cf,Cf,Cf,Cf,Cf,Cf,Cf,Cf,Cf,Cf,Cf,Cf,Cf,Cf,Cf,Cf,Cf,Cf,Cf,Cf,Cf,Cf,Cf,Cf,Cf,Cf,Cf,`
,,,,,,`,Cf,Cf,Cf,Cf,Cf,Cf,Cf,Cf,Cf,Cf,Cf,Cf,Cf,Cf,Cf,Cf,Cf,Cf,Cf,Cf,Cf,Cf,Cf,Cf,Cf,Cf,Cf,Cf,Cf,Cf,Cf,`
,,,,,,`,Cf,Cf,Cf,Cf,Cf,Cf,Cf,Cf,Cf,Cf,Cf,Cf,Cf,Cf,Cf,Cf,Cf,Cf,Cf,Cf,Cf,Cf,Cf,Cf,Cf,Cf,Cf,Cf,Cf,Cf,Cf,`
,,,,,,`,Cf,Cf,Cf,Cf,Cf,Cf,Cf,Cf,Cf,Cf,Cf,Cf,Cf,Cf,Cf,Cf,Cf,Cf,Cf,Cf,Cf,Cf,Cf,Cf,Cf,Cf,Cf,Cf,Cf,Cf,Cf,`
,,,,,,`,Cf,Cf,Cf,Cf,Cf,Cf,Cf,Cf,Cf,Cf,Cf,Cf,Cf,Cf,Cf,Cf,Cf,Cf,Cf,Cf,Cf,Cf,Cf,Cf,Cf,Cf,Cf,Cf,Cf,Cf,Cf,`
,,,,,,`,Cf,Cf,Cf,Cf,Cf,Cf,Cf,Cf,Cf,Cf,Cf,Cf,Cf,Cf,Cf,Cf,Cf,Cf,Cf,Cf,Cf,Cf,Cf,Cf,Cf,Cf,Cf,Cf,Cf,Cf,Cf,`
,,,,,,`,Cf,Cf,Cf,Cf,Cf,Cf,Cf,Cf,Cf,Cf,Cf,Cf,Cf,Cf,Cf,Cf,Cf,Cf,Cf,Cf,Cf,Cf,Cf,Cf,Cf,Cf,Cf,Cf,Cf,Cf,Cf,`
,,,,,,`,Cf,Cf,Cf,Cf,Cf,Cf,Cf,Cf,Cf,Cf,Cf,Cf,Cf,Cf,Cf,Cf,Cf,Cf,Cf,Cf,Cf,Cf,Cf,Cf,Cf,Cf,Cf,Cf,Cf,Cf,Cf,`
,,,,,,`,Cf,Cf,Cf,Cf,Cf,Cf,Cf,Cf,Cf,Cf,Cf,Cf,Cf,Cf,Cf,Cf,Cf,Cf,Cf,Cf,Cf,Cf,Cf,Cf,Cf,Cf,Cf,Cf,Cf,Cf,Cf,`
,,,,,,`,Cf,Cf,Cf,Cf,Cf,Cf,Cf,Cf,Cf,Cf,Cf,Cf,Cf,Cf,Cf,Cf,Cf,Cf,Cf,Cf,Cf,Cf,Cf,Cf,Cf,Cf,Cf,Cf,Cf,Cf,Cf,`
,,,,,,`,Cf,Cf,Cf,Cf,Cf,Cf,Cf,Cf,Cf,Cf,Cf,Cf,Cf,Cf,Cf,Cf,Cf,Cf,Cf,Cf,Cf,Cf,Cf,Cf,Cf,Cf,Cf,Cf,Cf,Cf,Cf,`
,,,,,,`,Cf,Cf,Cf,Cf,Cf,Cf,Cf,Cf,Cf,Cf,Cf,Cf,Cf,Cf,Cf,Cf,Cf,Cf,Cf,Cf,Cf,Cf,Cf,Cf,Cf,Cf,Cf,Cf,Cf,Cf,Cf,`
,,,,,,`,Cf,Cf,Cf,Cf,Cf,Cf,Cf,Cf,Cf,Cf,Cf,Cf,Cf,Cf,Cf,Cf,Cf,Cf,Cf,Cf,Cf,Cf,Cf,Cf,Cf,Cf,Cf,Cf,Cf,Cf,Cf,`
,,,,,,`,`,`,`,`,`,`,`,`,`,`,`,`,`,`,Cf,`,Cf,`,`,`,`,`,`,`,`,`,`,`,`,`,`,`
,,,,,,`,Cf,Cf,Cf,Cf,Cf,Cf,Cf,Cf,Cf,Cf,Cf,Cf,`,Cf,Cf,Cf,Cf,Cf,`,Cf,Cf,Cf,Cf,Cf,Cf,Cf,Cf,Cf,Cf,Cf,Cf,`
,,,,,,`,Cf,Cf,Cf,Cf,Cf,Cf,Cf,Cf,Cf,Cf,Cf,Cf,Cf,Cf,Cf,Cf,Cf,Cf,Cf,Cf,Cf,Cf,Cf,Cf,Cf,Cf,Cf,Cf,Cf,Cf,Cf,`
,,,,,,`,Cf,Cf,Cf,Cf,Cf,Cf,Cf,Cf,Cf,Cf,Cf,Cf,`,Cf,Cf,Cf,Cf,Cf,`,Cf,Cf,Cf,Cf,Cf,Cf,Cf,Cf,Cf,Cf,Cf,Cf,`
,,,,,,`,Cf,Cf,Cf,Cf,Cf,Cf,Cf,Cf,Cf,Cf,Cf,Cf,Cf,Cf,Cf,Cf,Cf,Cf,Cf,Cf,Cf,Cf,Cf,Cf,Cf,Cf,Cf,Cf,Cf,Cf,Cf,`
,,,,,,`,Cf,Cf,Cf,Cf,Cf,Cf,Cf,Cf,Cf,Cf,Cf,Cf,`,Cf,Cf,Cf,Cf,Cf,`,Cf,Cf,Cf,Cf,Cf,Cf,Cf,Cf,Cf,Cf,Cf,Cf,`
,,,,,,`,`,`,`,`,`,`,`,`,`,,`,`,`,`,,`,,`,`,`,`,,`,`,`,`,`,`,`,`,`,`
,,,,,,`,`,`,`,`,`,`,`,`,`,,`,`,,,,,,,,`,`,,`,`,`,`,`,`,`,`,`,`
,,,,,,`,,,,,,,,,,,,`,,,,,,,,`,,,,,,,,,,,,`
,,,,,,`,,,,,,,,,,,,`,,,,,,,,`,,,,,,,,,,,,`
,,,,,,`,,,,,,,,,,,,,,,,,,,,,,,,,,,,,,,,`
,,,,,,`,,,,,,,,,,,,,,,,,,,,,,,,,,,,,,,,`
,,,,,,`,,,,,,,,,,,,,,,,,,,,,,,,,,,,,,,,`
,,,,,,`,,,,,,,,,,,,`,,,,,,,,`,,,,,,,,,,,,`
,,,,,,`,,,,,,,,,,,,`,,,,,,,,`,,,,,,,,,,,,`
,,,,,,`,`,`,`,`,`,`,`,`,`,`,`,`,,,,,,,,`,`,`,`,`,`,`,`,`,`,`,`,`
,,,,,,`,`,`,`,`,`,`,`,`,`,`,`,`,,,,,,,,`,`,`,`,`,`,`,`,`,`,`,`,`



,,,,,,`,`,`,`,`,`,`,`,`,`,`,`,`,,,,,,,,`,`,`,`,`,`,`,`,`,`,`,`,`
,,,,,,,,,,,,,,,,,~,`,,,,,,,,`
,,,,,,,,,,,,,,,,,,`,,,,,,,,`





#notes label(farming_help)
"Sets up farming, food storage, and related industries. Also provides post-embark necessities that can later be disassembed."
""
Features:
- Pairs with the surface blueprints to provide miasma vents
- Farm plots (intended to be managed by DFHack autofarm)
- Plentiful food storage
- Refuse stockpile and quantum dump for useless body parts
- Small dormitory and dining room for post-embark needs
- Small office for your manager
""
Workshops:
- Kitchen
- Brewery
- Butcher
- Fishery
- Tannery
- Farmer's Workshop
- Quern
- Screw Press
""
Manual steps you have to take:
- Assign the office to your manager
- Assign a minecart to your quantum garbage stockpile hauling route
"- If the industry level is already built, configure the jugs, pots, and bags stockpiles to take from the ""Goods"" quantum stockpile on the industry level"
""
Farming Walkthough:
"1) Wait until you have completed /surface3 before digging out the farming level on the z-level below the surface, otherwise you will likely get caveins as your miners channel out the miasma vents over empty space."
""
"2) Start digging with /farming1 and get started on manufacturing furniture by running ""quickfort orders"" on /farming2."
""
"3) Once the level is dug out, run /farming2 to build workshops and build and configure stockpiles. Remember to assign a minecart to the newly-designated quantum garbage dump. There are also jugs, pots, and bags stockpiles on this level that should be configured to ""take"" from the industry level stockpiles once we get the industry level built."
""
"4) When the furniture is in place, run /farming3 to designate your temporary dining room and dormitory. The blueprint also attempts to assign the office to your manager, but double-check this assignment in case your dwarves are in an unexpected order."
"#dig label(farming1) start(23; 25; staircase center) message(This would be a good time to queue up manager orders for /farming2. Once the area is dug out, continue with /farming2.)"


,,,,,,,,,d,d,d,d,d,d,d,d,d,d,d,,d,,d,,d,d,d,d,d,d,d,d,d,d,d,d,d,d
,,,,,,,,,d,d,d,d,d,d,d,d,d,d,d,d,d,d,d,,d,d,d,d,d,d,d,d,d,d,d,d,d,d
,,,,,,,,,d,d,d,d,d,d,d,d,d,d,d,,d,d,d,d,d,d,d,d,d,d,d,d,d,d,d,d,d,d
,,,,,,,,,d,d,d,d,d,d,d,d,d,d,d,d,d,d,d,,d,d,d,d,d,d,d,d,d,d,d,d,d,d
,,,,,,,,,d,d,d,d,d,d,d,d,d,d,d,,d,d,d,,d,d,d,d,d,d,d,d,d,d,d,d,d,d
,,,,,,,,,,,d,,,d,,,d,,,,d,d,d,d,d,d,d,d,d,d,d,d,d,d,d,d,d,d
,,,,,,d,d,d,d,d,d,d,d,d,d,d,d,d,d,,d,d,d,,d,d,d,d,d,d,d,d,d,d,d,d,d,d
,,,,,,d,d,d,d,d,d,d,d,d,d,d,d,d,d,,d,d,d,,d,d,d,d,d,d,d,d,d,d,d,d,d,d
,,,,,,d,d,d,d,d,d,d,d,d,d,d,d,d,d,d,d,d,d,d,d,d,d,d,d,d,d,d,d,d,d,d,d,d
,,,,,,d,d,d,d,d,d,d,d,d,d,d,d,d,d,,d,d,d,,d,d,d,d,d,d,d,d,d,d,d,d,d,d
,,,,,,d,d,d,d,d,d,d,d,d,d,d,d,d,d,,d,d,d,,d,d,d,d,d,d,d,d,d,d,d,d,d,d
,,,,,,d,d,d,d,d,d,d,d,d,d,d,d,d,d,d,d,d,d,d,d,d,d,d,d,d,d,d,d,d,d,d,d,d
,,,,,,d,d,d,d,d,d,d,d,d,d,d,d,d,d,,d,d,d,,d,d,d,d,d,d,d,d,d,d,d,d,d,d
,,,,,,d,d,d,d,d,d,d,d,d,d,d,d,d,d,,d,d,d,,d,d,d,d,d,d,d,d,d,d,d,d,d,d
,,,,,,d,d,d,d,d,d,d,d,d,d,d,d,d,d,d,d,d,d,d,d,d,d,d,d,d,d,d,d,d,d,d,d,d
,,,,,,d,d,d,d,d,d,d,d,d,d,d,d,d,d,,d,d,d,,d,d,d,d,d,d,d,d,d,d,d,d,d,d
,,,,,,,,,d,,,,d,,,,d,,,,d,d,d,,,d,,,,d
,,,,,,,,d,d,d,d,d,d,d,d,d,d,d,d,,d,d,d,,d,d,d,,d,d,d
,,,,,,,,d,d,d,d,d,d,d,d,d,d,d,d,d,d,d,d,d,d,z,d,d,d,z,d
,,,,,,,,d,d,d,d,d,d,d,d,d,d,d,d,,d,,d,,d,d,d,,d,d,d
,,,,,,,,,d,,,,d,,,,d,,,,d,d,d,,,d,,,,d
,,,,,,,,d,d,d,d,d,d,d,d,d,d,d,d,d,i,i,i,d,d,d,d,d,d,d,d,d,d,d
,,,,,,,,,d,d,d,d,d,d,d,d,d,d,,d,i,i,i,d,,d,d,d,d,d,d,d,d
,,,,,,,,d,d,d,d,d,d,d,d,d,d,d,d,d,i,i,i,d,d,d,d,d,d,d,d,d,d,d
,,,,,,,,,,,,,,,,,,,,,d,d,d,,,,,d,,,,,d
,,,,,,,,,d,d,d,,d,d,d,d,d,d,d,,d,,d,,z,z,d,d,d,,z,d,d,d
,,,,,,,,,d,d,d,,d,d,d,d,d,d,d,,d,d,d,d,z,z,d,z,d,d,z,d,z,d
,,,,,,,,,d,d,d,d,d,d,d,d,d,d,d,d,d,d,d,,z,z,d,d,d,,z,d,d,d
,,,,,,,,,d,d,d,,d,d,d,d,d,d,d,,d,d,d,,,,,d,,,,,d
,,,,,,,,,d,d,d,,d,d,d,d,d,d,d,,d,d,d,,z,z,z,z,z,z,z,z,z,z,z,z,z,z
,,,,,,,,,d,d,d,d,d,d,d,d,d,d,d,d,d,d,d,d,z,z,z,z,z,z,z,z,z,z,z,z,z,z
,,,,,,,,,d,d,d,,d,d,d,d,d,d,d,,d,d,d,,z,z,z,z,z,z,z,z,z,z,z,z,z,z
,,,,,,,,,d,d,d,,d,d,d,d,d,d,d,,d,,d,,z,z,z,z,z,z,z,z,z,z,z,z,z,z
,,,,,,,,,,,,,,,,,,,,,,,,,z,z,z,z,z,z,z,z,z,z,z,z,z,z
,,,,,,,,,,,,,,,,,,,,,z,z,z,,z,z,z,z,z,z,z,z,z,z,z,z,z,z
,,,,,,,,,,,,,,,,,,,,,z,z,z,d,z,z,z,z,z,z,z,z,z,z,z,z,z,z
,,,,,,,,,,,,,,,,,,,,,z,z,z,,z,z,z,z,z,z,z,z,z,z,z,z,z,z
,,,,,,,,,,,,,,,,,,,,,,d,,,z,z,z,z,z,z,z,z,z,z,z,z,z,z
,,,,,,,,,,,,,,,,,,,,,,z,,,z,z,z,z,z,z,z,z,z,z,z,z,z,z


"#meta label(farming2) start(staircase center) message(Once furniture has been placed, continue with /farming3.) build workshops and stockpiles, configure stockpiles"
build_workshops/farming_workshops
build_furniture/farming_furniture
place/farming_place
query_stockpiles/farming_query_stockpiles
#build label(farming_workshops) start(23; 25) hidden() use the meta blueprints for normal application


,,,,,,,,,p(1x3),p(1x3),p(1x3),p(1x3),p(1x3),p(1x3),p(1x3),p(1x3),`,`,`,,`,,`,,`,`,`,`,`,`,`,`,`,`,`,`,`,`
,,,,,,,,,`,`,`,`,`,`,`,`,`,`,`,`,`,`,`,,`,`,`,`,`,`,`,`,`,`,`,`,`,`
,,,,,,,,,`,`,`,`,`,`,`,`,`,`,`,,`,`,`,`,`,`,`,`,`,`,`,`,`,`,`,`,`,`
,,,,,,,,,`,`,`,`,`,`,`,`,`,`,`,`,`,`,`,,`,`,`,`,`,`,`,`,`,`,`,`,`,`
,,,,,,,,,`,`,`,`,`,`,`,`,`,`,`,,`,`,`,,`,`,`,`,`,`,`,`,`,`,`,`,`,`
,,,,,,,,,,,`,,,`,,,`,,,,`,`,`,`,`,`,`,`,`,`,`,`,`,`,`,`,`,`
,,,,,,`,`,`,`,`,`,`,`,`,`,`,`,`,`,,`,`,`,,`,`,`,`,`,`,`,`,`,`,`,`,`,`
,,,,,,`,`,`,`,`,`,`,`,`,`,`,`,`,`,,`,`,`,,`,`,`,`,`,`,`,`,`,`,`,`,`,`
,,,,,,`,`,`,`,`,`,`,`,`,`,`,`,`,`,`,`,`,`,`,`,`,`,`,`,`,`,`,`,`,`,`,`,`
,,,,,,`,`,`,`,`,`,`,`,`,`,`,`,`,`,,`,`,`,,`,`,`,`,`,`,`,`,`,`,`,`,`,`
,,,,,,`,`,`,`,`,`,`,`,`,`,`,`,`,`,,`,`,`,,`,`,`,`,`,`,`,`,`,`,`,`,`,`
,,,,,,`,`,`,`,`,`,`,`,`,`,`,`,`,`,`,`,`,`,`,`,`,`,`,`,`,`,`,`,`,`,`,`,`
,,,,,,`,`,`,`,`,`,`,`,`,`,`,`,`,`,,`,`,`,,`,`,`,`,`,`,`,`,`,`,`,`,`,`
,,,,,,`,`,`,`,`,`,`,`,`,`,`,`,`,`,,`,`,`,,`,`,`,`,`,`,`,`,`,`,`,`,`,`
,,,,,,`,`,`,`,`,`,`,`,`,`,`,`,`,`,`,`,`,`,`,`,`,`,`,`,`,`,`,`,`,`,`,`,`
,,,,,,`,`,`,`,`,`,`,`,`,`,`,`,`,`,,`,`,`,,`,`,`,`,`,`,`,`,`,`,`,`,`,`
,,,,,,,,,`,,,,`,,,,`,,,,`,`,`,,,`,,,,`
,,,,,,,,`,`,`,`,`,`,`,`,`,`,`,`,,`,`,`,,`,`,`,,`,`,`
,,,,,,,,`,wq,wp,`,`,ww,`,`,`,wl,`,`,`,`,`,`,`,`,wu,`,`,`,wz,`
,,,,,,,,`,`,`,`,`,`,`,`,`,`,`,`,,`,,`,,`,`,`,,`,`,`
,,,,,,,,,`,,,,`,,,,`,,,,`,`,`,,,`,,,,`
,,,,,,,,`,`,`,`,`,`,`,`,`,`,`,`,`,`,`,`,`,`,`,`,`,`,`,`,`,`,`
,,,,,,,,,`,`,`,`,`,`,`,`,`,`,,`,`,`,`,`,,`,`,`,`,`,`,`,`
,,,,,,,,`,`,`,`,`,`,`,`,`,`,`,`,`,`,`,`,`,`,`,`,`,`,`,`,`,`,`
,,,,,,,,,,,,,,,,,,,,,`,`,`,,,,,`,,,,,`
,,,,,,,,,`,`,`,,`,`,`,`,`,`,`,,`,,`,,`,`,`,`,`,,`,`,`,`
,,,,,,,,,`,`,`,,`,`,`,`,`,`,`,,`,`,`,`,`,`,`,wn,`,`,`,`,wh,`
,,,,,,,,,`,`,`,`,`,`,`,`,`,`,`,`,`,`,`,,`,`,`,`,`,,`,`,`,`
,,,,,,,,,`,`,`,,`,`,`,`,`,`,`,,`,`,`,,,,,`,,,,,`
,,,,,,,,,`,`,`,,`,`,`,`,`,`,`,,`,`,`,,`,`,`,`,`,`,`,`,`,`,`,`,`,`
,,,,,,,,,`,`,`,`,`,`,`,`,`,`,`,`,`,`,`,`,`,`,`,`,`,`,`,`,`,`,`,`,`,`
,,,,,,,,,`,`,`,,`,`,`,`,`,`,`,,`,`,`,,`,`,`,`,`,`,`,`,`,`,`,`,`,`
,,,,,,,,,`,`,`,,`,`,`,`,`,`,`,,`,,`,,`,`,`,`,`,`,`,`,`,`,`,`,`,`
,,,,,,,,,,,,,,,,,,,,,,,,,`,`,`,`,`,`,`,`,`,`,`,`,`,`
,,,,,,,,,,,,,,,,,,,,,`,`,`,,`,`,`,`,`,`,`,`,`,`,`,`,`,`
,,,,,,,,,,,,,,,,,,,,,`,`,`,`,`,`,`,`,`,`,`,`,`,`,`,`,`,`
,,,,,,,,,,,,,,,,,,,,,`,`,`,,`,`,`,`,`,`,`,`,`,`,`,`,`,`
,,,,,,,,,,,,,,,,,,,,,,`,,,`,`,`,`,`,`,`,`,`,`,`,`,`,`
,,,,,,,,,,,,,,,,,,,,,,`,,,`,`,`,`,`,`,`,`,`,`,`,`,`,`


#build label(farming_furniture) start(23; 25) hidden() use the meta blueprints for normal application


,,,,,,,,,`,`,`,`,`,`,`,`,`,`,`,,s,,s,,`,`,`,`,`,`,`,`,`,`,`,`,`,`
,,,,,,,,,`,`,`,`,`,`,`,`,`,`,`,d,`,`,`,,`,`,`,`,`,`,`,`,`,`,`,`,`,`
,,,,,,,,,`,`,`,`,`,`,`,`,`,`,`,,`,`,`,d,`,`,`,`,`,`,`,`,`,`,`,`,`,`
,,,,,,,,,`,`,`,`,`,`,`,`,`,`,`,d,`,`,`,,`,`,`,`,`,`,`,`,`,`,`,`,`,`
,,,,,,,,,`,`,`,`,`,`,`,`,`,`,`,,`,`,`,,`,`,`,`,`,`,`,`,`,`,`,`,`,`
,,,,,,,,,,,d,,,d,,,d,,,,`,`,`,d,`,`,`,`,`,`,`,`,`,`,`,`,`,`
,,,,,,`,`,`,`,`,`,`,`,`,`,`,`,`,`,,`,`,`,,`,`,`,`,`,`,`,`,`,`,`,`,`,`
,,,,,,`,`,`,`,`,`,`,`,`,`,`,`,`,`,,`,`,`,,`,`,`,`,`,`,`,`,`,`,`,`,`,`
,,,,,,`,`,`,`,`,`,`,`,`,`,`,`,`,`,d,`,`,`,d,`,`,`,`,`,`,`,`,`,`,`,`,`,`
,,,,,,`,`,`,`,`,`,`,`,`,`,`,`,`,`,,`,`,`,,`,`,`,`,`,`,`,`,`,`,`,`,`,`
,,,,,,`,`,`,`,`,`,`,`,`,`,`,`,`,`,,`,`,`,,`,`,`,`,`,`,`,`,`,`,`,`,`,`
,,,,,,`,`,`,`,`,`,`,`,`,`,`,`,`,`,d,`,`,`,d,`,`,`,`,`,`,`,`,`,`,`,`,`,`
,,,,,,`,`,`,`,`,`,`,`,`,`,`,`,`,`,,`,`,`,,`,`,`,`,`,`,`,`,`,`,`,`,`,`
,,,,,,`,`,`,`,`,`,`,`,`,`,`,`,`,`,,`,`,`,,`,`,`,`,`,`,`,`,`,`,`,`,`,`
,,,,,,`,`,`,`,`,`,`,`,`,`,`,`,`,`,d,`,`,`,d,`,`,`,`,`,`,`,`,`,`,`,`,`,`
,,,,,,`,`,`,`,`,`,`,`,`,`,`,`,`,`,,`,`,`,,`,`,`,`,`,`,`,`,`,`,`,`,`,`
,,,,,,,,,d,,,,d,,,,d,,,,`,`,`,,,d,,,,d
,,,,,,,,`,`,`,`,`,`,`,`,`,`,`,`,,`,`,`,,`,`,`,,`,`,`
,,,,,,,,`,`,`,`,`,`,`,`,`,`,`,`,d,`,`,`,d,`,`,`,d,`,`,`
,,,,,,,,`,`,`,`,`,`,`,`,`,`,`,`,,d,,d,,`,`,`,,`,`,`
,,,,,,,,,d,,,,d,,,,d,,,,`,`,`,,,d,,,,d
,,,,,,,,s,`,`,`,`,`,`,`,`,`,`,d,`,`,`,`,`,d,`,`,`,`,`,`,`,`,s
,,,,,,,,,c,t,`,`,`,`,`,`,`,`,,`,`,`,`,`,,`,`,`,`,`,`,`,`
,,,,,,,,s,`,`,`,`,`,`,`,`,`,`,d,`,`,`,`,`,d,`,`,`,`,`,`,`,`,s
,,,,,,,,,,,,,,,,,,,,,`,`,`,,,,,d,,,,,d
,,,,,,,,,b,b,b,,`,`,`,`,`,`,`,,d,,d,,`,`,`,`,`,,`,`,`,`
,,,,,,,,,b,`,`,,`,`,`,`,`,`,`,,`,`,`,d,`,`,`,`,`,`,`,`,`,`
,,,,,,,,,b,`,`,d,`,c,c,c,c,c,`,d,`,`,`,,`,`,`,`,`,,`,`,`,`
,,,,,,,,,b,`,h,,`,t,t,t,t,t,`,,`,`,`,,,,,d,,,,,d
,,,,,,,,,b,`,f,,`,t,t,t,t,t,`,,`,`,`,,`,`,`,`,`,`,`,`,`,`,`,`,`,`
,,,,,,,,,b,`,`,d,`,c,c,c,c,c,`,d,`,`,`,d,`,`,`,`,`,`,`,`,`,`,`,`,`,`
,,,,,,,,,b,`,`,,`,`,`,`,`,`,`,,`,`,`,,`,`,`,`,`,`,`,`,`,`,`,`,`,`
,,,,,,,,,b,b,b,,`,`,`,`,`,`,`,,s,,s,,`,`,`,`,`,`,`,`,`,`,`,`,`,`
,,,,,,,,,,,,,,,,,,,,,,,,,`,`,`,`,`,`,`,`,`,`,`,`,`,`
,,,,,,,,,,,,,,,,,,,,,`,`,`,,`,`,`,`,`,`,`,`,`,`,`,`,`,`
,,,,,,,,,,,,,,,,,,,,,`,`,`,d,`,`,`,`,`,`,`,`,`,`,`,`,`,`
,,,,,,,,,,,,,,,,,,,,,`,`,`,,`,`,`,`,`,`,`,`,`,`,`,`,`,`
,,,,,,,,,,,,,,,,,,,,,,trackstopS,,,`,`,`,`,`,`,`,`,`,`,`,`,`,`
,,,,,,,,,,,,,,,,,,,,,,`,,,`,`,`,`,`,`,`,`,`,`,`,`,`,`


#place label(farming_place) start(23; 25) hidden() use the meta blueprints for normal application


,,,,,,,,,`,`,`,`,`,`,`,`,f(3x6),,,,`,,`,,f(14x16),,,,`,`,`,`,`,`,`,`,`,`
,,,,,,,,,`,`,`,`,`,`,`,`,`,`,`,`,`,`,`,,`,`,`,`,`,`,`,`,`,`,`,`,`,`
,,,,,,,,,`,`,`,`,`,`,`,`,`,`,`,,`,`,`,`,`,`,`,`,`,`,`,`,`,`,`,`,`,`
,,,,,,,,,f(8x1),,,`,`,`,`,`,`,`,`,`,`,`,`,,`,`,`,`,`,`,`,`,`,`,`,`,`,`
,,,,,,,,,b(8x1),,,`,`,`,`,`,`,`,`,,`,`,`,,`,`,`,`,`,`,`,`,`,`,`,`,`,`
,,,,,,,,,,,`,,,`,,,`,,,,`,`,`,`,`,`,`,`,`,`,`,`,`,`,`,`,`,`
,,,,,,f(14x10),,,,`,`,`,`,`,`,`,`,`,`,,`,`,`,,`,`,`,`,`,`,`,`,`,`,`,`,`,`
,,,,,,`,`,`,`,`,`,`,`,`,`,`,`,`,`,,`,`,`,,`,`,`,`,`,`,`,`,`,`,`,`,`,`
,,,,,,`,`,`,`,`,`,`,`,`,`,`,`,`,`,`,`,`,`,`,`,`,`,`,`,`,`,`,`,`,`,`,`,`
,,,,,,`,`,`,`,`,`,`,`,`,`,`,`,`,`,,`,`,`,,`,`,`,`,`,`,`,`,`,`,`,`,`,`
,,,,,,`,`,`,`,`,`,`,`,`,`,`,`,`,`,,`,`,`,,`,`,`,`,`,`,`,`,`,`,`,`,`,`
,,,,,,`,`,`,`,`,`,`,`,`,`,`,`,`,`,`,`,`,`,`,`,`,`,`,`,`,`,`,`,`,`,`,`,`
,,,,,,`,`,`,`,`,`,`,`,`,`,`,`,`,`,,`,`,`,,`,`,`,`,`,`,`,`,`,`,`,`,`,`
,,,,,,`,`,`,`,`,`,`,`,`,`,`,`,`,`,,`,`,`,,`,`,`,`,`,`,`,`,`,`,`,`,`,`
,,,,,,`,`,`,`,`,`,`,`,`,`,`,`,`,`,`,`,`,`,`,`,`,`,`,`,`,`,`,`,`,`,`,`,`
,,,,,,`,`,`,`,`,`,`,`,`,`,`,`,`,`,,`,`,`,,`,`,`,`,`,`,`,`,`,`,`,`,`,`
,,,,,,,,,`,,,,`,,,,`,,,,`,`,`,,,`,,,,`
,,,,,,,,u,u,u,u,`,`,`,u(5x3),,,`,`,,`,`,`,,`,`,`,,`,`,`
,,,,,,,,g,`,`,u,`,`,`,`,`,`,`,`,`,`,`,`,`,`,`,`,`,`,`,`
,,,,,,,,g,g,g,g,`,`,`,`,`,`,`,`,,`,,`,,`,`,`,,`,`,`
,,,,,,,,,`,,,,`,,,,`,,,,`,`,`,,,`,,,,`
,,,,,,,,`,`,`,`,`,`,`,`,`,`,`,`,`,`,`,`,`,`,`,`,`,`,`,`,`,`,`
,,,,,,,,,`,`,`,`,`,`,`,`,`,`,,`,`,`,`,`,,`,`,`,`,`,`,`,`
,,,,,,,,`,`,`,`,`,`,`,`,`,`,`,`,`,`,`,`,`,`,`,`,`,`,`,`,`,`,`
,,,,,,,,,,,,,,,,,,,,,`,`,`,,,,,`,,,,,`
,,,,,,,,,`,`,`,,f(7x2),,,`,`,`,`,,`,,`,,r(2x3),,,`,`,,f(1x3),,,`
,,,,,,,,,`,`,`,,`,`,`,`,`,`,`,,`,`,`,`,`,`,`,`,`,`,`,`,`,`
,,,,,,,,,`,`,`,`,`,`,`,`,`,`,`,`,`,`,`,,`,`,`,`,`,,`,`,`,`
,,,,,,,,,`,`,`,,`,`,`,`,`,`,`,,`,`,`,,,,,`,,,,,`
,,,,,,,,,`,`,`,,`,`,`,`,`,`,`,,`,`,`,,ry(14x10),,,,`,`,`,`,`,`,`,`,`,`
,,,,,,,,,`,`,`,`,`,`,`,`,`,`,`,`,`,`,`,`,`,`,`,`,`,`,`,`,`,`,`,`,`,`
,,,,,,,,,`,`,`,,f(7x2),,,`,`,`,`,,`,`,`,,`,`,`,`,`,`,`,`,`,`,`,`,`,`
,,,,,,,,,`,`,`,,`,`,`,`,`,`,`,,`,,`,,`,`,`,`,`,`,`,`,`,`,`,`,`,`
,,,,,,,,,,,,,,,,,,,,,,,,,`,`,`,`,`,`,`,`,`,`,`,`,`,`
,,,,,,,,,,,,,,,,,,,,,ry(3x3),,,,`,`,`,`,`,`,`,`,`,`,`,`,`,`
,,,,,,,,,,,,,,,,,,,,,`,`,`,`,`,`,`,`,`,`,`,`,`,`,`,`,`,`
,,,,,,,,,,,,,,,,,,,,,`,`,`,,`,`,`,`,`,`,`,`,`,`,`,`,`,`
,,,,,,,,,,,,,,,,,,,,,,`,,,`,`,`,`,`,`,`,`,`,`,`,`,`,`
,,,,,,,,,,,,,,,,,,,,,,ry,,,`,`,`,`,`,`,`,`,`,`,`,`,`,`


"#query label(farming_query_stockpiles) start(23; 25) hidden() message(remember to:
- assign a minecart to the garbage quantum stockpile
- if the industry level is already built, configure the jugs, pots, and bags stockpiles to take from the ""Goods"" quantum stockpile on the industry level) use the meta blueprints for normal application"


,,,,,,,,,`,`,`,`,`,`,`,`,"{givename name=""seeds feeder""}",`,`,,`,,`,,forbidplants,`,`,`,`,`,`,`,`,`,`,`,`,`
,,,,,,,,,`,`,`,`,`,`,`,`,`,`,`,`,`,`,`,,forbidtallow,`,`,`,`,`,`,`,`,`,`,`,`,`
,,,,,,,,,`,`,`,`,`,`,`,`,`,`,`,,`,`,`,`,forbiddye,`,`,`,`,`,`,`,`,`,`,`,`,`
,,,,,,,,,seeds,linksonly,"{givename name=""seeds""}",`,`,`,`,`,seeds,give2left,nocontainers,`,`,`,`,,forbidunpreparedfish,`,`,`,`,`,`,`,`,`,`,`,`,`
,,,,,,,,,potash,nocontainers,"{givename name=""potash""}",`,`,`,`,`,`,`,`,,`,`,`,,forbidmiscliquid,`,`,`,`,`,`,`,`,`,`,`,`,`
,,,,,,,,,,,`,,,`,,,`,,,,`,`,`,`,forbidpreparedfood,`,`,`,`,`,`,`,`,`,`,`,`,`
,,,,,,plants,"{givename name=""plants""}",`,`,`,`,`,`,`,`,`,`,`,`,,`,`,`,,"{givename name=""cookable food""}",`,`,`,`,`,`,`,`,`,`,`,`,`
,,,,,,`,`,`,`,`,`,`,`,`,`,`,`,`,`,,`,`,`,,`,`,`,`,`,`,`,`,`,`,`,`,`,`
,,,,,,`,`,`,`,`,`,`,`,`,`,`,`,`,`,`,`,`,`,`,`,`,`,`,`,`,`,`,`,`,`,`,`,`
,,,,,,`,`,`,`,`,`,`,`,`,`,`,`,`,`,,`,`,`,,`,`,`,`,`,`,`,`,`,`,`,`,`,`
,,,,,,`,`,`,`,`,`,`,`,`,`,`,`,`,`,,`,`,`,,`,`,`,`,`,`,`,`,`,`,`,`,`,`
,,,,,,`,`,`,`,`,`,`,`,`,`,`,`,`,`,`,`,`,`,`,`,`,`,`,`,`,`,`,`,`,`,`,`,`
,,,,,,`,`,`,`,`,`,`,`,`,`,`,`,`,`,,`,`,`,,`,`,`,`,`,`,`,`,`,`,`,`,`,`
,,,,,,`,`,`,`,`,`,`,`,`,`,`,`,`,`,,`,`,`,,`,`,`,`,`,`,`,`,`,`,`,`,`,`
,,,,,,`,`,`,`,`,`,`,`,`,`,`,`,`,`,`,`,`,`,`,`,`,`,`,`,`,`,`,`,`,`,`,`,`
,,,,,,`,`,`,`,`,`,`,`,`,`,`,`,`,`,,`,`,`,,`,`,`,`,`,`,`,`,`,`,`,`,`,`
,,,,,,,,,`,,,,`,,,,`,,,,`,`,`,,,`,,,,`
,,,,,,,,bags,nocontainers,"{givename name=""bags""}",`,`,`,`,pots,`,`,`,`,,`,`,`,,`,`,`,,`,`,`
,,,,,,,,`,`,`,`,`,`,`,"{givename name=""pots""}",`,`,`,`,`,`,`,`,`,`,`,`,`,`,`,`
,,,,,,,,jugs,nocontainers,"{givename name=""jugs""}",`,`,`,`,`,`,`,`,`,,`,,`,,`,`,`,,`,`,`
,,,,,,,,,`,,,,`,,,,`,,,,`,`,`,,,`,,,,`
,,,,,,,,`,`,`,`,`,`,`,`,`,`,`,`,`,`,`,`,`,`,`,`,`,`,`,`,`,`,`
,,,,,,,,,`,`,`,`,`,`,`,`,`,`,,`,`,`,`,`,,`,`,`,`,`,`,`,`
,,,,,,,,`,`,`,`,`,`,`,`,`,`,`,`,`,`,`,`,`,`,`,`,`,`,`,`,`,`,`
,,,,,,,,,,,,,,,,,,,,,`,`,`,,,,,`,,,,,`
,,,,,,,,,`,`,`,,preparedfood,"{givename name=""prepared food""}",`,`,`,`,`,,`,,`,,rawhides,`,`,`,`,,unpreparedfish,`,`,`
,,,,,,,,,`,`,`,,`,`,`,`,`,`,`,,`,`,`,`,"{givename name=""rawhides""}",`,`,`,`,`,nocontainers,`,`,`
,,,,,,,,,`,`,`,`,`,`,`,`,`,`,`,`,`,`,`,,`,`,`,`,`,,"{givename name=""unprepared fish""}",`,`,`
,,,,,,,,,`,`,`,,`,`,`,`,`,`,`,,`,`,`,,,,,`,,,,,`
,,,,,,,,,`,`,`,,`,`,`,`,`,`,`,,`,`,`,,give2up,"{givename name=""refuse and corpses""}",`,`,`,`,`,`,`,`,`,`,`,`
,,,,,,,,,`,`,`,`,`,`,`,`,`,`,`,`,`,`,`,`,`,`,`,`,`,`,`,`,`,`,`,`,`,`
,,,,,,,,,`,`,`,,booze,"{givename name=""booze""}",`,`,`,`,`,,`,`,`,,forbidcraftrefuse,`,`,`,`,`,`,`,`,`,`,`,`,`
,,,,,,,,,`,`,`,,`,`,`,`,`,`,`,,`,,`,,`,`,`,`,`,`,`,`,`,`,`,`,`,`
,,,,,,,,,,,,,,,,,,,,,,,,,`,`,`,`,`,`,`,`,`,`,`,`,`,`
,,,,,,,,,,,,,,,,,,,,,bodyparts,linksonly,`,,`,`,`,`,`,`,`,`,`,`,`,`,`,`
,,,,,,,,,,,,,,,,,,,,,"{givename name=""trash dumper feeder""}",`,`,`,give2left,`,`,`,`,`,`,`,`,`,`,`,`,`
,,,,,,,,,,,,,,,,,,,,,`,`,`,,`,`,`,`,`,`,`,`,`,`,`,`,`,`
,,,,,,,,,,,,,,,,,,,,,,"{quantumstopfromnorth name=""Trash Dumper""}",,,`,`,`,`,`,`,`,`,`,`,`,`,`,`
,,,,,,,,,,,,,,,,,,,,,,"{quantum name=""trash quantum""}",,,`,`,`,`,`,`,`,`,`,`,`,`,`,`


#query label(farming3) start(23; 25 staircase center) message(Check to ensure the office got assigned to your manager.) configure rooms


,,,,,,,,,`,`,`,`,`,`,`,`,`,`,`,,`,,`,,`,`,`,`,`,`,`,`,`,`,`,`,`,`
,,,,,,,,,`,`,`,`,`,`,`,`,`,`,`,`,`,`,`,,`,`,`,`,`,`,`,`,`,`,`,`,`,`
,,,,,,,,,`,`,`,`,`,`,`,`,`,`,`,,`,`,`,`,`,`,`,`,`,`,`,`,`,`,`,`,`,`
,,,,,,,,,`,`,`,`,`,`,`,`,`,`,`,`,`,`,`,,`,`,`,`,`,`,`,`,`,`,`,`,`,`
,,,,,,,,,`,`,`,`,`,`,`,`,`,`,`,,`,`,`,,`,`,`,`,`,`,`,`,`,`,`,`,`,`
,,,,,,,,,,,`,,,`,,,`,,,,`,`,`,`,`,`,`,`,`,`,`,`,`,`,`,`,`,`
,,,,,,`,`,`,`,`,`,`,`,`,`,`,`,`,`,,`,`,`,,`,`,`,`,`,`,`,`,`,`,`,`,`,`
,,,,,,`,`,`,`,`,`,`,`,`,`,`,`,`,`,,`,`,`,,`,`,`,`,`,`,`,`,`,`,`,`,`,`
,,,,,,`,`,`,`,`,`,`,`,`,`,`,`,`,`,`,`,`,`,`,`,`,`,`,`,`,`,`,`,`,`,`,`,`
,,,,,,`,`,`,`,`,`,`,`,`,`,`,`,`,`,,`,`,`,,`,`,`,`,`,`,`,`,`,`,`,`,`,`
,,,,,,`,`,`,`,`,`,`,`,`,`,`,`,`,`,,`,`,`,,`,`,`,`,`,`,`,`,`,`,`,`,`,`
,,,,,,`,`,`,`,`,`,`,`,`,`,`,`,`,`,`,`,`,`,`,`,`,`,`,`,`,`,`,`,`,`,`,`,`
,,,,,,`,`,`,`,`,`,`,`,`,`,`,`,`,`,,`,`,`,,`,`,`,`,`,`,`,`,`,`,`,`,`,`
,,,,,,`,`,`,`,`,`,`,`,`,`,`,`,`,`,,`,`,`,,`,`,`,`,`,`,`,`,`,`,`,`,`,`
,,,,,,`,`,`,`,`,`,`,`,`,`,`,`,`,`,`,`,`,`,`,`,`,`,`,`,`,`,`,`,`,`,`,`,`
,,,,,,`,`,`,`,`,`,`,`,`,`,`,`,`,`,,`,`,`,,`,`,`,`,`,`,`,`,`,`,`,`,`,`
,,,,,,,,,`,,,,`,,,,`,,,,`,`,`,,,`,,,,`
,,,,,,,,`,`,`,`,`,`,`,`,`,`,`,`,,`,`,`,,`,`,`,,`,`,`
,,,,,,,,`,`,`,`,`,`,`,`,`,`,`,`,`,`,`,`,`,`,`,`,`,`,`,`
,,,,,,,,`,`,`,`,`,`,`,`,`,`,`,`,,`,,`,,`,`,`,,`,`,`
,,,,,,,,,`,,,,`,,,,`,,,,`,`,`,,,`,,,,`
,,,,,,,,`,`,`,`,`,`,`,`,`,`,`,`,`,`,`,`,`,`,`,`,`,`,`,`,`,`,`
,,,,,,,,,r--&a+&,`,`,`,`,`,`,`,`,`,,`,`,`,`,`,,`,`,`,`,`,`,`,`
,,,,,,,,`,`,`,`,`,`,`,`,`,`,`,`,`,`,`,`,`,`,`,`,`,`,`,`,`,`,`
,,,,,,,,,,,,,,,,,,,,,`,`,`,,,,,`,,,,,`
,,,,,,,,,`,`,`,,`,`,`,`,`,`,`,,`,,`,,`,`,`,`,`,,`,`,`,`
,,,,,,,,,`,`,`,,`,`,`,`,`,`,`,,`,`,`,`,`,`,`,`,`,`,`,`,`,`
,,,,,,,,,`,`,`,`,`,`,`,`,`,`,`,`,`,`,`,,`,`,`,`,`,,`,`,`,`
,,,,,,,,,r++&d,`,`,,`,`,`,r++&h,`,`,`,,`,`,`,,,,,`,,,,,`
,,,,,,,,,`,`,`,,`,`,`,`,`,`,`,,`,`,`,,`,`,`,`,`,`,`,`,`,`,`,`,`,`
,,,,,,,,,`,`,`,`,`,`,`,`,`,`,`,`,`,`,`,`,`,`,`,`,`,`,`,`,`,`,`,`,`,`
,,,,,,,,,`,`,`,,`,`,`,`,`,`,`,,`,`,`,,`,`,`,`,`,`,`,`,`,`,`,`,`,`
,,,,,,,,,`,`,`,,`,`,`,`,`,`,`,,`,,`,,`,`,`,`,`,`,`,`,`,`,`,`,`,`
,,,,,,,,,,,,,,,,,,,,,,,,,`,`,`,`,`,`,`,`,`,`,`,`,`,`
,,,,,,,,,,,,,,,,,,,,,`,`,`,,`,`,`,`,`,`,`,`,`,`,`,`,`,`
,,,,,,,,,,,,,,,,,,,,,`,`,`,`,`,`,`,`,`,`,`,`,`,`,`,`,`,`
,,,,,,,,,,,,,,,,,,,,,`,`,`,,`,`,`,`,`,`,`,`,`,`,`,`,`,`
,,,,,,,,,,,,,,,,,,,,,,`,,,`,`,`,`,`,`,`,`,`,`,`,`,`,`
,,,,,,,,,,,,,,,,,,,,,,`,,,`,`,`,`,`,`,`,`,`,`,`,`,`,`


#notes label(industry_help)
Sets up workshops for all non-farming industries
""
Features:
- Quantum stockpiles
- Space-efficient layout for all workshops
with separate stockpiles for:
- A reserve of uncut gems for strange moods that the jeweler's workshop cannot take from
- Steel bars and coal so you can see at a glance if you're low on either
- Liquids that cannot be quantum stockpiled (e.g. lye)
- Meltable weapons and armor
""
Workshops:
- 3x Mason
- 4x Craftsdwarf
- 1x Jeweler
- 1x Mechanic
- 4x Smelter
- 1x Forge
- 1x Glassmaker
- 1x Kiln
- 4x Wood furnace
- 1x Ashery
- 1x Soap maker
- 1x Carpenter
- 1x Siege workshop
- 1x Bowyer
- 1x Dyer
- 1x Loom
- 1x Clothier
""
""
Manual steps you have to take:
- Assign minecarts to your quantum stockpile hauling routes
"- Give from the ""Goods"" quantum stockpile to the jugs, pots, and bags stockpiles on the farming level"
"- If desired, set the stockpiles in the bottom right to auto-melt. This results in melting all weapons and armor that are not masterwork steel. This is great for your military, but it takes a *lot* of fuel. If you enable this, be sure you're in a heavily forested area, enable auto-chop, and set up manager orders to keep your coal stocks high."
- Download automation.json from https://drive.google.com/file/d/17WcN5mK-rnADOm2B_JFpPnByYgkYjxhb/view and put it in your dfhack-config/orders/ directory.
""
Industry Walkthrough:
1) You can start digging out /industry1 immediately after embark. It is best to choose a stone layer at least two layers underground so the boulders can be used by your starting workshops to manufacture needed items.
""
"2) Queue up manufacturing by running ""quickfort orders"" on /industry2."
""
"3) Once the area is dug out, run /industry2. Remember to assign minecarts to to your quantum stockpile hauling routes, and if the farming level is already built, give from the ""Goods"" quantum stockpile to the jugs, pots, and bags stockpiles on the farming level."
""
"4) If you want to automatically melt goblinite and other low-quality weapons and armor, mark the south-east stockpiles for auto-melt."
""
"5) Run ""orders import automation"" to use the provided automation.json to take care of your fort's basic needs, such as food, booze, military supplies, and raw material processing."
"#dig label(industry1) start(18; 18; staircase center) message(This would be a good time to queue manager orders for /industry2. Once the area is dug out, continue with /industry2.)"


,,,,,,,,,,,d,d,d,d,d,d,d,d,d,d,d,d,d
,,,,,,,,,,,d,d,d,d,d,d,d,d,d,d,d,d,d
,,,,d,d,d,d,d,d,d,d,d,d,d,d,d,d,d,d,d,d,d,d,d,d,d,d,d,d,d
,,,,d,d,d,d,d,d,d,d,d,d,d,d,d,d,d,d,d,d,d,d,d,d,d,d,d,d,d
,,,,d,d,d,d,d,d,d,d,d,d,d,d,d,d,d,d,d,d,d,d,d,d,d,d,d,d,d
,,,,d,d,d,d,d,d,d,d,d,d,d,d,d,d,d,d,d,d,d,d,d,d,d,d,d,d,d
,,,,d,d,d,d,d,d,d,d,d,d,d,d,d,d,d,d,d,d,d,d,d,d,d,d,d,d,d
,,,,d,d,d,d,d,d,d,d,d,d,d,d,d,d,d,d,d,d,d,d,d,d,d,d,d,d,d
,,,,d,d,d,d,d,d,d,d,d,d,d,d,d,d,d,d,d,d,d,d,d,d,d,d,d,d,d
,,d,d,d,d,d,d,d,d,d,d,d,d,d,d,d,d,d,d,d,d,d,d,d,d,d,d,d,d,d,d,d
,,d,d,d,d,d,d,d,d,d,d,d,d,d,d,d,d,d,d,d,d,d,d,d,d,d,d,d,d,d,d,d
,,d,d,d,d,d,d,d,d,d,d,d,d,d,d,d,d,d,d,d,d,d,d,d,d,d,d,d,d,d,d,d
,,d,d,d,d,d,d,d,d,d,d,d,d,,,d,,d,,,d,d,d,d,d,d,d,d,d,d,d,d
,,d,d,d,d,d,d,d,d,d,d,d,d,,d,d,d,d,d,,d,d,d,d,d,d,d,d,d,d,d,d
,,d,d,d,d,d,d,d,d,d,d,d,d,d,d,i,i,i,d,d,d,d,d,d,d,d,d,d,d,d,d,d
,,d,d,d,d,d,d,d,d,d,d,d,d,,d,i,i,i,d,,d,d,d,d,d,d,d,d,d,d,d,d
,,d,d,d,d,d,d,d,d,d,d,d,d,d,d,i,i,i,d,d,d,d,d,d,d,d,d,d,d,d,d,d
,,d,d,d,d,d,d,d,d,d,d,d,d,,d,d,d,d,d,,d,d,d,d,d,d,d,d,d,d,d,d
,,d,d,d,d,d,d,d,d,d,d,d,d,,,d,,d,,,d,d,d,d,d,d,d,d,d,d,d,d
,,d,d,d,d,d,d,d,d,d,d,d,d,d,d,d,d,d,d,d,d,d,d,d,d,d,d,d,d,d,d,d
,,d,d,d,d,d,d,d,d,d,d,d,d,d,d,d,d,d,d,d,d,d,d,d,d,d,d,d,d,d,d,d
,,d,d,d,d,d,d,d,d,d,d,d,d,d,d,d,d,d,d,d,d,d,d,d,d,d,d,d,d,d,d,d
,,,,d,d,d,d,d,d,d,d,d,d,d,d,d,d,d,d,d,d,d,d,d,d,d,d,d,d,d
,,,,d,d,d,d,d,d,d,d,d,d,d,d,d,d,d,d,d,d,d,d,d,d,d,d,d,d,d
,,,,d,d,d,d,d,d,d,d,d,d,d,d,d,d,d,d,d,d,d,d,d,d,d,d,d,d,d
,,,,d,d,d,d,d,d,d,d,d,d,d,d,d,d,d,d,d,d,d,d,d,d,d,d,d,d,d
,,,,d,d,d,d,d,d,d,d,d,d,d,d,d,d,d,d,d,d,d,d,d,d,d,d,d,d,d
,,,,d,d,d,d,d,d,d,d,d,d,d,d,d,d,d,d,d,d,d,d,d,d,d,d,d,d,d
,,,,d,d,d,d,d,d,d,d,d,d,d,d,d,d,d,d,d,d,d,d,d,d,d,d,d,d,d
,,,,,,,,,,,d,d,d,d,d,d,d,d,d,d,d,d,d
,,,,,,,,,,,d,d,d,d,d,d,d,d,d,d,d,d,d


"#meta label(industry2) start(staircase center) build workshops and stockpiles, configure stockpiles"
build/industry_build
place/industry_place
query/industry_query
#build label(industry_build) start(18; 18) hidden() use the meta blueprints for normal application


,,,,,,,,,,,`,`,`,`,`,`,`,`,`,`,`,`,`
,,,,,,,,,,,`,`,`,`,`,`,`,`,`,`,`,`,`
,,,,`,`,`,`,`,`,`,`,`,`,`,`,`,`,`,`,`,`,`,`,`,`,`,`,`,`,`
,,,,`,`,`,`,`,`,`,`,`,`,`,`,`,wm,`,`,`,`,`,`,`,`,`,`,`,`,`
,,,,`,`,wr,`,`,wr,`,`,`,`,`,`,`,`,`,`,`,`,`,`,`,`,`,`,`,`,`
,,,,`,`,`,`,`,`,`,`,`,wj,`,`,`,`,`,`,`,wt,`,`,`,`,`,`,`,`,`
,,,,`,`,`,`,`,`,`,`,`,`,`,`,`,`,`,`,`,`,`,`,`,`,`,`,`,`,`
,,,,`,`,wr,`,`,wr,`,`,`,`,`,`,`,trackstopN,`,`,`,`,`,`,`,`,`,`,`,`,`
,,,,`,`,`,`,`,`,`,`,`,wm,`,`,`,`,`,`,`,wm,`,`,`,`,`,`,`,`,`
,,`,`,`,`,`,`,`,`,`,`,`,`,`,`,`,`,`,`,`,`,`,`,`,`,`,`,`,`,`,`,`
,,`,`,`,`,`,`,`,`,`,`,`,`,`,`,`,`,`,`,`,`,`,`,`,`,`,`,`,`,`,`,`
,,`,`,wy,`,`,ew,`,`,ew,`,`,`,`,`,`,`,`,`,`,`,`,`,es,`,`,es,`,`,ek,`,`
,,`,`,`,`,`,`,`,`,`,`,`,`,,,d,,d,,,`,`,`,`,`,`,`,`,`,`,`,`
,,`,`,`,`,`,`,`,`,`,`,`,`,,`,`,`,`,`,,`,`,`,`,`,`,`,`,`,`,`,`
,,`,`,`,`,`,`,`,`,`,`,`,`,d,`,,,,`,d,`,`,`,`,`,`,`,`,`,`,`,`
,,`,`,`,wc,`,`,`,trackstopW,`,`,`,`,,`,,`,,`,,`,`,`,`,trackstopE,`,`,`,wf,`,`,`
,,`,`,`,`,`,`,`,`,`,`,`,`,d,`,,,,`,d,`,`,`,`,`,`,`,`,`,`,`,`
,,`,`,`,`,`,`,`,`,`,`,`,`,,`,`,`,`,`,,`,`,`,`,`,`,`,`,`,`,`,`
,,`,`,`,`,`,`,`,`,`,`,`,`,,,d,,d,,,`,`,`,`,`,`,`,`,`,`,`,`
,,`,`,wS,`,`,ew,`,`,ew,`,`,`,`,`,`,`,`,`,`,`,`,`,es,`,`,es,`,`,eg,`,`
,,`,`,`,`,`,`,`,`,`,`,`,`,`,`,`,`,`,`,`,`,`,`,`,`,`,`,`,`,`,`,`
,,`,`,`,`,`,`,`,`,`,`,`,`,`,`,`,`,`,`,`,`,`,`,`,`,`,`,`,`,`,`,`
,,,,`,`,`,`,`,`,`,`,`,wb,`,`,`,`,`,`,`,wk,`,`,`,`,`,`,`,`,`
,,,,`,`,`,`,`,`,`,`,`,`,`,`,`,trackstopS,`,`,`,`,`,`,`,`,`,`,`,`,`
,,,,`,`,`,`,ws,`,`,`,`,`,`,`,`,`,`,`,`,`,`,`,`,`,`,`,`,`,`
,,,,`,`,`,`,`,`,`,`,`,wd,`,`,`,`,`,`,`,wo,`,`,`,`,`,`,`,`,`
,,,,`,`,`,`,`,`,`,`,`,`,`,`,`,`,`,`,`,`,`,`,`,`,`,`,`,`,`
,,,,`,`,`,`,`,`,`,`,`,`,`,`,`,we,`,`,`,`,`,`,`,`,`,`,`,`,`
,,,,`,`,`,`,`,`,`,`,`,`,`,`,`,`,`,`,`,`,`,`,`,`,`,`,`,`,`
,,,,,,,,,,,`,`,`,`,`,`,`,`,`,`,`,`,`
,,,,,,,,,,,`,`,`,`,`,`,`,`,`,`,`,`,`


#place label(industry_place) start(18; 18) hidden() use the meta blueprints for normal application


,,,,,,,,,,,e,e,e,e,e,e,e,e,e,e,e,e,e
,,,,,,,,,,,`,`,`,`,`,`,`,`,`,`,`,`,`
,,,,`,`,`,`,`,`,`,`,`,`,`,`,`,`,`,`,`,`,`,`,`,`,`,`,`,`,`
,,,,`,`,`,`,`,`,`,`,`,`,`,`,`,`,`,`,`,`,`,`,`,`,`,`,`,`,`
,,,,`,`,`,`,`,`,`,`,`,`,`,`,`,`,`,`,`,`,`,`,`,`,`,`,`,`,`
,,,,`,`,`,`,`,`,`,`,`,`,`,`,`,`,`,`,`,`,`,`,`,`,`,`,`,`,`
,,,,`,`,`,`,`,`,`,`,`,`,`,`,`,c,`,`,`,`,`,`,`,`,`,`,`,`,`
,,,,`,`,`,`,`,`,`,`,`,`,`,`,`,`,`,`,`,`,`,`,`,`,`,`,`,`,`
,,,,`,`,`,`,`,`,`,`,`,`,`,`,se(3x3),,,`,`,`,`,`,`,`,`,`,`,`,`
,,f,`,`,`,`,`,`,`,`,`,`,`,`,`,~,~,~,`,`,`,`,`,`,`,`,`,`,`,`,`,b(1x6)
,,f,`,`,`,`,`,`,`,`,`,`,`,`,`,~,~,~,`,`,`,`,`,`,`,`,`,`,`,`,`,`
,,f,`,`,`,`,`,`,`,`,`,`,`,`,`,`,`,`,`,`,`,`,`,`,`,`,`,`,`,`,`,`
,,f,`,`,`,`,`,`,`,`,`,`,`,,,`,,`,,,`,`,`,`,`,`,`,`,`,`,`,`
,,f,`,`,`,`,`,`,`,`,`,`,`,,`,`,`,`,`,,`,`,`,`,`,`,`,`,`,`,`,`
,,f,`,`,`,`,`,`,`,afngwS(3x3),,,`,`,`,,,,`,`,`,sbpdz(3x3),,,`,`,`,`,`,`,`,`
,,f,`,`,`,`,`,c,`,~,~,~,`,,`,,`,,`,,`,~,~,~,`,c,`,`,`,`,`,`
,,f,`,`,`,`,`,`,`,~,~,~,`,`,`,,,,`,`,`,~,~,~,`,`,`,`,`,`,`,b(1x6)
,,f,`,`,`,`,`,`,`,`,`,`,`,,`,`,`,`,`,,`,`,`,`,`,`,`,`,`,`,`,`
,,f,`,`,`,`,`,`,`,`,`,`,`,,,`,,`,,,`,`,`,`,`,`,`,`,`,`,`,`
,,f,`,`,`,`,`,`,`,`,`,`,`,`,`,`,`,`,`,`,`,`,`,`,`,`,`,`,`,`,`,`
,,f,`,`,`,`,`,`,`,`,`,`,`,`,`,rhl(3x3),,,`,`,`,`,`,`,`,`,`,`,`,`,`,`
,,f,`,`,`,`,`,`,`,`,`,`,`,`,`,~,~,~,`,`,`,`,`,`,`,`,`,`,`,`,`,`
,,,,`,`,`,`,`,`,`,`,`,`,`,`,~,~,~,`,`,`,`,`,pd(6x3),,,~,~,~,`
,,,,`,`,`,`,`,`,`,`,`,`,`,`,`,`,`,`,`,`,`,`,~,~,~,~,~,~,`
,,,,`,`,`,`,`,`,`,`,`,`,`,`,`,r,`,`,`,`,`,`,~,~,~,~,~,~,`
,,,,`,`,`,`,`,`,`,`,`,`,`,`,`,`,`,`,`,`,`,`,`,`,`,`,`,`,`
,,,,`,`,`,`,`,`,`,`,`,`,`,`,`,`,`,`,`,`,`,`,pd(6x3),,,~,~,~,`
,,,,`,`,`,`,`,`,`,`,`,`,`,`,`,`,`,`,`,`,`,`,~,~,~,~,~,~,`
,,,,`,`,`,`,`,`,`,`,`,`,`,`,`,`,`,`,`,`,`,`,~,~,~,~,~,~,`
,,,,,,,,,,,`,`,`,`,`,`,`,`,`,`,`,`,`
,,,,,,,,,,,`,`,`,`,`,`,`,`,`,`,`,`,`


"#query label(industry_query) start(18; 18) hidden() message(remember to:
- assign minecarts to to your quantum stockpile hauling routes
- if the farming level is already built, give from the ""Goods"" quantum stockpile to the jugs, pots, and bags stockpiles on the farming level
- if you want to automatically melt goblinite and other low-quality weapons and armor, mark the south-east stockpiles for auto-melt) use the meta blueprints for normal application
- now that your industry is set up, run ""orders import automation"" to automate your fort's basic needs (download automation.json from https://drive.google.com/file/d/17WcN5mK-rnADOm2B_JFpPnByYgkYjxhb/view?usp=sharing and put it in your dfhack-config/orders/ directory)"


,,,,,,,,,,,roughgems,nocontainers,"{givename name=""rough gems for moods""}",`,`,`,t{Down 6}&,`,`,`,`,`,`
,,,,,,,,,,,`,`,`,`,`,`,`,`,`,`,`,`,`
,,,,`,`,`,`,`,`,`,`,`,`,`,`,`,`,`,`,`,`,`,`,`,`,`,`,`,`,`
,,,,`,`,`,`,`,`,`,`,`,`,`,`,`,`,`,`,`,`,`,`,`,`,`,`,`,`,`
,,,,`,`,`,`,`,`,`,`,`,`,`,`,`,`,`,`,`,`,`,`,`,`,`,`,`,`,`
,,,,`,`,`,`,`,`,`,`,`,`,`,`,`,`,`,`,`,`,`,`,`,`,`,`,`,`,`
,,,,`,`,`,`,`,`,`,`,`,`,`,`,`,"{quantum name=""stoneworker quantum""}g{Up}{Left 5}&",`,`,`,`,`,`,`,`,`,`,`,`,`
,,,,`,`,`,`,`,`,`,`,`,`,`,`,`,"{quantumstopfromsouth name=""Stoneworker quantum""}{givename name=""stoneworker dumper""}",`,`,`,`,`,`,`,`,`,`,`,`,`
,,,,`,`,`,`,`,`,`,`,`,`,`,`,otherstone,,"{givename name=""stoneworker feeder""}",`,`,`,`,`,`,`,`,`,`,`,`
,,miscliquid,`,`,`,`,`,`,`,`,`,`,`,`,`,~,nocontainers,~,`,`,`,`,`,`,`,`,`,`,`,`,`,steelbars
,,nocontainers,`,`,`,`,`,`,`,`,`,`,`,`,`,~,~,~,`,`,`,`,`,`,`,`,`,`,`,`,`,"{givename name=""steel""}"
,,"{givename name=""non-quantum liquids""}",`,`,`,`,`,`,`,`,`,`,`,`,`,`,`,`,`,`,`,`,`,`,`,`,`,`,`,`,`,`
,,`,`,`,`,`,`,`,`,`,`,`,`,,,`,,`,,,`,`,`,`,`,`,`,`,`,`,`,`
,,`,`,`,`,`,`,`,`,`,`,`,`,,`,`,`,`,`,,`,`,`,`,`,`,`,`,`,`,`,`
,,`,`,`,`,`,`,`,`,{cages}{permittraps},,,`,`,`,,,,`,`,`,forbidotherstone,,,`,`,`,`,`,`,`,t{Left 6}{Down}&
,,`,`,`,`,`,`,"{quantum name=""goods/wood quantum""}g{Up 10}{Right 4}&","{quantumstopfromeast name=""Goods/Wood quantum""}{givename name=""goods/wood dumper""}",~,nocontainers,"{givename name=""goods/wood feeder""}",`,,`,,`,,`,,`,"{givename name=""metalworker feeder""}",nocontainers,~,"{quantumstopfromwest name=""Metalworker quantum""}{givename name=""metalworker dumper""}","{quantum name=""metalworker quantum""}",`,`,`,`,`,`
,,`,`,`,`,`,`,`,`,{tallow}{permitdye},,,`,`,`,,,,`,`,`,forbidpotash,,,`,`,`,`,`,`,`,t{Left 6}{Up}&
,,`,`,`,`,`,`,`,`,`,`,`,`,,`,`,`,`,`,,`,`,`,`,`,`,`,`,`,`,`,`
,,`,`,`,`,`,`,`,`,`,`,`,`,,,`,,`,,,`,`,`,`,`,`,`,`,`,`,`,`
,,`,`,`,`,`,`,`,`,`,`,`,`,`,`,`,`,`,`,`,`,`,`,`,`,`,`,`,`,`,`,`
,,`,`,`,`,`,`,`,`,`,`,`,`,`,`,craftrefuse,,"{givename name=""cloth/bones feeder""}",`,`,`,`,`,`,`,`,`,`,`,`,`,"{givename name=""coal""}"
,,`,`,`,`,`,`,`,`,`,`,`,`,`,`,~,nocontainers,~,`,`,`,`,`,`,`,`,`,`,`,`,`,coal
,,,,`,`,`,`,`,`,`,`,`,`,`,`,~,~,~,`,`,`,`,`,nocontainers,"{givename name=""meltable iron/steel""}",t{Up 7}&,~,~,~,~
,,,,`,`,`,`,`,`,`,`,`,`,`,`,`,"{quantumstopfromnorth name=""Clothier/Bones quantum""}{givename name=""cloth/bones dumper""}",`,`,`,`,`,`,{ironweapons}{permitsteelweapons}{forbidmasterworkweapons}{forbidartifactweapons}
,,,,`,`,`,`,`,`,`,`,`,`,`,`,`,"{quantum name=""cloth/bones quantum""}",`,`,`,`,`,`,{ironarmor}{permitsteelarmor},forbidmasterworkarmor,forbidartifactarmor,~,~,~,~
,,,,`,`,`,`,`,`,`,`,`,`,`,`,`,`,`,`,`,`,`,`,`,`,`,`,`,`,`
,,,,`,`,`,`,`,`,`,`,`,`,`,`,`,`,`,`,`,`,`,`,nocontainers,give2up,t{Up 11}&,"{givename name=""meltables""}",~,~,~
,,,,`,`,`,`,`,`,`,`,`,`,`,`,`,`,`,`,`,`,`,`,{metalweapons}{forbidmasterworkweapons}{forbidartifactweapons}
,,,,`,`,`,`,`,`,`,`,`,`,`,`,`,`,`,`,`,`,`,`,metalarmor,forbidmasterworkarmor,forbidartifactarmor,~,~,~,~
,,,,,,,,,,,`,`,`,`,`,`,`,`,`,`,`,`,`
,,,,,,,,,,,`,`,`,`,`,`,`,`,`,`,`,`,`


#notes label(services_help)
"Sets up public services (dining, hospital, etc.)"
""
Features:
- Spacious dining room (also usable as a tavern)
- Prepared food and drink stockpiles
- Well system (bring your own water)
- Public baths with soap stockpiles
- Three well-appointed jail cells
- Hospital with beds and storage
- Garbage dump
""
Manual steps you have to take:
"- If you want to declare the dining room as a tavern, the bedrooms at the top can be assigned to the tavern as rented rooms."
"- Configure the soap stockpiles to take from the industry level ""Metalworker"" quantum stockpile (which holds all the bars)"
"- Activate the bath pond zones when you are ready to fill them with 3-depth water. This is the only really fiddly bit, since you have to carefully disable the pond zone again when the final bucket to bring the water to an even 3-depth is on the way."
"- Fill the cisterns with water, either with a bucket brigade or by plumbing flowing water. Fill so that there are two z-levels of 7-depth water to prevent muddiness. If you want to fill with buckets, designate a pond zone on the level below the main floor. If you feel adventurous and are experienced with water pressure, you can instead route (depressurized!) water to the second-to-bottom level (the one above the up staircases)."
""
Services Walkthough:
1) Start this level before your fort grows beyond around 50 dwarves so everyone has a place to eat.
""
"2) Start digging with /services1. Note that this digs out the main level and three levels below for the well plumbing. Start manufacturing with ""quickfort orders"" on /services2."
""
"3) Once the area is dug out, set up the furniture, stockpiles, and hospital and garbage dump zones with /services2. Fill your soap stockpiles around the bath channels by configuring them to take from the bar quantum stockpile (the one on the right near the forge) on the industry level."
""
"4) When all furniture is placed, run /services3 to configure your dining room and jail."
""
5) Fill the bath and wells with either a bucket brigade or by carefully routing flowing water to them.
"#dig label(services1) start(23; 22; staircase center) message(This would be a good time to queue manager orders for /services2. Once the area is dug out, continue with /services2.)"


,,d,d,d,,,d,d,d,,,d,d,d
,,d,d,d,,,d,d,d,,,d,d,d
,,d,d,d,,,d,d,d,,,d,d,d
,,,d,,,,,d,,,,,d
,,d,d,d,d,d,d,d,d,d,d,d,d,d
,,d,d,d,d,d,d,d,d,d,d,d,d,d
,,d,d,d,d,d,d,d,d,d,d,d,d,d
,,d,d,d,d,d,d,d,d,d,d,d,d,d
,,d,d,d,d,d,d,d,d,d,d,d,d,d
,,d,d,d,d,d,d,d,d,d,d,d,d,d
,,d,d,d,d,d,d,d,d,d,d,d,d,d
,,d,d,d,d,d,d,d,d,d,d,d,d,d
,,d,d,d,d,d,d,d,d,d,d,d,d,d
,,d,d,h,d,d,d,h,d,d,d,h,d,d,,,,d,h,d,d,h,d,d,h,d
,,d,d,d,d,d,d,d,d,d,d,d,d,d,,,,d,d,d,d,d,d,d,d,d,,,,d,d,d,d,d,d,d,d,d
,,d,d,d,d,d,d,d,d,d,d,d,d,d,,,,d,d,d,d,d,d,d,d,d,,,,d,d,d,d,d,d,d,d,d
,,d,d,d,d,d,d,d,d,d,d,d,d,d,,,,,,,,d,,,,,,,,d,d,d,d,d,d,d,d,d
,,d,d,d,d,d,d,d,d,d,d,d,d,d,,d,d,d,,d,d,d,d,d,,d,d,d,,d,d,d,d,d,d,d,d,d
,,d,d,d,d,d,d,d,d,d,d,d,d,d,d,d,h,d,d,d,i,i,i,d,d,d,h,d,d,d,d,d,d,d,d,d,d,d
,,d,d,d,d,d,d,d,d,d,d,d,d,d,,d,h,d,,d,i,i,i,d,,d,h,d,,d,d,d,d,h,d,d,d,d
,,d,d,d,d,d,d,d,d,d,d,d,d,d,d,d,h,d,d,d,i,i,i,d,d,d,h,d,d,d,d,d,d,d,d,d,d,d
,,d,d,d,d,d,d,d,d,d,d,d,d,d,,d,d,d,,d,d,d,d,d,,d,d,d,,d,d,d,d,d,d,d,d,d
,,d,d,d,d,d,d,d,d,d,d,d,d,d,,,,,,,,d,,,,,,,,d,d,d,d,d,d,d,d,d
,,,,,,d,d,,d,d,,,,,,,,,,,,,,,,,,,,d,d,d,d,d,d,d,d,d
,,d,d,d,d,d,d,,d,d,d,d,d,d,,,,,,,,,,,,,,,,d,d,d,d,d,d,d,d,d
,,d,d,d,d,d,d,,d,d,d,d,d,d
,,d,d,d,d,d,d,,d,d,d,d,d,d
,,d,d,d,d,d,d,,d,d,d,d,d,d
,,d,d,d,d,d,d,,d,d,d,d,d,d
#>















,,,j,h,j,d,j,h,j,d,j,h,j,,,,,j,h,j,j,h,j,j,h,j
,,,d,d,d,d,d,d,d,d,d,d,d,,,,,d,d,d,d,d,d,d,d,d
,,,,,,,,d,,,,,,,,,,,,,,d
,,,,,,,,d,,,,,,,,,,,,,,d
,,,,,,,,d,,,,,,,,,,,,d,d,d,d,d
,,,,,,,,d,,,,,,,,,`,,,d,i,i,i,d,,,`
,,,,,,,,d,,,,,,,,,`,,,d,i,i,i,d,,,`,,,,,,j,h,j
,,,,,,,,d,,,,,,,,,`,,,d,i,i,i,d,,,`,,,,,,d,d,d
,,,,,,,,d,,,,,,,,,,,,d,d,d,d,d,,,,,,,,,,d
,,,,,,,,d,,,,,,,,,,,,,,d,,,,,,,,,,,,d
,,,,,,,,d,d,d,d,d,d,d,d,d,d,d,d,d,d,d,d,d,d,d,d,d,d,d,d,d,d,d
#>















,,,i,h5,i,,i,h5,i,,i,h5,i,,,,,i,h5,i,i,h5,i,i,h5,i



,,,,,,,,,,,,,,,,,,,,d,d,d,d,d
,,,,,,,,,,,,,,,,,,,,d,i,i,i,d
,,,,,,,,,,,,,,,,,,,,d,i,i,i,d,,,,,,,,,i,h5,i
,,,,,,,,,,,,,,,,,,,,d,i,i,i,d
,,,,,,,,,,,,,,,,,,,,d,d,d,d,d
#>















,,,u,d,u,,u,d,u,,u,d,u,,,,,u,d,u,u,d,u,u,d,u



,,,,,,,,,,,,,,,,,,,,d,d,d,d,d
,,,,,,,,,,,,,,,,,,,,d,i,i,i,d
,,,,,,,,,,,,,,,,,,,,d,i,i,i,d,,,,,,,,,u,d,u
,,,,,,,,,,,,,,,,,,,,d,i,i,i,d
,,,,,,,,,,,,,,,,,,,,d,d,d,d,d


"#meta label(services2) start(staircase center) message(Once furniture has been placed, continue with /services3.) furniture, stockpiles, hospital, garbage dump"
build/services_build
place/services_place
zone/services_zone
name_zones/services_name_zones
query_stockpiles/services_query_stockpiles
#build label(services_build) start(23; 22) hidden() use the meta blueprints for normal application


,,b,b,b,,,b,b,b,,,b,b,b
,,`,`,`,,,`,`,`,,,`,`,`
,,f,`,h,,,f,`,h,,,f,`,h
,,,d,,,,,d,,,,,d
,,s,`,`,s,s,`,`,`,s,s,`,`,s
,,`,`,`,`,`,`,`,`,`,`,`,`,`
,,s,`,`,`,`,`,`,`,`,`,`,`,s
,,`,`,`,`,`,`,`,`,`,`,`,`,`
,,s,`,`,`,`,`,`,`,`,`,`,`,s
,,`,`,`,`,`,`,`,`,`,`,`,`,`
,,s,`,`,`,`,`,`,`,`,`,`,`,s
,,`,`,`,`,`,`,`,`,`,`,`,`,`
,,s,`,`,`,`,`,`,`,`,`,`,`,s
,,`,`,l,`,`,`,l,`,`,`,l,`,`,,,,t,l,b,t,l,b,t,l,b
,,s,`,`,`,`,`,`,`,`,`,`,`,s,,,,c,v,`,c,v,`,c,v,`,,,,f,`,s,s,`,b,b,b,b
,,`,`,c,t,t,c,`,c,t,t,c,`,`,,,,`,`,`,`,`,`,`,`,`,,,,h,`,`,`,`,`,`,`,b
,,s,`,c,t,t,c,`,c,t,t,c,`,s,,,,,,,,d,,,,,,,,f,`,`,`,`,`,t,`,b
,,`,`,c,t,t,c,`,c,t,t,c,`,`,,`,s,`,,`,`,`,`,`,,`,s,`,,`,`,`,`,`,`,`,`,`
,,s,`,c,t,t,c,`,c,t,t,c,`,`,d,`,`,`,d,`,`,`,`,`,d,`,`,`,d,`,`,`,`,`,`,`,`,R
,,`,`,c,t,t,c,`,c,t,t,c,`,`,,`,`,`,,`,`,`,`,`,,`,`,`,,`,`,`,`,l,`,`,`,R
,,s,`,c,t,t,c,`,c,t,t,c,`,`,d,`,`,`,d,`,`,`,`,`,d,`,`,`,d,`,`,`,`,`,`,`,`,R
,,`,`,`,`,`,`,`,`,`,`,`,`,`,,`,s,`,,`,`,`,`,`,,`,s,`,,`,`,`,`,`,`,`,`,`
,,h,s,s,h,`,`,`,`,`,h,s,s,h,,,,,,,,`,,,,,,,,f,`,`,`,`,`,t,`,b
,,,,,,`,`,,`,`,,,,,,,,,,,,,,,,,,,,h,`,`,`,`,`,`,`,b
,,`,`,`,`,`,`,,`,`,`,`,`,`,,,,,,,,,,,,,,,,f,`,s,s,`,b,b,b,b
,,`,`,`,`,`,`,,`,`,`,`,`,`
,,`,`,`,`,`,`,,`,`,`,`,`,`
,,`,`,`,`,`,`,,`,`,`,`,`,`
,,`,`,`,`,`,`,,`,`,`,`,`,`
#>















,,,`,`,`,`,`,`,`,`,`,`,`,,,,,`,`,`,`,`,`,`,`,`
,,,`,`,`,`,`,`,`,`,`,`,`,,,,,`,`,`,`,`,`,`,`,`
,,,,,,,,d,,,,,,,,,,,,,,d
,,,,,,,,`,,,,,,,,,,,,,,d
,,,,,,,,`,,,,,,,,,,,,`,`,`,`,`
,,,,,,,,`,,,,,,,,,`,,,`,`,`,`,`,,,`
,,,,,,,,`,,,,,,,,,`,,,`,`,`,`,`,,,`,,,,,,`,`,`
,,,,,,,,`,,,,,,,,,`,,,`,`,`,`,`,,,`,,,,,,`,`,`
,,,,,,,,`,,,,,,,,,,,,`,`,`,`,`,,,,,,,,,,d
,,,,,,,,`,,,,,,,,,,,,,,d,,,,,,,,,,,,`
,,,,,,,,`,`,`,`,`,`,`,`,`,`,`,`,`,`,`,`,`,`,`,`,`,`,`,`,`,`,`


#place label(services_place) start(23; 22) hidden() use the meta blueprints for normal application


,,`,`,`,,,`,`,`,,,`,`,`
,,`,`,`,,,`,`,`,,,`,`,`
,,`,`,`,,,`,`,`,,,`,`,`
,,,`,,,,,`,,,,,`
,,`,`,`,`,`,`,`,`,`,`,`,`,`
,,`,`,`,`,`,`,`,`,`,`,`,`,`
,,`,`,`,`,`,`,`,`,`,`,`,`,`
,,`,`,`,`,`,`,`,`,`,`,`,`,`
,,`,`,`,`,`,`,`,`,`,`,`,`,`
,,`,`,`,`,`,`,`,`,`,`,`,`,`
,,`,`,`,`,`,`,`,`,`,`,`,`,`
,,`,`,`,`,`,`,`,`,`,`,`,`,`
,,`,`,`,`,`,`,`,`,`,`,`,`,`
,,`,`,`,`,`,`,`,`,`,`,`,`,`,,,,`,`,`,`,`,`,`,`,`
,,`,`,`,`,`,`,`,`,`,`,`,`,`,,,,`,`,f(1x2),`,`,f(1x2),`,`,f(1x2),,,,`,`,`,`,`,`,`,`,`
,,`,`,`,`,`,`,`,`,`,`,`,`,`,,,,f(2x1),`,`,f(2x1),`,`,f(2x1),`,`,,,,`,`,`,`,`,`,`,`,`
,,`,`,`,`,`,`,`,`,`,`,`,`,`,,,,,,,,`,,,,,,,,`,`,`,`,`,`,`,`,`
,,`,`,`,`,`,`,`,`,`,`,`,`,`,,b(3x5),`,`,,`,`,`,`,`,,b(3x5),`,`,,`,`,`,`,`,`,`,`,`
,,`,`,`,`,`,`,`,`,`,`,`,`,`,`,`,`,`,`,`,`,`,`,`,`,`,`,`,`,`,`,`,`,`,`,`,`,`
,,`,`,`,`,`,`,`,`,`,`,`,`,`,,`,`,`,,`,`,`,`,`,,`,`,`,,`,`,`,`,`,`,`,`,`
,,`,`,`,`,`,`,`,`,`,`,`,`,`,`,`,`,`,`,`,`,`,`,`,`,`,`,`,`,`,`,`,`,`,`,`,`,`
,,`,`,`,`,`,`,`,`,`,`,`,`,`,,`,`,`,,`,`,`,`,`,,`,`,`,,`,`,`,`,`,`,`,`,`
,,`,`,`,`,`,`,`,`,`,`,`,`,`,,,,,,,,`,,,,,,,,`,`,`,`,`,`,`,`,`
,,,,,,`,`,,`,`,,,,,,,,,,,,,,,,,,,,`,`,`,`,`,`,`,`,`
,,f(6x5),`,`,`,`,`,,f(6x5),`,`,`,`,`,,,,,,,,,,,,,,,,`,`,`,`,`,`,`,`,`
,,`,`,`,`,`,`,,`,`,`,`,`,`
,,`,`,`,`,`,`,,`,`,`,`,`,`
,,`,`,`,`,`,`,,`,`,`,`,`,`
,,`,`,`,`,`,`,,`,`,`,`,`,`


#zone label(services_zone) start(23; 22) hidden() message(activate the bath pond zones when you are ready to fill them with 3-depth water) use the meta blueprints for normal application


,,`,`,`,,,`,`,`,,,`,`,`
,,`,`,`,,,`,`,`,,,`,`,`
,,`,`,`,,,`,`,`,,,`,`,`
,,,`,,,,,`,,,,,`
,,`,`,`,`,`,`,`,`,`,`,`,`,`
,,`,`,`,`,`,`,`,`,`,`,`,`,`
,,`,`,`,`,`,`,`,`,`,`,`,`,`
,,`,`,`,`,`,`,`,`,`,`,`,`,`
,,`,`,`,`,`,`,`,`,`,`,`,`,`
,,`,`,`,`,`,`,`,`,`,`,`,`,`
,,`,`,`,`,`,`,`,`,`,`,`,`,`
,,`,`,`,`,`,`,`,`,`,`,`,`,`
,,`,`,`,`,`,`,`,`,`,`,`,`,`
,,`,`,`,`,`,`,`,`,`,`,`,`,`,,,,`,`,`,`,`,`,`,`,`
,,`,`,`,`,`,`,`,`,`,`,`,`,`,,,,`,`,`,`,`,`,`,`,`,,,,h(9x11),`,`,`,`,`,`,`,`
,,`,`,`,`,`,`,`,`,`,`,`,`,`,,,,`,`,`,`,`,`,`,`,`,,,,`,`,`,`,`,`,`,`,`
,,`,`,`,`,`,`,`,`,`,`,`,`,`,,,,,,,,`,,,,,,,,`,`,`,`,`,`,`,`,`
,,`,`,`,`,`,`,`,`,`,`,`,`,`,,`,`,`,,`,`,`,`,`,,`,`,`,,`,`,`,`,`,`,`,`,`
,,`,`,`,`,`,`,`,`,`,`,`,`,`,`,`,apPf(1x3),`,`,`,`,`,`,`,`,`,apPf(1x3),`,`,`,`,`,`,`,`,`,`,`
,,`,`,`,`,`,`,`,`,`,`,`,`,`,,`,~,`,,`,`,`,`,`,,`,~,`,,`,`,`,`,`,`,`,`,`
,,`,`,`,`,`,`,`,`,`,`,`,`,`,`,`,~,`,`,`,`,`,`,`,`,`,~,`,`,`,`,`,`,`,`,`,`,`
,,`,`,`,`,`,`,`,`,`,`,`,`,`,,`,`,`,,`,`,`,`,`,,`,`,`,,`,`,`,`,`,`,`,`,`
,,`,`,`,`,`,`,`,`,`,`,`,`,`,,,,,,,,d,,,,,,,,`,`,`,`,`,`,`,`,`
,,,,,,`,`,,`,`,,,,,,,,,,,,,,,,,,,,`,`,`,`,`,`,`,`,`
,,`,`,`,`,`,`,,`,`,`,`,`,`,,,,,,,,,,,,,,,,`,`,`,`,`,`,`,`,`
,,`,`,`,`,`,`,,`,`,`,`,`,`
,,`,`,`,`,`,`,,`,`,`,`,`,`
,,`,`,`,`,`,`,,`,`,`,`,`,`
,,`,`,`,`,`,`,,`,`,`,`,`,`


#query label(services_name_zones) start(23; 22) hidden() use the meta blueprints for normal application


,,`,`,`,,,`,`,`,,,`,`,`
,,`,`,`,,,`,`,`,,,`,`,`
,,`,`,`,,,`,`,`,,,`,`,`
,,,`,,,,,`,,,,,`
,,`,`,`,`,`,`,`,`,`,`,`,`,`
,,`,`,`,`,`,`,`,`,`,`,`,`,`
,,`,`,`,`,`,`,`,`,`,`,`,`,`
,,`,`,`,`,`,`,`,`,`,`,`,`,`
,,`,`,`,`,`,`,`,`,`,`,`,`,`
,,`,`,`,`,`,`,`,`,`,`,`,`,`
,,`,`,`,`,`,`,`,`,`,`,`,`,`
,,`,`,`,`,`,`,`,`,`,`,`,`,`
,,`,`,`,`,`,`,`,`,`,`,`,`,`
,,`,`,`,`,`,`,`,`,`,`,`,`,`,,,,`,`,`,`,`,`,`,`,`
,,`,`,`,`,`,`,`,`,`,`,`,`,`,,,,`,`,`,`,`,`,`,`,`,,,,"{namezone name=""hospital""}",`,`,`,`,`,`,`,`
,,`,`,`,`,`,`,`,`,`,`,`,`,`,,,,`,`,`,`,`,`,`,`,`,,,,`,`,`,`,`,`,`,`,`
,,`,`,`,`,`,`,`,`,`,`,`,`,`,,,,,,,,`,,,,,,,,`,`,`,`,`,`,`,`,`
,,`,`,`,`,`,`,`,`,`,`,`,`,`,,`,`,`,,`,`,`,`,`,,`,`,`,,`,`,`,`,`,`,`,`,`
,,`,`,`,`,`,`,`,`,`,`,`,`,`,`,`,"{namezone name=""bath1""}",`,`,`,`,`,`,`,`,`,"{namezone name=""bath2""}",`,`,`,`,`,`,`,`,`,`,`
,,`,`,`,`,`,`,`,`,`,`,`,`,`,,`,~,`,,`,`,`,`,`,,`,~,`,,`,`,`,`,`,`,`,`,`
,,`,`,`,`,`,`,`,`,`,`,`,`,`,`,`,~,`,`,`,`,`,`,`,`,`,~,`,`,`,`,`,`,`,`,`,`,`
,,`,`,`,`,`,`,`,`,`,`,`,`,`,,`,`,`,,`,`,`,`,`,,`,`,`,,`,`,`,`,`,`,`,`,`
,,`,`,`,`,`,`,`,`,`,`,`,`,`,,,,,,,,"{namezone name=""garbage dump""}",,,,,,,,`,`,`,`,`,`,`,`,`
,,,,,,`,`,,`,`,,,,,,,,,,,,,,,,,,,,`,`,`,`,`,`,`,`,`
,,`,`,`,`,`,`,,`,`,`,`,`,`,,,,,,,,,,,,,,,,`,`,`,`,`,`,`,`,`
,,`,`,`,`,`,`,,`,`,`,`,`,`
,,`,`,`,`,`,`,,`,`,`,`,`,`
,,`,`,`,`,`,`,,`,`,`,`,`,`
,,`,`,`,`,`,`,,`,`,`,`,`,`


"#query label(services_query_stockpiles) start(23; 22) hidden() message(remember to configure the soap stockpiles to take from the ""Metalworker"" quantum stockpile on the industry level (where all bars are stored)) use the meta blueprints for normal application"


,,`,`,`,,,`,`,`,,,`,`,`
,,`,`,`,,,`,`,`,,,`,`,`
,,`,`,`,,,`,`,`,,,`,`,`
,,,`,,,,,`,,,,,`
,,`,`,`,`,`,`,`,`,`,`,`,`,`
,,`,`,`,`,`,`,`,`,`,`,`,`,`
,,`,`,`,`,`,`,`,`,`,`,`,`,`
,,`,`,`,`,`,`,`,`,`,`,`,`,`
,,`,`,`,`,`,`,`,`,`,`,`,`,`
,,`,`,`,`,`,`,`,`,`,`,`,`,`
,,`,`,`,`,`,`,`,`,`,`,`,`,`
,,`,`,`,`,`,`,`,`,`,`,`,`,`
,,`,`,`,`,`,`,`,`,`,`,`,`,`
,,`,`,`,`,`,`,`,`,`,`,`,`,`,,,,`,`,`,`,`,`,`,`,`
,,`,`,`,`,`,`,`,`,`,`,`,`,`,,,,`,`,"{booze}{givename name=""booze""}",`,`,"{booze}{givename name=""booze""}",`,`,"{booze}{givename name=""booze""}",,,,`,`,`,`,`,`,`,`,`
,,`,`,`,`,`,`,`,`,`,`,`,`,`,,,,"{preparedfood}{givename name=""prepared food""}",t{Down 10}{Left 12}&,t{Down 10}{Left 10}&,"{preparedfood}{givename name=""prepared food""}",t{Down 10}{Left 20}&,t{Down 10}{Left 10}&,"{preparedfood}{givename name=""prepared food""}",t{Down 10}{Left 20}&,t{Down 10}{Left 12}&,,,,`,`,`,`,`,`,`,`,`
,,`,`,`,`,`,`,`,`,`,`,`,`,`,,,,,,,,`,,,,,,,,`,`,`,`,`,`,`,`,`
,,`,`,`,`,`,`,`,`,`,`,`,`,`,,soap,`,`,,`,`,`,`,`,,soap,`,`,,`,`,`,`,`,`,`,`,`
,,`,`,`,`,`,`,`,`,`,`,`,`,`,`,nocontainers,`,`,`,`,`,`,`,`,`,nocontainers,`,`,`,`,`,`,`,`,`,`,`,`
,,`,`,`,`,`,`,`,`,`,`,`,`,`,,"{givename name=""soap1""}",`,`,,`,`,`,`,`,,"{givename name=""soap2""}",`,`,,`,`,`,`,`,`,`,`,`
,,`,`,`,`,`,`,`,`,`,`,`,`,`,`,`,`,`,`,`,`,`,`,`,`,`,`,`,`,`,`,`,`,`,`,`,`,`
,,`,`,`,`,`,`,`,`,`,`,`,`,`,,`,`,`,,`,`,`,`,`,,`,`,`,,`,`,`,`,`,`,`,`,`
,,`,`,`,`,`,`,`,`,`,`,`,`,`,,,,,,,,`,,,,,,,,`,`,`,`,`,`,`,`,`
