#notes label(help) run me for the dreamfort walkthrough
"Welcome to Dreamfort! These blueprints will help you build a functional, secure, fully self-sustaining fortress that you can use as-is or extend to build the fortress of your dreams!"
""
"It can be difficult to apply a set of blueprints that you did not write yourself. This walkthrough will guide you through the high-level steps of building Dreamfort. Run ""quickfort run library/dreamfort.csv -n /checklist"" (or, if you're looking at the online version, switch to the ""checklist"" sheet) for a compact list of the commands you'll be running. Each level also has its own mini-walkthrough with more details."
""
"The final fort will have a walled-in area on the surface for livestock, trading, aboveground farming, and military training. One z-level down is the farming level, with related workshops and vents up to the surface for miasma prevention. The farming level also has a miniature dining hall and dormitory for use until you get the services and housing levels set up."
""
"Beyond those two, the other layers can be built in any order, at any z-level, according to your preference and the layout peculiarities of your embark site:"
"- The industry level has a compact, but complete set of workshops and stockpiles (minus what is already provided on the farming level)."
"- The services level has dining, hospital, marksman barracks, and justice services, plus a well system. It is 4 z-levels deep."
"- The guildhall level has large, empty rooms for building libraries, temples, and guildhalls."
- The suites level has fancy rooms for your nobles.
- The apartments levels have small but well-furnished bedrooms for your other dwarves.
""
"Run each level's ""help"" blueprint (e.g. ""quickfort run library/dreamfort.csv -n /surface_help"") for more details."
""
"Dreamfort has a central stairs-based design. For all Dreamfort levels, place the cursor on the center (undug) tile of the 3x3 stairs area when you apply the blueprints for that level. The first surface blueprint will designate a column of stairs that you can use as a guide. If you need to extend the stairs down further to lower levels, run ""quickfort run library/dreamfort.csv -n /central_stairs --repeat down,10"" with the cursor on the z-level below the lowest current stairs."
""
"Dreamfort blueprints take care of everything to get the fort up and running. You don't need to clear any extra trees or create any extra buildings or stockpiles (though of course you are free to do so). Blueprints that do require manual steps, like 'assign minecart to hauling route', will leave a message telling you so when you run them. Note that blueprints will designate buildings to build even if you don't have the materials needed to build them. You can use ""quickfort orders"" to automatically create the manager orders for all the needed items. Make sure your manager is available to validate all the incoming work orders!"
""
"There are some tasks common to all forts that Dreamfort doesn't specifically handle for you. For example, Dreamfort sets up a barracks, but managing squads is up to you. Here are some other common tasks that may need to be done manually (or with some other tool):"
- Exploratory mining for specific resources like iron
- Filling the well system with water
- Bringing magma up to the industry level to power magma forges/furnaces
- Manufacturing trade goods
- Assigning skilled labors to migrants (although the example professions included with DFHack will help with this)
"- Custom stockpile setups to assist with, for example, encrusting only high-quality items"
""
"Dreamfort works best at an embark site that is flat and has at least one soil layer. New players should avoid embarks with aquifers if they are not prepared to deal with them. Bring picks for mining, an axe for woodcutting, and an anvil for a forge. Bring a few blocks to speed up initial workshop construction as well. That's all you really need, but see the example embark profile in the online spreadsheets for a more complete setup."
""
"Other DFHack commands also work very well with Dreamfort, such as autofarm, autonestbox, prioritize, seedwatch, tailor, and, of course, buildingplan. An init file that gets everything configured for you is distributed with DFHack as hack/examples/init/onMapLoad_dreamfort.init."
Put that file in your Dwarf Fortress directory -- the same directory that has dfhack.init.
""
"Also copy the files in hack/examples/orders/ to dfhack-config/orders/ and the files in hack/examples/professions/ to professions/. We'll be using these files later. See https://docs.dfhack.org/en/stable/docs/guides/examples-guide.html for more information, including suggestions on how many dwarves of each profession you are likely to need at each stage of fort maturity."
""
"Once you have your starting surface workshops up and running, you might want to configure buildingplan (in its global settings, accessible from any building placement screen, e.g.: b-a-G) to only use blocks for constructions so it won't use your precious wood, boulders, and bars to build floors and walls. If you bring at least 7 blocks with you on embark, you can even set this in your onMapLoad.init file like this:"
on-new-fortress buildingplan set boulders false; buildingplan set logs false
""
"Directly after embark, run ""quickfort run library/dreamfort.csv -n /setup"" with your cursor on your wagon to set settings, and get started building your fort with ""quickfort run library/dreamfort.csv -n /surface1"" on the surface (see /surface_help for how to select a good spot). Read the walkthroughs for each level to understand what's going on and follow the checklist to keep track of where you are in the building process. Good luck, and have fun building an awesome Dreamfort-based fort!"
""
"The dreamfort.csv file distributed with DFHack is generated from online spreadsheet files. If you want to look at how these blueprints are put together, it is easier to look at the online spreadsheets than the giant .csv. You can view them at: https://drive.google.com/drive/folders/1iS90EEVqUkxTeZiiukVj1pLloZqabKuP"
You are welcome to copy the Dreamfort spreadsheets and make your own modifications!
""
"If you like, you can download a fully built Dreamfort-based fort from https://dffd.bay12games.com/file.php?id=15434 and explore it
interactively."
"# The dreamfort.csv distributed with DFHack is generated with the following command:
  for fname in dreamfort*.xlsx; do xlsx2csv -a -p '' ""$fname""; done | sed 's/,*$//'"
#notes label(checklist) command checklist
"Here is the recommended order for Dreamfort commands. You can copy/paste the command lines directly into the DFHack terminal, or, if you prefer, you can run the blueprints in the UI with gui/quickfort. See the walkthroughs (the ""help"" blueprints) for context and details. Also remember to read the messages the blueprints print out after you run them so you don't miss any important manual steps."
""
-- Preparation (before you embark!) --
Copy hack/examples/init/onMapLoad_dreamfort.init to your DF directory
Copy the fort automation orders from hack/examples/orders/*.json to the dfhack-config/orders/ directory
Optionally copy the premade profession definitions from hack/examples/professions/ to the professions/ directory
Optionally copy the premade Dreamfort embark profile from the online spreadsheets to the data/init/embark_profiles.txt file
""
-- Set settings and preload initial orders --
quickfort run library/dreamfort.csv -n /setup,# Run before making any manual adjustments to settings! Run the /setup_help blueprint for details on what this blueprint does.
"quickfort orders library/dreamfort.csv -n ""/surface2, /farming2, /surface3, /farming3, /industry2, /surface4""","# Queue up orders required to get the fort minimally functional and secure. You can remove the order for the anvil (you brought one with you, right?)."
""
-- Find a good starting spot on the surface --
gui/quickfort library/dreamfort.csv -n /perimeter,# Run at embark. Don't actually apply the blueprint. Just use the preview shadow to find a good spot on the surface.
""
-- Dig  --
quickfort run library/dreamfort.csv -n /surface1,# Run when you find your center tile.
quickfort run library/dreamfort.csv -n /dig_all,"# Run when you find a suitable rock layer for the industry level. It designates digging for industry, services, guildhall, suites, and apartments all in one go. This list does not include the farming level, which we'll dig in the uppermost soil layer a bit later. Note that it is more efficient for your miners if you designate your digging before they dig the central stairs past that level since the stairs are dug at a low priority. This keeps your miners focused on one level at a time. If you need to designate your levels individually due to caverns interrupting the sequence or just because it is your preference, run the level-specific dig blueprints (i.e. /industry1, /services1, /guildhall1, /suites1, and 5 levels of /apartments1) instead of running /dig_all."
""
-- Core fort (should finish at about the third migration wave) --
quickfort run library/dreamfort.csv -n /surface2,"# Run after initial trees are cleared. If you are deconstructing the wagon now, wait until after the wagon is deconstructed so the jobs that depend on wagon contents (e.g. blocks) don't get canceled later."
quickfort run library/dreamfort.csv -n /farming1,# Run when channels are dug and the additional designated trees are cleared.
quickfort run library/dreamfort.csv -n /farming2,# Run when the farming level has been dug out.
quickfort run library/dreamfort.csv -n /surface3,# Run right after /farming2.
quickfort run library/dreamfort.csv -n /farming3,# Run when furniture has been placed.
quickfort run library/dreamfort.csv -n /industry2,# Run when the industry level has been dug out.
prioritize ConstructBuilding,# To get those workshops up and running ASAP. You may have to run this several times as the materials for the building construction jobs become ready.
quickfort run library/dreamfort.csv -n /surface4,"# Run after the walls and floors are built on the surface. Even if /surface3 is finished before you run /industry2, though, wait until after /industry2 to run this blueprint so that surface walls, floors, and roofing don't prevent your workshops from being built (due to lack of blocks)."
"quickfort run,orders library/dreamfort.csv -n /services2",# Run when the services levels have been dug out. Feel free to remove the orders for the ropes if you already brought them with you.
orders import basic,"# Run after the first migration wave, so you have dorfs to do all the basic tasks. Note that this is the ""orders"" plugin, not the ""quickfort orders"" command."
"quickfort run,orders library/dreamfort.csv -n /surface5","# Run when all marked trees on the surface are chopped down and walls and floors have been constructed, including the roof section over the future barracks."
prioritize ConstructBuilding,# Run when you see the bridges ready to be built so the busy masons come and build them.
"quickfort run,orders library/dreamfort.csv -n /surface6",# Run when at least the beehives and weapon rack are constructed and you have linked all levers to their respective bridges.
"quickfort run,orders library/dreamfort.csv -n /surface7",# Run after the surface walls are completed and any marked trees are chopped down.
""
-- Plumbing --
"This is a good time to fill your well cisterns, either with a bucket brigade or by routing water from a freshwater stream or an aquifer (see the library/aquifer_tap.csv blueprint for help with this)."
"Also consider bringing magma up to your services level so you can replace the forge and furnaces on your industry level with more powerful magma versions. This is especially important if your embark has insufficient trees to convert into charcoal. Keep in mind that moving magma is a tricky process and can take a long time. Don't forget to continue making progress through the checklist! If you choose to use magma, I suggest getting it in place before importing the military and smelting automation orders since they make heavy use of furnaces and forges."
""
-- Mature fort (third migration wave onward) --
orders import furnace,# Automated production of basic furnace-related items. Don't forget to create a sand collection zone (or remove the sand- and glass-related orders if you have no sand).
"quickfort run,orders library/dreamfort.csv -n /suites2",# Run when the suites level has been dug out.
"quickfort run,orders library/dreamfort.csv -n /surface8","# Run if/when you need longer trap corridors on the surface for larger sieges, anytime after you run /surface7."
"quickfort run,orders library/dreamfort.csv -n /apartments2",# Run when the first apartment level has been dug out.
"quickfort run,orders library/dreamfort.csv -n /services3","# Run after the dining table and chair, weapon rack, and archery targets have been constructed. Also wait until after you complete /surface7, though, because surface defenses are more important than a grand dining hall."
"quickfort run,orders library/dreamfort.csv -n /guildhall2",# Run when the guildhall level has been dug out.
"quickfort run,orders library/dreamfort.csv -n ""/guildhall3, /guildhall4""",# Optionally run after /guildhall2 to build default furnishings and declare a library and temple.
"quickfort run,orders library/dreamfort.csv -n /apartments3",# Run when all beds have been constructed on the first apartments level.
"quickfort run,orders library/dreamfort.csv -n /farming4",# Run once you have a cache of potash.
orders import military,# Automated production of military equipment. Turn on automelt in the meltables piles on the industry level to automatically upgrade all metal military equipment to masterwork quality. These orders are optional if you are not using a military.
orders import smelting,# Automated production of all types of metal bars.
"quickfort run,orders library/dreamfort.csv -n /services4","# Run when you need a jail, anytime after the restraints are placed from /services3."
orders import rockstock,# Maintains a small stock of all types of rock furniture.
orders import glassstock,# Maintains a small stock of all types of glass furniture and parts (only import if you have sand).
""
-- Repeat for each remaining apartments level as needed --
"quickfort run,orders library/dreamfort.csv -n /apartments2",# Run when the apartment level has been dug out.
"quickfort run,orders library/dreamfort.csv -n /apartments3",# Run when all beds have been constructed.
burial -pets,# Run once the coffins are placed to set them to allow for burial.

See this checklist online at https://docs.google.com/spreadsheets/d/13PVZ2h3Mm3x_G1OXQvwKd7oIR2lK4A1Ahf6Om1kFigw/edit#gid=1459509569
#notes label(setup_help)
Makes common initial adjustments to in-game settings.
""
"The /setup blueprint is intended to be run once at the start of the game, before anything else is changed. Players are welcome to make any further customizations after this blueprint is run. Please be sure to run the /setup blueprint before making any other changes, though, so your settings are not overwritten!"
""
The following settings are changed:
"- The manager, chief medical dwarf, broker, and bookkeeper noble roles are assigned to the first suggested dwarf. This is likely to be the expedition leader, but the game could suggest others if they have relevant skills. Bookkeeping is set to the highest precision."
""
- Standing orders are set to:
  - only farmers harvest
  - gather refuse from outside (incl. vermin)
  - no autoloom (so the hospital always has thread -- we'll be managing cloth production with automated orders)
""
"- A burrow named ""Inside"" is created, but it's up to the player to define the area as the fort expands. It is intended for use in getting your civilians to safety during sieges. A military alert named ""Siege"" is also created and associated with the ""Inside"" burrow."
""
- Military uniforms get the following modifications:
  - all default uniforms set to replace clothing
"  - in the ""Metal armor"" uniform, the ""metal armor"" item is removed and replaced by ""metal breastplate"" and ""metal mail shirt"""
"  - in the ""Metal armor"" uniform, the ""metal legwear"" item is removed and replaced by ""metal greaves"""
""
"All default uniforms should also have a leather cloak added, but the position of the cloak in the equipment list changes for every embark. We suggest manually adding a leather cloak to your uniforms after running the /setup blueprint."
""
- Hotkeys are created for the 8 most interesting levels. Only the names are set -- it's up to the player to adjust them to actual locations in the (H) menu since the blueprint can't know where the levels will eventually be built. Feel free to replace any hotkeys with locations that *you* think are interesting : )
""
These are all set for your convenience. Nothing in Dreamfort depends on these settings staying as they are. Feel free to change any setting to your personal preference.
""
#aliases
startnobles: n{Down 4}{togglesequence 8}{Up}s{Up}&^^
startorders: ohrov^Wl^^
startburrows: wa&nInside&^^
metalarmorsetup: A{Right 2}{Down 2}&{Down}&{Left}&M{Right}{Down}&{Left}{Down}{Right}{Down}&{Left}{Down 2}L{Right}{Down 2}&{Left}{Down 3}&M{Right}{Down}&{Left 2}
startmilitary: mnr{Down}r{metalarmorsetup}{Down}racNSiege&{Right}&^
sethotkey: {fkey}n{name}&
starthotkeys: H{sethotkey fkey={F2} name=Farming}{sethotkey fkey={F3} name=Industry}{sethotkey fkey={F4} name=Services}{sethotkey fkey={F5} name=Guildhall}{sethotkey fkey={F6} name=Quarry}{sethotkey fkey={F7} name=Cavern}{sethotkey fkey={F8} name=Magma}^
""
"#config label(setup) message(Please set the zoom targets of the hotkeys (the 'H' menu) according to where you actually end up digging the levels.
As you build your fort, expand the ""Inside"" burrow to include new civilian-safe areas.
Optionally, add a leather cloak to your military uniforms to enhance their protection rating.
Nothing in Dreamfort depends on these settings staying as they are. Feel free to change any setting to your personal preference.) assign nobles, set standing orders, create burrows, make adjustments to military uniforms, and set hotkey names"
{startnobles}{startorders}{startburrows}{startmilitary}{starthotkeys}
"#meta label(dig_all) start(central stairs on industry level) dig industry, services, guildhall, suites, and apartments levels. does not include farming."
# Note that this blueprint will only work for the unified dreamfort.csv. It won't work for the individual .xlsx files (since #meta blueprints can't cross file boundaries).
""
/industry1
#>
/services1
#>4
/guildhall1
#>
/suites1
#>
/apartments1 repeat(down 5)
#ignore
"Here are the minimal labors needed for essential tasks in getting Dreamfort up and running, along with suggestions for which dwarves to assign them to. You can enable additional labors as you wish. Skills with an asterisk (*) are especially worth putting points into on the embark preparation screen."
""
Manager / Bookkeeper / Broker,Miner,Miner,Mason,Mason,Outdoorsdwarf,Farmer
Mechanic (*),Miner (*),Miner (*),Mason (*),Mason (*),Carpenter (*),Grower (*)
Stonecrafter,,,,,Wood Cutter (*)
Wood Cutter,,,,,Bee Keeper
Architect
Misc. labors needed for constructing workshops
""
"The most time-consuming tasks in early Dreamfort are: mining, chopping down trees, and making blocks. Starting with at least two miners, two woodcutters (assuming your embark has trees), and two masons helps in keeping the fort from stalling."
""
We suggest bringing at least:
2 picks,for the two miners
2 battleaxes,for the two woodcutters
1 anvil,for the forge
food and seeds,as per usual
4 ropes,"for the hospital well and traction benches. you could build the ropes out of raw materials, but dwarves are usually too busy to do textile work at the start of the game."
7 blocks,for starting workshops and the temporary trade depot. necessary if you have buildingplan configured for blocks only.
many boulders,for quickly turning into more blocks. blocks are the limiting factor in the early stages.
dogs and cats,for protection and vermin control
geese,"for bones and leather. bring at least 1 male and 2 females for the 2 early nestboxes. autobutcher settings in the included onMapLoad_dreamfort.init file are optimized for raising geese. if you prefer another bird, be sure to adjust the autobutcher settings."
""
Also bring logs for beds if embarking in an area without many trees.
""
See ldog's Dreamfort embark profile for a more advanced (and more thoroughly explained!) approach:
https://drive.google.com/file/d/1Et42JTzeYK23iI5wrPMsFJ7lUXwVBQob/view?usp=sharing
"#ignore Add these lines to the bottom of your ""data/init/embark_profiles.txt"" file to make the ""Dreamfort"" profile available in-game. Also see ldog's dreamfort embark profile for a more advanced, dwarfy approach."
[TITLE:Dreamfort]
[SKILL:1:STONECRAFT:1]
[SKILL:1:MECHANICS:5]
[SKILL:1:JUDGING_INTENT:1]
[SKILL:1:APPRAISAL:1]
[SKILL:1:ORGANIZATION:1]
[SKILL:1:RECORD_KEEPING:1]
[SKILL:2:MINING:5]
[SKILL:2:DETAILSTONE:2]
[SKILL:2:SWIMMING:1]
[SKILL:3:MINING:5]
[SKILL:3:DETAILSTONE:2]
[SKILL:3:SWIMMING:1]
[SKILL:4:MASONRY:5]
[SKILL:5:MASONRY:5]
[SKILL:6:WOODCUTTING:5]
[SKILL:6:CARPENTRY:5]
[SKILL:7:PLANT:3]
[ITEM:2:WEAPON:ITEM_WEAPON_PICK:INORGANIC:COPPER]
[ITEM:2:WEAPON:ITEM_WEAPON_AXE_BATTLE:INORGANIC:COPPER]
[ITEM:1:ANVIL:NONE:INORGANIC:IRON]
[ITEM:7:DRINK:NONE:PLANT_MAT:MUSHROOM_HELMET_PLUMP:DRINK]
[ITEM:26:DRINK:NONE:PLANT_MAT:GRASS_TAIL_PIG:DRINK]
[ITEM:26:DRINK:NONE:PLANT_MAT:GRASS_WHEAT_CAVE:DRINK]
[ITEM:26:DRINK:NONE:PLANT_MAT:POD_SWEET:DRINK]
[ITEM:10:SEEDS:NONE:PLANT_MAT:MUSHROOM_HELMET_PLUMP:SEED]
[ITEM:10:SEEDS:NONE:PLANT_MAT:GRASS_TAIL_PIG:SEED]
[ITEM:10:SEEDS:NONE:PLANT_MAT:GRASS_WHEAT_CAVE:SEED]
[ITEM:10:SEEDS:NONE:PLANT_MAT:POD_SWEET:SEED]
[ITEM:10:SEEDS:NONE:PLANT_MAT:BUSH_QUARRY:SEED]
[ITEM:10:SEEDS:NONE:PLANT_MAT:MUSHROOM_CUP_DIMPLE:SEED]
[ITEM:25:PLANT:NONE:PLANT_MAT:MUSHROOM_HELMET_PLUMP:STRUCTURAL]
[ITEM:4:CHAIN:NONE:CREATURE_MAT:SPIDER_CAVE:SILK]
[ITEM:5:CLOTH:NONE:CREATURE_MAT:SPIDER_CAVE:SILK]
[ITEM:5:THREAD:NONE:CREATURE_MAT:SPIDER_CAVE:SILK]
[ITEM:50:WOOD:NONE:PLANT_MAT:WILLOW:WOOD]
[ITEM:40:BOULDER:NONE:INORGANIC:QUARTZITE]
[ITEM:10:BLOCKS:NONE:INORGANIC:QUARTZITE]
[PET:2:DOG:FEMALE:STANDARD]
[PET:1:DOG:MALE:STANDARD]
[PET:2:CAT:FEMALE:STANDARD]
[PET:1:CAT:MALE:STANDARD]
[PET:2:BIRD_GOOSE:FEMALE:STANDARD]
[PET:2:BIRD_GOOSE:MALE:STANDARD]
#meta label(all_orders) hidden() references all blueprints that generate orders; for testing only
/surface2
/surface3
/surface4
/surface5
/surface6
/surface7
/surface8
/farming2
/farming3
/farming4
/industry2
/services2
/services3
/services4
/guildhall2
/suites2
/apartments2
/apartments2
/apartments2
/apartments2
/apartments2
/apartments2
/apartments3
/apartments3
/apartments3
/apartments3
/apartments3
/apartments3
#notes label(surface_help)
Sets up a protected entrance to your fort in a flat area on the surface.
Screenshot: https://drive.google.com/file/d/1YL_vQJLB2YnUEFrAg9y3HEdFq3Wpw9WP
""
Features:
- A starting set of workshops and stockpiles (which you can later remove once you establish your permanent workshops and storage)
- Livestock grazing area with nestbox zones and beehives
"- Walls, roof, and lever-controlled gates for security"
- Barracks (with prisoner processing quantum dump)
- Trap-filled hallways for invaders
- Optional extended trap hallways (to handle larger sieges)
- Protected trade depot
- A grid of 1x1 farm plots (intended to be managed by DFHack autofarm)
""
Manual steps you have to take:
- Assign grazing livestock to the large pasture and dogs to the pasture over the central stairs (DFHack's autonestbox can manage the nestbox zones)
- Connect levers to the gates that match the names of the levers
- Assign minecarts to the trade goods and prisoner processing quantum stockpile hauling routes
""
Be sure to choose an embark site that has a flat area on the surface large enough to use these blueprints!
""
Surface Walkthrough:
"1) Choose a tile for your central fortress stairs. The terrain around that tile should be perfectly flat. Trees are ok, but no slopes, rivers, or lakes. To be sure that the tile you've chosen is in a good spot, set the cursor over that tile and run ""quickfort run library/dreamfort.csv -n /perimeter"". This will show you the eventual boundaries of the fort. Some wall segments might be missing due to existing trees, but that's ok. Make sure the area within the exterior wall is flat. Run ""quickfort undo library/dreamfort.csv -n /perimeter"" to clean up."
""
"2) With the cursor on the chosen tile, run /surface1 to clear surrounding trees and set up your pastures. Deconstruct your wagon to get it out of the way of our upcoming walls and floors. Remember to assign your dogs to the pasture around the staircase and your grazing animals to the large pasture. Your egg-layers will automatically get assigned to nestbox zones once the nestboxes are built, so you don't need to worry about them. You can let your cats roam free to chase vermin."
""
"3) Once the marked trees have been cleared, run /surface2 to setup starting workshops/stockpiles, channel out the miasma vents for the farming level, and start clearing trees from a larger area. If you haven't done it already, now is a good time to configure buildingplan to only build buildings with blocks, not logs or raw boulders. Do this by entering buildingplan's global configuration (""baG"") and ensuring the only generic building material allowed is ""blocks"". Run ""quickfort orders"" for /surface2."
""
"4) Once the channels are dug out and the trees are cleared, start digging the farming level one z-level down. Once you have run /farming2, come back to the surface and run /surface3 to cover the vents and build an enclosure around your central stairs. Although the vents will be covered with flooring, they will still work to prevent miasma on the farming level. Run ""quickfort orders"" for /surface3."
""
"5) Once all walls and floors have been constructed around the stairwell, run /surface4 to build floors and walls to support upcoming buildings and furniture. Run ""quickfort orders"" for /surface4."
""
"6) Once walls and floors have been constructed (including the small roof segment one z-level up over the barracks), run /surface5 to build furniture, gates, and the permanent trade depot. Remember to deconstruct the temporary trade depot once nobody is using it. Run ""quickfort orders"" for /surface5."
""
"7) Once at least the beehives and weapon rack are built, run /surface6 to configure the rooms and build the remaining walls and floors. Run ""quickfort orders"" for /surface6."
""
"8) Once you have enough dwarves to do a lot of building without starving other important tasks, run /surface7 to build the roof. Run ""quickfort orders"" for /surface7."
""
"9) For extra security, you can run /surface8 any time after /surface7 to extend the trap corridors. Run ""quickfort orders"" for /surface8."
""
"10) Once your industry and farming levels are set up and running, you can disassemble the surface workshops and remove the surface stockpiles. Disassembling a workshop scatters the items stored within it and cancels any pending jobs that happen to use those items. In order to avoid job cancellations, first set the surface workshops to not accept general work orders. Do this by entering query mode (""q""), selecting a workshop, entering the workshop profile (""P""), moving to work orders (right arrow), and hitting Enter. Then enter view mode (""t"") and check to see if any items in a workshop are marked with ""TSK"". Once no items in the workshop have that marker, you are free to disassemble that workshop."
""
Sieges and Prisoner Processing:
Here are some tips and procedures for handling seiges -- including how to clean up afterwards!
""
"- Ensure your ""Inside"" burrow includes only below-ground areas and safe surface areas of your fort. In particular, don't include the ""atrium"" area (where the ""siege bait"" zone is) or the trapped hallways."
""
"- When a siege begins, set the civilian alert to ""Siege"" to ensure all your civilians stay out of danger. Immediately pull the lever to close the outer main gate. It is also wise to close the trade depot and inner main gate as well. That way, if enemies get past the traps, they'll have to go through the soldiers in your barracks."
""
"- During a siege, use the levers to control how attackers path through the trapped corridors. If there are more enemies than cage traps, time your lever pulling so that the inner gates snap closed before your last cage trap is sprung. Then the remaining attackers will have to backtrack and go through the other trap-filled hallway."
""
"- If your cage traps fill up, ensure your hallways are free of uncaged attackers, then close the trap hallway outer gates and open the inner gates. Unset the civilian alert and allow your dwarves to reset all the traps -- make some extra cages in preparation for this! Then re-set the civilian alert to ""Siege"" and open the trap hallway outer gates."
""
"- Once the last attacker is caged, open all the gates and unset the civilian alert. Life is normal again!"
""
"After a siege, you can use the caged prisoners to safely train your military. Here's how:"
""
"- Once the prisoners are hauled to the ""prisoner quantum"" stockpile, run ""stripcaged all"" in the DFHack console."
""
"- After all the prisoners' items have been confiscated, bring your military dwarves to the barracks (if they aren't already there)."
""
- Use the zone (i) menu to assign a group prisoners to the pasture that overlaps the prisoner quantum stockpile
""
"- Hauler dwarves will come and release prisoners one by one. Your military dwarves will immediately pounce on the released prisoner and chop them to bits, saving the hauler dwarves from being attacked. Repeat until all prisoners have been ""processed""."
""
"Only common hostile creatures are accepted by the prisoner hauling route by default. You can add additional creature types by configuring the hauling route stop in the 'h' menu. Note that generated creature types, like necromancer experiments, can't be explicitly added. You have to (at least temporarily) accept all animals to include them."
#meta label(perimeter) start(central stairs) message(Run quickfort undo on this blueprint to clean up.) show the eventual perimeter of the surface fort; useful for location scouting
walls/surface_walls
corridor/surface_corridor
""
"#meta label(surface1) start(central stairs)
message(Once the central stairs are mined out deeply enough, you should start digging the industry level in a non-aquifer rock layer. You'll need the boulders from the digging to make blocks.
If your wagon is within the fort perimeter, deconstruct it to get it out of the way.
Once the marked trees are all chopped down (if any), continue with /surface2.) clear trees and set up pastures"
clear_small/surface_clear_small
zones/surface_zones
name_zones/surface_name_zones
#>
central_stairs/central_stairs repeat(down 10)
""
"#meta label(surface2) start(central stairs) message(Remember to enqueue manager orders for this blueprint.
Once the channels are dug out and the marked trees are cleared, continue with /surface3.) set up starting workshops/stockpiles, channel miasma vents, and clear more trees"
build_start/surface_build_start
place_start/surface_place_start
query_start/surface_query_start
channel/surface_channel
clear/surface_clear
""
"#meta label(surface3) start(central stairs) message(Remember to enqueue manager orders for this blueprint.
Once the walls and floors have been constructed, continue with /surface4.) Cover vents and protect the central stairs."
cover_vents/surface_cover_vents
cover_stairs/surface_cover_stairs
""
"#meta label(surface4) start(central stairs) message(Remember to enqueue manager orders for this blueprint.
Once the walls and floors have been constructed, continue with /surface5. Be sure to check one z-level above the surface to ensure the roof segment above the future barracks has been finished.) build walls and flooring to support upcoming buildings and furniture"
stairs_doors/surface_stairs_doors
pre_building/surface_pre_building
""
"#meta label(surface5) start(central stairs) message(Remember to enqueue manager orders for this blueprint.
Disassemble the temporary trade depot in the pasture once the new one is constructed (and no merchants are using the old one).
Once the marked trees are cleared and at least the beehives and weapon rack have been constructed, continue with /surface6.) build gates, furniture, and trade stockpile/depot"
place/surface_place
build/surface_build
query/surface_query
clear_large/surface_clear_large
""
"#meta label(surface6) start(central stairs) message(Remember to enqueue manager orders for this blueprint.
Continue with /surface7 sometime after the walls are completed and any marked trees are chopped down, whenever you have enough dwarves to build the roof without starving other important construction tasks.) configure hives and barracks, build traps and remaining walls/floors"
query2/surface_query2
walls/surface_walls
floors/surface_floors
traps/surface_traps
clear_large/surface_clear_large
""
"#meta label(surface7) start(central stairs (on ground level)) message(Remember to enqueue manager orders for this blueprint.
For extra security, you can run /surface8 at any time to extend the trap corridors.) build roof"
#<
roof/surface_roof
roof2/surface_roof2
roof3/surface_roof3
roof4/surface_roof4
""
#meta label(surface8) start(central stairs) message(Remember to enqueue manager orders for this blueprint.) build extended trap corridors
corridor_gates/surface_corridor_gates
corridor/surface_corridor
corridor_traps/surface_corridor_traps
query_corridor/surface_query_corridor
#dig label(central_stairs_odd) start(2;2) hidden() spiral stairs odd levels
`,j6,`
u,`,u
`,j6,`
#meta label(central_stairs_even) hidden() spiral stairs even levels
/central_stairs_odd transform(cw)
#meta label(central_stairs) two levels of spiral stairs (use --repeat down)
/central_stairs_odd
#>
/central_stairs_even
#dig label(surface_clear_small) start(19; 19) hidden() clear trees for starting workshops and stockpiles



,,,`,,`,`,`,`,`,`,`,`,`,`,`,`,`,`,`,`,`,`,`,`,`,`,`,`,`,`,`,,`
,,,`,,`,,,,,,,,,,,,,,,,,,,,,,,,,,`,,`
,,,`,,`,,,,,,,,,,,,,,,,,,,,,,,,,,`,,`
,,,`,,`,t1(25x9),,,,,,,,,,,,,,,,,,,,,,,,,`,,`
,,,`,,`,,,,,,,,,,,,,,,,,,,,,,,,,,`,,`
,,,`,,`,,,,,,,,,,,,,,,,,,,,,,,,,,`,,`
,,,`,,`,,,,,,,,,,,,,,,,,,,,,,,,,,`,,`
,,,`,,`,,,,,,,,,,,,,,,,,,,,,,,,,,`,,`
,,,`,,`,,,,,,,,,,,,,,,,,,,,,,,,,,`,,`
,,,`,,`,,,,,,,,,,,,,,,,,,,,,,,,,,`,,`
,,,`,,`,,,,,,,,,,,,,,,,,,,,,,,,,,`,,`
,,,`,,`,,,,,,,,,,,,,,,,,,,,,,,,,,`,,`
,,,`,,`,`,`,`,`,t1,`,`,`,`,`,`,,`,,`,`,`,`,`,t1,`,`,`,t1,`,`,,`
,,,`,,`,,`,t1,t1,,,,,,`,t1,t1,t1,t1,t1,`,,,,,,,,,,`,,`
,,,`,,`,,`,,,,,,,,,t1,t1,t1,t1,t1,,,,,,,,,,,`,,`
,,,`,,`,,,,,,,,,,`,t1,j,t1,j,t1,`,,,,,,,,,,`,,`
,,,`,,`,,`,,,,,,,,,t1,t1,t1,t1,t1,,,,,,,,,,,`,,`
,,,`,,`,,`,,,,,,,,`,t1,t1,t1,t1,t1,`,,,,,,,,,,`,,`
,,,`,,`,`,`,`,`,`,`,,`,`,`,`,,`,,`,`,`,`,,`,`,`,`,`,`,`,,`
,,,`,,`,,,,,,,,,`,t1,,,,,,t1,`,,,,,,,,,`,,`
,,,`,,`,,,,,,,,,t1,t1,,,,,,t1,t1,,,,,,,,,`,,`
,,,`,,`,,,,,,,,,t1,t1,,t1,t1,t1,,t1,t1,,,,,,,,,`,,`
,,,`,,`,,,,,,,,,,,,t1,t1,t1,,,,,,,,,,,,`,,`
,,,`,,`,,,,,,,,,t1,,,t1,t1,t1,,,t1,,,,,,,,,`,,`
,,,`,,`,`,`,`,`,`,`,`,`,`,,,,,,,,`,`,`,`,`,`,`,`,`,`,,`
,,,`,,,,,,,,,,,,,,,t1,,,,,,,,,,,,,,,`
,,,`,`,`,`,`,`,`,`,`,`,`,`,,,,,,,,`,`,`,`,`,`,`,`,`,`,`,`



"#zone label(surface_zones) start(19; 19) hidden() message(Remember to assign your dogs to the pasture surrounding the central stairs and your grazing animals to the large pasture.
Feel free to assign an unimportant animal to the pasture in the main entranceway to use as bait during sieges.) pastures and training areas"



,,,`,,`,`,`,`,`,`,`,`,`,`,`,`,`,`,`,`,`,`,`,`,`,`,`,`,`,`,`,,`
,,,`,,`,nmt(25x11),,,,,,,,,,,,,,,,,,,,,,,,,`,,`
,,,`,,`,,,,,,,,,,,,,,,,,,,,,,,,,,`,,`
,,,`,,`,,,,,,,,,,,,,,,,,,,,,,,,,,`,,`
,,,`,,`,,,,,,,,,,,,,,,,,,,,,,,,,,`,,`
,,,`,,`,,,,,,,,,,,,,,,,,,,,,,,,,,`,,`
,,,`,,`,,,,,,,,,,,,,,,,,,,,,,,,,,`,,`
,,,`,,`,,,,,,,,,,,,,,,,,,,,,,,,,,`,,`
,,,`,,`,,,,,,,,,,,,,,,,,,,,,,,,,,`,,`
,,,`,,`,,,,,,,,,,,,,,,,,,,,,,,,,,`,,`
,,,`,,`,,,,,,,,,,,,,,,,,,,,,,,,,,`,,`
,,,`,,`,,,,,,,,,,,,,,,,,,,,,,,,,,`,,`
,,,`,,`,`,`,`,`,`,`,`,`,`,`,`,,`,,`,`,`,`,`,`,`,`,`,`,`,`,,`
,,,`,,`,,`,n(1x1),n(1x1),n(1x1),n(1x1),n(1x1),n(1x1),n(1x1),`,,,,,,`,nt(9x5),,,,,,,,,`,,`
,,,`,,`,,`,,,,,,,,,nt,nt,nt,nt,nt,,,,,,,,,,,`,,`
,,,`,,`,,,,,,,,,,`,nt,`,~,`,nt,`,,,,,,,,,,`,,`
,,,`,,`,,`,,,,,,,,,nt,nt,nt,nt,nt,,,,,,,,,,,`,,`
,,,`,,`,,`,n(1x1),n(1x1),n(1x1),n(1x1),n(1x1),n(1x1),n(1x1),`,,,,,,`,,,,,,,,,,`,,`
,,,`,,`,`,`,`,`,`,`,,`,`,`,`,,`,,`,`,`,`,,`,`,`,`,`,`,`,,`
,,,`,,`,,,,,,,,,`,,,,,,,,`,,,,,,,,,`,,`
,,,`,,`,,,,,,,,,,,,,,,,,,,,,,,,,,`,,`
,,,`,,`,,,,,,,,,,,,,n,,,,,,,,,,,,,`,,`
,,,`,,`,,,,,,,,,,,,,,,,,,,,,,,,,,`,,`
,,,`,,`,,,,,,,,,`,,,,,,,,`,,n,,,,,,,`,,`
,,,`,,`,`,`,`,`,`,`,`,`,`,,,,,,,,`,`,`,`,`,`,`,`,`,`,,`
,,,`,,,,,,,,,,,,,,,,,,,,,,,,,,,,,,`
,,,`,`,`,`,`,`,`,`,`,`,`,`,,,,,,,,`,`,`,`,`,`,`,`,`,`,`,`



#query label(surface_name_zones) start(19; 19) hidden()



,,,`,,`,`,`,`,`,`,`,`,`,`,`,`,`,`,`,`,`,`,`,`,`,`,`,`,`,`,`,,`
,,,`,,`,"{namezone name=""main pasture""}",,,,,,,,,,,,,,,,,,,,,,,,,`,,`
,,,`,,`,,,,,,,,,,,,,,,,,,,,,,,,,,`,,`
,,,`,,`,,,,,,,,,,,,,,,,,,,,,,,,,,`,,`
,,,`,,`,,,,,,,,,,,,,,,,,,,,,,,,,,`,,`
,,,`,,`,,,,,,,,,,,,,,,,,,,,,,,,,,`,,`
,,,`,,`,,,,,,,,,,,,,,,,,,,,,,,,,,`,,`
,,,`,,`,,,,,,,,,,,,,,,,,,,,,,,,,,`,,`
,,,`,,`,,,,,,,,,,,,,,,,,,,,,,,,,,`,,`
,,,`,,`,,,,,,,,,,,,,,,,,,,,,,,,,,`,,`
,,,`,,`,,,,,,,,,,,,,,,,,,,,,,,,,,`,,`
,,,`,,`,,,,,,,,,,,,,,,,,,,,,,,,,,`,,`
,,,`,,`,`,`,`,`,`,`,`,`,`,`,`,,`,,`,`,`,`,`,`,`,`,`,`,`,`,,`
,,,`,,`,,`,"{namezone name=""nestbox1""}","{namezone name=""nestbox2""}","{namezone name=""nestbox3""}","{namezone name=""nestbox4""}","{namezone name=""nestbox5""}","{namezone name=""nestbox6""}","{namezone name=""nestbox7""}",`,,,,,,`,"{namezone name=""taming area""}",,,,,,,,,`,,`
,,,`,,`,,`,,,,,,,,,,`,`,`,"{namezone name=""guard dogs""}",,,,,,,,,,,`,,`
,,,`,,`,,,,,,,,,,`,,`,~,`,,`,,,,,,,,,,`,,`
,,,`,,`,,`,,,,,,,,,,`,`,`,,,,,,,,,,,,`,,`
,,,`,,`,,`,"{namezone name=""nestbox8""}","{namezone name=""nestbox9""}","{namezone name=""nestbox10""}","{namezone name=""nestbox11""}","{namezone name=""nestbox12""}","{namezone name=""nestbox13""}","{namezone name=""nestbox14""}",`,,,,,,`,,,,,,,,,,`,,`
,,,`,,`,`,`,`,`,`,`,,`,`,`,`,,`,,`,`,`,`,,`,`,`,`,`,`,`,,`
,,,`,,`,,,,,,,,,`,,,,,,,,`,,,,,,,,,`,,`
,,,`,,`,,,,,,,,,,,,,,,,,,,,,,,,,,`,,`
,,,`,,`,,,,,,,,,,,,,"{namezone name=""siege bait""}",,,,,,,,,,,,,`,,`
,,,`,,`,,,,,,,,,,,,,,,,,,,,,,,,,,`,,`
,,,`,,`,,,,,,,,,`,,,,,,,,`,,"{namezone name=""prisoner processing""}",,,,,,,`,,`
,,,`,,`,`,`,`,`,`,`,`,`,`,,,,,,,,`,`,`,`,`,`,`,`,`,`,,`
,,,`,,,,,,,,,,,,,,,,,,,,,,,,,,,,,,`
,,,`,`,`,`,`,`,`,`,`,`,`,`,,,,,,,,`,`,`,`,`,`,`,`,`,`,`,`



#build label(surface_build_start) start(19; 19) hidden() message(There is room to the left of the carpenter's workshop to build one more workshop of any type if you need it.) starting workshops



,,,`,,`,`,`,`,`,`,`,`,`,`,`,`,`,`,`,`,`,`,`,`,`,`,`,`,`,`,`,,`
,,,`,,`,,,,,,,,,,,,,,,,,,,,,,,,,,`,,`
,,,`,,`,,,,,,,,,,,,,,,,,,,,,,,,,,`,,`
,,,`,,`,,,,,,,,,,,,,,,,,,,,,,,,,,`,,`
,,,`,,`,,,,,,,,,,,,,,,,,,,,,,,,,,`,,`
,,,`,,`,,,,,,,,,,,,,,,,,,,,,,,,,,`,,`
,,,`,,`,,,,,,,,,,,,,,,,,,,,,,,,,,`,,`
,,,`,,`,,,,,,,,,,,,,,,,,,,,,,,,,,`,,`
,,,`,,`,,,,,,,,,,,,,,,,,,,,,,,,,,`,,`
,,,`,,`,,,,,,wc,,,,wr,,,,wm,,,,wt,,,,,D,,,`,,`
,,,`,,`,,,,,,,,,,,,,,,,,,,,,,,,,,`,,`
,,,`,,`,,,,,,,,,,,,,,,,,,,,,,,,,,`,,`
,,,`,,`,`,`,`,`,`,`,`,`,`,`,`,,`,,`,`,`,`,`,`,`,`,`,`,`,`,,`
,,,`,,`,,`,N,N,,,,,,`,,,,,,`,,,,,,,,,,`,,`
,,,`,,`,,`,,,,,,,,,,`,`,`,,,,,,,,,,,,`,,`
,,,`,,`,,,,,,,,,,`,,`,~,`,,`,,,,,,,,,,`,,`
,,,`,,`,,`,,,,,,,,,,`,`,`,,,,,,,,,,,,`,,`
,,,`,,`,,`,,,,,,,,`,,,,,,`,,,,,,,,,,`,,`
,,,`,,`,`,`,`,`,`,`,,`,`,`,`,,`,,`,`,`,`,,`,`,`,`,`,`,`,,`
,,,`,,`,,,,,,,,,`,,,,,,,,`,,,,,,,,,`,,`
,,,`,,`,,,,,,,,,,,,,,,,,,,,,,,,,,`,,`
,,,`,,`,,,,,,,,,,,,,,,,,,,,,,,,,,`,,`
,,,`,,`,,,,,,,,,,,,,,,,,,,,,,,,,,`,,`
,,,`,,`,,,,,,,,,`,,,,,,,,`,,,,,,,,,`,,`
,,,`,,`,`,`,`,`,`,`,`,`,`,,,,,,,,`,`,`,`,`,`,`,`,`,`,,`
,,,`,,,,,,,,,,,,,,,,,,,,,,,,,,,,,,`
,,,`,`,`,`,`,`,`,`,`,`,`,`,,,,,,,,`,`,`,`,`,`,`,`,`,`,`,`



#place label(surface_place_start) start(19; 19) hidden() starting stockpiles



,,,`,,`,`,`,`,`,`,`,`,`,`,`,`,`,`,`,`,`,`,`,`,`,`,`,`,`,`,`,,`
,,,`,,`,,,,,,,,,,,,,,,,,,,,,,,,,,`,,`
,,,`,,`,,,,,,,,,,,,,,,,,,,,,,,,,,`,,`
,,,`,,`,f(8x4),,,,,,,,w(4x4),,,,s2(5x4),,,,,gunzSpd(4x4),,,,hlr(4x4),,,,`,,`
,,,`,,`,,,,,,,,,,,,,,,,,,,,,,,,,,`,,`
,,,`,,`,,,,,,,,,,,,,,,,,,,,,,,,,,`,,`
,,,`,,`,,,,,,,,,,,,,,,,,,,,,,,,,,`,,`
,,,`,,`,,,,,,,,,,,,,,,,,,,,,,,,,,`,,`
,,,`,,`,,,,,,,,,,,,,,,,,,,,,,,,,,`,,`
,,,`,,`,,,,,,,,,,,,,,,,,,,,,,,,,,`,,`
,,,`,,`,,,,,,,,,,,,,,,,,,,,,,,,,,`,,`
,,,`,,`,,,,,,,,,,,,,,,,,,,,,,,,,,`,,`
,,,`,,`,`,`,`,`,`,`,`,`,`,`,`,,`,,`,`,`,`,`,`,`,`,`,`,`,`,,`
,,,`,,`,,`,,,,,,,,`,,,,,,`,,,,,,,,,,`,,`
,,,`,,`,,`,,,,,,,,,,`,`,`,,,,,,,,,,,,`,,`
,,,`,,`,,,,,,,,,,`,,`,~,`,,`,,,,,,,,,,`,,`
,,,`,,`,,`,,,,,,,,,,`,`,`,,,,,,,,,,,,`,,`
,,,`,,`,,`,,,,,,,,`,,,,,,`,,,,,,,,,,`,,`
,,,`,,`,`,`,`,`,`,`,,`,`,`,`,,`,,`,`,`,`,,`,`,`,`,`,`,`,,`
,,,`,,`,,,,,,,,,`,,,,,,,,`,,,,,,,,,`,,`
,,,`,,`,,,,,,,,,,,,,,,,,,,,,,,,,,`,,`
,,,`,,`,,,,,,,,,,,,,,,,,,,,,,,,,,`,,`
,,,`,,`,,,,,,,,,,,,,,,,,,,,,,,,,,`,,`
,,,`,,`,,,,,,,,,`,,,,,,,,`,,,,,,,,,`,,`
,,,`,,`,`,`,`,`,`,`,`,`,`,,,,,,,,`,`,`,`,`,`,`,`,`,`,,`
,,,`,,,,,,,,,,,,,,,,,,,,,,,,,,,,,,`
,,,`,`,`,`,`,`,`,`,`,`,`,`,,,,,,,,`,`,`,`,`,`,`,`,`,`,`,`



#query label(surface_query_start) start(19; 19) hidden() config stockpiles



,,,`,,`,`,`,`,`,`,`,`,`,`,`,`,`,`,`,`,`,`,`,`,`,`,`,`,`,`,`,,`
,,,`,,`,,,,,,,,,,,,,,,,,,,,,,,,,,`,,`
,,,`,,`,,,,,,,,,,,,,,,,,,,,,,,,,,`,,`
,,,`,,`,,,,,,,,"{givename name=""starting food""}",,,,"{givename name=""starting wood""}",,,,,"{givename name=""starting stone""}",,,,"{givename name=""starting misc""}",,,,"{givename name=""starting cloth/trash""}",`,,`
,,,`,,`,,,,,,,,,,,,,otherstone,,,,,nocontainers,,,,nocontainers,,,,`,,`
,,,`,,`,,,,,,,,,,,,,,,,,,,,,,,,,,`,,`
,,,`,,`,,,,,,,,,,,,,,,,,,,,,,,,,,`,,`
,,,`,,`,,,,,,,,,,,,,,,,,,,,,,,,,,`,,`
,,,`,,`,,,,,,,,,,,,,,,,,,,,,,,,,,`,,`
,,,`,,`,,,,,,,,,,,,,,,,,,,,,,,,,,`,,`
,,,`,,`,,,,,,,,,,,,,,,,,,,,,,,,,,`,,`
,,,`,,`,,,,,,,,,,,,,,,,,,,,,,,,,,`,,`
,,,`,,`,`,`,`,`,`,`,`,`,`,`,`,,`,,`,`,`,`,`,`,`,`,`,`,`,`,,`
,,,`,,`,,`,,,,,,,,`,,,,,,`,,,,,,,,,,`,,`
,,,`,,`,,`,,,,,,,,,,`,`,`,,,,,,,,,,,,`,,`
,,,`,,`,,,,,,,,,,`,,`,~,`,,`,,,,,,,,,,`,,`
,,,`,,`,,`,,,,,,,,,,`,`,`,,,,,,,,,,,,`,,`
,,,`,,`,,`,,,,,,,,`,,,,,,`,,,,,,,,,,`,,`
,,,`,,`,`,`,`,`,`,`,,`,`,`,`,,`,,`,`,`,`,,`,`,`,`,`,`,`,,`
,,,`,,`,,,,,,,,,`,,,,,,,,`,,,,,,,,,`,,`
,,,`,,`,,,,,,,,,,,,,,,,,,,,,,,,,,`,,`
,,,`,,`,,,,,,,,,,,,,,,,,,,,,,,,,,`,,`
,,,`,,`,,,,,,,,,,,,,,,,,,,,,,,,,,`,,`
,,,`,,`,,,,,,,,,`,,,,,,,,`,,,,,,,,,`,,`
,,,`,,`,`,`,`,`,`,`,`,`,`,,,,,,,,`,`,`,`,`,`,`,`,`,`,,`
,,,`,,,,,,,,,,,,,,,,,,,,,,,,,,,,,,`
,,,`,`,`,`,`,`,`,`,`,`,`,`,,,,,,,,`,`,`,`,`,`,`,`,`,`,`,`



#dig label(surface_channel) start(19; 19) hidden() channel miasma vents



,,,`,,`,`,`,`,`,`,`,`,`,`,`,`,`,`,`,`,`,`,`,`,`,`,`,`,`,`,`,,`
,,,`,,`,,,,,,,,,,,,,,,,,,,,,,,,,,`,,`
,,,`,,`,,,,,,,,,,,,,,,,,,,,,,,,,,`,,`
,,,`,,`,,,,,,,,,,,,,,,,,,,,,,,,,,`,,`
,,,`,,`,,,,,,,,,,,,,,,,,,,,,,,,,,`,,`
,,,`,,`,,,,,,,,,,,,,,,,,,,,,,,,,,`,,`
,,,`,,`,,,,,,,,,,,,,,,,,,,,,,,,,,`,,`
,,,`,,`,,,,,,,,,,,,,,,,,,,,,,,,,,`,,`
,,,`,,`,,,,,,,,,,,,,,,,,,,,,,,,,,`,,`
,,,`,,`,,,,,,,,,,,,,,,,,,,,,,,,,,`,,`
,,,`,,`,,,,,,,,,,,,,,,,,,,,,,,,,,`,,`
,,,`,,`,,,,,,,,,,,,,,,,,,,,,,,,,,`,,`
,,,`,,`,`,`,`,`,h1,`,`,`,`,`,`,,`,,`,`,`,`,`,h1,`,`,`,h1,`,`,,`
,,,`,,`,,`,,,,,,,,`,,,,,,`,,,,,,,,,,`,,`
,,,`,,`,,`,,,,,,,,,,`,`,`,,,,,,,,,,,,`,,`
,,,`,,`,,,,,,,,,,`,,`,~,`,,`,,,,,,,,,,`,,`
,,,`,,`,,`,,,,,,,,,,`,`,`,,,,,,,,,,,,`,,`
,,,`,,`,,`,,,,,,,,`,,,,,,`,,,,,,,,,,`,,`
,,,`,,`,`,`,`,`,`,`,,`,`,`,`,,`,,`,`,`,`,,`,`,`,`,`,`,`,,`
,,,`,,`,,,,,,,,,`,h1,,,,,,h1,`,,,,,,,,,`,,`
,,,`,,`,,,,,,,,,h1,h1,,,,,,h1,h1,,,,,,,,,`,,`
,,,`,,`,,,,,,,,,h1,h1,,h1,h1,h1,,h1,h1,,,,,,,,,`,,`
,,,`,,`,,,,,,,,,,,,h1,h1,h1,,,,,,,,,,,,`,,`
,,,`,,`,,,,,,,,,h1,,,h1,h1,h1,,,h1,,,,,,,,,`,,`
,,,`,,`,`,`,`,`,`,`,`,`,`,,,,,,,,`,`,`,`,`,`,`,`,`,`,,`
,,,`,,,,,,,,,,,,,,,h1,,,,,,,,,,,,,,,`
,,,`,`,`,`,`,`,`,`,`,`,`,`,,,,,,,,`,`,`,`,`,`,`,`,`,`,`,`



#dig label(surface_clear) start(19; 19) hidden() clear trees so the farming level can be dug without fear of generating surface holes


,,,,t1(29x29)
,,,`,,`,`,`,`,`,`,`,`,`,`,`,`,`,`,`,`,`,`,`,`,`,`,`,`,`,`,`,,`
,,,`,,`,,,,,,,,,,,,,,,,,,,,,,,,,,`,,`
,,,`,,`,,,,,,,,,,,,,,,,,,,,,,,,,,`,,`
,,,`,,`,,,,,,,,,,,,,,,,,,,,,,,,,,`,,`
,,,`,,`,,,,,,,,,,,,,,,,,,,,,,,,,,`,,`
,,,`,,`,,,,,,,,,,,,,,,,,,,,,,,,,,`,,`
,,,`,,`,,,,,,,,,,,,,,,,,,,,,,,,,,`,,`
,,,`,,`,,,,,,,,,,,,,,,,,,,,,,,,,,`,,`
,,,`,,`,,,,,,,,,,,,,,,,,,,,,,,,,,`,,`
,,,`,,`,,,,,,,,,,,,,,,,,,,,,,,,,,`,,`
,,,`,,`,,,,,,,,,,,,,,,,,,,,,,,,,,`,,`
,,,`,,`,,,,,,,,,,,,,,,,,,,,,,,,,,`,,`
,,,`,,`,`,`,`,`,,`,`,`,`,`,`,,`,,`,`,`,`,`,,`,`,`,,`,`,,`
,,,`,,`,,`,,,,,,,,`,,,,,,`,,,,,,,,,,`,,`
,,,`,,`,,`,,,,,,,,,,`,`,`,,,,,,,,,,,,`,,`
,,,`,,`,,,,,,,,,,`,,`,~,`,,`,,,,,,,,,,`,,`
,,,`,,`,,`,,,,,,,,,,`,`,`,,,,,,,,,,,,`,,`
,,,`,,`,,`,,,,,,,,`,,,,,,`,,,,,,,,,,`,,t1,t1
,,,`,,`,`,`,`,`,`,`,,`,`,`,`,,`,,`,`,`,`,,`,`,`,`,`,`,`,,t1,t1
,,,`,,`,,,,,,,,,`,,,,,,,,`,,,,,,,,,`,,t1,t1
,,,`,,`,,,,,,,,,,,,,,,,,,,,,,,,,,`,,t1,t1
,,,`,,`,,,,,,,,,,,,,,,,,,,,,,,,,,`,,t1,t1
,,,`,,`,,,,,,,,,,,,,,,,,,,,,,,,,,`,,t1,t1
,,,`,,`,,,,,,,,,`,,,,,,,,`,,,,,,,,,`,,t1,t1
,,,`,,`,`,`,`,`,`,`,`,`,`,,,,,,,,`,`,`,`,`,`,`,`,`,`,,t1,t1
,,,`,,,,,,,,,,,,,,,,,,,,,,,,,,,,,,t1,t1
,,,`,`,`,`,`,`,`,`,`,`,`,`,,,,,,,,`,`,`,`,`,`,`,`,`,`,`,`

,,,,,,,,,,,,,,,t1,t1,t1,t1,t1,t1,t1

#build label(surface_cover_vents) start(19; 19) hidden() cover the miasma vents



,,,`,,`,`,`,`,`,`,`,`,`,`,`,`,`,`,`,`,`,`,`,`,`,`,`,`,`,`,`,,`
,,,`,,`,,,,,,,,,,,,,,,,,,,,,,,,,,`,,`
,,,`,,`,,,,,,,,,,,,,,,,,,,,,,,,,,`,,`
,,,`,,`,,,,,,,,,,,,,,,,,,,,,,,,,,`,,`
,,,`,,`,,,,,,,,,,,,,,,,,,,,,,,,,,`,,`
,,,`,,`,,,,,,,,,,,,,,,,,,,,,,,,,,`,,`
,,,`,,`,,,,,,,,,,,,,,,,,,,,,,,,,,`,,`
,,,`,,`,,,,,,,,,,,,,,,,,,,,,,,,,,`,,`
,,,`,,`,,,,,,,,,,,,,,,,,,,,,,,,,,`,,`
,,,`,,`,,,,,,,,,,,,,,,,,,,,,,,,,,`,,`
,,,`,,`,,,,,,,,,,,,,,,,,,,,,,,,,,`,,`
,,,`,,`,,,,,,,,,,,,,,,,,,,,,,,,,,`,,`
,,,`,,`,`,`,`,`,Cw,`,`,`,`,`,`,,`,,`,`,`,`,`,Cw,`,`,`,Cw,`,`,,`
,,,`,,`,,`,,,,,,,,`,,,,,,`,,,,,,,,,,`,,`
,,,`,,`,,`,,,,,,,,,,`,`,`,,,,,,,,,,,,`,,`
,,,`,,`,,,,,,,,,,`,,`,~,`,,`,,,,,,,,,,`,,`
,,,`,,`,,`,,,,,,,,,,`,`,`,,,,,,,,,,,,`,,`
,,,`,,`,,`,,,,,,,,`,,,,,,`,,,,,,,,,,`,,`
,,,`,,`,`,`,`,`,`,`,,`,`,`,`,,`,,`,`,`,`,,`,`,`,`,`,`,`,,`
,,,`,,`,,,,,,,,,`,Cf,,,,,,Cf,`,,,,,,,,,`,,`
,,,`,,`,,,,,,,,,Cf,Cf,,,,,,Cf,Cf,,,,,,,,,`,,`
,,,`,,`,,,,,,,,,Cf,Cf,,Cf,Cf,Cf,,Cf,Cf,,,,,,,,,`,,`
,,,`,,`,,,,,,,,,,,,Cf,Cf,Cf,,,,,,,,,,,,`,,`
,,,`,,`,,,,,,,,,Cw,,,Cf,Cf,Cf,,,Cw,,,,,,,,,`,,`
,,,`,,`,`,`,`,`,`,`,`,`,`,,,,,,,,`,`,`,`,`,`,`,`,`,`,,`
,,,`,,,,,,,,,,,,,,,Cf,,,,,,,,,,,,,,,`
,,,`,`,`,`,`,`,`,`,`,`,`,`,,,,,,,,`,`,`,`,`,`,`,`,`,`,`,`



#build label(surface_cover_stairs) start(19; 19) hidden() protect the central stairs



,,,`,,`,`,`,`,`,`,`,`,`,`,`,`,`,`,`,`,`,`,`,`,`,`,`,`,`,`,`,,`
,,,`,,`,,,,,,,,,,,,,,,,,,,,,,,,,,`,,`
,,,`,,`,,,,,,,,,,,,,,,,,,,,,,,,,,`,,`
,,,`,,`,,,,,,,,,,,,,,,,,,,,,,,,,,`,,`
,,,`,,`,,,,,,,,,,,,,,,,,,,,,,,,,,`,,`
,,,`,,`,,,,,,,,,,,,,,,,,,,,,,,,,,`,,`
,,,`,,`,,,,,,,,,,,,,,,,,,,,,,,,,,`,,`
,,,`,,`,,,,,,,,,,,,,,,,,,,,,,,,,,`,,`
,,,`,,`,,,,,,,,,,,,,,,,,,,,,,,,,,`,,`
,,,`,,`,,,,,,,,,,,,,,,,,,,,,,,,,,`,,`
,,,`,,`,,,,,,,,,,,,,,,,,,,,,,,,,,`,,`
,,,`,,`,,,,,,,,,,,,,Cr,,,,,,,,,,,,,`,,`
,,,`,,`,`,`,`,`,`,`,`,`,`,Cw,Cw,Cf,Cw,Cf,Cw,Cw,`,`,`,`,`,`,`,`,`,`,,`
,,,`,,`,,`,,,,,,,,Cw,,,,,,Cw,,,,,,,,,,`,,`
,,,`,,`,,`,,,,,,,,Cf,,`,`,`,,Cf,,,,,,,,,,`,,`
,,,`,,`,,,,,,,,,,Cw,,H,~,H,,Cw,,,,,,,,,,`,,`
,,,`,,`,,`,,,,,,,,Cf,,`,`,`,,Cf,,,,,,,,,,`,,`
,,,`,,`,,`,,,,,,,,Cw,,,,,,Cw,,,,,,,,,,`,,`
,,,`,,`,`,`,`,`,`,`,,`,`,Cw,Cw,Cf,Cw,Cf,Cw,Cw,`,`,,`,`,`,`,`,`,`,,`
,,,`,,`,,,,,,,,,`,,,,,,,,`,,,,,,,,,`,,`
,,,`,,`,,,,,,,,,,,,,,,,,,,,,,,,,,`,,`
,,,`,,`,,,,,,,,,,,,,,,,,,,,,,,,,,`,,`
,,,`,,`,,,,,,,,,,,,,,,,,,,,,,,,,,`,,`
,,,`,,`,,,,,,,,,`,,,,,,,,`,,,,,,,,,`,,`
,,,`,,`,`,`,`,`,`,`,`,`,`,,,,,,,,`,`,`,`,`,`,`,`,`,`,,`
,,,`,,,,,,,,,,,,,,,,,,,,,,,,,,,,,,`
,,,`,`,`,`,`,`,`,`,`,`,`,`,,,,,,,,`,`,`,`,`,`,`,`,`,`,`,`



#<



,,,`,,`,`,`,`,`,`,`,`,`,`,`,`,`,`,`,`,`,`,`,`,`,`,`,`,`,`,`,,`
,,,`,,`,,,,,,,,,,,,,,,,,,,,,,,,,,`,,`
,,,`,,`,,,,,,,,,,,,,,,,,,,,,,,,,,`,,`
,,,`,,`,,,,,,,,,,,,,,,,,,,,,,,,,,`,,`
,,,`,,`,,,,,,,,,,,,,,,,,,,,,,,,,,`,,`
,,,`,,`,,,,,,,,,,,,,,,,,,,,,,,,,,`,,`
,,,`,,`,,,,,,,,,,,,,,,,,,,,,,,,,,`,,`
,,,`,,`,,,,,,,,,,,,,,,,,,,,,,,,,,`,,`
,,,`,,`,,,,,,,,,,,,,,,,,,,,,,,,,,`,,`
,,,`,,`,,,,,,,,,,,,,,,,,,,,,,,,,,`,,`
,,,`,,`,,,,,,,,,,,,,,,,,,,,,,,,,,`,,`
,,,`,,`,,,,,,,,,,,,,,,,,,,,,,,,,,`,,`
,,,`,,`,`,`,`,`,`,`,`,`,`,`,`,Cf,`,Cf,`,`,`,`,`,`,`,`,`,`,`,`,,`
,,,`,,`,,`,,,,,,,,`,Cf,Cf,Cf,Cf,Cf,`,,,,,,,,,,`,,`
,,,`,,`,,`,,,,,,,,Cf,Cf,Cf,Cf,Cf,Cf,Cf,,,,,,,,,,`,,`
,,,`,,`,,,,,,,,,,`,Cf,Cf,Cf,Cf,Cf,`,,,,,,,,,,`,,`
,,,`,,`,,`,,,,,,,,Cf,Cf,Cf,Cf,Cf,Cf,Cf,,,,,,,,,,`,,`
,,,`,,`,,`,,,,,,,,`,Cf,Cf,Cf,Cf,Cf,`,,,,,,,,,,`,,`
,,,`,,`,`,`,`,`,`,`,,`,`,`,`,Cf,`,Cf,`,`,`,`,,`,`,`,`,`,`,`,,`
,,,`,,`,,,,,,,,,`,,,,,,,,`,,,,,,,,,`,,`
,,,`,,`,,,,,,,,,,,,,,,,,,,,,,,,,,`,,`
,,,`,,`,,,,,,,,,,,,,,,,,,,,,,,,,,`,,`
,,,`,,`,,,,,,,,,,,,,,,,,,,,,,,,,,`,,`
,,,`,,`,,,,,,,,,`,,,,,,,,`,,,,,,,,,`,,`
,,,`,,`,`,`,`,`,`,`,`,`,`,,,,,,,,`,`,`,`,`,`,`,`,`,`,,`
,,,`,,,,,,,,,,,,,,,,,,,,,,,,,,,,,,`
,,,`,`,`,`,`,`,`,`,`,`,`,`,,,,,,,,`,`,`,`,`,`,`,`,`,`,`,`



#build label(surface_stairs_doors) start(19; 19) hidden()



,,,`,,`,`,`,`,`,`,`,`,`,`,`,`,`,`,`,`,`,`,`,`,`,`,`,`,`,`,`,,`
,,,`,,`,,,,,,,,,,,,,,,,,,,,,,,,,,`,,`
,,,`,,`,,,,,,,,,,,,,,,,,,,,,,,,,,`,,`
,,,`,,`,,,,,,,,,,,,,,,,,,,,,,,,,,`,,`
,,,`,,`,,,,,,,,,,,,,,,,,,,,,,,,,,`,,`
,,,`,,`,,,,,,,,,,,,,,,,,,,,,,,,,,`,,`
,,,`,,`,,,,,,,,,,,,,,,,,,,,,,,,,,`,,`
,,,`,,`,,,,,,,,,,,,,,,,,,,,,,,,,,`,,`
,,,`,,`,,,,,,,,,,,,,,,,,,,,,,,,,,`,,`
,,,`,,`,,,,,,,,,,,,,,,,,,,,,,,,,,`,,`
,,,`,,`,,,,,,,,,,,,,,,,,,,,,,,,,,`,,`
,,,`,,`,,,,,,,,,,,,,,,,,,,,,,,,,,`,,`
,,,`,,`,`,`,`,`,`,`,`,`,`,`,`,d,`,d,`,`,`,`,`,`,`,`,`,`,`,`,,`
,,,`,,`,,`,,,,,,,,`,,,,,,`,,,,,,,,,,`,,`
,,,`,,`,,`,,,,,,,,d,,`,`,`,,d,,,,,,,,,,`,,`
,,,`,,`,,,,,,,,,,`,,`,`,`,,`,,,,,,,,,,`,,`
,,,`,,`,,`,,,,,,,,d,,`,`,`,,d,,,,,,,,,,`,,`
,,,`,,`,,`,,,,,,,,`,,,,,,`,,,,,,,,,,`,,`
,,,`,,`,`,`,`,`,`,`,,`,`,`,`,d,`,d,`,`,`,`,,`,`,`,`,`,`,`,,`
,,,`,,`,,,,,,,,,`,,,,,,,,`,,,,,,,,,`,,`
,,,`,,`,,,,,,,,,,,,,,,,,,,,,,,,,,`,,`
,,,`,,`,,,,,,,,,,,,,,,,,,,,,,,,,,`,,`
,,,`,,`,,,,,,,,,,,,,,,,,,,,,,,,,,`,,`
,,,`,,`,,,,,,,,,`,,,,,,,,`,,,,,,,,,`,,`
,,,`,,`,`,`,`,`,`,`,`,`,`,,,,,,,,`,`,`,`,`,`,`,`,`,`,,`
,,,`,,,,,,,,,,,,,,,,,,,,,,,,,,,,,,`
,,,`,`,`,`,`,`,`,`,`,`,`,`,,,,,,,,`,`,`,`,`,`,`,`,`,`,`,`



#build label(surface_pre_building) start(19; 19) hidden() flooring and anchoring walls for future buildings/doors
#<



,,,`,,`,`,`,`,`,`,`,`,`,`,`,`,`,`,`,`,`,`,`,`,`,`,`,`,`,`,`,,`
,,,`,,`,,,,,,,,,,,,,,,,,,,,,,,,,,`,,`
,,,`,,`,,,,,,,,,,,,,,,,,,,,,,,,,,`,,`
,,,`,,`,,,,,,,,,,,,,,,,,,,,,,,,,,`,,`
,,,`,,`,,,,,,,,,,,,,,,,,,,,,,,,,,`,,`
,,,`,,`,,,,,,,,,,,,,,,,,,,,,,,,,,`,,`
,,,`,,`,,,,,,,,,,,,,,,,,,,,,,,,,,`,,`
,,,`,,`,,,,,,,,,,,,,,,,,,,,,,,,,,`,,`
,,,`,,`,,,,,,,,,,,,,,,,,,,,,,,,,,`,,`
,,,`,,`,,,,,,,,,,,,,,,,,,,,,,,,,,`,,`
,,,`,,`,,,,,,,,,,,,,,,,,,,,,,,,,,`,,`
,,,`,,`,,,,,,,,,,,,,~,,,,,,,,,,,,,`,,`
,,,`,,`,`,`,`,`,`,`,`,`,`,`,`,~,`,~,`,`,`,`,`,`,`,`,`,`,`,`,,`
,,,`,,`,,`,,,,,,,,`,~,~,~,~,~,`,,,,,,,,,,`,,`
,,,`,,`,,`,,,,,,,,~,~,~,~,~,~,~,,,,,,,,,,`,,`
,,,`,,`,,,,,,,,,,`,~,~,~,~,~,`,,,,,,,,,,`,,`
,,,`,,`,,`,,,,,,,,~,~,~,~,~,~,~,Cf,Cf,Cf,,,,,,,`,,`
,,,`,,`,,`,,,,,,,,`,~,~,~,~,~,`,,,Cf,,,,,,,`,,`
,,,`,,`,`,`,`,`,`,`,,`,`,`,`,~,`,~,`,`,`,`,Cf,`,`,`,`,`,`,`,,`
,,,`,,`,,,,,,,,,`,,,,,,,,`,,Cf,Cf,Cf,Cf,Cf,Cf,Cf,`,,`
,,,`,,`,,,,,,,,,,,,,,,,,,,,,,,,,Cf,`,,`
,,,`,,`,,,,,,,,,,,,,,,,,,,,,,,,,Cf,`,,`
,,,`,,`,,,,,,,,,,,,,,,,,,,,,,,,,Cf,`,,`
,,,`,,`,,,,,,,,,`,,,,,,,,`,,,,,,,,Cf,`,,`
,,,`,,`,`,`,`,`,`,`,`,`,`,,,,,,,,`,`,`,`,`,`,`,`,`,`,,`
,,,`,,,,,,,,,,,,,,,,,,,,,,,,,,,,,,`
,,,`,`,`,`,`,`,`,`,`,`,`,`,,,,,,,,`,`,`,`,`,`,`,`,`,`,`,`



#>



,,,`,,`,`,`,`,`,`,`,`,`,`,`,`,`,`,`,`,`,`,`,`,`,`,`,`,`,`,`,,`
,,,`,,`,,,,,,,,,,,,,,,,,,,,,,,,,,`,,`
,,,`,,`,,,,,,,,,,,,,,,,,,,,,,,,,,`,,`
,,,`,,`,,,,,,,,,,,,,,,,,,,,,,,,,,`,,`
,,,`,,`,,,,,,,,,,,,,,,,,,,,,,,,,,`,,`
,,,`,,`,,,,,,,,,,,,,,,,,,,,,,,,,,`,,`
,,,`,,`,,,,,,,,,,,,,,,,,,,,,,,,,,`,,`
,,,`,,`,,,,,,,,,,,,,,,,,,,,,,,,,,`,,`
,,,`,,`,,,,,,,,,,,,,,,,,,,,,,,,,,`,,`
,,,`,,`,,,,,,,,,,,,,,,,,,,,,,,,,,`,,`
,,,`,,`,,,,,,,,,,,,,,,,,,,,,,,,,,`,,`
,,,`,,`,,,,,,,,,,,,,,,,,,,,,,,,,,`,,`
,,,`,,`,`,`,`,`,`,`,`,`,`,`,`,,`,,`,`,`,`,`,`,`,`,`,`,`,`,,`
,,,`,,`,,`,,,,,,,,`,Cf,,Cf,,Cf,`,,,,,,,,,,`,,`
,,,`,,`,,Cw,,,,,,,,,,`,`,`,,,,,,,,,,,,`,,`
,,,`,,`,,Cf,,,,,,,,`,,`,`,`,,`,,,,,,,,,,`,,`
,,,`,,`,,Cw,,,,,,,,,,`,`,`,,,,,,,,,,,,`,,`
,,,`,,`,,`,,,,,,,,`,Cf,Cf,Cf,Cf,Cf,`,,,,,,,,,,`,,`
,,,`,,`,`,`,`,`,`,Cw,Cf,Cw,`,`,`,,`,,`,`,`,Cw,Cf,Cw,`,`,`,`,`,`,,`
,,,`,,`,Cf,Cf,Cf,Cf,Cf,Cf,Cf,Cf,`,~,,,,,,~,`,,,,,,,Cf,Cf,`,,`
,,,`,,`,Cf,Cf,Cf,Cf,Cf,Cf,Cf,Cf,~,~,Cf,Cf,Cf,Cf,Cf,~,~,,,,,,,,Cf,`,,`
,,,`,,`,Cf,Cf,Cf,Cf,Cf,Cf,Cf,Cf,~,~,,~,~,~,,~,~,,,,,Cf,Cf,,Cf,`,,`
,,,`,,`,,Cf,,Cf,Cf,Cf,Cf,Cf,,Cf,,~,~,~,,Cf,,,,,,,,,Cf,`,,`
,,,`,,`,,Cf,,Cf,Cf,Cf,Cf,Cf,`,,,~,~,~,,,`,,,,,,,Cf,Cf,`,,`
,,,`,,`,`,`,`,`,`,`,`,`,`,,,,,,,,`,`,`,`,`,`,`,`,`,`,,`
,,,`,Cf,,,,,,,,,Cf,,,,,~,,,,,Cf,,,,,,,,,Cf,`
,,,`,`,`,`,`,`,`,`,`,`,`,`,,,,,,,,`,`,`,`,`,`,`,`,`,`,`,`



#place label(surface_place) start(19; 19) hidden() remaining surface stockpiles



,,,`,,`,`,`,`,`,`,`,`,`,`,`,`,`,`,`,`,`,`,`,`,`,`,`,`,`,`,`,,`
,,,`,,`,,,,,,,,,,,,,,,,,,,,,,,,,,`,,`
,,,`,,`,,,,,,,,,,,,,,,,,,,,,,,,,,`,,`
,,,`,,`,,,,,,,,,,,,,,,,,,,,,,,,,,`,,`
,,,`,,`,,,,,,,,,,,,,,,,,,,,,,,,,,`,,`
,,,`,,`,,,,,,,,,,,,,,,,,,,,,,,,,,`,,`
,,,`,,`,,,,,,,,,,,,,,,,,,,,,,,,,,`,,`
,,,`,,`,,,,,,,,,,,,,,,,,,,,,,,,,,`,,`
,,,`,,`,,,,,,,,,,,,,,,,,,,,,,,,,,`,,`
,,,`,,`,,,,,,,,,,,,,,,,,,,,,,,,,,`,,`
,,,`,,`,,,,,,,,,,,,,,,,,,,,,,,,,,`,,`
,,,`,,`,,,,,,,,,,,,,,,,,,,,,,,,,,`,,`
,,,`,,`,`,`,`,`,`,`,`,`,`,`,`,,`,,`,`,`,`,`,`,`,`,`,`,`,`,,`
,,,`,,`,,`,,,,,,,,`,,,,,,`,a5(9x5),,,,,,,,,`,,`
,,,`,,`,,`,,,,,,,,,,`,`,`,,,,,,,,,,,,`,,`
,,,`,,`,,,,,,,,,,`,,`,`,`,,`,,,,,,,,,,`,,`
,,,`,,`,,`,,,,,,,,,,`,`,`,,,,,,,,,,,,`,,`
,,,`,,`,,`,,,,,,,,`,,,,,,`,,,,,,,,,,`,,`
,,,`,,`,`,`,`,`,`,`,,`,`,`,`,,`,,`,`,`,`,,`,`,`,`,`,`,`,,`
,,,`,,`,g(3x3),,,,,,,,`,,,,,,,,`,,,,,,,,,`,,`
,,,`,,`,,,,,,,,,,,,,,,,,,,,,,,,,,`,,`
,,,`,,`,,,,,,,,,,,,,,,,,,,,,,,,,,`,,`
,,,`,,`,,,,,,,,,,,,,,,,,,,,,,,,,,`,,`
,,,`,,`,,c,,,,,,,`,,,,,,,,`,,c,,,,,,,`,,`
,,,`,,`,`,`,`,`,`,`,`,`,`,,,,,,,,`,`,`,`,`,`,`,`,`,`,,`
,,,`,,,,,,,,,,,,,,,,,,,,,,,,,,,,,,`
,,,`,`,`,`,`,`,`,`,`,`,`,`,,,,,,,,`,`,`,`,`,`,`,`,`,`,`,`



"#build label(surface_build) start(19; 19) hidden() message(Use autofarm to manage farm crop selection.
Remember to connect the levers to the gates once they are built.) gates, barracks, farm area, and trade area"



,,,`,,`,`,`,`,`,`,`,`,`,`,`,`,`,`,`,`,`,`,`,`,`,`,`,`,`,`,`,,`
,,,`,,`,,,,,,,,,,,,,,,,,,,,,,,,,,`,,`
,,,`,,`,,,,,,,,,,,,,,,,,,,,,,,,,,`,,`
,,,`,,`,,,,,,,,,,,,,,,,,,,,,,,,,,`,,`
,,,`,,`,,,,,,,,,,,,,,,,,,,,,,,,,,`,,`
,,,`,,`,,,,,,,,,,,,,,,,,,,,,,,,,,`,,`
,,,`,,`,,,,,,,,,,,,,,,,,,,,,,,,,,`,,`
,,,`,,`,,,,,,,,,,,,,,,,,,,,,,,,,,`,,`
,,,`,,`,,,,,,,,,,,,,,,,,,,,,,,,,,`,,`
,,,`,,`,,,,,,,,,,,,,,,,,,,,,,,,,,`,,`
,,,`,,`,,,,,,,,,,,,,,,,,,,,,,,,,,`,,`
,,,`,,`,,,,,,,,,,,,,,,,,,,,,,,,,,`,,`
,,,`,,`,`,`,`,`,`,`,`,`,`,`,`,,`,,`,`,`,`,`,`,`,`,`,`,`,`,,`
,,,`,,`,~h,`,~,~,N,N,N,N,N,`,Tl,,Tl,,Tl,`,,,,,,,,,,`,,`
,,,`,,`,~h,`,p(1x1),p(1x1),p(1x1),p(1x1),p(1x1),p(1x1),p(1x1),,,`,`,`,,,,,,,,,,,,`,,`
,,,`,,`,~h,d,p(1x1),p(1x1),p(1x1),p(1x1),p(1x1),p(1x1),p(1x1),`,,`,`,`,,`,,,,,,,,,,`,,`
,,,`,,`,~h,`,p(1x1),p(1x1),p(1x1),p(1x1),p(1x1),p(1x1),p(1x1),,,`,`,`,,,,,,,,,,,,`,,`
,,,`,,`,~h,`,N,N,N,N,N,N,N,`,Tl,Tl,Tl,Tl,Tl,`,,,,,,,,,,`,,`
,,,`,,`,`,`,`,`,`,`,d,`,`,`,`,,`,,`,`,`,`,d,`,`,`,`,`,`,`,,`
,,,`,,`,,,,,,,,,`,,gw,gw,gw,gw,gw,,`,,,,,,,h,b,`,,`
,,,`,,`,,,,,,,,,ga,ga,gw,gw,gw,gw,gw,gd,gd,,,,,,,,b,`,,`
,,,`,,`,,,,,,D,,,ga,ga,,,,,,gd,gd,,,,,a,r,,b,`,,`
,,,`,,`,,trackstopS,,,,,,,ga,ga,,,,,,gd,gd,,trackstopS,,,,,,b,`,,`
,,,`,,`,,,,,,,,,`,,,,,,,,`,,,,,,,h,b,`,,`
,,,`,,`,`,`,`,`,`,`,`,`,`,,,,,,,,`,`,`,`,`,`,`,`,`,`,,`
,,,`,gd,gd,,,,,,,,gd,gd,,,,,,,,ga,ga,,,,,,,,ga,ga,`
,,,`,`,`,`,`,`,`,`,`,`,`,`,gw,gw,gw,gw,gw,gw,gw,`,`,`,`,`,`,`,`,`,`,`,`
,,,,,,,,,,,,,,,gw,gw,gw,gw,gw,gw,gw
,,,,,,,,,,,,,,,gw,gw,gw,gw,gw,gw,gw

#aliases
"prisoner_route_enable: {enableanimals}{cages}{permittraps}{animalsprefix}{Right}{permitsearch search="" men""}{permitsearch search=dwarves}{permitsearch search=elves}{permitsearch search=humans}{permitsearch search=kobolds}{permitsearch search=gremlins}{permitsearch search=giants}{permitsearch search=goblins}{permitsearch search=ettins}{permitsearch search=cyclopes}{permitsearch search=ogres}{permitsearch search=eyes}{permitsearch search=reachers}{permitsearch search=gorlaks}{permitsearch search=trolls}{permitsearch search=minotaurs}^"

"#query label(surface_query) start(19; 19) hidden() message(Remember to assign minecarts to the trade goods and prisoner processing quantum stockpiles (run ""assign-minecarts all"").
Feel free to adjust the configuration of the ""trade goods"" feeder stockpile so it accepts the item types you want to trade away. If those items types are also accepted by other stockpiles, configure those stockpiles to give to the ""trade goods"" stockpile.
You might also want to set the ""trade goods quantum"" stockpile to Auto Trade if you have the autotrade DFHack plugin enabled.)"



,,,`,,`,`,`,`,`,`,`,`,`,`,`,`,`,`,`,`,`,`,`,`,`,`,`,`,`,`,`,,`
,,,`,,`,,,,,,,,,,,,,,,,,,,,,,,,,,`,,`
,,,`,,`,,,,,,,,,,,,,,,,,,,,,,,,,,`,,`
,,,`,,`,,,,,,,,,,,,,,,,,,,,,,,,,,`,,`
,,,`,,`,,,,,,,,,,,,,,,,,,,,,,,,,,`,,`
,,,`,,`,,,,,,,,,,,,,,,,,,,,,,,,,,`,,`
,,,`,,`,,,,,,,,,,,,,,,,,,,,,,,,,,`,,`
,,,`,,`,,,,,,,,,,,,,,,,,,,,,,,,,,`,,`
,,,`,,`,,,,,,,,,,,,,,,,,,,,,,,,,,`,,`
,,,`,,`,,,,,,,,,,,,,,,,,,,,,,,,,,`,,`
,,,`,,`,,,,,,,,,,,,,,,,,,,,,,,,,,`,,`
,,,`,,`,,,,,,,,,,,,,,,,,,,,,,,,,,`,,`
,,,`,,`,`,`,`,`,`,`,`,`,`,`,`,,`,,`,`,`,`,`,`,`,`,`,`,`,`,,`
,,,`,,`,,`,,,,,,,,`,"{givename name=""trade depo gate""}",,"{givename name=""inner main gate""}",,"{givename name=""barracks gate""}",`,"{givename name=""prison/training area""}",,,,,,,,,`,,`
,,,`,,`,,`,,,,,,,,,,`,`,`,,,,,,,,,,,,`,,`
,,,`,,`,,,,,,,,,,`,,`,`,`,,`,,,,,,,,,,`,,`
,,,`,,`,,`,,,,,,,,,,`,`,`,,,,,,,,,,,,`,,`
,,,`,,`,,`,,,,,,,,`,"{givename name=""left outer gate""}","{givename name=""left inner gate""}","{givename name=""outer main gate""}","{givename name=""right inner gate""}","{givename name=""right outer gate""}",`,,,,,,,,,,`,,`
,,,`,,`,`,`,`,`,`,`,,`,`,`,`,,`,,`,`,`,`,,`,`,`,`,`,`,`,,`
,,,`,,`,nocontainers,crafts,,,,,,,`,,,,"{givename name=""inner main gate""}",,,,`,,,,,,,,,`,,`
,,,`,,`,"{givename name=""trade goods""}",,,,,,,,,,,,,,,,,,,,,,,,,`,,`
,,,`,,`,{forbidmasterworkfinishedgoods}{forbidartifactfinishedgoods},,,,,,,,"{givename name=""trade depo gate""}",,,,,,,,"{givename name=""barracks gate""}",,,,,,,,,`,,`
,,,`,,`,,"{quantumstopfromnorth name=""Trade Goods quantum""}",,,,,,,,,,,,,,,,,"{quantumstop name=""Prisoner/Cage quantum"" move={Up 5} move_back={Down 5} route_enable={prisoner_route_enable}}{givename name=""prisoner/cage dumper""}",,,,,,,`,,`
,,,`,,`,,"{quantum name=""trade goods quantum""}",,,,,,,`,,,,,,,,`,,"{quantum name=""prisoner/cage quantum"" quantum_enable={enableanimals}}",,,,,,,`,,`
,,,`,,`,`,`,`,`,`,`,`,`,`,,,,,,,,`,`,`,`,`,`,`,`,`,`,,`
,,,`,,"{givename name=""left outer gate""}",,,,,,,,,"{givename name=""left inner gate""}",,,,,,,,"{givename name=""right inner gate""}",,,,,,,,,"{givename name=""right outer gate""}",,`
,,,`,`,`,`,`,`,`,`,`,`,`,`,,,,"{givename name=""outer main gate""}",,,,`,`,`,`,`,`,`,`,`,`,`,`



#dig label(surface_clear_large) start(19; 19) hidden() clear wider area of trees
t1(37x33)


,,,`,,`,`,`,`,`,`,`,`,`,`,`,`,`,`,`,`,`,`,`,`,`,`,`,`,`,`,`,,`
,,,`,,`,,,,,,,,,,,,,,,,,,,,,,,,,,`,,`
,,,`,,`,,,,,,,,,,,,,,,,,,,,,,,,,,`,,`
,,,`,,`,,,,,,,,,,,,,,,,,,,,,,,,,,`,,`
,,,`,,`,,,,,,,,,,,,,,,,,,,,,,,,,,`,,`
,,,`,,`,,,,,,,,,,,,,,,,,,,,,,,,,,`,,`
,,,`,,`,,,,,,,,,,,,,,,,,,,,,,,,,,`,,`
,,,`,,`,,,,,,,,,,,,,,,,,,,,,,,,,,`,,`
,,,`,,`,,,,,,,,,,,,,,,,,,,,,,,,,,`,,`
,,,`,,`,,,,,,,,,,,,,,,,,,,,,,,,,,`,,`
,,,`,,`,,,,,,,,,,,,,,,,,,,,,,,,,,`,,`
,,,`,,`,,,,,,,,,,,,,,,,,,,,,,,,,,`,,`
,,,`,,`,`,`,`,`,,`,`,`,`,`,`,,`,,`,`,`,`,`,,`,`,`,,`,`,,`
,,,`,,`,,`,,,,,,,,`,,,,,,`,,,,,,,,,,`,,`
,,,`,,`,,`,,,,,,,,,,`,`,`,,,,,,,,,,,,`,,`
,,,`,,`,,,,,,,,,,`,,`,~,`,,`,,,,,,,,,,`,,`
,,,`,,`,,`,,,,,,,,,,`,`,`,,,,,,,,,,,,`,,`
,,,`,,`,,`,,,,,,,,`,,,,,,`,,,,,,,,,,`,,`
,,,`,,`,`,`,`,`,`,`,,`,`,`,`,,`,,`,`,`,`,,`,`,`,`,`,`,`,,`
,,,`,,`,,,,,,,,,`,,,,,,,,`,,,,,,,,,`,,`
,,,`,,`,,,,,,,,,,,,,,,,,,,,,,,,,,`,,`
,,,`,,`,,,,,,,,,,,,,,,,,,,,,,,,,,`,,`
,,,`,,`,,,,,,,,,,,,,,,,,,,,,,,,,,`,,`
,,,`,,`,,,,,,,,,`,,,,,,,,`,,,,,,,,,`,,`
,,,`,,`,`,`,`,`,`,`,`,`,`,,,,,,,,`,`,`,`,`,`,`,`,`,`,,`
,,,`,,,,,,,,,,,,,,,,,,,,,,,,,,,,,,`
,,,`,`,`,`,`,`,`,`,`,`,`,`,,,,,,,,`,`,`,`,`,`,`,`,`,`,`,`



#query label(surface_query2) start(19; 19) hidden()



,,,`,,`,`,`,`,`,`,`,`,`,`,`,`,`,`,`,`,`,`,`,`,`,`,`,`,`,`,`,,`
,,,`,,`,,,,,,,,,,,,,,,,,,,,,,,,,,`,,`
,,,`,,`,,,,,,,,,,,,,,,,,,,,,,,,,,`,,`
,,,`,,`,,,,,,,,,,,,,,,,,,,,,,,,,,`,,`
,,,`,,`,,,,,,,,,,,,,,,,,,,,,,,,,,`,,`
,,,`,,`,,,,,,,,,,,,,,,,,,,,,,,,,,`,,`
,,,`,,`,,,,,,,,,,,,,,,,,,,,,,,,,,`,,`
,,,`,,`,,,,,,,,,,,,,,,,,,,,,,,,,,`,,`
,,,`,,`,,,,,,,,,,,,,,,,,,,,,,,,,,`,,`
,,,`,,`,,,,,,,,,,,,,,,,,,,,,,,,,,`,,`
,,,`,,`,,,,,,,,,,,,,,,,,,,,,,,,,,`,,`
,,,`,,`,,,,,,,,,,,,,,,,,,,,,,,,,,`,,`
,,,`,,`,`,`,`,`,`,`,`,`,`,`,`,,`,,`,`,`,`,`,`,`,`,`,`,`,`,,`
,,,`,,`,cg,`,,,,,,,,`,,,,,,`,,,,,,,,,,`,,`
,,,`,,`,cg,`,,,,,,,,,,`,`,`,,,,,,,,,,,,`,,`
,,,`,,`,c,,,,,,,,,`,,`,`,`,,`,,,,,,,,,,`,,`
,,,`,,`,cg,`,,,,,,,,,,`,`,`,,,,,,,,,,,,`,,`
,,,`,,`,cg,`,,,,,,,,`,,,,,,`,,,,,,,,,,`,,`
,,,`,,`,`,`,`,`,`,`,,`,`,`,`,,`,,`,`,`,`,,`,`,`,`,`,`,`,,`
,,,`,,`,,,,,,,,,`,,,,,,,,`,,,,,,,,,`,,`
,,,`,,`,,,,,,,,,,,,,,,,,,,,,,,,,,`,,`
,,,`,,`,,,,,,,,,,,,,,,,,,,,,,,r&,,,`,,`
,,,`,,`,,,,,,,,,,,,,,,,,,,,,,,,,,`,,`
,,,`,,`,,,,,,,,,`,,,,,,,,`,,,,,,,,,`,,`
,,,`,,`,`,`,`,`,`,`,`,`,`,,,,,,,,`,`,`,`,`,`,`,`,`,`,,`
,,,`,,,,,,,,,,,,,,,,,,,,,,,,,,,,,,`
,,,`,`,`,`,`,`,`,`,`,`,`,`,,,,,,,,`,`,`,`,`,`,`,`,`,`,`,`



#build label(surface_walls) start(19; 19) hidden() build remaining walls



,,,`,,Cw,Cw,Cw,Cw,Cw,Cw,Cw,Cw,Cw,Cw,Cw,Cw,Cw,Cw,Cw,Cw,Cw,Cw,Cw,Cw,Cw,Cw,Cw,Cw,Cw,Cw,Cw,,`
,,,`,,Cw,,,,,,,,,,,,,,,,,,,,,,,,,,Cw,,`
,,,`,,Cw,,,,,,,,,,,,,,,,,,,,,,,,,,Cw,,`
,,,`,,Cw,,,,,,,,,,,,,,,,,,,,,,,,,,Cw,,`
,,,`,,Cw,,,,,,,,,,,,,,,,,,,,,,,,,,Cw,,`
,,,`,,Cw,,,,,,,,,,,,,,,,,,,,,,,,,,Cw,,`
,,,`,,Cw,,,,,,,,,,,,,,,,,,,,,,,,,,Cw,,`
,,,`,,Cw,,,,,,,,,,,,,,,,,,,,,,,,,,Cw,,`
,,,`,,Cw,,,,,,,,,,,,,,,,,,,,,,,,,,Cw,,`
,,,`,,Cw,,,,,,,,,,,,,,,,,,,,,,,,,,Cw,,`
,,,`,,Cw,,,,,,,,,,,,,,,,,,,,,,,,,,Cw,,`
,,,`,,Cw,,,,,,,,,,,,,,,,,,,,,,,,,,Cw,,`
,,,`,,Cw,Cw,Cw,Cw,Cw,~,Cw,Cw,Cw,Cw,~,~,,~,,~,~,Cw,Cw,Cw,~,Cw,Cw,Cw,~,Cw,Cw,,`
,,,`,,Cw,,Cw,,,,,,,,~,,,,,,~,,,,,,,,,,Cw,,`
,,,`,,Cw,,~,,,,,,,,,,`,`,`,,,,,,,,,,,,Cw,,`
,,,`,,Cw,,,,,,,,,,~,,`,`,`,,~,,,,,,,,,,Cw,,`
,,,`,,Cw,,~,,,,,,,,,,`,`,`,,,,,,,,,,,,Cw,,`
,,,`,,Cw,,Cw,,,,,,,,~,,,,,,~,,,,,,,,,,Cw,,`
,,,`,,Cw,Cw,Cw,Cw,Cw,Cw,~,,~,Cw,~,~,,~,,~,~,Cw,~,,~,Cw,Cw,Cw,Cw,Cw,Cw,,`
,,,`,,Cw,,,,,,,,,Cw,,,,,,,,Cw,,,,,,,,,Cw,,`
,,,`,,Cw,,,,,,,,,,,,,,,,,,,,,,,,,,Cw,,`
,,,`,,Cw,,,,,,,,,,,,,,,,,,,,,,,,,,Cw,,`
,,,`,,Cw,,,,,,,,,,,,,,,,,,,,,,,,,,Cw,,`
,,,`,,Cw,,,,,,,,,~,,,,,,,,~,,,,,,,,,Cw,,`
,,,`,,Cw,Cw,Cw,Cw,Cw,Cw,Cw,Cw,Cw,Cw,,,,,,,,Cw,Cw,Cw,Cw,Cw,Cw,Cw,Cw,Cw,Cw,,`
,,,`,,,,,,,,,,,,,,,,,,,,,,,,,,,,,,`
,,,`,`,Cw,Cw,Cw,Cw,Cw,Cw,Cw,Cw,Cw,Cw,,,,,,,,Cw,Cw,Cw,Cw,Cw,Cw,Cw,Cw,Cw,Cw,`,`



#build label(surface_floors) start(19; 19) hidden() build remaining flooring



,,,`,,`,`,`,`,`,`,`,`,`,`,`,`,`,`,`,`,`,`,`,`,`,`,`,`,`,`,`,,`
,,,`,,`,,,,,,,,,,,,,,,,,,,,,,,,,,`,,`
,,,`,,`,,,,,,,,,,,,,,,,,,,,,,,,,,`,,`
,,,`,,`,,,,,,,,,,,,,,,,,,,,,,,,,,`,,`
,,,`,,`,,,,,,,,,,,,,,,,,,,,,,,,,,`,,`
,,,`,,`,,,,,,,,,,,,,,,,,,,,,,,,,,`,,`
,,,`,,`,,,,,,,,,,,,,,,,,,,,,,,,,,`,,`
,,,`,,`,,,,,,,,,,,,,,,,,,,,,,,,,,`,,`
,,,`,,`,,,,,,,,,,,,,,,,,,,,,,,,,,`,,`
,,,`,,`,,,,,,,,,,,,,,,,,,,,,,,,,,`,,`
,,,`,,`,,,,,,,,,,,,,,,,,,,,,,,,,,`,,`
,,,`,,`,,,,,,,,,,,,,,,,,,,,,,,,,,`,,`
,,,`,,`,`,`,`,`,`,`,`,`,`,`,`,~,`,~,`,`,`,`,`,`,`,`,`,`,`,`,,`
,,,`,,`,,`,,,,,,,,`,~,Cf,~,Cf,~,`,,,,,,,,,,`,,`
,,,`,,`,,`,,,,,,,,~,Cf,Cf,Cf,Cf,Cf,~,,,,,,,,,,`,,`
,,,`,,`,,~,,,,,,,,`,Cf,`,Cf,`,Cf,`,,,,,,,,,,`,,`
,,,`,,`,,`,,,,,,,,~,Cf,Cf,Cf,Cf,Cf,~,,,,,,,,,,`,,`
,,,`,,`,,`,,,,,,,,`,~,~,~,~,~,`,,,,,,,,,,`,,`
,,,`,,`,`,`,`,`,`,`,~,`,`,`,`,~,`,~,`,`,`,`,~,`,`,`,`,`,`,`,,`
,,,`,,`,~,~,~,~,~,~,~,~,`,~,~,~,~,~,~,~,`,Cf,Cf,Cf,Cf,Cf,Cf,~,~,`,,`
,,,`,,`,~,~,~,~,~,~,~,~,~,~,~,~,~,~,~,~,~,Cf,Cf,Cf,Cf,Cf,Cf,Cf,~,`,,`
,,,`,,`,~,~,~,~,~,~,~,~,~,~,Cf,~,~,~,Cf,~,~,Cf,Cf,Cf,Cf,~,~,Cf,~,`,,`
,,,`,,`,Cf,~,Cf,~,~,~,~,~,~,~,Cf,~,~,~,Cf,~,~,Cf,Cf,Cf,Cf,Cf,Cf,Cf,~,`,,`
,,,`,,`,Cf,~,Cf,~,~,~,~,~,`,Cf,Cf,~,~,~,Cf,Cf,`,Cf,Cf,Cf,Cf,Cf,Cf,~,~,`,,`
,,,`,,`,`,`,`,`,`,`,`,`,`,Cf,Cf,Cf,Cf,Cf,Cf,Cf,`,`,`,`,`,`,`,`,`,`,,`
,,,`,~,,,,,,,,,,,Cf,Cf,Cf,~,Cf,Cf,Cf,,,,,,,,,,,~,`
,,,`,`,`,`,`,`,`,`,`,`,`,`,,,,,,,,`,`,`,`,`,`,`,`,`,`,`,`



#build label(surface_traps) start(19; 19) hidden()

,,,,,Tc,Tc,,,,,,,,,,,,,,,,,,,,,,,,Tc,Tc
,,,,,Tc,Tc,,,,,,,,,,,,,,,,,,,,,,,,Tc,Tc
,,,`,,`,`,`,`,`,`,`,`,`,`,`,`,`,`,`,`,`,`,`,`,`,`,`,`,`,`,`,,`
,,,`,,`,,,,,,,,,,,,,,,,,,,,,,,,,,`,,`
,,,`,,`,,,,,,,,,,,,,,,,,,,,,,,,,,`,,`
,,,`,,`,,,,,,,,,,,,,,,,,,,,,,,,,,`,,`
,,,`,,`,,,,,,,,,,,,,,,,,,,,,,,,,,`,,`
,,,`,,`,,,,,,,,,,,,,,,,,,,,,,,,,,`,,`
,,,`,,`,,,,,,,,,,,,,,,,,,,,,,,,,,`,,`
,,,`,,`,,,,,,,,,,,,,,,,,,,,,,,,,,`,,`
,,,`,,`,,,,,,,,,,,,,,,,,,,,,,,,,,`,,`
,,,`,,`,,,,,,,,,,,,,,,,,,,,,,,,,,`,,`
,,,`,,`,,,,,,,,,,,,,,,,,,,,,,,,,,`,,`
,,,`,,`,,,,,,,,,,,,,,,,,,,,,,,,,,`,,`
,,,`,,`,`,`,`,`,`,`,`,`,`,`,`,,`,,`,`,`,`,`,`,`,`,`,`,`,`,,`
,,,`,,`,,`,,,,,,,,`,,,,,,`,,,,,,,,,,`,,`
,,,`,,`,,`,,,,,,,,,,`,`,`,,,,,,,,,,,,`,,`
,,,`,,`,,,,,,,,,,`,,`,`,`,,`,,,,,,,,,,`,,`
,,,`,,`,,`,,,,,,,,,,`,`,`,,,,,,,,,,,,`,,`
,,,`,,`,,`,,,,,,,,`,,,,,,`,,,,,,,,,,`,,`
,,,`,,`,`,`,`,`,`,`,,`,`,`,`,,`,,`,`,`,`,,`,`,`,`,`,`,`,,`
,,,`,,`,,,,,,,,,`,,,,,,,,`,,,,,,,,,`,,`
,,,`,,`,,,,,,,,,,,,,,,,,,,,,,,,,,`,,`
,,,`,,`,,,,,,,,,,,,,,,,,,,,,,,,,,`,,`
,,,`,,`,,,,,,,,,,,,,,,,,,,,,,,,,,`,,`
,,,`,,`,,,,,,,,,`,,,,,,,,`,,,,,,,,,`,,`
,,,`,,`,`,`,`,`,`,`,`,`,`,,,,,,,,`,`,`,`,`,`,`,`,`,`,,`
,,,`,,,Tc,Tc,Tc,Tc,Tc,Tc,Tc,,,,,,,,,,,,Tc,Tc,Tc,Tc,Tc,Tc,Tc,,,`
,,,`,`,`,`,`,`,`,`,`,`,`,`,,,,,,,,`,`,`,`,`,`,`,`,`,`,`,`
,,,,,,,,,,,,,Tc,Tc,,,,,,,,Tc,Tc
,,,,,,,,,,,,,Tc,Tc,,,,,,,,Tc,Tc

#build label(surface_roof) start(19; 19) hidden() roof hatch and adjacent tiles



,,,`,,`,`,`,`,`,`,`,`,`,`,`,`,`,`,`,`,`,`,`,`,`,`,`,`,`,`,`,,`
,,,`,,`,,,,,,,,,,,,,,,,,,,,,,,,,,`,,`
,,,`,,`,,,,,,,,,,,,,,,,,,,,,,,,,,`,,`
,,,`,,`,,,,,,,,,,,,,,,,,,,,,,,,,,`,,`
,,,`,,`,,,,,,,,,,,,,,,,,,,,,,,,,,`,,`
,,,`,,`,,,,,,,,,,,,,,,,,,,,,,,,,,`,,`
,,,`,,`,,,,,,,,,,,,,,,,,,,,,,,,,,`,,`
,,,`,,`,,,,,,,,,,,,,,,,,,,,,,,,,,`,,`
,,,`,,`,,,,,,,,,,,,,,,,,,,,,,,,,,`,,`
,,,`,,`,,,,,,,,,,,,,,,,,,,,,,,,,,`,,`
,,,`,,`,,,,,,,,,,,,Cf,,Cf,,,,,,,,,,,,`,,`
,,,`,,`,,,,,,,,,,,,Cf,H,Cf,,,,,,,,,,,,`,,`
,,,`,,`,`,`,`,`,`,`,`,`,`,`,`,~,`,~,`,`,`,`,`,`,`,`,`,`,`,`,,`
,,,`,,`,,`,,,,,,,,`,~,~,~,~,~,`,,,,,,,,,,`,,`
,,,`,,`,,`,,,,,,,,~,~,~,~,~,~,~,,,,,,,,,,`,,`
,,,`,,`,,,,,,,,,,`,~,~,~,~,~,`,,,,,,,,,,`,,`
,,,`,,`,,`,,,,,,,,~,~,~,~,~,~,~,~,~,~,,,,,,,`,,`
,,,`,,`,,`,,,,,,,,`,~,~,~,~,~,`,,,~,,,,,,,`,,`
,,,`,,`,`,`,`,`,`,`,,`,`,`,`,~,`,~,`,`,`,`,~,`,`,`,`,`,`,`,,`
,,,`,,`,,,,,,,,,`,,,,,,,,`,,~,~,~,~,~,~,~,`,,`
,,,`,,`,,,,,,,,,,,,,,,,,,,,,,,,,~,`,,`
,,,`,,`,,,,,,,,,,,,,,,,,,,,,,,,,~,`,,`
,,,`,,`,,,,,,,,,,,,,,,,,,,,,,,,,~,`,,`
,,,`,,`,,,,,,,,,`,,,,,,,,`,,,,,,,,~,`,,`
,,,`,,`,`,`,`,`,`,`,`,`,`,,,,,,,,`,`,`,`,`,`,`,`,`,`,,`
,,,`,,,,,,,,,,,,,,,,,,,,,,,,,,,,,,`
,,,`,`,`,`,`,`,`,`,`,`,`,`,,,,,,,,`,`,`,`,`,`,`,`,`,`,`,`



#build label(surface_roof2) start(19; 19) hidden() lower half of the roof



,,,`,,`,`,`,`,`,`,`,`,`,`,`,`,`,`,`,`,`,`,`,`,`,`,`,`,`,`,`,,`
,,,`,,`,,,,,,,,,,,,,,,,,,,,,,,,,,`,,`
,,,`,,`,,,,,,,,,,,,,,,,,,,,,,,,,,`,,`
,,,`,,`,,,,,,,,,,,,,,,,,,,,,,,,,,`,,`
,,,`,,`,,,,,,,,,,,,,,,,,,,,,,,,,,`,,`
,,,`,,`,,,,,,,,,,,,,,,,,,,,,,,,,,`,,`
,,,`,,`,,,,,,,,,,,,,,,,,,,,,,,,,,`,,`
,,,`,,`,,,,,,,,,,,,,,,,,,,,,,,,,,`,,`
,,,`,,`,,,,,,,,,,,,,,,,,,,,,,,,,,`,,`
,,,`,,`,,,,,,,,,,,,,,,,,,,,,,,,,,`,,`
,,,`,,`,,,,,,,,,,,,~,,~,,,,,,,,,,,,`,,`
,,,`,,`,,,,,,,,,,,,~,~,~,,,,,,,,,,,,`,,`
,,,`,,`,`,`,`,`,`,`,`,`,`,`,`,~,`,~,`,`,`,`,`,`,`,`,`,`,`,`,,`
,,,`,,`,Cf,`,Cf,Cf,Cf,Cf,Cf,Cf,Cf,`,~,~,~,~,~,`,Cf,Cf,Cf,Cf,Cf,Cf,Cf,Cf,Cf,`,,`
,,,`,,`,Cf,`,Cf,Cf,Cf,Cf,Cf,Cf,Cf,~,~,~,~,~,~,~,Cf,Cf,Cf,Cf,Cf,Cf,Cf,Cf,Cf,`,,`
,,,`,,`,Cf,Cf,Cf,Cf,Cf,Cf,Cf,Cf,Cf,`,~,~,~,~,~,`,Cf,Cf,Cf,Cf,Cf,Cf,Cf,Cf,Cf,`,,`
,,,`,,`,Cf,`,Cf,Cf,Cf,Cf,Cf,Cf,Cf,~,~,~,~,~,~,~,~,~,~,Cf,Cf,Cf,Cf,Cf,Cf,`,,`
,,,`,,`,Cf,`,Cf,Cf,Cf,Cf,Cf,Cf,Cf,`,~,~,~,~,~,`,Cf,Cf,~,Cf,Cf,Cf,Cf,Cf,Cf,`,,`
,,,`,,`,`,`,`,`,`,`,Cf,`,`,`,`,~,`,~,`,`,`,`,~,`,`,`,`,`,`,`,,`
,,,`,,`,Cf,Cf,Cf,Cf,Cf,Cf,Cf,Cf,`,Cf,Cf,Cf,Cf,Cf,Cf,Cf,`,Cf,~,~,~,~,~,~,~,`,,`
,,,`,,`,Cf,Cf,Cf,Cf,Cf,Cf,Cf,Cf,Cf,Cf,Cf,Cf,Cf,Cf,Cf,Cf,Cf,Cf,Cf,Cf,Cf,Cf,Cf,Cf,~,`,,`
,,,`,,`,Cf,Cf,Cf,Cf,Cf,Cf,Cf,Cf,Cf,Cf,Cf,Cf,Cf,Cf,Cf,Cf,Cf,Cf,Cf,Cf,Cf,Cf,Cf,Cf,~,`,,`
,,,`,,`,Cf,Cf,Cf,Cf,Cf,Cf,Cf,Cf,Cf,Cf,Cf,Cf,Cf,Cf,Cf,Cf,Cf,Cf,Cf,Cf,Cf,Cf,Cf,Cf,~,`,,`
,,,`,,`,Cf,Cf,Cf,Cf,Cf,Cf,Cf,Cf,`,Cf,Cf,Cf,Cf,Cf,Cf,Cf,`,Cf,Cf,Cf,Cf,Cf,Cf,Cf,~,`,,`
,,,`,,`,`,`,`,`,`,`,`,`,`,Cf,Cf,Cf,Cf,Cf,Cf,Cf,`,`,`,`,`,`,`,`,`,`,,`
,,,`,,Cf,Cf,Cf,Cf,Cf,Cf,Cf,Cf,Cf,Cf,Cf,Cf,Cf,Cf,Cf,Cf,Cf,Cf,Cf,Cf,Cf,Cf,Cf,Cf,Cf,Cf,Cf,,`
,,,`,`,`,`,`,`,`,`,`,`,`,`,Cf,Cf,Cf,Cf,Cf,Cf,Cf,`,`,`,`,`,`,`,`,`,`,`,`



#build label(surface_roof3) start(19; 19) hidden() upper half center of the roof



,,,`,,`,`,`,`,`,`,`,`,`,`,`,`,`,`,`,`,`,`,`,`,`,`,`,`,`,`,`,,`
,,,`,,`,,,,,,,,,,,,,,,,,,,,,,,,,,`,,`
,,,`,,`,,Cf,Cf,Cf,Cf,Cf,Cf,Cf,Cf,Cf,Cf,Cf,Cf,Cf,Cf,Cf,Cf,Cf,Cf,Cf,Cf,Cf,Cf,Cf,,`,,`
,,,`,,`,,Cf,Cf,Cf,Cf,Cf,Cf,Cf,Cf,Cf,Cf,Cf,Cf,Cf,Cf,Cf,Cf,Cf,Cf,Cf,Cf,Cf,Cf,Cf,,`,,`
,,,`,,`,,Cf,Cf,Cf,Cf,Cf,Cf,Cf,Cf,Cf,Cf,Cf,Cf,Cf,Cf,Cf,Cf,Cf,Cf,Cf,Cf,Cf,Cf,Cf,,`,,`
,,,`,,`,,Cf,Cf,Cf,Cf,Cf,Cf,Cf,Cf,Cf,Cf,Cf,Cf,Cf,Cf,Cf,Cf,Cf,Cf,Cf,Cf,Cf,Cf,Cf,,`,,`
,,,`,,`,,Cf,Cf,Cf,Cf,Cf,Cf,Cf,Cf,Cf,Cf,Cf,Cf,Cf,Cf,Cf,Cf,Cf,Cf,Cf,Cf,Cf,Cf,Cf,,`,,`
,,,`,,`,,Cf,Cf,Cf,Cf,Cf,Cf,Cf,Cf,Cf,Cf,Cf,Cf,Cf,Cf,Cf,Cf,Cf,Cf,Cf,Cf,Cf,Cf,Cf,,`,,`
,,,`,,`,,Cf,Cf,Cf,Cf,Cf,Cf,Cf,Cf,Cf,Cf,Cf,Cf,Cf,Cf,Cf,Cf,Cf,Cf,Cf,Cf,Cf,Cf,Cf,,`,,`
,,,`,,`,,Cf,Cf,Cf,Cf,Cf,Cf,Cf,Cf,Cf,Cf,Cf,Cf,Cf,Cf,Cf,Cf,Cf,Cf,Cf,Cf,Cf,Cf,Cf,,`,,`
,,,`,,`,,Cf,Cf,Cf,Cf,Cf,Cf,Cf,Cf,Cf,Cf,~,Cf,~,Cf,Cf,Cf,Cf,Cf,Cf,Cf,Cf,Cf,Cf,,`,,`
,,,`,,`,,Cf,Cf,Cf,Cf,Cf,Cf,Cf,Cf,Cf,Cf,~,~,~,Cf,Cf,Cf,Cf,Cf,Cf,Cf,Cf,Cf,Cf,,`,,`
,,,`,,`,`,`,`,`,`,`,`,`,`,`,`,~,`,~,`,`,`,`,`,`,`,`,`,`,`,`,,`
,,,`,,`,~,`,~,~,~,~,~,~,~,`,~,~,~,~,~,`,~,~,~,~,~,~,~,~,~,`,,`
,,,`,,`,~,`,~,~,~,~,~,~,~,~,~,~,~,~,~,~,~,~,~,~,~,~,~,~,~,`,,`
,,,`,,`,~,~,~,~,~,~,~,~,~,`,~,~,~,~,~,`,~,~,~,~,~,~,~,~,~,`,,`
,,,`,,`,~,`,~,~,~,~,~,~,~,~,~,~,~,~,~,~,~,~,~,~,~,~,~,~,~,`,,`
,,,`,,`,~,`,~,~,~,~,~,~,~,`,~,~,~,~,~,`,~,~,~,~,~,~,~,~,~,`,,`
,,,`,,`,`,`,`,`,`,`,~,`,`,`,`,~,`,~,`,`,`,`,~,`,`,`,`,`,`,`,,`
,,,`,,`,~,~,~,~,~,~,~,~,`,~,~,~,~,~,~,~,`,~,~,~,~,~,~,~,~,`,,`
,,,`,,`,~,~,~,~,~,~,~,~,~,~,~,~,~,~,~,~,~,~,~,~,~,~,~,~,~,`,,`
,,,`,,`,~,~,~,~,~,~,~,~,~,~,~,~,~,~,~,~,~,~,~,~,~,~,~,~,~,`,,`
,,,`,,`,~,~,~,~,~,~,~,~,~,~,~,~,~,~,~,~,~,~,~,~,~,~,~,~,~,`,,`
,,,`,,`,~,~,~,~,~,~,~,~,`,~,~,~,~,~,~,~,`,~,~,~,~,~,~,~,~,`,,`
,,,`,,`,`,`,`,`,`,`,`,`,`,~,~,~,~,~,~,~,`,`,`,`,`,`,`,`,`,`,,`
,,,`,,~,~,~,~,~,~,~,~,~,~,~,~,~,~,~,~,~,~,~,~,~,~,~,~,~,~,~,,`
,,,`,`,`,`,`,`,`,`,`,`,`,`,~,~,~,~,~,~,~,`,`,`,`,`,`,`,`,`,`,`,`



#build label(surface_roof4) start(19; 19) hidden() upper half remainder of the roof



,,,`,,`,`,`,`,`,`,`,`,`,`,`,`,`,`,`,`,`,`,`,`,`,`,`,`,`,`,`,,`
,,,`,,`,Cf,Cf,Cf,Cf,Cf,Cf,Cf,Cf,Cf,Cf,Cf,Cf,Cf,Cf,Cf,Cf,Cf,Cf,Cf,Cf,Cf,Cf,Cf,Cf,Cf,`,,`
,,,`,,`,Cf,~,~,~,~,~,~,~,~,~,~,~,~,~,~,~,~,~,~,~,~,~,~,~,Cf,`,,`
,,,`,,`,Cf,~,~,~,~,~,~,~,~,~,~,~,~,~,~,~,~,~,~,~,~,~,~,~,Cf,`,,`
,,,`,,`,Cf,~,~,~,~,~,~,~,~,~,~,~,~,~,~,~,~,~,~,~,~,~,~,~,Cf,`,,`
,,,`,,`,Cf,~,~,~,~,~,~,~,~,~,~,~,~,~,~,~,~,~,~,~,~,~,~,~,Cf,`,,`
,,,`,,`,Cf,~,~,~,~,~,~,~,~,~,~,~,~,~,~,~,~,~,~,~,~,~,~,~,Cf,`,,`
,,,`,,`,Cf,~,~,~,~,~,~,~,~,~,~,~,~,~,~,~,~,~,~,~,~,~,~,~,Cf,`,,`
,,,`,,`,Cf,~,~,~,~,~,~,~,~,~,~,~,~,~,~,~,~,~,~,~,~,~,~,~,Cf,`,,`
,,,`,,`,Cf,~,~,~,~,~,~,~,~,~,~,~,~,~,~,~,~,~,~,~,~,~,~,~,Cf,`,,`
,,,`,,`,Cf,~,~,~,~,~,~,~,~,~,~,~,~,~,~,~,~,~,~,~,~,~,~,~,Cf,`,,`
,,,`,,`,Cf,~,~,~,~,~,~,~,~,~,~,~,~,~,~,~,~,~,~,~,~,~,~,~,Cf,`,,`
,,,`,,`,`,`,`,`,`,`,`,`,`,`,`,~,`,~,`,`,`,`,`,`,`,`,`,`,`,`,,`
,,,`,,`,~,`,~,~,~,~,~,~,~,`,~,~,~,~,~,`,~,~,~,~,~,~,~,~,~,`,,`
,,,`,,`,~,`,~,~,~,~,~,~,~,~,~,~,~,~,~,~,~,~,~,~,~,~,~,~,~,`,,`
,,,`,,`,~,~,~,~,~,~,~,~,~,`,~,~,~,~,~,`,~,~,~,~,~,~,~,~,~,`,,`
,,,`,,`,~,`,~,~,~,~,~,~,~,~,~,~,~,~,~,~,~,~,~,~,~,~,~,~,~,`,,`
,,,`,,`,~,`,~,~,~,~,~,~,~,`,~,~,~,~,~,`,~,~,~,~,~,~,~,~,~,`,,`
,,,`,,`,`,`,`,`,`,`,~,`,`,`,`,~,`,~,`,`,`,`,~,`,`,`,`,`,`,`,,`
,,,`,,`,~,~,~,~,~,~,~,~,`,~,~,~,~,~,~,~,`,~,~,~,~,~,~,~,~,`,,`
,,,`,,`,~,~,~,~,~,~,~,~,~,~,~,~,~,~,~,~,~,~,~,~,~,~,~,~,~,`,,`
,,,`,,`,~,~,~,~,~,~,~,~,~,~,~,~,~,~,~,~,~,~,~,~,~,~,~,~,~,`,,`
,,,`,,`,~,~,~,~,~,~,~,~,~,~,~,~,~,~,~,~,~,~,~,~,~,~,~,~,~,`,,`
,,,`,,`,~,~,~,~,~,~,~,~,`,~,~,~,~,~,~,~,`,~,~,~,~,~,~,~,~,`,,`
,,,`,,`,`,`,`,`,`,`,`,`,`,~,~,~,~,~,~,~,`,`,`,`,`,`,`,`,`,`,,`
,,,`,,~,~,~,~,~,~,~,~,~,~,~,~,~,~,~,~,~,~,~,~,~,~,~,~,~,~,~,,`
,,,`,`,`,`,`,`,`,`,`,`,`,`,~,~,~,~,~,~,~,`,`,`,`,`,`,`,`,`,`,`,`



#build label(surface_corridor_gates) start(19; 19) hidden() gates for the longer trap hallways


,,,,gx,,,,,,,,,,,,,,,,,,,,,,,,,,,,gx
,,,`,gx,`,`,`,`,`,`,`,`,`,`,`,`,`,`,`,`,`,`,`,`,`,`,`,`,`,`,`,gx,`
,,,`,,`,,,,,,,,,,,,,,,,,,,,,,,,,,`,,`
,,,`,,`,,,,,,,,,,,,,,,,,,,,,,,,,,`,,`
,,,`,,`,,,,,,,,,,,,,,,,,,,,,,,,,,`,,`
,,,`,,`,,,,,,,,,,,,,,,,,,,,,,,,,,`,,`
,,,`,,`,,,,,,,,,,,,,,,,,,,,,,,,,,`,,`
,,,`,,`,,,,,,,,,,,,,,,,,,,,,,,,,,`,,`
,,,`,,`,,,,,,,,,,,,,,,,,,,,,,,,,,`,,`
,,,`,,`,,,,,,,,,,,,,,,,,,,,,,,,,,`,,`
,,,`,,`,,,,,,,,,,,,,,,,,,,,,,,,,,`,,`
,,,`,,`,,,,,,,,,,,,,,,,,,,,,,,,,,`,,`
,,,`,,`,,,,,,,,,,,,,,,,,,,,,,,,,,`,,`
,,,`,,`,`,`,`,`,`,`,`,`,`,`,`,,`,,`,`,`,`,`,`,`,`,`,`,`,`,,`
,,,`,,`,,`,,,,,,,,`,,,,,,`,,,,,,,,,,`,,`
,,,`,,`,,`,,,,,,,,,,`,`,`,,,,,,,,,,,,`,,`
,,,`,,`,,,,,,,,,,`,Tl,`,`,`,Tl,`,,,,,,,,,,`,,`
,,,`,,`,,`,,,,,,,,,,`,`,`,,,,,,,,,,,,`,,`
,,,`,,`,,`,,,,,,,,`,,,,,,`,,,,,,,,,,`,,`
,,,`,,`,`,`,`,`,`,`,,`,`,`,`,,`,,`,`,`,`,,`,`,`,`,`,`,`,,`
,,,`,,`,,,,,,,,,`,,,,,,,,`,,,,,,,,,`,,`
,,,`,,`,,,,,,,,,,,,,,,,,,,,,,,,,,`,,`
,,,`,,`,,,,,,,,,,,,,,,,,,,,,,,,,,`,,`
,,,`,,`,,,,,,,,,,,,,,,,,,,,,,,,,,`,,`
,,,`,,`,,,,,,,,,`,,,,,,,,`,,,,,,,,,`,,`
,,,`,,`,`,`,`,`,`,`,`,`,`,,,,,,,,`,`,`,`,`,`,`,`,`,`,,`
,,,`,,,,,,,,,,,,,,,,,,,,,,,,,,,,,,`
,,,`,`,`,`,`,`,`,`,`,`,`,`,,,,,,,,`,`,`,`,`,`,`,`,`,`,`,`



#build label(surface_corridor) start(19; 19) hidden() longer trap hallway walls


,,,,~,,,,,,,,,,,,,,,,,,,,,,,,,,,,~
,,,Cw,~,`,`,`,`,`,`,`,`,`,`,`,`,`,`,`,`,`,`,`,`,`,`,`,`,`,`,`,~,Cw
,,,Cw,,`,,,,,,,,,,,,,,,,,,,,,,,,,,`,,Cw
,,,Cw,,`,,,,,,,,,,,,,,,,,,,,,,,,,,`,,Cw
,,,Cw,,`,,,,,,,,,,,,,,,,,,,,,,,,,,`,,Cw
,,,Cw,,`,,,,,,,,,,,,,,,,,,,,,,,,,,`,,Cw
,,,Cw,,`,,,,,,,,,,,,,,,,,,,,,,,,,,`,,Cw
,,,Cw,,`,,,,,,,,,,,,,,,,,,,,,,,,,,`,,Cw
,,,Cw,,`,,,,,,,,,,,,,,,,,,,,,,,,,,`,,Cw
,,,Cw,,`,,,,,,,,,,,,,,,,,,,,,,,,,,`,,Cw
,,,Cw,,`,,,,,,,,,,,,,,,,,,,,,,,,,,`,,Cw
,,,Cw,,`,,,,,,,,,,,,,,,,,,,,,,,,,,`,,Cw
,,,Cw,,`,,,,,,,,,,,,,,,,,,,,,,,,,,`,,Cw
,,,Cw,,`,`,`,`,`,`,`,`,`,`,`,`,,`,,`,`,`,`,`,`,`,`,`,`,`,`,,Cw
,,,Cw,,`,,`,,,,,,,,`,,,,,,`,,,,,,,,,,`,,Cw
,,,Cw,,`,,`,,,,,,,,,,`,`,`,,,,,,,,,,,,`,,Cw
,,,Cw,,`,,,,,,,,,,`,~,`,`,`,~,`,,,,,,,,,,`,,Cw
,,,Cw,,`,,`,,,,,,,,,,`,`,`,,,,,,,,,,,,`,,Cw
,,,Cw,,`,,`,,,,,,,,`,,,,,,`,,,,,,,,,,`,,Cw
,,,Cw,,`,`,`,`,`,`,`,,`,`,`,`,,`,,`,`,`,`,,`,`,`,`,`,`,`,,Cw
,,,Cw,,`,,,,,,,,,`,,,,,,,,`,,,,,,,,,`,,Cw
,,,Cw,,`,,,,,,,,,,,,,,,,,,,,,,,,,,`,,Cw
,,,Cw,,`,,,,,,,,,,,,,,,,,,,,,,,,,,`,,Cw
,,,Cw,,`,,,,,,,,,,,,,,,,,,,,,,,,,,`,,Cw
,,,Cw,,`,,,,,,,,,`,,,,,,,,`,,,,,,,,,`,,Cw
,,,Cw,,`,`,`,`,`,`,`,`,`,`,,,,,,,,`,`,`,`,`,`,`,`,`,`,,Cw
,,,Cw,,,,,,,,,,,,,,,,,,,,,,,,,,,,,,Cw
,,,Cw,Cw,`,`,`,`,`,`,`,`,`,`,,,,,,,,`,`,`,`,`,`,`,`,`,`,Cw,Cw



#<



,,,`,Cf,`,`,`,`,`,`,`,`,`,`,`,`,`,`,`,`,`,`,`,`,`,`,`,`,`,`,`,Cf,`
,,,`,Cf,`,~,~,~,~,~,~,~,~,~,~,~,~,~,~,~,~,~,~,~,~,~,~,~,~,~,`,Cf,`
,,,`,Cf,`,~,~,~,~,~,~,~,~,~,~,~,~,~,~,~,~,~,~,~,~,~,~,~,~,~,`,Cf,`
,,,`,Cf,`,~,~,~,~,~,~,~,~,~,~,~,~,~,~,~,~,~,~,~,~,~,~,~,~,~,`,Cf,`
,,,`,Cf,`,~,~,~,~,~,~,~,~,~,~,~,~,~,~,~,~,~,~,~,~,~,~,~,~,~,`,Cf,`
,,,`,Cf,`,~,~,~,~,~,~,~,~,~,~,~,~,~,~,~,~,~,~,~,~,~,~,~,~,~,`,Cf,`
,,,`,Cf,`,~,~,~,~,~,~,~,~,~,~,~,~,~,~,~,~,~,~,~,~,~,~,~,~,~,`,Cf,`
,,,`,Cf,`,~,~,~,~,~,~,~,~,~,~,~,~,~,~,~,~,~,~,~,~,~,~,~,~,~,`,Cf,`
,,,`,Cf,`,~,~,~,~,~,~,~,~,~,~,~,~,~,~,~,~,~,~,~,~,~,~,~,~,~,`,Cf,`
,,,`,Cf,`,~,~,~,~,~,~,~,~,~,~,~,~,~,~,~,~,~,~,~,~,~,~,~,~,~,`,Cf,`
,,,`,Cf,`,~,~,~,~,~,~,~,~,~,~,~,~,~,~,~,~,~,~,~,~,~,~,~,~,~,`,Cf,`
,,,`,Cf,`,~,~,~,~,~,~,~,~,~,~,~,~,~,~,~,~,~,~,~,~,~,~,~,~,~,`,Cf,`
,,,`,Cf,`,`,`,`,`,`,`,`,`,`,`,`,~,`,~,`,`,`,`,`,`,`,`,`,`,`,`,Cf,`
,,,`,Cf,`,~,`,~,~,~,~,~,~,~,`,~,~,~,~,~,`,~,~,~,~,~,~,~,~,~,`,Cf,`
,,,`,Cf,`,~,`,~,~,~,~,~,~,~,~,~,~,~,~,~,~,~,~,~,~,~,~,~,~,~,`,Cf,`
,,,`,Cf,`,~,~,~,~,~,~,~,~,~,`,~,~,~,~,~,`,~,~,~,~,~,~,~,~,~,`,Cf,`
,,,`,Cf,`,~,`,~,~,~,~,~,~,~,~,~,~,~,~,~,~,~,~,~,~,~,~,~,~,~,`,Cf,`
,,,`,Cf,`,~,`,~,~,~,~,~,~,~,`,~,~,~,~,~,`,~,~,~,~,~,~,~,~,~,`,Cf,`
,,,`,Cf,`,`,`,`,`,`,`,~,`,`,`,`,~,`,~,`,`,`,`,~,`,`,`,`,`,`,`,Cf,`
,,,`,Cf,`,~,~,~,~,~,~,~,~,`,~,~,~,~,~,~,~,`,~,~,~,~,~,~,~,~,`,Cf,`
,,,`,Cf,`,~,~,~,~,~,~,~,~,~,~,~,~,~,~,~,~,~,~,~,~,~,~,~,~,~,`,Cf,`
,,,`,Cf,`,~,~,~,~,~,~,~,~,~,~,~,~,~,~,~,~,~,~,~,~,~,~,~,~,~,`,Cf,`
,,,`,Cf,`,~,~,~,~,~,~,~,~,~,~,~,~,~,~,~,~,~,~,~,~,~,~,~,~,~,`,Cf,`
,,,`,Cf,`,~,~,~,~,~,~,~,~,`,~,~,~,~,~,~,~,`,~,~,~,~,~,~,~,~,`,Cf,`
,,,`,Cf,`,`,`,`,`,`,`,`,`,`,~,~,~,~,~,~,~,`,`,`,`,`,`,`,`,`,`,Cf,`
,,,`,Cf,~,~,~,~,~,~,~,~,~,~,~,~,~,~,~,~,~,~,~,~,~,~,~,~,~,~,~,Cf,`
,,,`,`,`,`,`,`,`,`,`,`,`,`,~,~,~,~,~,~,~,`,`,`,`,`,`,`,`,`,`,`,`



#build label(surface_corridor_traps) start(19; 19) hidden() traps for the longer trap hallways


,,,,~,,,,,,,,,,,,,,,,,,,,,,,,,,,,~
,,,`,~,`,`,`,`,`,`,`,`,`,`,`,`,`,`,`,`,`,`,`,`,`,`,`,`,`,`,`,~,`
,,,`,Tc,`,,,,,,,,,,,,,,,,,,,,,,,,,,`,Tc,`
,,,`,Tc,`,,,,,,,,,,,,,,,,,,,,,,,,,,`,Tc,`
,,,`,Tc,`,,,,,,,,,,,,,,,,,,,,,,,,,,`,Tc,`
,,,`,Tc,`,,,,,,,,,,,,,,,,,,,,,,,,,,`,Tc,`
,,,`,Tc,`,,,,,,,,,,,,,,,,,,,,,,,,,,`,Tc,`
,,,`,Tc,`,,,,,,,,,,,,,,,,,,,,,,,,,,`,Tc,`
,,,`,Tc,`,,,,,,,,,,,,,,,,,,,,,,,,,,`,Tc,`
,,,`,Tc,`,,,,,,,,,,,,,,,,,,,,,,,,,,`,Tc,`
,,,`,Tc,`,,,,,,,,,,,,,,,,,,,,,,,,,,`,Tc,`
,,,`,Tc,`,,,,,,,,,,,,,,,,,,,,,,,,,,`,Tc,`
,,,`,Tc,`,,,,,,,,,,,,,,,,,,,,,,,,,,`,Tc,`
,,,`,Tc,`,`,`,`,`,`,`,`,`,`,`,`,,`,,`,`,`,`,`,`,`,`,`,`,`,`,Tc,`
,,,`,Tc,`,,`,,,,,,,,`,,,,,,`,,,,,,,,,,`,Tc,`
,,,`,Tc,`,,`,,,,,,,,,,`,`,`,,,,,,,,,,,,`,Tc,`
,,,`,Tc,`,,,,,,,,,,`,~,`,`,`,~,`,,,,,,,,,,`,Tc,`
,,,`,Tc,`,,`,,,,,,,,,,`,`,`,,,,,,,,,,,,`,Tc,`
,,,`,Tc,`,,`,,,,,,,,`,,,,,,`,,,,,,,,,,`,Tc,`
,,,`,Tc,`,`,`,`,`,`,`,,`,`,`,`,,`,,`,`,`,`,,`,`,`,`,`,`,`,Tc,`
,,,`,Tc,`,,,,,,,,,`,,,,,,,,`,,,,,,,,,`,Tc,`
,,,`,Tc,`,,,,,,,,,,,,,,,,,,,,,,,,,,`,Tc,`
,,,`,Tc,`,,,,,,,,,,,,,,,,,,,,,,,,,,`,Tc,`
,,,`,Tc,`,,,,,,,,,,,,,,,,,,,,,,,,,,`,Tc,`
,,,`,Tc,`,,,,,,,,,`,,,,,,,,`,,,,,,,,,`,Tc,`
,,,`,Tc,`,`,`,`,`,`,`,`,`,`,,,,,,,,`,`,`,`,`,`,`,`,`,`,Tc,`
,,,`,,,,,,,,,,,,,,,,,,,,,,,,,,,,,,`
,,,`,`,`,`,`,`,`,`,`,`,`,`,,,,,,,,`,`,`,`,`,`,`,`,`,`,`,`



#query label(surface_query_corridor) start(19; 19) hidden() (Remember to connect the levers to the new external trap gates.) configure barracks and name outer levers/gates



,,,`,"{givename name=""left trap gate""}",`,`,`,`,`,`,`,`,`,`,`,`,`,`,`,`,`,`,`,`,`,`,`,`,`,`,`,"{givename name=""right trap gate""}",`
,,,`,,`,,,,,,,,,,,,,,,,,,,,,,,,,,`,,`
,,,`,,`,,,,,,,,,,,,,,,,,,,,,,,,,,`,,`
,,,`,,`,,,,,,,,,,,,,,,,,,,,,,,,,,`,,`
,,,`,,`,,,,,,,,,,,,,,,,,,,,,,,,,,`,,`
,,,`,,`,,,,,,,,,,,,,,,,,,,,,,,,,,`,,`
,,,`,,`,,,,,,,,,,,,,,,,,,,,,,,,,,`,,`
,,,`,,`,,,,,,,,,,,,,,,,,,,,,,,,,,`,,`
,,,`,,`,,,,,,,,,,,,,,,,,,,,,,,,,,`,,`
,,,`,,`,,,,,,,,,,,,,,,,,,,,,,,,,,`,,`
,,,`,,`,,,,,,,,,,,,,,,,,,,,,,,,,,`,,`
,,,`,,`,,,,,,,,,,,,,,,,,,,,,,,,,,`,,`
,,,`,,`,`,`,`,`,`,`,`,`,`,`,`,,`,,`,`,`,`,`,`,`,`,`,`,`,`,,`
,,,`,,`,,`,,,,,,,,`,,,,,,`,,,,,,,,,,`,,`
,,,`,,`,,`,,,,,,,,,,`,`,`,,,,,,,,,,,,`,,`
,,,`,,`,,,,,,,,,,`,"{givename name=""left trap gate""}",`,`,`,"{givename name=""right trap gate""}",`,,,,,,,,,,`,,`
,,,`,,`,,`,,,,,,,,,,`,`,`,,,,,,,,,,,,`,,`
,,,`,,`,,`,,,,,,,,`,,,,,,`,,,,,,,,,,`,,`
,,,`,,`,`,`,`,`,`,`,,`,`,`,`,,`,,`,`,`,`,,`,`,`,`,`,`,`,,`
,,,`,,`,,,,,,,,,`,,,,,,,,`,,,,,,,,,`,,`
,,,`,,`,,,,,,,,,,,,,,,,,,,,,,,,,,`,,`
,,,`,,`,,,,,,,,,,,,,,,,,,,,,,,,,,`,,`
,,,`,,`,,,,,,,,,,,,,,,,,,,,,,,,,,`,,`
,,,`,,`,,,,,,,,,`,,,,,,,,`,,,,,,,,,`,,`
,,,`,,`,`,`,`,`,`,`,`,`,`,,,,,,,,`,`,`,`,`,`,`,`,`,`,,`
,,,`,,,,,,,,,,,,,,,,,,,,,,,,,,,,,,`
,,,`,`,`,`,`,`,`,`,`,`,`,`,,,,,,,,`,`,`,`,`,`,`,`,`,`,`,`



#notes label(farming_help)
"Sets up farming, food storage, and related industries. Also provides post-embark necessities that can later be disassembled."
Screenshot: https://drive.google.com/file/d/1fBC3G5Y888l4tVe5REAyAd_zeojADVme
""
Features:
- Pairs with the surface blueprints for vents that prevent miasma
- Farm plots (intended to be managed by DFHack autofarm)
- Plentiful food storage
- Refuse/corpse quantum stockpile
- Small dormitory and dining room for post-embark needs
- Small offices for your manager and bookkeeper
""
Workshops:
- Kitchen
- Brewery
- Butcher
- Fishery
- Tannery
- Farmer's Workshop
- Quern
- Screw Press
""
Manual steps you have to take:
- Check to make sure the lower office is assigned to your manager and assign the upper office to your bookkeeper (if different from your manager)
"- Assign a minecart to your refuse quantum stockpile hauling route (you can run ""assign-minecarts all"" at the DFHack prompt to do this)"
"- If the industry level is already built, configure the jugs, pots, and bags stockpiles to take from the ""Goods"" quantum stockpile (the one on the left) on the industry level"
""
Farming Walkthrough:
"1) Wait until you have channeled the miasma vents and cleared trees on the surface before digging out the farming level on the z-level below the surface, otherwise you will end up with extra ramps on the farming level and unprotected holes through the surface when you later chop down trees growing above empty space."
""
"2) Start digging with /farming1 and get started on manufacturing furniture by running ""quickfort orders"" on /farming2 and /farming3."
""
"3) Once the level is dug out, run /farming2 to build workshops, stockpiles, and the furniture we need to anchor the rooms. Remember to assign a minecart to the newly-designated quantum refuse dump. There are also jugs, pots, and bags stockpiles on this level that should be configured to ""take"" from the industry level stockpile once we get the industry level built."
""
"4) When the furniture is in place, run /farming3 to designate your starter dining room and dormitory and build the farm plots and remaining furniture. The blueprint also attempts to assign the lower office to your manager, but double-check this assignment in case your dwarves are in an unexpected order."
""
"5) Once your fort has enough free time to build the remaining doors, run /farming4. This will also enable seasonal fertilization for your farm plots. Run ""quickfort orders"" for /farming4."
""
"6) You can disassemble the dining room and dormitory once the services and apartments levels are up and running, if you like."
"#dig label(farming1) start(16; 18; central stairs) message(Once the area is dug out, continue with /farming2.)"
# this level is dug at priority 2 since it is dug in soil. it's worth the miner's time to stop digging the industry level and
# quickly dig out this one.
,,,,,,,,,2,2,2,,2,2,2,2,2,,2,2,2,2
,,,,,,,,,2,2,2,,2,2,2,2,2,,2,2,2,2
,,,,,,,,,2,2,2,,2,2,2,2,2,,2,2,2,2
,,,,,,,,,,,2,,2,2,2,2,2,,2,2,2,2
,,,,,,,2,2,2,,2,,2,2,2,2,2,,2,2,2,2
,,,,,,,2,2,2,2,2,,2,2,2,2,2,,2,2,2,2
,,,,,,,2,2,2,,2,,2,2,2,2,2,,2
,,,,,,,,,,,2,,2,2,2,2,2,,2,,2,2,2
,,,,,,2,2,2,2,,2,,2,2,2,2,2,,2,2,2,2,2
,,,,,,2,2,2,2,,2,,2,2,2,2,2,,2,,2,2,2
,,,2,2,,2,2,2,2,,2,,2,2,2,2,2,,2
,,2,2,2,,2,2,2,2,,2,,2,2,2,2,2,,2,,2,2,2,,2,2,2
,,2,2,2,2,2,z2,2,2,2,2,,,2,,2,,,2,2,2,z2,2,2,2,z2,2
,,,2,2,,2,2,2,2,,2,2,2,2,2,2,2,2,2,,2,2,2,,2,2,2
,,,,2,,,2,,,,,,2,`,`,`,2,,,,,2,,,,2
,,2,2,2,2,2,2,2,2,2,2,,2,`,~,`,2,,2,2,2,2,2,2,2,2,2,2
,,2,2,2,2,2,2,2,2,2,2,2,2,`,`,`,2,2,2,2,2,2,2,2,2,2,2,2
,,2,2,2,2,2,2,2,2,2,2,,2,2,2,2,2,,2,2,2,2,2,2,2,2,2,2
,,2,2,2,2,2,2,2,2,2,,,,2,,2,,,,2,2,2,2,2,2,2,2,2
,,2,2,2,2,2,2,2,2,,,z2,2,2,2,2,2,z2,,,2,2,2,2,2,2,2,2
,,2,2,2,2,2,2,2,2,,z2,z2,,,2,,,z2,z2,,2,2,2,2,2,2,2,2
,,2,2,2,2,2,2,2,,,z2,z2,,z2,z2,z2,,z2,z2,,,2,2,2,2,2,2,2
,,2,2,2,2,2,2,2,,2,2,2,,z2,z2,z2,,2,2,2,,2,2,2,2,2,2,2
,,2,2,2,2,2,2,2,,2,z2,2,,z2,z2,z2,,2,z2,2,,2,2,2,2,2,2,2
,,2,2,2,2,2,2,2,,2,2,2,,,2,,,2,2,2,,2,2,2,2,2,2,2
,,,,,,,,,,,,,,,z2


"#meta label(farming2) start(central stairs) message(Remember to enqueue manager orders for this blueprint.
Once furniture has been placed, continue with /farming3.) workshops, stockpiles, and important furniture"
build/farming_build
place/farming_place
query_stockpiles/farming_query_stockpiles
link_stockpiles/farming_link
""
#meta label(farming3) start(central stairs) message(Remember to enqueue manager orders for this blueprint.) configure rooms and build farm plots and more furniture
query_rooms/farming_rooms
build2/farming_build2
""
#meta label(farming4) start(central stairs) message(Remember to enqueue manager orders for this blueprint.) configure farm plots and build remaining furniture
query_plots/farming_query_plots
build3/farming_build3
#build label(farming_build) start(16; 18) hidden() workshops and important furniture


,,,,,,,,,`,`,`,,`,`,`,`,`,,`,`,`,`
,,,,,,,,,c,t,`,,`,`,`,`,`,,`,`,`,`
,,,,,,,,,`,`,`,,`,`,`,`,`,,`,`,t,c
,,,,,,,,,,,`,,`,`,`,`,`,,`,`,`,`
,,,,,,,`,`,`,,`,,`,`,`,`,`,,`,`,`,`
,,,,,,,c,t,`,`,`,,`,`,`,`,`,,`,`,`,`
,,,,,,,`,`,`,,`,,`,`,`,`,`,,`
,,,,,,,,,,,`,,`,`,`,`,`,,`,,`,`,b
,,,,,,`,`,`,`,,`,,`,`,`,`,`,,`,`,`,`,`
,,,,,,`,wl,`,`,,`,,`,`,`,`,`,,`,,`,`,`
,,,`,`,,`,`,`,`,,`,,`,`,`,`,`,,`
,,wq,`,`,,`,`,`,`,,`,,`,`,`,`,`,,`,,`,`,`,,`,`,`
,,wp,`,`,`,`,ww,`,`,`,`,,,`,,`,,,`,`,`,wu,`,`,`,wz,`
,,,`,`,,`,`,`,`,,`,`,`,`,`,`,`,`,`,,`,`,`,,`,`,`
,,,,`,,,`,,,,,,`,`,`,`,`,,,,,`,,,,`
,,`,`,`,`,`,`,`,`,`,`,,`,`,~,`,`,,`,`,`,`,`,`,`,`,`,`
,,`,`,`,`,`,`,`,`,`,`,`,`,`,`,`,`,`,`,`,`,`,`,`,`,`,`,`
,,`,`,`,`,`,`,`,`,`,`,,`,`,`,`,`,,`,`,`,`,`,`,`,`,`,`
,,`,`,`,`,`,`,`,`,`,,,,`,,`,,,,`,`,`,`,`,`,`,`,`
,,`,`,`,`,`,`,`,`,,,`,`,`,`,`,`,`,,,`,`,`,`,`,`,`,`
,,`,`,`,`,`,`,`,`,,`,`,,,`,,,`,`,,`,`,`,`,`,`,`,`
,,`,`,`,`,`,`,`,,,`,`,,`,`,`,,`,`,,,`,`,`,`,`,`,`
,,`,`,`,`,`,`,`,,`,`,`,,`,`,`,,`,`,`,,`,`,`,`,`,`,`
,,`,`,`,`,`,`,`,,`,wh,`,,`,`,`,,`,wn,`,,`,`,`,`,`,`,`
,,`,`,`,`,`,`,`,,`,`,`,,,trackstopS,,,`,`,`,,`,`,`,`,`,`,`
,,,,,,,,,,,,,,,`


#place label(farming_place) start(16; 18) hidden() stockpiles


,,,,,,,,,`,`,`,,`,`,`,f10(1x9),b(1x12),,f(4x2),,,`
,,,,,,,,,`,`,`,,`,`,`,`,`,,`,`,`,`
,,,,,,,,,`,`,`,,`,`,`,`,`,,`,`,`,`
,,,,,,,,,,,`,,`,`,`,`,`,,`,`,`,`
,,,,,,,`,`,`,,`,,`,`,`,`,`,,`,f(3x2),,`
,,,,,,,`,`,`,`,`,,`,`,`,`,`,,`,`,`,`
,,,,,,,`,`,`,,`,,`,`,`,`,`,,`
,,,,,,,,,,,`,,`,`,`,`,`,,`,,`,`,`
,,,,,,`,`,`,u,,`,,`,`,`,`,`,,`,`,`,`,`
,,,,,,`,`,`,u,,`,,f(4x3),,,`,`,,`,,`,`,`
,,,u,u,,`,`,`,u,,`,,`,`,`,`,`,,`
,,`,u,u,,`,`,`,u,,`,,`,`,`,`,`,,`,,`,`,`,,`,`,`
,,`,g,g,`,`,`,`,u,`,`,,,`,,`,,,`,`,`,`,`,`,`,`,`
,,,g,g,,`,`,`,u,,`,`,`,`,`,`,`,`,`,,`,`,`,,`,`,`
,,,,`,,,`,,,,,,`,`,`,`,`,,,,,`,,,,`
,,f,f,f,f,f,f,f,f,f,f,,`,`,~,`,`,,f,f,f,f,f,f,f,f,f,f
,,f,f,f,f,f,f,f,f,f,f,`,`,`,`,`,`,`,f,f,f,f,f,f,f,f,f,f
,,f,f,f,f,f,f,f,f,f,f,,`,`,`,`,`,,f,f,f,f,f,f,f,f,f,f
,,f,f,f,f,f,f,f,f,f,,,,`,,`,,,,f,f,f,f,f,f,f,f,f
,,f,f,f,f,f,f,f,f,,,f,`,`,`,`,`,r,,,f,f,f,f,f,f,f,f
,,f,f,f,f,f,f,f,f,,f,f,,,`,,,r,r,,f,f,f,f,f,f,f,f
,,f,f,f,f,f,f,f,,,f,f,,r(2x3),,ry2(1x3),,r,r,,,f,f,f,f,f,f,f
,,f,f,f,f,f,f,f,,`,`,`,,`,`,`,,`,`,`,,f,f,f,f,f,f,f
,,f,f,f,f,f,f,f,,`,`,`,,`,`,`,,`,`,`,,f,f,f,f,f,f,f
,,f,f,f,f,f,f,f,,`,`,`,,,`,,,`,`,`,,f,f,f,f,f,f,f
,,,,,,,,,,,,,,,ry


"#query label(farming_query_stockpiles) start(16; 18) hidden() message(remember to:
- assign a minecart to the refuse quantum stockpile (run ""assign-minecarts all"")
- if the industry level is already built, configure the jugs, pots, and bags stockpiles to take from the ""Goods"" quantum stockpile on the industry level) config stockpiles"


,,,,,,,,,`,`,`,,`,`,`,seeds,potash,,booze,,,`
,,,,,,,,,`,`,`,,`,`,`,linksonly,nocontainers,,"{givename name=""booze""}",`,`,`
,,,,,,,,,`,`,`,,`,`,`,"{givename name=""seeds""}","{givename name=""potash""}",,`,`,`,`
,,,,,,,,,,,`,,`,`,`,`,`,,`,`,`,`
,,,,,,,`,`,`,,`,,`,`,`,`,`,,`,preparedfood
,,,,,,,`,`,`,`,`,,`,`,`,`,`,,`,"{givename name=""prepared food""}",`,`
,,,,,,,`,`,`,,`,,`,`,`,`,`,,`
,,,,,,,,,,,`,,`,`,`,`,`,,`,,`,`,`
,,,,,,`,`,`,pots,,`,,`,`,`,`,`,,`,`,`,`,`
,,,,,,`,`,`,"{givename name=""pots""}",,`,,seeds,nocontainers,"{givename name=""seeds feeder""}",give2up,`,,`,,`,`,`
,,,bags,,,`,`,`,`,,`,,`,`,`,`,`,,`
,,`,nocontainers,"{givename name=""bags""}",,`,`,`,`,,`,,`,`,`,`,`,,`,,`,`,`,,`,`,`
,,`,woodentools,,`,`,`,`,`,`,`,,,`,,`,,,`,`,`,`,`,`,`,`,`
,,,nocontainers,"{givename name=""jugs""}",,`,`,`,`,,`,`,`,`,`,`,`,`,`,,`,`,`,,`,`,`
,,,,`,,,`,,,,,,`,`,`,`,`,,,,,`,,,,`
,,plants,,,`,`,`,`,`,`,`,,`,`,~,`,`,,`,`,`,,,,,,,"{givename name=""cookable food""}"
,,`,,,,"{givename name=""plants""}",`,`,`,`,`,`,`,`,`,`,`,`,`,`,`,forbidplants,,,,,`,`
,,`,`,`,`,`,`,`,`,`,`,,`,`,`,`,`,,`,`,`,forbidtallow,,,,,`,`
,,`,`,`,`,`,`,`,`,`,,,,`,,`,,,,`,`,forbiddye,,,,`,`,`
,,`,`,`,`,`,`,`,`,,,unpreparedfish,,,,,,rawhides,,,`,forbidunpreparedfish,,,,,,`
,,`,`,`,`,`,`,`,`,,`,nocontainers,,,`,,,"{givename name=""rawhides""}",`,,`,forbidmiscliquid,,,,,,`
,,`,`,`,`,`,`,`,,,`,"{givename name=""unprepared fish""}",,forbidcraftrefuse,"{givename name=""refuse feeder""}",corpses,,t{Left 3}{Down 4}&,`,,,forbidpreparedfood,,,,,,`
,,`,`,`,`,`,`,`,,`,`,`,,forbidcorpses,"{give move=""{Right 3}{Up}""}","{givename name=""corpse feeder""}",,`,`,`,,forbidbooze,,,,,`,`
,,`,`,`,`,`,`,`,,`,`,`,,`,`,`,,`,`,`,,forbidseeds,,,,,`,`
,,`,`,`,`,`,`,`,,`,`,`,,,"{quantumstop name=""Refuse/Corpse quantum"" sp_links=""{sp_link move={Up} move_back={Down}}{sp_link move=""""{Right}{Up}"""" move_back=""""{Down}{Left}""""}""}{givename name=""refuse/corpse dumper""}",,,`,`,`,,forbidwax,,,,`,`,`
,,,,,,,,,,,,,,,"{quantum name=""refuse/corpse quantum""}"


#query label(farming_link) start(16; 18) hidden() set farming stockpiles to take from starting surface stockpiles


,,,,,,,,,`,`,`,,`,`,`,t{Down 6}{Left 10}<&,`,,t{Down 6}{Left 13}<&,`,`,`
,,,,,,,,,`,`,`,,`,`,`,`,`,,`,`,`,`
,,,,,,,,,`,`,`,,`,`,`,`,`,,`,`,`,`
,,,,,,,,,,,`,,`,`,`,`,`,,`,`,`,`
,,,,,,,`,`,`,,`,,`,`,`,`,`,,`,t{Down 2}{Left 14}<&,`,`
,,,,,,,`,`,`,`,`,,`,`,`,`,`,,`,`,`,`
,,,,,,,`,`,`,,`,,`,`,`,`,`,,`
,,,,,,,,,,,`,,`,`,`,`,`,,`,,`,`,`
,,,,,,`,`,`,t{Up 2}{Right 11}<&,,`,,`,`,`,`,`,,`,`,`,`,`
,,,,,,`,`,`,`,,`,,t{Up 3}{Left 7}<&,`,`,`,`,,`,,`,`,`
,,,t{Up 4}{Right 17}<&,`,,`,`,`,`,,`,,`,`,`,`,`,,`
,,`,`,`,,`,`,`,`,,`,,`,`,`,`,`,,`,,`,`,`,,`,`,`
,,`,t{Up 6}{Right 17}<&,`,`,`,`,`,`,`,`,,,`,,`,,,`,`,`,`,`,`,`,`,`
,,,`,`,,`,`,`,`,,`,`,`,`,`,`,`,`,`,,`,`,`,,`,`,`
,,,,`,,,`,,,,,,`,`,`,`,`,,,,,`,,,,`
,,t{Up 9}{Right 4}<&,`,`,`,`,`,`,`,`,`,,`,`,~,`,`,,t{Up 9}{Left 13}<&,`,`,`,`,`,`,`,`,`
,,`,`,`,`,`,`,`,`,`,`,`,`,`,`,`,`,`,`,`,`,`,`,`,`,`,`,`
,,`,`,`,`,`,`,`,`,`,`,,`,`,`,`,`,,`,`,`,`,`,`,`,`,`,`
,,`,`,`,`,`,`,`,`,`,,,,`,,`,,,,`,`,`,`,`,`,`,`,`
,,`,`,`,`,`,`,`,`,,,t{Up 13}{Left 6}<&,`,`,`,`,`,`,,,`,`,`,`,`,`,`,`
,,`,`,`,`,`,`,`,`,,`,`,,,`,,,`,`,,`,`,`,`,`,`,`,`
,,`,`,`,`,`,`,`,,,`,`,,t{Up 15}{Right 10}<&,`,`,,`,`,,,`,`,`,`,`,`,`
,,`,`,`,`,`,`,`,,`,`,`,,`,`,`,,`,`,`,,`,`,`,`,`,`,`
,,`,`,`,`,`,`,`,,`,`,`,,`,`,`,,`,`,`,,`,`,`,`,`,`,`
,,`,`,`,`,`,`,`,,`,`,`,,,`,,,`,`,`,,`,`,`,`,`,`,`
,,,,,,,,,,,,,,,`


#query label(farming_rooms) start(16; 18) hidden() message(Check to ensure the lower office got assigned to your manager and assign the upper office to your bookkeeper (if different from your manager).) configure rooms


,,,,,,,,,`,`,`,,`,`,`,`,`,,`,`,`,`
,,,,,,,,,r&,`,`,,`,`,`,`,`,,`,`,`,`
,,,,,,,,,`,`,`,,`,`,`,`,`,,`,`,r+&h
,,,,,,,,,,,`,,`,`,`,`,`,,`,`,`,`
,,,,,,,`,`,`,,`,,`,`,`,`,`,,`,`,`,`
,,,,,,,r&a+&,,,`,`,,`,`,`,`,`,,`,`,`,`
,,,,,,,`,`,`,,`,,`,`,`,`,`,,`
,,,,,,,,,,,`,,`,`,`,`,`,,`,,`,`,r&d
,,,,,,`,`,`,`,,`,,`,`,`,`,`,,`,`,`,`,`
,,,,,,`,`,`,`,,`,,`,`,`,`,`,,`,,`,`,`
,,,`,`,,`,`,`,`,,`,,`,`,`,`,`,,`
,,`,`,`,,`,`,`,`,,`,,`,`,`,`,`,,`,,`,`,`,,`,`,`
,,`,`,`,`,`,`,`,`,`,`,,,`,,`,,,`,`,`,`,`,`,`,`,`
,,,`,`,,`,`,`,`,,`,`,`,`,`,`,`,`,`,,`,`,`,,`,`,`
,,,,`,,,`,,,,,,`,`,`,`,`,,,,,`,,,,`
,,`,`,`,`,`,`,`,`,`,`,,`,`,~,`,`,,`,`,`,`,`,`,`,`,`,`
,,`,`,`,`,`,`,`,`,`,`,`,`,`,`,`,`,`,`,`,`,`,`,`,`,`,`,`
,,`,`,`,`,`,`,`,`,`,`,,`,`,`,`,`,,`,`,`,`,`,`,`,`,`,`
,,`,`,`,`,`,`,`,`,`,,,,`,,`,,,,`,`,`,`,`,`,`,`,`
,,`,`,`,`,`,`,`,`,,,`,`,`,`,`,`,`,,,`,`,`,`,`,`,`,`
,,`,`,`,`,`,`,`,`,,`,`,,,`,,,`,`,,`,`,`,`,`,`,`,`
,,`,`,`,`,`,`,`,,,`,`,,`,`,`,,`,`,,,`,`,`,`,`,`,`
,,`,`,`,`,`,`,`,,`,`,`,,`,`,`,,`,`,`,,`,`,`,`,`,`,`
,,`,`,`,`,`,`,`,,`,`,`,,`,`,`,,`,`,`,,`,`,`,`,`,`,`
,,`,`,`,`,`,`,`,,`,`,`,,,`,,,`,`,`,,`,`,`,`,`,`,`
,,,,,,,,,,,,,,,`


"#build label(farming_build2) start(16; 18) hidden() farm plots, remaining furniture, and important doors"


,,,,,,,,,`,`,`,,p(3x1),,,`,`,,`,`,`,`
,,,,,,,,,`,`,`,,p(3x1),,,`,`,,`,`,`,`
,,,,,,,,,`,`,`,,p(3x1),,,`,`,,c,t,~,~
,,,,,,,,,,,`,,p(3x1),,,`,`,,c,t,t,c
,,,,,,,`,`,`,,`,,p(3x1),,,`,`,,`,`,`,`
,,,,,,,`,`,`,`,`,,p(3x1),,,`,`,,`,`,`,`
,,,,,,,`,`,`,,`,,p(3x1),,,`,`,,`
,,,,,,,,,,,`,,p(3x1),,,`,`,,`,,b,b,~
,,,,,,`,`,`,`,,`,,p(3x1),,,`,`,,`,`,`,`,h
,,,,,,`,`,`,`,,`,,`,`,`,`,`,,`,,b,b,b
,,,`,`,,`,`,`,`,,`,,`,`,`,`,`,,`
,,`,`,`,,`,`,`,`,,`,,`,`,`,`,`,,`,,`,`,`,,`,`,`
,,`,`,`,`,`,`,`,`,`,`,,,`,,`,,,`,`,`,`,`,`,`,`,`
,,,`,`,,`,`,`,`,,`,`,`,`,`,`,`,`,`,,`,`,`,,`,`,`
,,,,`,,,`,,,,,,`,`,`,`,`,,,,,`,,,,`
,,`,`,`,`,`,`,`,`,`,`,,`,`,~,`,`,,`,`,`,`,`,`,`,`,`,`
,,`,`,`,`,`,`,`,`,`,`,`,`,`,`,`,`,`,`,`,`,`,`,`,`,`,`,`
,,`,`,`,`,`,`,`,`,`,`,,`,`,`,`,`,,`,`,`,`,`,`,`,`,`,`
,,`,`,`,`,`,`,`,`,`,,,,`,,`,,,,`,`,`,`,`,`,`,`,`
,,`,`,`,`,`,`,`,`,,,`,d,`,`,`,d,`,,,`,`,`,`,`,`,`,`
,,`,`,`,`,`,`,`,`,,`,`,,,d,,,`,`,,`,`,`,`,`,`,`,`
,,`,`,`,`,`,`,`,,,`,`,,`,`,`,,`,`,,,`,`,`,`,`,`,`
,,`,`,`,`,`,`,`,,`,`,`,,`,`,`,,`,`,`,,`,`,`,`,`,`,`
,,`,`,`,`,`,`,`,,`,`,`,,`,`,`,,`,`,`,,`,`,`,`,`,`,`
,,`,`,`,`,`,`,`,,`,`,`,,,`,,,`,`,`,,`,`,`,`,`,`,`
,,,,,,,,,,,,,,,`


#query label(farming_query_plots) start(16; 18) hidden() configure farm plots for seasonal fertilization


,,,,,,,,,`,`,`,,s,`,`,`,`,,`,`,`,`
,,,,,,,,,`,`,`,,s,`,`,`,`,,`,`,`,`
,,,,,,,,,`,`,`,,s,`,`,`,`,,`,`,`,`
,,,,,,,,,,,`,,s,`,`,`,`,,`,`,`,`
,,,,,,,`,`,`,,`,,s,`,`,`,`,,`,`,`,`
,,,,,,,`,`,`,`,`,,s,`,`,`,`,,`,`,`,`
,,,,,,,`,`,`,,`,,s,`,`,`,`,,`
,,,,,,,,,,,`,,s,`,`,`,`,,`,,`,`,`
,,,,,,`,`,`,`,,`,,s,`,`,`,`,,`,`,`,`,`
,,,,,,`,`,`,`,,`,,`,`,`,`,`,,`,,`,`,`
,,,`,`,,`,`,`,`,,`,,`,`,`,`,`,,`
,,`,`,`,,`,`,`,`,,`,,`,`,`,`,`,,`,,`,`,`,,`,`,`
,,`,`,`,`,`,`,`,`,`,`,,,`,,`,,,`,`,`,`,`,`,`,`,`
,,,`,`,,`,`,`,`,,`,`,`,`,`,`,`,`,`,,`,`,`,,`,`,`
,,,,`,,,`,,,,,,`,`,`,`,`,,,,,`,,,,`
,,`,`,`,`,`,`,`,`,`,`,,`,`,~,`,`,,`,`,`,`,`,`,`,`,`,`
,,`,`,`,`,`,`,`,`,`,`,`,`,`,`,`,`,`,`,`,`,`,`,`,`,`,`,`
,,`,`,`,`,`,`,`,`,`,`,,`,`,`,`,`,,`,`,`,`,`,`,`,`,`,`
,,`,`,`,`,`,`,`,`,`,,,,`,,`,,,,`,`,`,`,`,`,`,`,`
,,`,`,`,`,`,`,`,`,,,`,`,`,`,`,`,`,,,`,`,`,`,`,`,`,`
,,`,`,`,`,`,`,`,`,,`,`,,,`,,,`,`,,`,`,`,`,`,`,`,`
,,`,`,`,`,`,`,`,,,`,`,,`,`,`,,`,`,,,`,`,`,`,`,`,`
,,`,`,`,`,`,`,`,,`,`,`,,`,`,`,,`,`,`,,`,`,`,`,`,`,`
,,`,`,`,`,`,`,`,,`,`,`,,`,`,`,,`,`,`,,`,`,`,`,`,`,`
,,`,`,`,`,`,`,`,,`,`,`,,,`,,,`,`,`,,`,`,`,`,`,`,`
,,,,,,,,,,,,,,,`


#build label(farming_build3) start(16; 18) hidden() remaining doors


,,,,,,,,,`,`,`,,`,`,`,`,`,,`,`,`,`
,,,,,,,,,`,`,`,,`,`,`,`,`,,`,`,`,`
,,,,,,,,,`,`,`,,`,`,`,`,`,,~,~,~,~
,,,,,,,,,,,d,,`,`,`,`,`,,~,~,~,~
,,,,,,,`,`,`,,`,,`,`,`,`,`,,`,`,`,`
,,,,,,,`,`,`,d,`,,`,`,`,`,`,,`,`,`,`
,,,,,,,`,`,`,,`,,`,`,`,`,`,,d
,,,,,,,,,,,`,,`,`,`,`,`,,`,,~,~,~
,,,,,,`,`,`,`,,`,,`,`,`,`,`,,`,d,`,`,~
,,,,,,`,`,`,`,,`,,`,`,`,`,`,,`,,~,~,~
,,,`,`,,`,`,`,`,,`,,`,`,`,`,`,,`
,,`,`,`,,`,`,`,`,,`,,`,`,`,`,`,,`,,`,`,`,,`,`,`
,,`,`,`,d,`,`,`,`,d,`,,,d,,d,,,`,d,`,`,`,d,`,`,`
,,,`,`,,`,`,`,`,,`,d,`,`,`,`,`,d,`,,`,`,`,,`,`,`
,,,,d,,,d,,,,,,`,`,`,`,`,,,,,d,,,,d
,,`,`,`,`,`,`,`,`,`,`,,`,`,~,`,`,,`,`,`,`,`,`,`,`,`,`
,,`,`,`,`,`,`,`,`,`,`,d,`,`,`,`,`,d,`,`,`,`,`,`,`,`,`,`
,,`,`,`,`,`,`,`,`,`,`,,`,`,`,`,`,,`,`,`,`,`,`,`,`,`,`
,,`,`,`,`,`,`,`,`,`,,,,d,,d,,,,`,`,`,`,`,`,`,`,`
,,`,`,`,`,`,`,`,`,,,`,~,`,`,`,~,`,,,`,`,`,`,`,`,`,`
,,`,`,`,`,`,`,`,`,,`,`,,,~,,,`,`,,`,`,`,`,`,`,`,`
,,`,`,`,`,`,`,`,,,`,`,,`,`,`,,`,`,,,`,`,`,`,`,`,`
,,`,`,`,`,`,`,`,,`,`,`,,`,`,`,,`,`,`,,`,`,`,`,`,`,`
,,`,`,`,`,`,`,`,,`,`,`,,`,`,`,,`,`,`,,`,`,`,`,`,`,`
,,`,`,`,`,`,`,`,,`,`,`,,,`,,,`,`,`,,`,`,`,`,`,`,`
,,,,,,,,,,,,,,,`


#notes label(industry_help)
Sets up workshops for all non-farming industries
Screenshot: https://drive.google.com/file/d/1emMaHHCaUPcdRbkLQqvr-0ZCs2tdM5X7
""
Features:
- Space-efficient layout for all workshops
- Manager orders that automate basic fortress maintenance
"- Space available underneath the forge and smelters for magma, allowing the starting forge and smelters to be eventually replaced by magma versions."
- Quantum stockpiles for compact storage
with separate stockpiles for:
- A reserve of uncut gems for strange moods that the jeweler's workshop cannot take from
"- Wood, steel bars, and coal so you can see at a glance if you're low on stock"
- Items that cannot be quantum stockpiled (e.g. lye and sand bags)
- Meltable weapons and armor
""
Workshops:
- 2x Mason
- 4x Craftsdwarf
- 1x Jeweler
- 1x Mechanic
- 4x Smelter
- 1x Forge
- 1x Glassmaker
- 1x Kiln
- 4x Wood furnace
- 1x Ashery
- 1x Soap maker
- 1x Carpenter
- 1x Siege workshop
- 1x Bowyer
- 1x Dyer
- 1x Loom
- 1x Clothier
""
""
Manual steps you have to take:
- Assign minecarts to your quantum stockpile hauling routes
"- Give from the ""Goods"" quantum stockpile to the jugs, pots, and bags stockpiles on the farming level"
- Copy the fort automation manager orders (the .json files) from hack/examples/orders/ and put them in your dfhack-config/orders/ directory.
""
Optional manual steps you can take:
- Restrict the Mechanic's workshop to only allow skilled workers so unskilled trap-resetters won't be tasked to build mechanisms.
"- Restrict the Craftsdwarf's workshops to only allow labors that take from the adjacent stockpiles. That is, only allow Woodcrafting for the Craftsdwarf's workshop on the left near the wood stockpile, Stonecrafting and Strand Extraction for the Craftsdwarf's workshop near the Mason's workshops, and Bonecrafting for one of the Craftsdwarf's workshop near the Clothier's workshop. The last Craftdwarf's workshop can hold all the remaining labors, or it can be a secondary workshop for a labor that you want more dwarves working on."
"- To encourage your masons to concentrate on building blocks and other high-volume orders, it helps to set one of your Mason's workshops to service a maximum of 2 manager orders at a time."
"- Once you have enough haulers, you can increase the rate of stone and ore hauling jobs by building more wheelbarrows and adding them to the stone and ore feeder stockpiles."
"- If desired, set one or both stockpiles in the bottom left to auto-melt. This results in melting all weapons and armor that are inferior to masterwork. This is great for upgrading your military, but it takes a *lot* of fuel unless you have first replaced the forge and smelters with magma versions. If you enable automelt and you don't have magma forges and magma smelters, be sure to be in a heavily forested area, enable auto-chop, and keep your coal stocks high."
""
Industry Walkthrough:
"1) Start digging out /industry1 as soon as you find a stone layer at least two layers beneath the surface so the boulders can be used by your starting workshops. The services level is intended to be dug beneath this one, and there is space on that level to route magma underneath your furnaces so you can replace the furnaces on this level with magma-powered equivalents."
""
