#notes label(help) run me for the dreamfort walkthrough
Welcome to the Dreamfort Walkthrough!
"It can be difficult to apply a set of blueprints that you did not write yourself. This walkthrough will guide you through the high-level steps of building Dreamfort. Run the /checklist blueprint for a compact list of all commands you need to run, in order. Each level has its own mini-walkthrough with details on *when* to run each command."
""
"The final fort will have a walled-in area on the surface for livestock, trading, surface farming, and military. One z-level down is the farming level, with related workshops and vents up to the surface for miasma control. The farming level also has a miniature dining hall and dormitory for use until you get the services and housing levels set up."
""
"Beyond those two, the other layers can be built in any order, at any z-level, according to your preference and the layout peculiarities of your embark site:"
"- The industry level has a compact, but complete set of workshops and stockpiles (minus what is already provided on the farming level)."
"- The services level has dining, hospital, barracks, and justice services, plus a well system. Services is 4 z-levels deep."
"- The guildhall level has many empty rooms for building libraries, temples, and guildhalls."
- The suites level has fancy rooms for your nobles.
- The apartments levels have small but well-furnished bedrooms for your other dwarves.
""
"Run each level's ""help"" blueprint (e.g. /surface_help) for more details."
""
"Dreamfort has a central stairs-based design. For all Dreamfort levels, place the cursor on the center tile of the 3x3 stairs area when you apply the blueprints. The first surface blueprint will designate a column of stairs that you can use as a guide. If you need to extend the stairs down further to lower levels, run ""quickfort run library/dreamfort.csv -n /central_stairs"" with the cursor on the z-level below the lowest current stairs."
""
"Dreamfort blueprints take care of everything to get the fort up and running. You don't need to clear any extra trees or create any extra buildings/stockpiles (though of course you are free to do so). Blueprints that do require manual steps (like 'assign minecart to hauling route') will leave a message telling you so when you run them. Blueprints will also leave messages with hints when you might want to run ""quickfort orders"" to start manufacturing needed items, like blocks or tables. Make sure you appoint a manager to handle all the incoming work orders!"
""
"Dreamfort works best at an embark site that is flat and has at least one soil layer. New players should also avoid aquifers if they are not prepared to deal with them. Bring picks for mining, an axe for woodcutting, and an anvil for a forge. Bring a few blocks to speed up initial workshop construction as well."
""
"Other DFHack scripts and plugins also work very well with Dreamfort, in particular autofarm, automelt, autonestbox, burial, seedwatch, tailor, and, of course, buildingplan. You can download an onMapLoad.init file that configures all these plugins here: https://drive.google.com/file/d/16JX21nSe0_t84BgoL7DJX1OVD2E6pJgH"
Put that file in your Dwarf Fortress directory -- the same directory that has dfhack.init.
""
"Once you have your starting workshops up and running, you might want to configure buildingplan (in its global settings, accessible from any building placement screen, e.g.: b-a-G) to only use blocks for constructions so it won't use your precious wood, boulders, and bars to build floors and walls. If you bring at least 4 blocks with you on embark, you can even set this in your onMapLoad.init file like this:"
on-new-fortress buildingplan set boulders false; buildingplan set logs false
""
"Directly after embark, apply /surface1 on the surface (see /surface_help for how to select a good spot) and /industry1 in a rock layer at least two z-levels underground (the z-level immediately below the surface is reserved for the farming level). The walkthroughs for those levels will guide you. Once you channel out the miasma vents and clear the trees on the surface, you can start the farming sequence on the z-level below the surface with /farming1. You should wait to start farming unitl after you clear the trees because if you clear trees later over a hollow underground, you'll be left with holes in the surface where the trunks were. You can start the services, guildhall, suites, and apartments sequences as your fort needs those levels."
""
"This .csv file is generated from source .xlsx files. If you want to look at how these blueprints are put together, it is easier to look at the online spreadsheets than this giant .csv. You can view them at: https://drive.google.com/drive/folders/1iS90EEVqUkxTeZiiukVj1pLloZqabKuP"
You are welcome to copy those spreadsheets and make your own modifications!
"# dreamfort.csv is generated with the following command:
  for fname in dreamfort*.xlsx; do xlsx2csv -a -p '' $fname; done | sed 's/,*$//'"
#notes label(checklist) command checklist
Here is the recommended order for Dreamfort commands. You can copy/paste the quickfort commands directly into the DFHack terminal. See the level walkthroughs for context and details. Also remember to read the messages the blueprints print out after you run them so you don't miss any important manual steps.

-- Preparation --
download onMapLoad.init and put in your DF directory: https://drive.google.com/file/d/16JX21nSe0_t84BgoL7DJX1OVD2E6pJgH
download automation.json and put in dfhack-config/orders: https://drive.google.com/file/d/17WcN5mK-rnADOm2B_JFpPnByYgkYjxhb

-- Find a good starting spot on the surface --
quickfort run library/dreamfort.csv -n /perimeter,# Run at embark
quickfort undo library/dreamfort.csv -n /perimeter

-- Dig and  preload important orders --
quickfort run library/dreamfort.csv -n /surface1,# Run at embark
quickfort run library/dreamfort.csv -n /industry1,"# Run when you find a suitable rock layer. Note that we'll dig the farming level a bit later, so be sure to leave room for it. Alternately, instead of each of the dig blueprints individually, run /dig_all_underground, which designates digging for industry, services, guildhall, suites, and apartments all in one go. It is more efficient for your miners if you designate your digging before they dig the central stairs past that level."
quickfort run library/dreamfort.csv -n /services1
quickfort run library/dreamfort.csv -n /guildhall1
quickfort run library/dreamfort.csv -n /suites1
quickfort run library/dreamfort.csv -n /apartments1_stack
quickfort orders library/dreamfort.csv -n /surface2,# Queue up orders required to get the fort minimally functional and secure
quickfort orders library/dreamfort.csv -n /surface3
quickfort orders library/dreamfort.csv -n /farming2
quickfort orders library/dreamfort.csv -n /farming3
quickfort orders library/dreamfort.csv -n /industry2
quickfort orders library/dreamfort.csv -n /services2

-- Core fort (should finish at about the third migration wave) -- 
quickfort run library/dreamfort.csv -n /surface2,# Run after initial trees are cleared
quickfort run library/dreamfort.csv -n /farming1,# Run when channels are dug and trees are cleared
quickfort run library/dreamfort.csv -n /farming2,# Run when the farming level has been dug out
quickfort run library/dreamfort.csv -n /surface3,# Run after /farming2
quickfort run library/dreamfort.csv -n /farming3,# Run when furniture has been placed
quickfort run library/dreamfort.csv -n /industry2,# Run when the industry level has been dug out
quickfort run library/dreamfort.csv -n /surface4,"# Run after the walls and floors are built on the surface. Even if the surface is finished before you run /industry2, though, wait until after /industry2 so that surface walls, floors, and roofing don't prevent your workshops from being built (due to lack of blocks)."
quickfort orders library/dreamfort.csv -n /surface4
quickfort run library/dreamfort.csv -n /services2,# Run when the services level has been dug out
orders import automation,"# Run after the first migration wave, so you have dorfs to do all the tasks"
quickfort run library/dreamfort.csv -n /surface5
quickfort orders library/dreamfort.csv -n /surface5
quickfort run library/dreamfort.csv -n /surface6,# Run when at least the beehives and weapon rack are constructed and you have linked all levers to their respective bridges.
quickfort orders library/dreamfort.csv -n /surface6
quickfort run library/dreamfort.csv -n /surface7,# Run after the surface walls are completed and any marked trees are chopped down
quickfort orders library/dreamfort.csv -n /surface7

-- Mature fort (third migration wave onward) -- 
quickfort run library/dreamfort.csv -n /services3,"# Run after the dining table and chair, weapon rack, and archery targets have been constructed. Also wait until after you run /surface7, though, because surface defenses are more important than a grand dining hall."
quickfort orders library/dreamfort.csv -n /services3
quickfort run library/dreamfort.csv -n /guildhall2,# Run when the guildhall level has been dug out
quickfort orders library/dreamfort.csv -n /guildhall2
quickfort run library/dreamfort.csv -n /suites2,# Run when the suites level has been dug out
quickfort orders library/dreamfort.csv -n /suites2
quickfort run library/dreamfort.csv -n /farming4,# Run right after /suites2
quickfort orders library/dreamfort.csv -n /farming4
quickfort run library/dreamfort.csv -n /surface8,"# Run if/when you need longer trap corridors on the surface, anytime after you run /surface7"
quickfort orders library/dreamfort.csv -n /surface8
quickfort run library/dreamfort.csv -n /services4,"# Run when you need a jail and/or fancy statues in the dining room, anytime after the restraints are placed from /services3"
quickfort orders library/dreamfort.csv -n /services4

-- Repeat for each apartments level --
quickfort run library/dreamfort.csv -n /apartments2,# Run when the apartment level has been dug out
quickfort orders library/dreamfort.csv -n /apartments2
quickfort run library/dreamfort.csv -n /apartments3,# Run when all beds have been constructed
quickfort orders library/dreamfort.csv -n /apartments3
burial -pets,# Run once the coffins are placed to set them to allow for burial

See this checklist online at https://docs.google.com/spreadsheets/d/13PVZ2h3Mm3x_G1OXQvwKd7oIR2lK4A1Ahf6Om1kFigw/edit#gid=1459509569
"#meta label(dig_all_underground) start(central stairs on industry level) hidden() dig industry, services, guildhall, suites, and apartments levels"
# Note that this blueprint will only work for the unified dreamfort.csv. It won't work for the individual .xlsx files (since #meta blueprints can't cross file boundaries).
""
/industry1
#>
/services1
#>
#>
#>
#>
/guildhall1
#>
/suites1
#>
/apartments1_stack
#ignore
"Here are the minimal skills needed for essential tasks in getting Dreamfort up and running, along with suggestions for which dwarves to assign them to. You can enable additional skills as you wish. Skills with an asterisk (*) are especially worth putting points into on the embark preparation screen."
Manager / Bookkeeper / Broker,Dwarf2,Dwarf3,Dwarf4,Dwarf5,Dwarf6,Dwarf7
Cook (*),Miner (*),Miner (*),Mason (*),Mason (*),Wood Cutter (*),Carpenter (*)
Weaver,,,Architect/Building Designer,Architect/Building Designer,Brewer,Mechanic
Clothesmaker,,,,,Mechanic (*)
Grower/Farmer,,,Stone Crafter (*),Stone Crafter (*)
Wood Cutter,,,Bee Keeper,Bee Keeper
Judge of Intent (*)
All other labors until you can assign them to a migrant

"The most time-comsuming tasks in early Dreamfort are: mining, chopping down trees, and making blocks. Starting with at least two miners, two woodcutters (assuming your embark has trees), and two masons is essential to keeping the fort from stalling. Note you may have to turn off all other labors for your wood cutters to get them focused on wood cutting when there are trees to clear before you can run the next surface blueprint."
"Moreover, it is important to always have one more mason than you have Mason's Workshops so other buildings that require masonry can get built (like bridges). Give the masons Beekeeping for the same reason -- it is a low-priority task, but it's important to have someone free to do it since otherwise the surface set of blueprints can stall."

We suggest bringing at least:
2 picks,for the two miners
2 battleaxes,for the two woodcutters
1 anvil,for the forge
7 blocks,for starting workshops and the temporary trade depot. necessary if you have buildingplan configured for blocks only.
many boulders,for quickly turning into more blocks. blocks are the limiting factor in the early stages.
12 cloth,"to make into rope for traction benches and the jail cells. you could try thread, but that tends to get eaten by the hospital"
food and seeds,as per usual
dogs and cats,for protection and vermin control
turkeys,for eggs and leather
#notes label(surface_help)
Sets up a protected entrance to your fort in a flat area on the surface.
""
Features:
- A starting set of workshops and stockpiles (which you can later remove once you establish your permanent workshops and storage)
- Protected trade depot
"- Walls, roof, and lever-controlled gates for security"
- Trap-filled hallways for invaders
- Optional barracks and extended trap hallways (for extra security)
- Livestock grazing area with nestbox zones and beehives
- A grid of 1x1 farm plots (meant to be managed with DFHack autofarm)
- Miasma vent covers for the farming level that is intended to be built in the layer directly beneath the surface
""
Manual steps you have to take:
- Assign grazing livestock to the large pasture and dogs to the pasture over the central stairs (DFHack's autonestbox can manage the nestbox zones)
- Connect levers to the gates that match the names of the levers
""
Be sure to choose an embark site that has an area flat enough to use these blueprints!
""
Surface Walkthrough:
"1) Choose a center tile for your central fortress stairs. The terrain around that tile should be perfectly flat. Trees are ok, but no slopes, rivers, or lakes. To be sure that the tile you've chosen is in a good spot, set the cursor over that tile and run ""quickfort run library/dreamfort.csv -n /perimeter"". This will show you the eventual boundaries of the fort. Some wall segments might be missing due to existing trees, but that's ok. Make sure the area within the exterior wall is flat. Run ""quickfort undo library/dreamfort.csv -n /perimeter"" to clean up."
""
"2) With the cursor on the chosen tile, run /surface1 to clear surrounding trees and set up your pastures. Deconstruct your wagon to get it out of the way of our upcoming walls and floors. Remember to assign your dogs to the pasture around the staircase and your grazing animals to the large pasture. You can let your cats roam free. Run ""quickfort orders"" for /surface3 to get a head start in manufacturing."
""
"3) Once the marked trees have been cleared, run /surface2 to set up starting workshops/stockpiles, channel out the miasma vents for the farming level, and start clearing trees from a larger area. Run ""quickfort orders"" for /surface3. Make sure you have appointed a manager so the orders get fulfilled! If you haven't done it already, now is a good time to configure buildingplan to only build buildings with blocks, not logs or raw boulders. Do this by entering buildingplan's global configuration (""baG"") and ensuring the only generic building material allowed is ""blocks""."
""
"4) Once the channels are dug out and the trees are cleared, start the farming level one z-level down. Once you have run /farming2, come back to the surface and run /surface3 to cover the vents and build an enclosure around your central stairs. Although the vents will be covered with flooring, they will still work to prevent miasma on the farming level."
""
"5) Once all walls and floors have been constructed around the stairwell, run /surface4 to build floors and walls to support upcoming buildings and furniture. Run ""quickfort orders"" for /surface4."
""
"6) Once walls and floors have been constructed (including the small roof segment one z-level up over the barracks), run /surface5 to build furniture, gates, and the permanent trade depot. Remember to deconstruct the temporary trade depot once nobody is using it. Run ""quickfort orders"" for /surface5."
""
"7) Once at least the beehives and weapon rack are built, run /surface6 to configure the rooms and build the remaining walls and floors. Run ""quickfort orders"" for /surface6."
""
"8) Once you have enough dwarves to do a lot of building without starving other important tasks, run /surface7 to build the roof. Run ""quickfort orders"" for /surface7."
""
"9) For extra security, you can run /surface8 any time after /surface7 to extend the trap corridors. Run ""quickfort orders"" for /surface8."
""
"10) Once your industry and farming levels are set up and running, you can disassemble the surface workshops and remove the surface stockpiles. Disassembling a workshop scatters the items stored within it and cancels any pending jobs that happen to use those items. In order to avoid job cancellations, first set the surface workshops to not accept general work orders. Do this by entering query mode (""q""), selecting a workshop, entering the workshop profile (""P""), moving to work orders (right arrow), and hitting Enter. Then enter view mode (""t"") and check to see if any items in a workshop are marked with ""TSK"". Once no items in the workshop have that marker, you are free to disassemble that workshop."
#meta label(perimeter) start(central stairs) message(Run quickfort undo on this blueprint to clean up.) show the eventual perimeter of the surface fort; useful for location scouting
walls/surface_walls
corridor/surface_corridor
""
"#meta label(surface1) start(central stairs)
message(Once the central stairs is mined out deeply enough, you should start digging the industry level in a non-aquifer rock layer. You'll need the boulders from the digging to make blocks.
If your wagon is within the fort perimeter, deconstruct it to get it out of the way.
Enqueue manager orders for /surface3 to get a head start on building required materials.
Once the marked trees are all chopped down (if any), continue with /surface2.) clear trees and set up pastures"
central_stairs/central_stairs
clear_small/surface_clear_small
zones/surface_zones
name_zones/surface_name_zones
""
"#meta label(surface2) start(central stairs) message(Once the channels are dug out and the marked trees are cleared, continue with /surface3.) set up starting workshops/stockpiles, channel miasma vents, and clear more trees"
build_start/surface_build_start
place_start/surface_place_start
query_start/surface_query_start
channel/surface_channel
clear/surface_clear
""
"#meta label(surface3) start(central stairs) message(Once the walls and floors have been constructed, continue with /surface4.) Cover vents and protect the central stairs."
cover_vents/surface_cover_vents
cover_stairs/surface_cover_stairs
""
"#meta label(surface4) start(central stairs) message(Remember to enqueue manager orders for this blueprint.
Once the walls and floors have been constructed, continue with /surface5. Be sure to check one z-level above the surface to ensure the roof segment above the future barracks has been finished.) build walls and flooring to support upcoming buildings and furniture"
stairs_doors/surface_stairs_doors
pre_building/surface_pre_building
""
"#meta label(surface5) start(central stairs) message(Remember to enqueue manager orders for this blueprint.
Disassemble the temporary trade depot in the pasture once the new one is constructed (and no merchants are using the old one).
Once the marked trees are cleared and at least the beehives and weapon rack have been constructed, continue with /surface6.) build gates, furniture, and trade stockpile/depot"
place/surface_place
build/surface_build
query/surface_query
clear_large/surface_clear_large
""
"#meta label(surface6) start(central stairs) message(Remember to enqueue manager orders for this blueprint.
Continue with /surface7 sometime after the walls are completed and any marked trees are chopped down, whenever you have enough dwarves to build the roof without starving other important construction tasks.) configure hives and barracks, build traps and remaining walls/floors"
query2/surface_query2
walls/surface_walls
floors/surface_floors
traps/surface_traps
clear_large/surface_clear_large
""
"#meta label(surface7) start(central stairs (on ground level)) message(Remember to enqueue manager orders for this blueprint. For extra security, you can run /surface8 at any time to extend the trap corridors.) build roof"
#<
roof/surface_roof
roof2/surface_roof2
""
#meta label(surface8) start(central stairs) message(Remember to enqueue manager orders for this blueprint.) build extended trap corridors
corridor/surface_corridor
corridor_traps/surface_corridor_traps
query_corridor/surface_query_corridor
#dig label(central_stairs) start(2;2) hidden() spiral stairs that go down 20 levels
`,u,`
j7,`,j7
`,u,`
#>
`,j7,`
u,`,u
`,j7,`
#>
`,u,`
j7,`,j7
`,u,`
#>
`,j7,`
u,`,u
`,j7,`
#>
`,u,`
j7,`,j7
`,u,`
#>
`,j7,`
u,`,u
`,j7,`
#>
`,u,`
j7,`,j7
`,u,`
#>
`,j7,`
u,`,u
`,j7,`
#>
`,u,`
j7,`,j7
`,u,`
#>
`,j7,`
u,`,u
`,j7,`
#>
`,u,`
j7,`,j7
`,u,`
#>
`,j7,`
u,`,u
`,j7,`
#>
`,u,`
j7,`,j7
`,u,`
#>
`,j7,`
u,`,u
`,j7,`
#>
`,u,`
j7,`,j7
`,u,`
#>
`,j7,`
u,`,u
`,j7,`
#>
`,u,`
j7,`,j7
`,u,`
#>
`,j7,`
u,`,u
`,j7,`
#>
`,u,`
j7,`,j7
`,u,`
#>
`,j7,`
u,`,u
`,j7,`
#dig label(surface_clear_small) start(19; 19) hidden() clear trees for starting workshops and stockpiles



,,,`,,`,`,`,`,`,`,`,`,`,`,`,`,`,`,`,`,`,`,`,`,`,`,`,`,`,`,`,,`
,,,`,,`,,,,,,,,,,,,,,,,,,,,,,,,,,`,,`
,,,`,,`,,,,,,,,,,,,,,,,,,,,,,,,,,`,,`
,,,`,,`,t,t,t,t,t,t,t,t,t,t,t,t,t,t,t,t,t,t,t,t,t,t,t,t,t,`,,`
,,,`,,`,t,t,t,t,t,t,t,t,t,t,t,t,t,t,t,t,t,t,t,t,t,t,t,t,t,`,,`
,,,`,,`,t,t,t,t,t,t,t,t,t,t,t,t,t,t,t,t,t,t,t,t,t,t,t,t,t,`,,`
,,,`,,`,t,t,t,t,t,t,t,t,t,t,t,t,t,t,t,t,t,t,t,t,t,t,t,t,t,`,,`
,,,`,,`,t,t,t,t,t,t,t,t,t,t,t,t,t,t,t,t,t,t,t,t,t,t,t,t,t,`,,`
,,,`,,`,t,t,t,t,t,t,t,t,t,t,t,t,t,t,t,t,t,t,t,t,t,t,t,t,t,`,,`
,,,`,,`,t,t,t,t,t,t,t,t,t,t,t,t,t,t,t,t,t,t,t,t,t,t,t,t,t,`,,`
,,,`,,`,t,t,t,t,t,t,t,t,t,t,t,t,t,t,t,t,t,t,t,t,t,t,t,t,t,`,,`
,,,`,,`,t,t,t,t,t,t,t,t,t,t,t,t,t,t,t,t,t,t,t,t,t,t,t,t,t,`,,`
,,,`,,`,`,`,`,`,t,`,`,`,`,`,`,,`,,`,`,`,`,`,t,`,`,`,t,`,`,,`
,,,`,,`,,`,t,t,,,,,,`,,,,,,`,,,,,,,,,,`,,`
,,,`,,`,,`,,,,,,,,,,`,`,`,,,,,,,,,,,,`,,`
,,,`,,`,,,,,,,,,,`,,`,~,`,,`,,,,,,,,,,`,,`
,,,`,,`,,`,,,,,,,,,,`,`,`,,,,,,,,,,,,`,,`
,,,`,,`,,`,,,,,,,,`,,,,,,`,,,,,,,,,,`,,`
,,,`,,`,`,`,`,`,`,`,,`,`,`,`,,`,,`,`,`,`,,`,`,`,`,`,`,`,,`
,,,`,,`,,,,,,,,,`,t,,,,,,t,`,,,,,,,,,`,,`
,,,`,,`,,,,,,,,,t,t,,,,,,t,t,,,,,,,,,`,,`
,,,`,,`,,,,,,,,,t,t,,t,t,t,,t,t,,,,,,,,,`,,`
,,,`,,`,,,,,,,,,,,,t,t,t,,,,,,,,,,,,`,,`
,,,`,,`,,,,,,,,,t,,,t,t,t,,,t,,,,,,,,,`,,`
,,,`,,`,`,`,`,`,`,`,`,`,`,,,,,,,,`,`,`,`,`,`,`,`,`,`,,`
,,,`,,,,,,,,,,,,,,,t,,,,,,,,,,,,,,,`
,,,`,`,`,`,`,`,`,`,`,`,`,`,,,,,,,,`,`,`,`,`,`,`,`,`,`,`,`



"#zone label(surface_zones) start(19; 19) hidden() message(Remember to assign your dogs to the pasture surrounding the central stairs and your grazing animals to the large pasture.
Feel free to assign an unimportant animal to the pasture in the main entranceway to use as bait during sieges.) pastures and training areas"



,,,`,,`,`,`,`,`,`,`,`,`,`,`,`,`,`,`,`,`,`,`,`,`,`,`,`,`,`,`,,`
,,,`,,`,nmt(25x11),,,,,,,,,,,,,,,,,,,,,,,,,`,,`
,,,`,,`,,,,,,,,,,,,,,,,,,,,,,,,,,`,,`
,,,`,,`,,,,,,,,,,,,,,,,,,,,,,,,,,`,,`
,,,`,,`,,,,,,,,,,,,,,,,,,,,,,,,,,`,,`
,,,`,,`,,,,,,,,,,,,,,,,,,,,,,,,,,`,,`
,,,`,,`,,,,,,,,,,,,,,,,,,,,,,,,,,`,,`
,,,`,,`,,,,,,,,,,,,,,,,,,,,,,,,,,`,,`
,,,`,,`,,,,,,,,,,,,,,,,,,,,,,,,,,`,,`
,,,`,,`,,,,,,,,,,,,,,,,,,,,,,,,,,`,,`
,,,`,,`,,,,,,,,,,,,,,,,,,,,,,,,,,`,,`
,,,`,,`,,,,,,,,,,,,,,,,,,,,,,,,,,`,,`
,,,`,,`,`,`,`,`,`,`,`,`,`,`,`,,`,,`,`,`,`,`,`,`,`,`,`,`,`,,`
,,,`,,`,,`,n(1x1),n(1x1),n(1x1),n(1x1),n(1x1),n(1x1),n(1x1),`,,,,,,`,tn(9x5),,,,,,,,,`,,`
,,,`,,`,,`,,,,,,,,,nt,nt,nt,nt,nt,,,,,,,,,,,`,,`
,,,`,,`,,,,,,,,,,`,nt,`,~,`,nt,`,,,,,,,,,,`,,`
,,,`,,`,,`,,,,,,,,,nt,nt,nt,nt,nt,,,,,,,,,,,`,,`
,,,`,,`,,`,n(1x1),n(1x1),n(1x1),n(1x1),n(1x1),n(1x1),n(1x1),`,,,,,,`,,,,,,,,,,`,,`
,,,`,,`,`,`,`,`,`,`,,`,`,`,`,,`,,`,`,`,`,,`,`,`,`,`,`,`,,`
,,,`,,`,,,,,,,,,`,,,,,,,,`,,,,,,,,,`,,`
,,,`,,`,,,,,,,,,,,,,,,,,,,,,,,,,,`,,`
,,,`,,`,,,,,,,,,,,,,n,,,,,,,,,,,,,`,,`
,,,`,,`,,,,,,,,,,,,,,,,,,,,,,,,,,`,,`
,,,`,,`,,,,,,,,,`,,,,,,,,`,,,,,,,,,`,,`
,,,`,,`,`,`,`,`,`,`,`,`,`,,,,,,,,`,`,`,`,`,`,`,`,`,`,,`
,,,`,,,,,,,,,,,,,,,,,,,,,,,,,,,,,,`
,,,`,`,`,`,`,`,`,`,`,`,`,`,,,,,,,,`,`,`,`,`,`,`,`,`,`,`,`



#query label(surface_name_zones) start(19; 19) hidden()



,,,`,,`,`,`,`,`,`,`,`,`,`,`,`,`,`,`,`,`,`,`,`,`,`,`,`,`,`,`,,`
,,,`,,`,"{namezone name=""main pasture""}",,,,,,,,,,,,,,,,,,,,,,,,,`,,`
,,,`,,`,,,,,,,,,,,,,,,,,,,,,,,,,,`,,`
,,,`,,`,,,,,,,,,,,,,,,,,,,,,,,,,,`,,`
,,,`,,`,,,,,,,,,,,,,,,,,,,,,,,,,,`,,`
,,,`,,`,,,,,,,,,,,,,,,,,,,,,,,,,,`,,`
,,,`,,`,,,,,,,,,,,,,,,,,,,,,,,,,,`,,`
,,,`,,`,,,,,,,,,,,,,,,,,,,,,,,,,,`,,`
,,,`,,`,,,,,,,,,,,,,,,,,,,,,,,,,,`,,`
,,,`,,`,,,,,,,,,,,,,,,,,,,,,,,,,,`,,`
,,,`,,`,,,,,,,,,,,,,,,,,,,,,,,,,,`,,`
,,,`,,`,,,,,,,,,,,,,,,,,,,,,,,,,,`,,`
,,,`,,`,`,`,`,`,`,`,`,`,`,`,`,,`,,`,`,`,`,`,`,`,`,`,`,`,`,,`
,,,`,,`,,`,"{namezone name=""nestbox1""}","{namezone name=""nestbox2""}","{namezone name=""nestbox3""}","{namezone name=""nestbox4""}","{namezone name=""nestbox5""}","{namezone name=""nestbox6""}","{namezone name=""nestbox7""}",`,,,,,,`,"{namezone name=""taming area""}",,,,,,,,,`,,`
,,,`,,`,,`,,,,,,,,,,`,`,`,"{namezone name=""guard dogs""}",,,,,,,,,,,`,,`
,,,`,,`,,,,,,,,,,`,,`,~,`,,`,,,,,,,,,,`,,`
,,,`,,`,,`,,,,,,,,,,`,`,`,,,,,,,,,,,,`,,`
,,,`,,`,,`,"{namezone name=""nestbox8""}","{namezone name=""nestbox9""}","{namezone name=""nestbox10""}","{namezone name=""nestbox11""}","{namezone name=""nestbox12""}","{namezone name=""nestbox13""}","{namezone name=""nestbox14""}",`,,,,,,`,,,,,,,,,,`,,`
,,,`,,`,`,`,`,`,`,`,,`,`,`,`,,`,,`,`,`,`,,`,`,`,`,`,`,`,,`
,,,`,,`,,,,,,,,,`,,,,,,,,`,,,,,,,,,`,,`
,,,`,,`,,,,,,,,,,,,,,,,,,,,,,,,,,`,,`
,,,`,,`,,,,,,,,,,,,,"{namezone name=""siege bait""}",,,,,,,,,,,,,`,,`
,,,`,,`,,,,,,,,,,,,,,,,,,,,,,,,,,`,,`
,,,`,,`,,,,,,,,,`,,,,,,,,`,,,,,,,,,`,,`
,,,`,,`,`,`,`,`,`,`,`,`,`,,,,,,,,`,`,`,`,`,`,`,`,`,`,,`
,,,`,,,,,,,,,,,,,,,,,,,,,,,,,,,,,,`
,,,`,`,`,`,`,`,`,`,`,`,`,`,,,,,,,,`,`,`,`,`,`,`,`,`,`,`,`



#build label(surface_build_start) start(19; 19) hidden() message(There is room to the left of the carpenter's workshop to build one more workshop of any type if you need it.) starting workshops



,,,`,,`,`,`,`,`,`,`,`,`,`,`,`,`,`,`,`,`,`,`,`,`,`,`,`,`,`,`,,`
,,,`,,`,,,,,,,,,,,,,,,,,,,,,,,,,,`,,`
,,,`,,`,,,,,,,,,,,,,,,,,,,,,,,,,,`,,`
,,,`,,`,,,,,,,,,,,,,,,,,,,,,,,,,,`,,`
,,,`,,`,,,,,,,,,,,,,,,,,,,,,,,,,,`,,`
,,,`,,`,,,,,,,,,,,,,,,,,,,,,,,,,,`,,`
,,,`,,`,,,,,,,,,,,,,,,,,,,,,,,,,,`,,`
,,,`,,`,,,,,,,,,,,,,,,,,,,,,,,,,,`,,`
,,,`,,`,,,,,,,,,,,,,,,,,,,,,,,,,,`,,`
,,,`,,`,,,,,,wc,,,,wr,,,,wm,,,,wt,,,,,D,,,`,,`
,,,`,,`,,,,,,,,,,,,,,,,,,,,,,,,,,`,,`
,,,`,,`,,,,,,,,,,,,,,,,,,,,,,,,,,`,,`
,,,`,,`,`,`,`,`,`,`,`,`,`,`,`,,`,,`,`,`,`,`,`,`,`,`,`,`,`,,`
,,,`,,`,,`,N,N,,,,,,`,,,,,,`,,,,,,,,,,`,,`
,,,`,,`,,`,,,,,,,,,,`,`,`,,,,,,,,,,,,`,,`
,,,`,,`,,,,,,,,,,`,,`,~,`,,`,,,,,,,,,,`,,`
,,,`,,`,,`,,,,,,,,,,`,`,`,,,,,,,,,,,,`,,`
,,,`,,`,,`,,,,,,,,`,,,,,,`,,,,,,,,,,`,,`
,,,`,,`,`,`,`,`,`,`,,`,`,`,`,,`,,`,`,`,`,,`,`,`,`,`,`,`,,`
,,,`,,`,,,,,,,,,`,,,,,,,,`,,,,,,,,,`,,`
,,,`,,`,,,,,,,,,,,,,,,,,,,,,,,,,,`,,`
,,,`,,`,,,,,,,,,,,,,,,,,,,,,,,,,,`,,`
,,,`,,`,,,,,,,,,,,,,,,,,,,,,,,,,,`,,`
,,,`,,`,,,,,,,,,`,,,,,,,,`,,,,,,,,,`,,`
,,,`,,`,`,`,`,`,`,`,`,`,`,,,,,,,,`,`,`,`,`,`,`,`,`,`,,`
,,,`,,,,,,,,,,,,,,,,,,,,,,,,,,,,,,`
,,,`,`,`,`,`,`,`,`,`,`,`,`,,,,,,,,`,`,`,`,`,`,`,`,`,`,`,`



"#place label(surface_place_start) start(19; 19) hidden() message(if you haven't already, now is a good time to deconstruct the wagon) starting stockpiles"



,,,`,,`,`,`,`,`,`,`,`,`,`,`,`,`,`,`,`,`,`,`,`,`,`,`,`,`,`,`,,`
,,,`,,`,,,,,,,,,,,,,,,,,,,,,,,,,,`,,`
,,,`,,`,,,,,,,,,,,,,,,,,,,,,,,,,,`,,`
,,,`,,`,f(8x4),,,,,,,,w(4x4),,,,s2(5x4),,,,,gunbzSpd(4x4),,,,hl(4x4),,,,`,,`
,,,`,,`,,,,,,,,,,,,,,,,,,,,,,,,,,`,,`
,,,`,,`,,,,,,,,,,,,,,,,,,,,,,,,,,`,,`
,,,`,,`,,,,,,,,,,,,,,,,,,,,,,,,,,`,,`
,,,`,,`,,,,,,,,,,,,,,,,,,,,,,,,,,`,,`
,,,`,,`,,,,,,,,,,,,,,,,,,,,,,,,,,`,,`
,,,`,,`,,,,,,,,,,,,,,,,,,,,,,,,,,`,,`
,,,`,,`,,,,,,,,,,,,,,,,,,,,,,,,,,`,,`
,,,`,,`,,,,,,,,,,,,,,,,,,,,,,,,,,`,,`
,,,`,,`,`,`,`,`,`,`,`,`,`,`,`,,`,,`,`,`,`,`,`,`,`,`,`,`,`,,`
,,,`,,`,,`,,,,,,,,`,,,,,,`,,,,,,,,,,`,,`
,,,`,,`,,`,,,,,,,,,,`,`,`,,,,,,,,,,,,`,,`
,,,`,,`,,,,,,,,,,`,,`,~,`,,`,,,,,,,,,,`,,`
,,,`,,`,,`,,,,,,,,,,`,`,`,,,,,,,,,,,,`,,`
,,,`,,`,,`,,,,,,,,`,,,,,,`,,,,,,,,,,`,,`
,,,`,,`,`,`,`,`,`,`,,`,`,`,`,,`,,`,`,`,`,,`,`,`,`,`,`,`,,`
,,,`,,`,,,,,,,,,`,,,,,,,,`,,,,,,,,,`,,`
,,,`,,`,,,,,,,,,,,,,,,,,,,,,,,,,,`,,`
,,,`,,`,,,,,,,,,,,,,,,,,,,,,,,,,,`,,`
,,,`,,`,,,,,,,,,,,,,,,,,,,,,,,,,,`,,`
,,,`,,`,,,,,,,,,`,,,,,,,,`,,,,,,,,,`,,`
,,,`,,`,`,`,`,`,`,`,`,`,`,,,,,,,,`,`,`,`,`,`,`,`,`,`,,`
,,,`,,,,,,,,,,,,,,,,,,,,,,,,,,,,,,`
,,,`,`,`,`,`,`,`,`,`,`,`,`,,,,,,,,`,`,`,`,`,`,`,`,`,`,`,`



#query label(surface_query_start) start(19; 19) hidden() config stockpiles



,,,`,,`,`,`,`,`,`,`,`,`,`,`,`,`,`,`,`,`,`,`,`,`,`,`,`,`,`,`,,`
,,,`,,`,,,,,,,,,,,,,,,,,,,,,,,,,,`,,`
,,,`,,`,,,,,,,,,,,,,,,,,,,,,,,,,,`,,`
,,,`,,`,,,,,,,,"{givename name=""starting food""}",,,,"{givename name=""starting wood""}",,,,,"{givename name=""starting stone""}",,,,"{givename name=""starting misc""}",,,,"{givename name=""starting textile""}",`,,`
,,,`,,`,forbidtallow,forbiddye,forbidunpreparedfish,forbidmiscliquid,forbidseeds,,,,,,,,otherstone,,,,,nocontainers,,,,nocontainers,,,,`,,`
,,,`,,`,,,,,,,,,,,,,,,,,,,,,,,,,,`,,`
,,,`,,`,,,,,,,,,,,,,,,,,,,,,,,,,,`,,`
,,,`,,`,,,,,,,,,,,,,,,,,,,,,,,,,,`,,`
,,,`,,`,,,,,,,,,,,,,,,,,,,,,,,,,,`,,`
,,,`,,`,,,,,,,,,,,,,,,,,,,,,,,,,,`,,`
,,,`,,`,,,,,,,,,,,,,,,,,,,,,,,,,,`,,`
,,,`,,`,,,,,,,,,,,,,,,,,,,,,,,,,,`,,`
,,,`,,`,`,`,`,`,`,`,`,`,`,`,`,,`,,`,`,`,`,`,`,`,`,`,`,`,`,,`
,,,`,,`,,`,,,,,,,,`,,,,,,`,,,,,,,,,,`,,`
,,,`,,`,,`,,,,,,,,,,`,`,`,,,,,,,,,,,,`,,`
,,,`,,`,,,,,,,,,,`,,`,~,`,,`,,,,,,,,,,`,,`
,,,`,,`,,`,,,,,,,,,,`,`,`,,,,,,,,,,,,`,,`
,,,`,,`,,`,,,,,,,,`,,,,,,`,,,,,,,,,,`,,`
,,,`,,`,`,`,`,`,`,`,,`,`,`,`,,`,,`,`,`,`,,`,`,`,`,`,`,`,,`
,,,`,,`,,,,,,,,,`,,,,,,,,`,,,,,,,,,`,,`
,,,`,,`,,,,,,,,,,,,,,,,,,,,,,,,,,`,,`
,,,`,,`,,,,,,,,,,,,,,,,,,,,,,,,,,`,,`
,,,`,,`,,,,,,,,,,,,,,,,,,,,,,,,,,`,,`
,,,`,,`,,,,,,,,,`,,,,,,,,`,,,,,,,,,`,,`
,,,`,,`,`,`,`,`,`,`,`,`,`,,,,,,,,`,`,`,`,`,`,`,`,`,`,,`
,,,`,,,,,,,,,,,,,,,,,,,,,,,,,,,,,,`
,,,`,`,`,`,`,`,`,`,`,`,`,`,,,,,,,,`,`,`,`,`,`,`,`,`,`,`,`



#dig label(surface_channel) start(19; 19) hidden() channel miasma vents



,,,`,,`,`,`,`,`,`,`,`,`,`,`,`,`,`,`,`,`,`,`,`,`,`,`,`,`,`,`,,`
,,,`,,`,,,,,,,,,,,,,,,,,,,,,,,,,,`,,`
,,,`,,`,,,,,,,,,,,,,,,,,,,,,,,,,,`,,`
,,,`,,`,,,,,,,,,,,,,,,,,,,,,,,,,,`,,`
,,,`,,`,,,,,,,,,,,,,,,,,,,,,,,,,,`,,`
,,,`,,`,,,,,,,,,,,,,,,,,,,,,,,,,,`,,`
,,,`,,`,,,,,,,,,,,,,,,,,,,,,,,,,,`,,`
,,,`,,`,,,,,,,,,,,,,,,,,,,,,,,,,,`,,`
,,,`,,`,,,,,,,,,,,,,,,,,,,,,,,,,,`,,`
,,,`,,`,,,,,,,,,,,,,,,,,,,,,,,,,,`,,`
,,,`,,`,,,,,,,,,,,,,,,,,,,,,,,,,,`,,`
,,,`,,`,,,,,,,,,,,,,,,,,,,,,,,,,,`,,`
,,,`,,`,`,`,`,`,h1,`,`,`,`,`,`,,`,,`,`,`,`,`,h1,`,`,`,h1,`,`,,`
,,,`,,`,,`,,,,,,,,`,,,,,,`,,,,,,,,,,`,,`
,,,`,,`,,`,,,,,,,,,,`,`,`,,,,,,,,,,,,`,,`
,,,`,,`,,,,,,,,,,`,,`,~,`,,`,,,,,,,,,,`,,`
,,,`,,`,,`,,,,,,,,,,`,`,`,,,,,,,,,,,,`,,`
,,,`,,`,,`,,,,,,,,`,,,,,,`,,,,,,,,,,`,,`
,,,`,,`,`,`,`,`,`,`,,`,`,`,`,,`,,`,`,`,`,,`,`,`,`,`,`,`,,`
,,,`,,`,,,,,,,,,`,h1,,,,,,h1,`,,,,,,,,,`,,`
,,,`,,`,,,,,,,,,h1,h1,,,,,,h1,h1,,,,,,,,,`,,`
,,,`,,`,,,,,,,,,h1,h1,,h1,h1,h1,,h1,h1,,,,,,,,,`,,`
,,,`,,`,,,,,,,,,,,,h1,h1,h1,,,,,,,,,,,,`,,`
,,,`,,`,,,,,,,,,h1,,,h1,h1,h1,,,h1,,,,,,,,,`,,`
,,,`,,`,`,`,`,`,`,`,`,`,`,,,,,,,,`,`,`,`,`,`,`,`,`,`,,`
,,,`,,,,,,,,,,,,,,,h1,,,,,,,,,,,,,,,`
,,,`,`,`,`,`,`,`,`,`,`,`,`,,,,,,,,`,`,`,`,`,`,`,`,`,`,`,`



#dig label(surface_clear) start(19; 19) hidden() clear trees so the farming level can be dug without fear of generating surface holes


,,,,t,t,t,t,t,t,t,t,t,t,t,t,t,t,t,t,t,t,t,t,t,t,t,t,t,t,t,t,t
,,,`,t,t,t,t,t,t,t,t,t,t,t,t,t,t,t,t,t,t,t,t,t,t,t,t,t,t,t,t,t,`
,,,`,t,t,t,t,t,t,t,t,t,t,t,t,t,t,t,t,t,t,t,t,t,t,t,t,t,t,t,t,t,`
,,,`,t,t,t,t,t,t,t,t,t,t,t,t,t,t,t,t,t,t,t,t,t,t,t,t,t,t,t,t,t,`
,,,`,t,t,t,t,t,t,t,t,t,t,t,t,t,t,t,t,t,t,t,t,t,t,t,t,t,t,t,t,t,`
,,,`,t,t,t,t,t,t,t,t,t,t,t,t,t,t,t,t,t,t,t,t,t,t,t,t,t,t,t,t,t,`
,,,`,t,t,t,t,t,t,t,t,t,t,t,t,t,t,t,t,t,t,t,t,t,t,t,t,t,t,t,t,t,`
,,,`,t,t,t,t,t,t,t,t,t,t,t,t,t,t,t,t,t,t,t,t,t,t,t,t,t,t,t,t,t,`
,,,`,t,t,t,t,t,t,t,t,t,t,t,t,t,t,t,t,t,t,t,t,t,t,t,t,t,t,t,t,t,`
,,,`,t,t,t,t,t,t,t,t,t,t,t,t,t,t,t,t,t,t,t,t,t,t,t,t,t,t,t,t,t,`
,,,`,t,t,t,t,t,t,t,t,t,t,t,t,t,t,t,t,t,t,t,t,t,t,t,t,t,t,t,t,t,`
,,,`,t,t,t,t,t,t,t,t,t,t,t,t,t,t,t,t,t,t,t,t,t,t,t,t,t,t,t,t,t,`
,,,`,t,t,t,t,t,t,t,t,t,t,t,t,t,t,t,t,t,t,t,t,t,t,t,t,t,t,t,t,t,`
,,,`,t,t,t,t,t,t,t,t,t,t,t,t,t,t,t,t,t,t,t,t,t,t,t,t,t,t,t,t,t,`
,,,`,t,t,t,t,t,t,t,t,t,t,t,t,t,t,t,t,t,t,t,t,t,t,t,t,t,t,t,t,t,`
,,,`,t,t,t,t,t,t,t,t,t,t,t,t,t,t,t,t,t,t,t,t,t,t,t,t,t,t,t,t,t,`
,,,`,t,t,t,t,t,t,t,t,t,t,t,t,t,t,t,t,t,t,t,t,t,t,t,t,t,t,t,t,t,`
,,,`,t,t,t,t,t,t,t,t,t,t,t,t,t,t,t,t,t,t,t,t,t,t,t,t,t,t,t,t,t,`
,,,`,t,t,t,t,t,t,t,t,t,t,t,t,t,t,t,t,t,t,t,t,t,t,t,t,t,t,t,t,t,t,t
,,,`,t,t,t,t,t,t,t,t,t,t,t,t,t,t,t,t,t,t,t,t,t,t,t,t,t,t,t,t,t,t,t
,,,`,t,t,t,t,t,t,t,t,t,t,t,t,t,t,t,t,t,t,t,t,t,t,t,t,t,t,t,t,t,t,t
,,,`,t,t,t,t,t,t,t,t,t,t,t,t,t,t,t,t,t,t,t,t,t,t,t,t,t,t,t,t,t,t,t
,,,`,t,t,t,t,t,t,t,t,t,t,t,t,t,t,t,t,t,t,t,t,t,t,t,t,t,t,t,t,t,t,t
,,,`,t,t,t,t,t,t,t,t,t,t,t,t,t,t,t,t,t,t,t,t,t,t,t,t,t,t,t,t,t,t,t
,,,`,t,t,t,t,t,t,t,t,t,t,t,t,t,t,t,t,t,t,t,t,t,t,t,t,t,t,t,t,t,t,t
,,,`,t,t,t,t,t,t,t,t,t,t,t,t,t,t,t,t,t,t,t,t,t,t,t,t,t,t,t,t,t,t,t
,,,`,t,t,t,t,t,t,t,t,t,t,t,t,t,t,t,t,t,t,t,t,t,t,t,t,t,t,t,t,t,t,t
,,,`,t,t,t,t,t,t,t,t,t,t,t,t,t,t,t,t,t,t,t,t,t,t,t,t,t,t,t,t,t,`
,,,,t,t,t,t,t,t,t,t,t,t,t,t,t,t,t,t,t,t,t,t,t,t,t,t,t,t,t,t,t
,,,,,,,,,,,,,,,t,t,t,t,t,t,t

#build label(surface_cover_vents) start(19; 19) hidden() cover the miasma vents



,,,`,,`,`,`,`,`,`,`,`,`,`,`,`,`,`,`,`,`,`,`,`,`,`,`,`,`,`,`,,`
,,,`,,`,,,,,,,,,,,,,,,,,,,,,,,,,,`,,`
,,,`,,`,,,,,,,,,,,,,,,,,,,,,,,,,,`,,`
,,,`,,`,,,,,,,,,,,,,,,,,,,,,,,,,,`,,`
,,,`,,`,,,,,,,,,,,,,,,,,,,,,,,,,,`,,`
,,,`,,`,,,,,,,,,,,,,,,,,,,,,,,,,,`,,`
,,,`,,`,,,,,,,,,,,,,,,,,,,,,,,,,,`,,`
,,,`,,`,,,,,,,,,,,,,,,,,,,,,,,,,,`,,`
,,,`,,`,,,,,,,,,,,,,,,,,,,,,,,,,,`,,`
,,,`,,`,,,,,,,,,,,,,,,,,,,,,,,,,,`,,`
,,,`,,`,,,,,,,,,,,,,,,,,,,,,,,,,,`,,`
,,,`,,`,,,,,,,,,,,,,,,,,,,,,,,,,,`,,`
,,,`,,`,`,`,`,`,Cw,`,`,`,`,`,`,,`,,`,`,`,`,`,Cw,`,`,`,Cw,`,`,,`
,,,`,,`,,`,,,,,,,,`,,,,,,`,,,,,,,,,,`,,`
,,,`,,`,,`,,,,,,,,,,`,`,`,,,,,,,,,,,,`,,`
,,,`,,`,,,,,,,,,,`,,`,~,`,,`,,,,,,,,,,`,,`
,,,`,,`,,`,,,,,,,,,,`,`,`,,,,,,,,,,,,`,,`
,,,`,,`,,`,,,,,,,,`,,,,,,`,,,,,,,,,,`,,`
,,,`,,`,`,`,`,`,`,`,,`,`,`,`,,`,,`,`,`,`,,`,`,`,`,`,`,`,,`
,,,`,,`,,,,,,,,,`,Cf,,,,,,Cf,`,,,,,,,,,`,,`
,,,`,,`,,,,,,,,,Cf,Cf,,,,,,Cf,Cf,,,,,,,,,`,,`
,,,`,,`,,,,,,,,,Cf,Cf,,Cf,Cf,Cf,,Cf,Cf,,,,,,,,,`,,`
,,,`,,`,,,,,,,,,,,,Cf,Cf,Cf,,,,,,,,,,,,`,,`
,,,`,,`,,,,,,,,,Cw,,,Cf,Cf,Cf,,,Cw,,,,,,,,,`,,`
,,,`,,`,`,`,`,`,`,`,`,`,`,,,,,,,,`,`,`,`,`,`,`,`,`,`,,`
,,,`,,,,,,,,,,,,,,,Cf,,,,,,,,,,,,,,,`
,,,`,`,`,`,`,`,`,`,`,`,`,`,,,,,,,,`,`,`,`,`,`,`,`,`,`,`,`



#build label(surface_cover_stairs) start(19; 19) hidden() protect the central stairs



,,,`,,`,`,`,`,`,`,`,`,`,`,`,`,`,`,`,`,`,`,`,`,`,`,`,`,`,`,`,,`
,,,`,,`,,,,,,,,,,,,,,,,,,,,,,,,,,`,,`
,,,`,,`,,,,,,,,,,,,,,,,,,,,,,,,,,`,,`
,,,`,,`,,,,,,,,,,,,,,,,,,,,,,,,,,`,,`
,,,`,,`,,,,,,,,,,,,,,,,,,,,,,,,,,`,,`
,,,`,,`,,,,,,,,,,,,,,,,,,,,,,,,,,`,,`
,,,`,,`,,,,,,,,,,,,,,,,,,,,,,,,,,`,,`
,,,`,,`,,,,,,,,,,,,,,,,,,,,,,,,,,`,,`
,,,`,,`,,,,,,,,,,,,,,,,,,,,,,,,,,`,,`
,,,`,,`,,,,,,,,,,,,,,,,,,,,,,,,,,`,,`
,,,`,,`,,,,,,,,,,,,,,,,,,,,,,,,,,`,,`
,,,`,,`,,,,,,,,,,,,,Cr,,,,,,,,,,,,,`,,`
,,,`,,`,`,`,`,`,`,`,`,`,`,Cw,Cw,Cf,Cw,Cf,Cw,Cw,`,`,`,`,`,`,`,`,`,`,,`
,,,`,,`,,`,,,,,,,,Cw,,,,,,Cw,,,,,,,,,,`,,`
,,,`,,`,,`,,,,,,,,Cf,,`,`,`,,Cf,,,,,,,,,,`,,`
,,,`,,`,,,,,,,,,,Cw,,H,~,H,,Cw,,,,,,,,,,`,,`
,,,`,,`,,`,,,,,,,,Cf,,`,`,`,,Cf,,,,,,,,,,`,,`
,,,`,,`,,`,,,,,,,,Cw,,,,,,Cw,,,,,,,,,,`,,`
,,,`,,`,`,`,`,`,`,`,,`,`,Cw,Cw,Cf,Cw,Cf,Cw,Cw,`,`,,`,`,`,`,`,`,`,,`
,,,`,,`,,,,,,,,,`,,,,,,,,`,,,,,,,,,`,,`
,,,`,,`,,,,,,,,,,,,,,,,,,,,,,,,,,`,,`
,,,`,,`,,,,,,,,,,,,,,,,,,,,,,,,,,`,,`
,,,`,,`,,,,,,,,,,,,,,,,,,,,,,,,,,`,,`
,,,`,,`,,,,,,,,,`,,,,,,,,`,,,,,,,,,`,,`
,,,`,,`,`,`,`,`,`,`,`,`,`,,,,,,,,`,`,`,`,`,`,`,`,`,`,,`
,,,`,,,,,,,,,,,,,,,,,,,,,,,,,,,,,,`
,,,`,`,`,`,`,`,`,`,`,`,`,`,,,,,,,,`,`,`,`,`,`,`,`,`,`,`,`



#<



,,,`,,`,`,`,`,`,`,`,`,`,`,`,`,`,`,`,`,`,`,`,`,`,`,`,`,`,`,`,,`
,,,`,,`,,,,,,,,,,,,,,,,,,,,,,,,,,`,,`
,,,`,,`,,,,,,,,,,,,,,,,,,,,,,,,,,`,,`
,,,`,,`,,,,,,,,,,,,,,,,,,,,,,,,,,`,,`
,,,`,,`,,,,,,,,,,,,,,,,,,,,,,,,,,`,,`
,,,`,,`,,,,,,,,,,,,,,,,,,,,,,,,,,`,,`
,,,`,,`,,,,,,,,,,,,,,,,,,,,,,,,,,`,,`
,,,`,,`,,,,,,,,,,,,,,,,,,,,,,,,,,`,,`
,,,`,,`,,,,,,,,,,,,,,,,,,,,,,,,,,`,,`
,,,`,,`,,,,,,,,,,,,,,,,,,,,,,,,,,`,,`
,,,`,,`,,,,,,,,,,,,,,,,,,,,,,,,,,`,,`
,,,`,,`,,,,,,,,,,,,,,,,,,,,,,,,,,`,,`
,,,`,,`,`,`,`,`,`,`,`,`,`,`,`,Cf,`,Cf,`,`,`,`,`,`,`,`,`,`,`,`,,`
,,,`,,`,,`,,,,,,,,`,Cf,Cf,Cf,Cf,Cf,`,,,,,,,,,,`,,`
,,,`,,`,,`,,,,,,,,Cf,Cf,Cf,Cf,Cf,Cf,Cf,,,,,,,,,,`,,`
,,,`,,`,,,,,,,,,,`,Cf,Cf,Cf,Cf,Cf,`,,,,,,,,,,`,,`
,,,`,,`,,`,,,,,,,,Cf,Cf,Cf,Cf,Cf,Cf,Cf,,,,,,,,,,`,,`
,,,`,,`,,`,,,,,,,,`,Cf,Cf,Cf,Cf,Cf,`,,,,,,,,,,`,,`
,,,`,,`,`,`,`,`,`,`,,`,`,`,`,Cf,`,Cf,`,`,`,`,,`,`,`,`,`,`,`,,`
,,,`,,`,,,,,,,,,`,,,,,,,,`,,,,,,,,,`,,`
,,,`,,`,,,,,,,,,,,,,,,,,,,,,,,,,,`,,`
,,,`,,`,,,,,,,,,,,,,,,,,,,,,,,,,,`,,`
,,,`,,`,,,,,,,,,,,,,,,,,,,,,,,,,,`,,`
,,,`,,`,,,,,,,,,`,,,,,,,,`,,,,,,,,,`,,`
,,,`,,`,`,`,`,`,`,`,`,`,`,,,,,,,,`,`,`,`,`,`,`,`,`,`,,`
,,,`,,,,,,,,,,,,,,,,,,,,,,,,,,,,,,`
,,,`,`,`,`,`,`,`,`,`,`,`,`,,,,,,,,`,`,`,`,`,`,`,`,`,`,`,`



#build label(surface_stairs_doors) start(19; 19) hidden()



,,,`,,`,`,`,`,`,`,`,`,`,`,`,`,`,`,`,`,`,`,`,`,`,`,`,`,`,`,`,,`
,,,`,,`,,,,,,,,,,,,,,,,,,,,,,,,,,`,,`
,,,`,,`,,,,,,,,,,,,,,,,,,,,,,,,,,`,,`
,,,`,,`,,,,,,,,,,,,,,,,,,,,,,,,,,`,,`
,,,`,,`,,,,,,,,,,,,,,,,,,,,,,,,,,`,,`
,,,`,,`,,,,,,,,,,,,,,,,,,,,,,,,,,`,,`
,,,`,,`,,,,,,,,,,,,,,,,,,,,,,,,,,`,,`
,,,`,,`,,,,,,,,,,,,,,,,,,,,,,,,,,`,,`
,,,`,,`,,,,,,,,,,,,,,,,,,,,,,,,,,`,,`
,,,`,,`,,,,,,,,,,,,,,,,,,,,,,,,,,`,,`
,,,`,,`,,,,,,,,,,,,,,,,,,,,,,,,,,`,,`
,,,`,,`,,,,,,,,,,,,,,,,,,,,,,,,,,`,,`
,,,`,,`,`,`,`,`,`,`,`,`,`,`,`,d,`,d,`,`,`,`,`,`,`,`,`,`,`,`,,`
,,,`,,`,,`,,,,,,,,`,,,,,,`,,,,,,,,,,`,,`
,,,`,,`,,`,,,,,,,,d,,`,`,`,,d,,,,,,,,,,`,,`
,,,`,,`,,,,,,,,,,`,,`,`,`,,`,,,,,,,,,,`,,`
,,,`,,`,,`,,,,,,,,d,,`,`,`,,d,,,,,,,,,,`,,`
,,,`,,`,,`,,,,,,,,`,,,,,,`,,,,,,,,,,`,,`
,,,`,,`,`,`,`,`,`,`,,`,`,`,`,d,`,d,`,`,`,`,,`,`,`,`,`,`,`,,`
,,,`,,`,,,,,,,,,`,,,,,,,,`,,,,,,,,,`,,`
,,,`,,`,,,,,,,,,,,,,,,,,,,,,,,,,,`,,`
,,,`,,`,,,,,,,,,,,,,,,,,,,,,,,,,,`,,`
,,,`,,`,,,,,,,,,,,,,,,,,,,,,,,,,,`,,`
,,,`,,`,,,,,,,,,`,,,,,,,,`,,,,,,,,,`,,`
,,,`,,`,`,`,`,`,`,`,`,`,`,,,,,,,,`,`,`,`,`,`,`,`,`,`,,`
,,,`,,,,,,,,,,,,,,,,,,,,,,,,,,,,,,`
,,,`,`,`,`,`,`,`,`,`,`,`,`,,,,,,,,`,`,`,`,`,`,`,`,`,`,`,`



#build label(surface_pre_building) start(19; 19) hidden() flooring and anchoring walls for future buildings/doors



,,,`,,`,`,`,`,`,`,`,`,`,`,`,`,`,`,`,`,`,`,`,`,`,`,`,`,`,`,`,,`
,,,`,,`,,,,,,,,,,,,,,,,,,,,,,,,,,`,,`
,,,`,,`,,,,,,,,,,,,,,,,,,,,,,,,,,`,,`
,,,`,,`,,,,,,,,,,,,,,,,,,,,,,,,,,`,,`
,,,`,,`,,,,,,,,,,,,,,,,,,,,,,,,,,`,,`
,,,`,,`,,,,,,,,,,,,,,,,,,,,,,,,,,`,,`
,,,`,,`,,,,,,,,,,,,,,,,,,,,,,,,,,`,,`
,,,`,,`,,,,,,,,,,,,,,,,,,,,,,,,,,`,,`
,,,`,,`,,,,,,,,,,,,,,,,,,,,,,,,,,`,,`
,,,`,,`,,,,,,,,,,,,,,,,,,,,,,,,,,`,,`
,,,`,,`,,,,,,,,,,,,,,,,,,,,,,,,,,`,,`
,,,`,,`,,,,,,,,,,,,,,,,,,,,,,,,,,`,,`
,,,`,,`,`,`,`,`,`,`,`,`,`,`,`,,`,,`,`,`,`,`,`,`,`,`,`,`,`,,`
,,,`,,`,,`,,,,,,,,`,Cf,,Cf,,Cf,`,,,,,,,,,,`,,`
,,,`,,`,,Cw,,,,,,,,,,`,`,`,,,,,,,,,,,,`,,`
,,,`,,`,,Cf,,,,,,,,`,,`,`,`,,`,,,,,,,,,,`,,`
,,,`,,`,,Cw,,,,,,,,,,`,`,`,,,,,,,,,,,,`,,`
,,,`,,`,,`,,,,,,,,`,Cf,Cf,Cf,Cf,Cf,`,,,,,,,,,,`,,`
,,,`,,`,`,`,`,`,`,Cw,Cf,Cw,`,`,`,,`,,`,`,`,Cw,Cf,Cw,`,`,`,`,`,`,,`
,,,`,,`,Cf,Cf,Cf,Cf,Cf,Cf,Cf,Cf,`,~,,,,,,~,`,,,,,,,Cf,Cf,`,,`
,,,`,,`,Cf,Cf,Cf,Cf,Cf,Cf,Cf,Cf,~,~,Cf,Cf,Cf,Cf,Cf,~,~,,,,,,,,Cf,`,,`
,,,`,,`,Cf,Cf,Cf,Cf,Cf,Cf,Cf,Cf,~,~,,~,~,~,,~,~,,,,,Cf,Cf,,Cf,`,,`
,,,`,,`,,Cf,,Cf,Cf,Cf,Cf,Cf,,Cf,,~,~,~,,Cf,,,,,,,,,Cf,`,,`
,,,`,,`,,Cf,,Cf,Cf,Cf,Cf,Cf,`,,,~,~,~,,,`,,,,,,,Cf,Cf,`,,`
,,,`,,`,`,`,`,`,`,`,`,`,`,,,,,,,,`,`,`,`,`,`,`,`,`,`,,`
,,,`,Cf,,,,,,,,,Cf,,,,,~,,,,,Cf,,,,,,,,,Cf,`
,,,`,`,`,`,`,`,`,`,`,`,`,`,,,,,,,,`,`,`,`,`,`,`,`,`,`,`,`



#<



,,,`,,`,`,`,`,`,`,`,`,`,`,`,`,`,`,`,`,`,`,`,`,`,`,`,`,`,`,`,,`
,,,`,,`,,,,,,,,,,,,,,,,,,,,,,,,,,`,,`
,,,`,,`,,,,,,,,,,,,,,,,,,,,,,,,,,`,,`
,,,`,,`,,,,,,,,,,,,,,,,,,,,,,,,,,`,,`
,,,`,,`,,,,,,,,,,,,,,,,,,,,,,,,,,`,,`
,,,`,,`,,,,,,,,,,,,,,,,,,,,,,,,,,`,,`
,,,`,,`,,,,,,,,,,,,,,,,,,,,,,,,,,`,,`
,,,`,,`,,,,,,,,,,,,,,,,,,,,,,,,,,`,,`
,,,`,,`,,,,,,,,,,,,,,,,,,,,,,,,,,`,,`
,,,`,,`,,,,,,,,,,,,,,,,,,,,,,,,,,`,,`
,,,`,,`,,,,,,,,,,,,,,,,,,,,,,,,,,`,,`
,,,`,,`,,,,,,,,,,,,,~,,,,,,,,,,,,,`,,`
,,,`,,`,`,`,`,`,`,`,`,`,`,`,`,~,`,~,`,`,`,`,`,`,`,`,`,`,`,`,,`
,,,`,,`,,`,,,,,,,,`,~,~,~,~,~,`,,,,,,,,,,`,,`
,,,`,,`,,`,,,,,,,,~,~,~,~,~,~,~,,,,,,,,,,`,,`
,,,`,,`,,,,,,,,,,`,~,~,~,~,~,`,,,,,,,,,,`,,`
,,,`,,`,,`,,,,,,,,~,~,~,~,~,~,~,Cf,Cf,Cf,,,,,,,`,,`
,,,`,,`,,`,,,,,,,,`,~,~,~,~,~,`,,,Cf,,,,,,,`,,`
,,,`,,`,`,`,`,`,`,`,,`,`,`,`,~,`,~,`,`,`,`,Cf,`,`,`,`,`,`,`,,`
,,,`,,`,,,,,,,,,`,,,,,,,,`,,Cf,Cf,Cf,Cf,Cf,Cf,Cf,`,,`
,,,`,,`,,,,,,,,,,,,,,,,,,,,,,,,,Cf,`,,`
,,,`,,`,,,,,,,,,,,,,,,,,,,,,,,,,Cf,`,,`
,,,`,,`,,,,,,,,,,,,,,,,,,,,,,,,,Cf,`,,`
,,,`,,`,,,,,,,,,`,,,,,,,,`,,,,,,,,Cf,`,,`
,,,`,,`,`,`,`,`,`,`,`,`,`,,,,,,,,`,`,`,`,`,`,`,`,`,`,,`
,,,`,,,,,,,,,,,,,,,,,,,,,,,,,,,,,,`
,,,`,`,`,`,`,`,`,`,`,`,`,`,,,,,,,,`,`,`,`,`,`,`,`,`,`,`,`



#place label(surface_place) start(19; 19) hidden() remaining surface stockpiles



,,,`,,`,`,`,`,`,`,`,`,`,`,`,`,`,`,`,`,`,`,`,`,`,`,`,`,`,`,`,,`
,,,`,,`,,,,,,,,,,,,,,,,,,,,,,,,,,`,,`
,,,`,,`,,,,,,,,,,,,,,,,,,,,,,,,,,`,,`
,,,`,,`,,,,,,,,,,,,,,,,,,,,,,,,,,`,,`
,,,`,,`,,,,,,,,,,,,,,,,,,,,,,,,,,`,,`
,,,`,,`,,,,,,,,,,,,,,,,,,,,,,,,,,`,,`
,,,`,,`,,,,,,,,,,,,,,,,,,,,,,,,,,`,,`
,,,`,,`,,,,,,,,,,,,,,,,,,,,,,,,,,`,,`
,,,`,,`,,,,,,,,,,,,,,,,,,,,,,,,,,`,,`
,,,`,,`,,,,,,,,,,,,,,,,,,,,,,,,,,`,,`
,,,`,,`,,,,,,,,,,,,,,,,,,,,,,,,,,`,,`
,,,`,,`,,,,,,,,,,,,,,,,,,,,,,,,,,`,,`
,,,`,,`,`,`,`,`,`,`,`,`,`,`,`,,`,,`,`,`,`,`,`,`,`,`,`,`,`,,`
,,,`,,`,,`,,,,,,,,`,,,,,,`,a5(9x5),,,,,,,,,`,,`
,,,`,,`,,`,,,,,,,,,,`,`,`,,,,,,,,,,,,`,,`
,,,`,,`,,,,,,,,,,`,,`,`,`,,`,,,,,,,,,,`,,`
,,,`,,`,,`,,,,,,,,,,`,`,`,,,,,,,,,,,,`,,`
,,,`,,`,,`,,,,,,,,`,,,,,,`,,,,,,,,,,`,,`
,,,`,,`,`,`,`,`,`,`,,`,`,`,`,,`,,`,`,`,`,,`,`,`,`,`,`,`,,`
,,,`,,`,g(3x3),,,,,,,,`,,,,,,,,`,,,,,,,,,`,,`
,,,`,,`,,,,,,,,,,,,,,,,,,,,,,,,,,`,,`
,,,`,,`,,,,,,,,,,,,,,,,,,,,,,,,,,`,,`
,,,`,,`,,,,,,,,,,,,,,,,,,,,,,,,,,`,,`
,,,`,,`,,c,,,,,,,`,,,,,,,,`,,,,,,,,,`,,`
,,,`,,`,`,`,`,`,`,`,`,`,`,,,,,,,,`,`,`,`,`,`,`,`,`,`,,`
,,,`,,,,,,,,,,,,,,,,,,,,,,,,,,,,,,`
,,,`,`,`,`,`,`,`,`,`,`,`,`,,,,,,,,`,`,`,`,`,`,`,`,`,`,`,`



"#build label(surface_build) start(19; 19) hidden() message(Use autofarm to manage farm crop selection.
Remember to connect the levers to the gates once they are built.) gates, barracks, farm area, and trade area"



,,,`,,`,`,`,`,`,`,`,`,`,`,`,`,`,`,`,`,`,`,`,`,`,`,`,`,`,`,`,,`
,,,`,,`,,,,,,,,,,,,,,,,,,,,,,,,,,`,,`
,,,`,,`,,,,,,,,,,,,,,,,,,,,,,,,,,`,,`
,,,`,,`,,,,,,,,,,,,,,,,,,,,,,,,,,`,,`
,,,`,,`,,,,,,,,,,,,,,,,,,,,,,,,,,`,,`
,,,`,,`,,,,,,,,,,,,,,,,,,,,,,,,,,`,,`
,,,`,,`,,,,,,,,,,,,,,,,,,,,,,,,,,`,,`
,,,`,,`,,,,,,,,,,,,,,,,,,,,,,,,,,`,,`
,,,`,,`,,,,,,,,,,,,,,,,,,,,,,,,,,`,,`
,,,`,,`,,,,,,,,,,,,,,,,,,,,,,,,,,`,,`
,,,`,,`,,,,,,,,,,,,,,,,,,,,,,,,,,`,,`
,,,`,,`,,,,,,,,,,,,,,,,,,,,,,,,,,`,,`
,,,`,,`,`,`,`,`,`,`,`,`,`,`,`,,`,,`,`,`,`,`,`,`,`,`,`,`,`,,`
,,,`,,`,~h,`,~,~,N,N,N,N,N,`,Tl,,Tl,,Tl,`,,,,,,,,,,`,,`
,,,`,,`,~h,`,p(1x1),p(1x1),p(1x1),p(1x1),p(1x1),p(1x1),p(1x1),,,`,`,`,,,,,,,,,,,,`,,`
,,,`,,`,~h,d,p(1x1),p(1x1),p(1x1),p(1x1),p(1x1),p(1x1),p(1x1),`,,`,`,`,,`,,,,,,,,,,`,,`
,,,`,,`,~h,`,p(1x1),p(1x1),p(1x1),p(1x1),p(1x1),p(1x1),p(1x1),,,`,`,`,,,,,,,,,,,,`,,`
,,,`,,`,~h,`,N,N,N,N,N,N,N,`,Tl,Tl,Tl,Tl,Tl,`,,,,,,,,,,`,,`
,,,`,,`,`,`,`,`,`,`,d,`,`,`,`,,`,,`,`,`,`,d,`,`,`,`,`,`,`,,`
,,,`,,`,,,,,,,,,`,,gw,gw,gw,gw,gw,,`,,,,,,,h,b,`,,`
,,,`,,`,,,,,,,,,ga,ga,gw,gw,gw,gw,gw,gd,gd,,,,,,,,b,`,,`
,,,`,,`,,,,,,D,,,ga,ga,,,,,,gd,gd,,,,,a,r,,b,`,,`
,,,`,,`,,trackstopS,,,,,,,ga,ga,,,,,,gd,gd,,,,,,,,b,`,,`
,,,`,,`,,,,,,,,,`,,,,,,,,`,,,,,,,h,b,`,,`
,,,`,,`,`,`,`,`,`,`,`,`,`,,,,,,,,`,`,`,`,`,`,`,`,`,`,,`
,,,`,gd,gd,,,,,,,,gd,gd,,,,,,,,ga,ga,,,,,,,,ga,ga,`
,,,`,`,`,`,`,`,`,`,`,`,`,`,gw,gw,gw,gw,gw,gw,gw,`,`,`,`,`,`,`,`,`,`,`,`
,,,,,,,,,,,,,,,gw,gw,gw,gw,gw,gw,gw
,,,,,,,,,,,,,,,gw,gw,gw,gw,gw,gw,gw

"#query label(surface_query) start(19; 19) hidden() message(Remember to assign a minecart to the trade goods quantum stockpile.
Feel free to adjust the configuration of the ""trade goods"" feeder stockpile so it accepts the item types you want to trade away. If those items types are also accepted by other stockpiles, configure those stockpiles to give to the ""trade goods"" stockpile.
You might also want to set the ""trade goods quantum"" stockpile to Auto Trade if you have the autotrade DFHack plugin enabled.)"



,,,`,,`,`,`,`,`,`,`,`,`,`,`,`,`,`,`,`,`,`,`,`,`,`,`,`,`,`,`,,`
,,,`,,`,,,,,,,,,,,,,,,,,,,,,,,,,,`,,`
,,,`,,`,,,,,,,,,,,,,,,,,,,,,,,,,,`,,`
,,,`,,`,,,,,,,,,,,,,,,,,,,,,,,,,,`,,`
,,,`,,`,,,,,,,,,,,,,,,,,,,,,,,,,,`,,`
,,,`,,`,,,,,,,,,,,,,,,,,,,,,,,,,,`,,`
,,,`,,`,,,,,,,,,,,,,,,,,,,,,,,,,,`,,`
,,,`,,`,,,,,,,,,,,,,,,,,,,,,,,,,,`,,`
,,,`,,`,,,,,,,,,,,,,,,,,,,,,,,,,,`,,`
,,,`,,`,,,,,,,,,,,,,,,,,,,,,,,,,,`,,`
,,,`,,`,,,,,,,,,,,,,,,,,,,,,,,,,,`,,`
,,,`,,`,,,,,,,,,,,,,,,,,,,,,,,,,,`,,`
,,,`,,`,`,`,`,`,`,`,`,`,`,`,`,,`,,`,`,`,`,`,`,`,`,`,`,`,`,,`
,,,`,,`,,`,,,,,,,,`,"{givename name=""trade depo gate""}",,"{givename name=""inner main gate""}",,"{givename name=""barracks gate""}",`,"{givename name=""prison/training area""}",,,,,,,,,`,,`
,,,`,,`,,`,,,,,,,,,,`,`,`,,,forbidcages,,,,,,,,,`,,`
,,,`,,`,,,,,,,,,,`,,`,`,`,,`,forbidtraps,,,,,,,,,`,,`
,,,`,,`,,`,,,,,,,,,,`,`,`,,,,,,,,,,,,`,,`
,,,`,,`,,`,,,,,,,,`,"{givename name=""left outer gate""}","{givename name=""left inner gate""}","{givename name=""outer main gate""}","{givename name=""right inner gate""}","{givename name=""right outer gate""}",`,,,,,,,,,,`,,`
,,,`,,`,`,`,`,`,`,`,,`,`,`,`,,`,,`,`,`,`,,`,`,`,`,`,`,`,,`
,,,`,,`,nocontainers,crafts,,,,,,,`,,,,"{givename name=""inner main gate""}",,,,`,,,,,,,,,`,,`
,,,`,,`,"{givename name=""trade goods""}",,,,,,,,,,,,,,,,,,,,,,,,,`,,`
,,,`,,`,{forbidmasterworkfinishedgoods}{forbidartifactfinishedgoods},,,,,,,,"{givename name=""trade depo gate""}",,,,,,,,"{givename name=""barracks gate""}",,,,,,,,,`,,`
,,,`,,`,,"{quantumstopfromnorth name=""Trade Goods Dumper""}",,,,,,,,,,,,,,,,,,,,,,,,`,,`
,,,`,,`,,"{quantum name=""trade goods quantum""}",,,,,,,`,,,,,,,,`,,,,,,,,,`,,`
,,,`,,`,`,`,`,`,`,`,`,`,`,,,,,,,,`,`,`,`,`,`,`,`,`,`,,`
,,,`,,"{givename name=""left outer gate""}",,,,,,,,,"{givename name=""left inner gate""}",,,,,,,,"{givename name=""right inner gate""}",,,,,,,,,"{givename name=""right outer gate""}",,`
,,,`,`,`,`,`,`,`,`,`,`,`,`,,,,"{givename name=""outer main gate""}",,,,`,`,`,`,`,`,`,`,`,`,`,`



#dig label(surface_clear_large) start(19; 19) hidden() clear wider area of trees

,t,t,t,t,t,t,t,t,t,t,t,t,t,t,t,t,t,t,t,t,t,t,t,t,t,t,t,t,t,t,t,t,t,t,t
,t,t,t,t,t,t,t,t,t,t,t,t,t,t,t,t,t,t,t,t,t,t,t,t,t,t,t,t,t,t,t,t,t,t,t
,t,t,t,t,t,t,t,t,t,t,t,t,t,t,t,t,t,t,t,t,t,t,t,t,t,t,t,t,t,t,t,t,t,t,t
,t,t,t,t,t,t,t,t,t,t,t,t,t,t,t,t,t,t,t,t,t,t,t,t,t,t,t,t,t,t,t,t,t,t,t
,t,t,t,t,t,t,t,t,t,t,t,t,t,t,t,t,t,t,t,t,t,t,t,t,t,t,t,t,t,t,t,t,t,t,t
,t,t,t,t,t,t,t,t,t,t,t,t,t,t,t,t,t,t,t,t,t,t,t,t,t,t,t,t,t,t,t,t,t,t,t
,t,t,t,t,t,t,t,t,t,t,t,t,t,t,t,t,t,t,t,t,t,t,t,t,t,t,t,t,t,t,t,t,t,t,t
,t,t,t,t,t,t,t,t,t,t,t,t,t,t,t,t,t,t,t,t,t,t,t,t,t,t,t,t,t,t,t,t,t,t,t
,t,t,t,t,t,t,t,t,t,t,t,t,t,t,t,t,t,t,t,t,t,t,t,t,t,t,t,t,t,t,t,t,t,t,t
,t,t,t,t,t,t,t,t,t,t,t,t,t,t,t,t,t,t,t,t,t,t,t,t,t,t,t,t,t,t,t,t,t,t,t
,t,t,t,t,t,t,t,t,t,t,t,t,t,t,t,t,t,t,t,t,t,t,t,t,t,t,t,t,t,t,t,t,t,t,t
,t,t,t,t,t,t,t,t,t,t,t,t,t,t,t,t,t,t,t,t,t,t,t,t,t,t,t,t,t,t,t,t,t,t,t
,t,t,t,t,t,t,t,t,t,t,t,t,t,t,t,t,t,t,t,t,t,t,t,t,t,t,t,t,t,t,t,t,t,t,t
,t,t,t,t,t,t,t,t,t,t,t,t,t,t,t,t,t,t,t,t,t,t,t,t,t,t,t,t,t,t,t,t,t,t,t
,t,t,t,t,t,t,t,t,t,t,t,t,t,t,t,t,t,t,t,t,t,t,t,t,t,t,t,t,t,t,t,t,t,t,t
,t,t,t,t,t,t,t,t,t,t,t,t,t,t,t,t,t,t,t,t,t,t,t,t,t,t,t,t,t,t,t,t,t,t,t
,t,t,t,t,t,t,t,t,t,t,t,t,t,t,t,t,t,t,t,t,t,t,t,t,t,t,t,t,t,t,t,t,t,t,t
,t,t,t,t,t,t,t,t,t,t,t,t,t,t,t,t,t,t,t,t,t,t,t,t,t,t,t,t,t,t,t,t,t,t,t
,t,t,t,t,t,t,t,t,t,t,t,t,t,t,t,t,t,t,t,t,t,t,t,t,t,t,t,t,t,t,t,t,t,t,t
,t,t,t,t,t,t,t,t,t,t,t,t,t,t,t,t,t,t,t,t,t,t,t,t,t,t,t,t,t,t,t,t,t,t,t
,t,t,t,t,t,t,t,t,t,t,t,t,t,t,t,t,t,t,t,t,t,t,t,t,t,t,t,t,t,t,t,t,t,t,t
,t,t,t,t,t,t,t,t,t,t,t,t,t,t,t,t,t,t,t,t,t,t,t,t,t,t,t,t,t,t,t,t,t,t,t
,t,t,t,t,t,t,t,t,t,t,t,t,t,t,t,t,t,t,t,t,t,t,t,t,t,t,t,t,t,t,t,t,t,t,t
,t,t,t,t,t,t,t,t,t,t,t,t,t,t,t,t,t,t,t,t,t,t,t,t,t,t,t,t,t,t,t,t,t,t,t
,t,t,t,t,t,t,t,t,t,t,t,t,t,t,t,t,t,t,t,t,t,t,t,t,t,t,t,t,t,t,t,t,t,t,t
,t,t,t,t,t,t,t,t,t,t,t,t,t,t,t,t,t,t,t,t,t,t,t,t,t,t,t,t,t,t,t,t,t,t,t
,t,t,t,t,t,t,t,t,t,t,t,t,t,t,t,t,t,t,t,t,t,t,t,t,t,t,t,t,t,t,t,t,t,t,t
,t,t,t,t,t,t,t,t,t,t,t,t,t,t,t,t,t,t,t,t,t,t,t,t,t,t,t,t,t,t,t,t,t,t,t
,t,t,t,t,t,t,t,t,t,t,t,t,t,t,t,t,t,t,t,t,t,t,t,t,t,t,t,t,t,t,t,t,t,t,t
,t,t,t,t,t,t,t,t,t,t,t,t,t,t,t,t,t,t,t,t,t,t,t,t,t,t,t,t,t,t,t,t,t,t,t
,t,t,t,t,t,t,t,t,t,t,t,t,t,t,t,t,t,t,t,t,t,t,t,t,t,t,t,t,t,t,t,t,t,t,t

#query label(surface_query2) start(19; 19) hidden()



,,,`,,`,`,`,`,`,`,`,`,`,`,`,`,`,`,`,`,`,`,`,`,`,`,`,`,`,`,`,,`
,,,`,,`,,,,,,,,,,,,,,,,,,,,,,,,,,`,,`
,,,`,,`,,,,,,,,,,,,,,,,,,,,,,,,,,`,,`
,,,`,,`,,,,,,,,,,,,,,,,,,,,,,,,,,`,,`
,,,`,,`,,,,,,,,,,,,,,,,,,,,,,,,,,`,,`
,,,`,,`,,,,,,,,,,,,,,,,,,,,,,,,,,`,,`
,,,`,,`,,,,,,,,,,,,,,,,,,,,,,,,,,`,,`
,,,`,,`,,,,,,,,,,,,,,,,,,,,,,,,,,`,,`
,,,`,,`,,,,,,,,,,,,,,,,,,,,,,,,,,`,,`
,,,`,,`,,,,,,,,,,,,,,,,,,,,,,,,,,`,,`
,,,`,,`,,,,,,,,,,,,,,,,,,,,,,,,,,`,,`
,,,`,,`,,,,,,,,,,,,,,,,,,,,,,,,,,`,,`
,,,`,,`,`,`,`,`,`,`,`,`,`,`,`,,`,,`,`,`,`,`,`,`,`,`,`,`,`,,`
,,,`,,`,cg,`,,,,,,,,`,,,,,,`,,,,,,,,,,`,,`
,,,`,,`,cg,`,,,,,,,,,,`,`,`,,,,,,,,,,,,`,,`
,,,`,,`,c,,,,,,,,,`,,`,`,`,,`,,,,,,,,,,`,,`
,,,`,,`,cg,`,,,,,,,,,,`,`,`,,,,,,,,,,,,`,,`
,,,`,,`,cg,`,,,,,,,,`,,,,,,`,,,,,,,,,,`,,`
,,,`,,`,`,`,`,`,`,`,,`,`,`,`,,`,,`,`,`,`,,`,`,`,`,`,`,`,,`
,,,`,,`,,,,,,,,,`,,,,,,,,`,,,,,,,,,`,,`
,,,`,,`,,,,,,,,,,,,,,,,,,,,,,,,,,`,,`
,,,`,,`,,,,,,,,,,,,,,,,,,,,,,,r&,,,`,,`
,,,`,,`,,,,,,,,,,,,,,,,,,,,,,,,,,`,,`
,,,`,,`,,,,,,,,,`,,,,,,,,`,,,,,,,,,`,,`
,,,`,,`,`,`,`,`,`,`,`,`,`,,,,,,,,`,`,`,`,`,`,`,`,`,`,,`
,,,`,,,,,,,,,,,,,,,,,,,,,,,,,,,,,,`
,,,`,`,`,`,`,`,`,`,`,`,`,`,,,,,,,,`,`,`,`,`,`,`,`,`,`,`,`



#build label(surface_walls) start(19; 19) hidden() build remaining walls



,,,`,,Cw,Cw,Cw,Cw,Cw,Cw,Cw,Cw,Cw,Cw,Cw,Cw,Cw,Cw,Cw,Cw,Cw,Cw,Cw,Cw,Cw,Cw,Cw,Cw,Cw,Cw,Cw,,`
,,,`,,Cw,,,,,,,,,,,,,,,,,,,,,,,,,,Cw,,`
,,,`,,Cw,,,,,,,,,,,,,,,,,,,,,,,,,,Cw,,`
,,,`,,Cw,,,,,,,,,,,,,,,,,,,,,,,,,,Cw,,`
,,,`,,Cw,,,,,,,,,,,,,,,,,,,,,,,,,,Cw,,`
,,,`,,Cw,,,,,,,,,,,,,,,,,,,,,,,,,,Cw,,`
,,,`,,Cw,,,,,,,,,,,,,,,,,,,,,,,,,,Cw,,`
,,,`,,Cw,,,,,,,,,,,,,,,,,,,,,,,,,,Cw,,`
,,,`,,Cw,,,,,,,,,,,,,,,,,,,,,,,,,,Cw,,`
,,,`,,Cw,,,,,,,,,,,,,,,,,,,,,,,,,,Cw,,`
,,,`,,Cw,,,,,,,,,,,,,,,,,,,,,,,,,,Cw,,`
,,,`,,Cw,,,,,,,,,,,,,,,,,,,,,,,,,,Cw,,`
,,,`,,Cw,Cw,Cw,Cw,Cw,~,Cw,Cw,Cw,Cw,~,~,,~,,~,~,Cw,Cw,Cw,~,Cw,Cw,Cw,~,Cw,Cw,,`
,,,`,,Cw,,Cw,,,,,,,,~,,,,,,~,,,,,,,,,,Cw,,`
,,,`,,Cw,,~,,,,,,,,,,`,`,`,,,,,,,,,,,,Cw,,`
,,,`,,Cw,,,,,,,,,,~,,`,`,`,,~,,,,,,,,,,Cw,,`
,,,`,,Cw,,~,,,,,,,,,,`,`,`,,,,,,,,,,,,Cw,,`
,,,`,,Cw,,Cw,,,,,,,,~,,,,,,~,,,,,,,,,,Cw,,`
,,,`,,Cw,Cw,Cw,Cw,Cw,Cw,~,,~,Cw,~,~,,~,,~,~,Cw,~,,~,Cw,Cw,Cw,Cw,Cw,Cw,,`
,,,`,,Cw,,,,,,,,,Cw,,,,,,,,Cw,,,,,,,,,Cw,,`
,,,`,,Cw,,,,,,,,,,,,,,,,,,,,,,,,,,Cw,,`
,,,`,,Cw,,,,,,,,,,,,,,,,,,,,,,,,,,Cw,,`
,,,`,,Cw,,,,,,,,,,,,,,,,,,,,,,,,,,Cw,,`
,,,`,,Cw,,,,,,,,,~,,,,,,,,~,,,,,,,,,Cw,,`
,,,`,,Cw,Cw,Cw,Cw,Cw,Cw,Cw,Cw,Cw,Cw,,,,,,,,Cw,Cw,Cw,Cw,Cw,Cw,Cw,Cw,Cw,Cw,,`
,,,`,,,,,,,,,,,,,,,,,,,,,,,,,,,,,,`
,,,`,`,Cw,Cw,Cw,Cw,Cw,Cw,Cw,Cw,Cw,Cw,,,,,,,,Cw,Cw,Cw,Cw,Cw,Cw,Cw,Cw,Cw,Cw,`,`



#build label(surface_floors) start(19; 19) hidden() build remaining flooring



,,,`,,`,`,`,`,`,`,`,`,`,`,`,`,`,`,`,`,`,`,`,`,`,`,`,`,`,`,`,,`
,,,`,,`,,,,,,,,,,,,,,,,,,,,,,,,,,`,,`
,,,`,,`,,,,,,,,,,,,,,,,,,,,,,,,,,`,,`
,,,`,,`,,,,,,,,,,,,,,,,,,,,,,,,,,`,,`
,,,`,,`,,,,,,,,,,,,,,,,,,,,,,,,,,`,,`
,,,`,,`,,,,,,,,,,,,,,,,,,,,,,,,,,`,,`
,,,`,,`,,,,,,,,,,,,,,,,,,,,,,,,,,`,,`
,,,`,,`,,,,,,,,,,,,,,,,,,,,,,,,,,`,,`
,,,`,,`,,,,,,,,,,,,,,,,,,,,,,,,,,`,,`
,,,`,,`,,,,,,,,,,,,,,,,,,,,,,,,,,`,,`
,,,`,,`,,,,,,,,,,,,,,,,,,,,,,,,,,`,,`
,,,`,,`,,,,,,,,,,,,,,,,,,,,,,,,,,`,,`
,,,`,,`,`,`,`,`,`,`,`,`,`,`,`,~,`,~,`,`,`,`,`,`,`,`,`,`,`,`,,`
,,,`,,`,,`,,,,,,,,`,~,Cf,~,Cf,~,`,,,,,,,,,,`,,`
,,,`,,`,,`,,,,,,,,~,Cf,Cf,Cf,Cf,Cf,~,,,,,,,,,,`,,`
,,,`,,`,,~,,,,,,,,`,Cf,`,Cf,`,Cf,`,,,,,,,,,,`,,`
,,,`,,`,,`,,,,,,,,~,Cf,Cf,Cf,Cf,Cf,~,,,,,,,,,,`,,`
,,,`,,`,,`,,,,,,,,`,~,~,~,~,~,`,,,,,,,,,,`,,`
,,,`,,`,`,`,`,`,`,`,~,`,`,`,`,~,`,~,`,`,`,`,~,`,`,`,`,`,`,`,,`
,,,`,,`,~,~,~,~,~,~,~,~,`,~,~,~,~,~,~,~,`,Cf,Cf,Cf,Cf,Cf,Cf,~,~,`,,`
,,,`,,`,~,~,~,~,~,~,~,~,~,~,~,~,~,~,~,~,~,Cf,Cf,Cf,Cf,Cf,Cf,Cf,~,`,,`
,,,`,,`,~,~,~,~,~,~,~,~,~,~,Cf,~,~,~,Cf,~,~,Cf,Cf,Cf,Cf,~,~,Cf,~,`,,`
,,,`,,`,Cf,~,Cf,~,~,~,~,~,~,~,Cf,~,~,~,Cf,~,~,Cf,Cf,Cf,Cf,Cf,Cf,Cf,~,`,,`
,,,`,,`,Cf,~,Cf,~,~,~,~,~,`,Cf,Cf,~,~,~,Cf,Cf,`,Cf,Cf,Cf,Cf,Cf,Cf,~,~,`,,`
,,,`,,`,`,`,`,`,`,`,`,`,`,Cf,Cf,Cf,Cf,Cf,Cf,Cf,`,`,`,`,`,`,`,`,`,`,,`
,,,`,~,,,,,,,,,,,Cf,Cf,Cf,~,Cf,Cf,Cf,,,,,,,,,,,~,`
,,,`,`,`,`,`,`,`,`,`,`,`,`,,,,,,,,`,`,`,`,`,`,`,`,`,`,`,`



#build label(surface_traps) start(19; 19) hidden()



,,,`,,`,`,`,`,`,`,`,`,`,`,`,`,`,`,`,`,`,`,`,`,`,`,`,`,`,`,`,,`
,,,`,,`,,,,,,,,,,,,,,,,,,,,,,,,,,`,,`
,,,`,,`,,,,,,,,,,,,,,,,,,,,,,,,,,`,,`
,,,`,,`,,,,,,,,,,,,,,,,,,,,,,,,,,`,,`
,,,`,,`,,,,,,,,,,,,,,,,,,,,,,,,,,`,,`
,,,`,,`,,,,,,,,,,,,,,,,,,,,,,,,,,`,,`
,,,`,,`,,,,,,,,,,,,,,,,,,,,,,,,,,`,,`
,,,`,,`,,,,,,,,,,,,,,,,,,,,,,,,,,`,,`
,,,`,,`,,,,,,,,,,,,,,,,,,,,,,,,,,`,,`
,,,`,,`,,,,,,,,,,,,,,,,,,,,,,,,,,`,,`
,,,`,,`,,,,,,,,,,,,,,,,,,,,,,,,,,`,,`
,,,`,,`,,,,,,,,,,,,,,,,,,,,,,,,,,`,,`
,,,`,,`,`,`,`,`,`,`,`,`,`,`,`,,`,,`,`,`,`,`,`,`,`,`,`,`,`,,`
,,,`,,`,,`,,,,,,,,`,,,,,,`,,,,,,,,,,`,,`
,,,`,,`,,`,,,,,,,,,,`,`,`,,,,,,,,,,,,`,,`
,,,`,,`,,,,,,,,,,`,,`,`,`,,`,,,,,,,,,,`,,`
,,,`,,`,,`,,,,,,,,,,`,`,`,,,,,,,,,,,,`,,`
,,,`,,`,,`,,,,,,,,`,,,,,,`,,,,,,,,,,`,,`
,,,`,,`,`,`,`,`,`,`,,`,`,`,`,,`,,`,`,`,`,,`,`,`,`,`,`,`,,`
,,,`,,`,,,,,,,,,`,,,,,,,,`,,,,,,,,,`,,`
,,,`,,`,,,,,,,,,,,,,,,,,,,,,,,,,,`,,`
,,,`,,`,,,,,,,,,,,,,,,,,,,,,,,,,,`,,`
,,,`,,`,,,,,,,,,,,,,,,,,,,,,,,,,,`,,`
,,,`,,`,,,,,,,,,`,,,,,,,,`,,,,,,,,,`,,`
,,,`,,`,`,`,`,`,`,`,`,`,`,,,,,,,,`,`,`,`,`,`,`,`,`,`,,`
,,,`,,,Tc,Tc,Tc,Tc,Tc,Tc,Tc,,,,,,,,,,,,Tc,Tc,Tc,Tc,Tc,Tc,Tc,,,`
,,,`,`,`,`,`,`,`,`,`,`,`,`,,,,,,,,`,`,`,`,`,`,`,`,`,`,`,`
,,,,,,,,,,,,,Tc,Tc,,,,,,,,Tc,Tc
,,,,,,,,,,,,,Tc,Tc,,,,,,,,Tc,Tc

#build label(surface_roof) start(19; 19) hidden() lower half of the roof



,,,`,,`,`,`,`,`,`,`,`,`,`,`,`,`,`,`,`,`,`,`,`,`,`,`,`,`,`,`,,`
,,,`,,`,,,,,,,,,,,,,,,,,,,,,,,,,,`,,`
,,,`,,`,,,,,,,,,,,,,,,,,,,,,,,,,,`,,`
,,,`,,`,,,,,,,,,,,,,,,,,,,,,,,,,,`,,`
,,,`,,`,,,,,,,,,,,,,,,,,,,,,,,,,,`,,`
,,,`,,`,,,,,,,,,,,,,,,,,,,,,,,,,,`,,`
,,,`,,`,,,,,,,,,,,,,,,,,,,,,,,,,,`,,`
,,,`,,`,,,,,,,,,,,,,,,,,,,,,,,,,,`,,`
,,,`,,`,,,,,,,,,,,,,,,,,,,,,,,,,,`,,`
,,,`,,`,,,,,,,,,,,,,,,,,,,,,,,,,,`,,`
,,,`,,`,,,,,,,,,,,,,,,,,,,,,,,,,,`,,`
,,,`,,`,,,,,,,,,,,,,~,,,,,,,,,,,,,`,,`
,,,`,,`,`,`,`,`,`,`,`,`,`,`,`,~,`,~,`,`,`,`,`,`,`,`,`,`,`,`,,`
,,,`,,`,Cf,`,Cf,Cf,Cf,Cf,Cf,Cf,Cf,`,~,~,~,~,~,`,Cf,Cf,Cf,Cf,Cf,Cf,Cf,Cf,Cf,`,,`
,,,`,,`,Cf,`,Cf,Cf,Cf,Cf,Cf,Cf,Cf,~,~,~,~,~,~,~,Cf,Cf,Cf,Cf,Cf,Cf,Cf,Cf,Cf,`,,`
,,,`,,`,Cf,Cf,Cf,Cf,Cf,Cf,Cf,Cf,Cf,`,~,~,~,~,~,`,Cf,Cf,Cf,Cf,Cf,Cf,Cf,Cf,Cf,`,,`
,,,`,,`,Cf,`,Cf,Cf,Cf,Cf,Cf,Cf,Cf,~,~,~,~,~,~,~,~,~,~,Cf,Cf,Cf,Cf,Cf,Cf,`,,`
,,,`,,`,Cf,`,Cf,Cf,Cf,Cf,Cf,Cf,Cf,`,~,~,~,~,~,`,Cf,Cf,~,Cf,Cf,Cf,Cf,Cf,Cf,`,,`
,,,`,,`,`,`,`,`,`,`,Cf,`,`,`,`,~,`,~,`,`,`,`,~,`,`,`,`,`,`,`,,`
,,,`,,`,Cf,Cf,Cf,Cf,Cf,Cf,Cf,Cf,`,Cf,Cf,Cf,Cf,Cf,Cf,Cf,`,Cf,~,~,~,~,~,~,~,`,,`
,,,`,,`,Cf,Cf,Cf,Cf,Cf,Cf,Cf,Cf,Cf,Cf,Cf,Cf,Cf,Cf,Cf,Cf,Cf,Cf,Cf,Cf,Cf,Cf,Cf,Cf,~,`,,`
,,,`,,`,Cf,Cf,Cf,Cf,Cf,Cf,Cf,Cf,Cf,Cf,Cf,Cf,Cf,Cf,Cf,Cf,Cf,Cf,Cf,Cf,Cf,Cf,Cf,Cf,~,`,,`
,,,`,,`,Cf,Cf,Cf,Cf,Cf,Cf,Cf,Cf,Cf,Cf,Cf,Cf,Cf,Cf,Cf,Cf,Cf,Cf,Cf,Cf,Cf,Cf,Cf,Cf,~,`,,`
,,,`,,`,Cf,Cf,Cf,Cf,Cf,Cf,Cf,Cf,`,Cf,Cf,Cf,Cf,Cf,Cf,Cf,`,Cf,Cf,Cf,Cf,Cf,Cf,Cf,~,`,,`
,,,`,,`,`,`,`,`,`,`,`,`,`,Cf,Cf,Cf,Cf,Cf,Cf,Cf,`,`,`,`,`,`,`,`,`,`,,`
,,,`,,Cf,Cf,Cf,Cf,Cf,Cf,Cf,Cf,Cf,Cf,Cf,Cf,Cf,Cf,Cf,Cf,Cf,Cf,Cf,Cf,Cf,Cf,Cf,Cf,Cf,Cf,Cf,,`
,,,`,`,`,`,`,`,`,`,`,`,`,`,Cf,Cf,Cf,Cf,Cf,Cf,Cf,`,`,`,`,`,`,`,`,`,`,`,`



#build label(surface_roof2) start(19; 19) hidden() upper half of the roof



,,,`,,`,`,`,`,`,`,`,`,`,`,`,`,`,`,`,`,`,`,`,`,`,`,`,`,`,`,`,,`
,,,`,,`,Cf,Cf,Cf,Cf,Cf,Cf,Cf,Cf,Cf,Cf,Cf,Cf,Cf,Cf,Cf,Cf,Cf,Cf,Cf,Cf,Cf,Cf,Cf,Cf,Cf,`,,`
,,,`,,`,Cf,Cf,Cf,Cf,Cf,Cf,Cf,Cf,Cf,Cf,Cf,Cf,Cf,Cf,Cf,Cf,Cf,Cf,Cf,Cf,Cf,Cf,Cf,Cf,Cf,`,,`
,,,`,,`,Cf,Cf,Cf,Cf,Cf,Cf,Cf,Cf,Cf,Cf,Cf,Cf,Cf,Cf,Cf,Cf,Cf,Cf,Cf,Cf,Cf,Cf,Cf,Cf,Cf,`,,`
,,,`,,`,Cf,Cf,Cf,Cf,Cf,Cf,Cf,Cf,Cf,Cf,Cf,Cf,Cf,Cf,Cf,Cf,Cf,Cf,Cf,Cf,Cf,Cf,Cf,Cf,Cf,`,,`
,,,`,,`,Cf,Cf,Cf,Cf,Cf,Cf,Cf,Cf,Cf,Cf,Cf,Cf,Cf,Cf,Cf,Cf,Cf,Cf,Cf,Cf,Cf,Cf,Cf,Cf,Cf,`,,`
,,,`,,`,Cf,Cf,Cf,Cf,Cf,Cf,Cf,Cf,Cf,Cf,Cf,Cf,Cf,Cf,Cf,Cf,Cf,Cf,Cf,Cf,Cf,Cf,Cf,Cf,Cf,`,,`
,,,`,,`,Cf,Cf,Cf,Cf,Cf,Cf,Cf,Cf,Cf,Cf,Cf,Cf,Cf,Cf,Cf,Cf,Cf,Cf,Cf,Cf,Cf,Cf,Cf,Cf,Cf,`,,`
,,,`,,`,Cf,Cf,Cf,Cf,Cf,Cf,Cf,Cf,Cf,Cf,Cf,Cf,Cf,Cf,Cf,Cf,Cf,Cf,Cf,Cf,Cf,Cf,Cf,Cf,Cf,`,,`
,,,`,,`,Cf,Cf,Cf,Cf,Cf,Cf,Cf,Cf,Cf,Cf,Cf,Cf,Cf,Cf,Cf,Cf,Cf,Cf,Cf,Cf,Cf,Cf,Cf,Cf,Cf,`,,`
,,,`,,`,Cf,Cf,Cf,Cf,Cf,Cf,Cf,Cf,Cf,Cf,Cf,Cf,Cf,Cf,Cf,Cf,Cf,Cf,Cf,Cf,Cf,Cf,Cf,Cf,Cf,`,,`
,,,`,,`,Cf,Cf,Cf,Cf,Cf,Cf,Cf,Cf,Cf,Cf,Cf,Cf,H,Cf,Cf,Cf,Cf,Cf,Cf,Cf,Cf,Cf,Cf,Cf,Cf,`,,`
,,,`,,`,`,`,`,`,`,`,`,`,`,`,`,~,`,~,`,`,`,`,`,`,`,`,`,`,`,`,,`
,,,`,,`,~,`,~,~,~,~,~,~,~,`,~,~,~,~,~,`,~,~,~,~,~,~,~,~,~,`,,`
,,,`,,`,~,`,~,~,~,~,~,~,~,~,~,~,~,~,~,~,~,~,~,~,~,~,~,~,~,`,,`
,,,`,,`,~,~,~,~,~,~,~,~,~,`,~,~,~,~,~,`,~,~,~,~,~,~,~,~,~,`,,`
,,,`,,`,~,`,~,~,~,~,~,~,~,~,~,~,~,~,~,~,~,~,~,~,~,~,~,~,~,`,,`
,,,`,,`,~,`,~,~,~,~,~,~,~,`,~,~,~,~,~,`,~,~,~,~,~,~,~,~,~,`,,`
,,,`,,`,`,`,`,`,`,`,~,`,`,`,`,~,`,~,`,`,`,`,~,`,`,`,`,`,`,`,,`
,,,`,,`,~,~,~,~,~,~,~,~,`,~,~,~,~,~,~,~,`,~,~,~,~,~,~,~,~,`,,`
,,,`,,`,~,~,~,~,~,~,~,~,~,~,~,~,~,~,~,~,~,~,~,~,~,~,~,~,~,`,,`
,,,`,,`,~,~,~,~,~,~,~,~,~,~,~,~,~,~,~,~,~,~,~,~,~,~,~,~,~,`,,`
,,,`,,`,~,~,~,~,~,~,~,~,~,~,~,~,~,~,~,~,~,~,~,~,~,~,~,~,~,`,,`
,,,`,,`,~,~,~,~,~,~,~,~,`,~,~,~,~,~,~,~,`,~,~,~,~,~,~,~,~,`,,`
,,,`,,`,`,`,`,`,`,`,`,`,`,~,~,~,~,~,~,~,`,`,`,`,`,`,`,`,`,`,,`
,,,`,,~,~,~,~,~,~,~,~,~,~,~,~,~,~,~,~,~,~,~,~,~,~,~,~,~,~,~,,`
,,,`,`,`,`,`,`,`,`,`,`,`,`,~,~,~,~,~,~,~,`,`,`,`,`,`,`,`,`,`,`,`



#build label(surface_corridor) start(19; 19) hidden() trap hallway walls



,,,Cw,,`,`,`,`,`,`,`,`,`,`,`,`,`,`,`,`,`,`,`,`,`,`,`,`,`,`,`,,Cw
,,,Cw,,`,,,,,,,,,,,,,,,,,,,,,,,,,,`,,Cw
,,,Cw,,`,,,,,,,,,,,,,,,,,,,,,,,,,,`,,Cw
,,,Cw,,`,,,,,,,,,,,,,,,,,,,,,,,,,,`,,Cw
,,,Cw,,`,,,,,,,,,,,,,,,,,,,,,,,,,,`,,Cw
,,,Cw,,`,,,,,,,,,,,,,,,,,,,,,,,,,,`,,Cw
,,,Cw,,`,,,,,,,,,,,,,,,,,,,,,,,,,,`,,Cw
,,,Cw,,`,,,,,,,,,,,,,,,,,,,,,,,,,,`,,Cw
,,,Cw,,`,,,,,,,,,,,,,,,,,,,,,,,,,,`,,Cw
,,,Cw,,`,,,,,,,,,,,,,,,,,,,,,,,,,,`,,Cw
,,,Cw,,`,,,,,,,,,,,,,,,,,,,,,,,,,,`,,Cw
,,,Cw,,`,,,,,,,,,,,,,,,,,,,,,,,,,,`,,Cw
,,,Cw,,`,`,`,`,`,`,`,`,`,`,`,`,,`,,`,`,`,`,`,`,`,`,`,`,`,`,,Cw
,,,Cw,,`,,`,,,,,,,,`,,,,,,`,,,,,,,,,,`,,Cw
,,,Cw,,`,,`,,,,,,,,,,`,`,`,,,,,,,,,,,,`,,Cw
,,,Cw,,`,,,,,,,,,,`,,`,`,`,,`,,,,,,,,,,`,,Cw
,,,Cw,,`,,`,,,,,,,,,,`,`,`,,,,,,,,,,,,`,,Cw
,,,Cw,,`,,`,,,,,,,,`,,,,,,`,,,,,,,,,,`,,Cw
,,,Cw,,`,`,`,`,`,`,`,,`,`,`,`,,`,,`,`,`,`,,`,`,`,`,`,`,`,,Cw
,,,Cw,,`,,,,,,,,,`,,,,,,,,`,,,,,,,,,`,,Cw
,,,Cw,,`,,,,,,,,,,,,,,,,,,,,,,,,,,`,,Cw
,,,Cw,,`,,,,,,,,,,,,,,,,,,,,,,,,,,`,,Cw
,,,Cw,,`,,,,,,,,,,,,,,,,,,,,,,,,,,`,,Cw
,,,Cw,,`,,,,,,,,,`,,,,,,,,`,,,,,,,,,`,,Cw
,,,Cw,,`,`,`,`,`,`,`,`,`,`,,,,,,,,`,`,`,`,`,`,`,`,`,`,,Cw
,,,Cw,,,,,,,,,,,,,,,,,,,,,,,,,,,,,,Cw
,,,Cw,Cw,`,`,`,`,`,`,`,`,`,`,,,,,,,,`,`,`,`,`,`,`,`,`,`,Cw,Cw



#<



,,,`,Cf,`,`,`,`,`,`,`,`,`,`,`,`,`,`,`,`,`,`,`,`,`,`,`,`,`,`,`,Cf,`
,,,`,Cf,`,~,~,~,~,~,~,~,~,~,~,~,~,~,~,~,~,~,~,~,~,~,~,~,~,~,`,Cf,`
,,,`,Cf,`,~,~,~,~,~,~,~,~,~,~,~,~,~,~,~,~,~,~,~,~,~,~,~,~,~,`,Cf,`
,,,`,Cf,`,~,~,~,~,~,~,~,~,~,~,~,~,~,~,~,~,~,~,~,~,~,~,~,~,~,`,Cf,`
,,,`,Cf,`,~,~,~,~,~,~,~,~,~,~,~,~,~,~,~,~,~,~,~,~,~,~,~,~,~,`,Cf,`
,,,`,Cf,`,~,~,~,~,~,~,~,~,~,~,~,~,~,~,~,~,~,~,~,~,~,~,~,~,~,`,Cf,`
,,,`,Cf,`,~,~,~,~,~,~,~,~,~,~,~,~,~,~,~,~,~,~,~,~,~,~,~,~,~,`,Cf,`
,,,`,Cf,`,~,~,~,~,~,~,~,~,~,~,~,~,~,~,~,~,~,~,~,~,~,~,~,~,~,`,Cf,`
,,,`,Cf,`,~,~,~,~,~,~,~,~,~,~,~,~,~,~,~,~,~,~,~,~,~,~,~,~,~,`,Cf,`
,,,`,Cf,`,~,~,~,~,~,~,~,~,~,~,~,~,~,~,~,~,~,~,~,~,~,~,~,~,~,`,Cf,`
,,,`,Cf,`,~,~,~,~,~,~,~,~,~,~,~,~,~,~,~,~,~,~,~,~,~,~,~,~,~,`,Cf,`
,,,`,Cf,`,~,~,~,~,~,~,~,~,~,~,~,~,~,~,~,~,~,~,~,~,~,~,~,~,~,`,Cf,`
,,,`,Cf,`,`,`,`,`,`,`,`,`,`,`,`,~,`,~,`,`,`,`,`,`,`,`,`,`,`,`,Cf,`
,,,`,Cf,`,~,`,~,~,~,~,~,~,~,`,~,~,~,~,~,`,~,~,~,~,~,~,~,~,~,`,Cf,`
,,,`,Cf,`,~,`,~,~,~,~,~,~,~,~,~,~,~,~,~,~,~,~,~,~,~,~,~,~,~,`,Cf,`
,,,`,Cf,`,~,~,~,~,~,~,~,~,~,`,~,~,~,~,~,`,~,~,~,~,~,~,~,~,~,`,Cf,`
,,,`,Cf,`,~,`,~,~,~,~,~,~,~,~,~,~,~,~,~,~,~,~,~,~,~,~,~,~,~,`,Cf,`
,,,`,Cf,`,~,`,~,~,~,~,~,~,~,`,~,~,~,~,~,`,~,~,~,~,~,~,~,~,~,`,Cf,`
,,,`,Cf,`,`,`,`,`,`,`,~,`,`,`,`,~,`,~,`,`,`,`,~,`,`,`,`,`,`,`,Cf,`
,,,`,Cf,`,~,~,~,~,~,~,~,~,`,~,~,~,~,~,~,~,`,~,~,~,~,~,~,~,~,`,Cf,`
,,,`,Cf,`,~,~,~,~,~,~,~,~,~,~,~,~,~,~,~,~,~,~,~,~,~,~,~,~,~,`,Cf,`
,,,`,Cf,`,~,~,~,~,~,~,~,~,~,~,~,~,~,~,~,~,~,~,~,~,~,~,~,~,~,`,Cf,`
,,,`,Cf,`,~,~,~,~,~,~,~,~,~,~,~,~,~,~,~,~,~,~,~,~,~,~,~,~,~,`,Cf,`
,,,`,Cf,`,~,~,~,~,~,~,~,~,`,~,~,~,~,~,~,~,`,~,~,~,~,~,~,~,~,`,Cf,`
,,,`,Cf,`,`,`,`,`,`,`,`,`,`,~,~,~,~,~,~,~,`,`,`,`,`,`,`,`,`,`,Cf,`
,,,`,Cf,~,~,~,~,~,~,~,~,~,~,~,~,~,~,~,~,~,~,~,~,~,~,~,~,~,~,~,Cf,`
,,,`,`,`,`,`,`,`,`,`,`,`,`,~,~,~,~,~,~,~,`,`,`,`,`,`,`,`,`,`,`,`



"#build label(surface_corridor_traps) start(19; 19) hidden() barracks, longer trap hallways, and outer levers/gates"


,,,,gx,,,,,,,,,,,,,,,,,,,,,,,,,,,,gx
,,,`,gx,`,`,`,`,`,`,`,`,`,`,`,`,`,`,`,`,`,`,`,`,`,`,`,`,`,`,`,gx,`
,,,`,Tc,`,,,,,,,,,,,,,,,,,,,,,,,,,,`,Tc,`
,,,`,Tc,`,,,,,,,,,,,,,,,,,,,,,,,,,,`,Tc,`
,,,`,Tc,`,,,,,,,,,,,,,,,,,,,,,,,,,,`,Tc,`
,,,`,Tc,`,,,,,,,,,,,,,,,,,,,,,,,,,,`,Tc,`
,,,`,Tc,`,,,,,,,,,,,,,,,,,,,,,,,,,,`,Tc,`
,,,`,Tc,`,,,,,,,,,,,,,,,,,,,,,,,,,,`,Tc,`
,,,`,Tc,`,,,,,,,,,,,,,,,,,,,,,,,,,,`,Tc,`
,,,`,Tc,`,,,,,,,,,,,,,,,,,,,,,,,,,,`,Tc,`
,,,`,Tc,`,,,,,,,,,,,,,,,,,,,,,,,,,,`,Tc,`
,,,`,Tc,`,,,,,,,,,,,,,,,,,,,,,,,,,,`,Tc,`
,,,`,Tc,`,,,,,,,,,,,,,,,,,,,,,,,,,,`,Tc,`
,,,`,Tc,`,`,`,`,`,`,`,`,`,`,`,`,,`,,`,`,`,`,`,`,`,`,`,`,`,`,Tc,`
,,,`,Tc,`,,`,,,,,,,,`,,,,,,`,,,,,,,,,,`,Tc,`
,,,`,Tc,`,,`,,,,,,,,,,`,`,`,,,,,,,,,,,,`,Tc,`
,,,`,Tc,`,,,,,,,,,,`,Tl,`,`,`,Tl,`,,,,,,,,,,`,Tc,`
,,,`,Tc,`,,`,,,,,,,,,,`,`,`,,,,,,,,,,,,`,Tc,`
,,,`,Tc,`,,`,,,,,,,,`,,,,,,`,,,,,,,,,,`,Tc,`
,,,`,Tc,`,`,`,`,`,`,`,,`,`,`,`,,`,,`,`,`,`,,`,`,`,`,`,`,`,Tc,`
,,,`,Tc,`,,,,,,,,,`,,,,,,,,`,,,,,,,,,`,Tc,`
,,,`,Tc,`,,,,,,,,,,,,,,,,,,,,,,,,,,`,Tc,`
,,,`,Tc,`,,,,,,,,,,,,,,,,,,,,,,,,,,`,Tc,`
,,,`,Tc,`,,,,,,,,,,,,,,,,,,,,,,,,,,`,Tc,`
,,,`,Tc,`,,,,,,,,,`,,,,,,,,`,,,,,,,,,`,Tc,`
,,,`,Tc,`,`,`,`,`,`,`,`,`,`,,,,,,,,`,`,`,`,`,`,`,`,`,`,Tc,`
,,,`,,,,,,,,,,,,,,,,,,,,,,,,,,,,,,`
,,,`,`,`,`,`,`,`,`,`,`,`,`,,,,,,,,`,`,`,`,`,`,`,`,`,`,`,`



#query label(surface_query_corridor) start(19; 19) hidden() (Remember to connect the levers to the new external trap gates.) configure barracks and name outer levers/gates



,,,`,"{givename name=""left trap gate""}",`,`,`,`,`,`,`,`,`,`,`,`,`,`,`,`,`,`,`,`,`,`,`,`,`,`,`,"{givename name=""right trap gate""}",`
,,,`,,`,,,,,,,,,,,,,,,,,,,,,,,,,,`,,`
,,,`,,`,,,,,,,,,,,,,,,,,,,,,,,,,,`,,`
,,,`,,`,,,,,,,,,,,,,,,,,,,,,,,,,,`,,`
,,,`,,`,,,,,,,,,,,,,,,,,,,,,,,,,,`,,`
,,,`,,`,,,,,,,,,,,,,,,,,,,,,,,,,,`,,`
,,,`,,`,,,,,,,,,,,,,,,,,,,,,,,,,,`,,`
,,,`,,`,,,,,,,,,,,,,,,,,,,,,,,,,,`,,`
,,,`,,`,,,,,,,,,,,,,,,,,,,,,,,,,,`,,`
,,,`,,`,,,,,,,,,,,,,,,,,,,,,,,,,,`,,`
,,,`,,`,,,,,,,,,,,,,,,,,,,,,,,,,,`,,`
,,,`,,`,,,,,,,,,,,,,,,,,,,,,,,,,,`,,`
,,,`,,`,`,`,`,`,`,`,`,`,`,`,`,,`,,`,`,`,`,`,`,`,`,`,`,`,`,,`
,,,`,,`,,`,,,,,,,,`,,,,,,`,,,,,,,,,,`,,`
,,,`,,`,,`,,,,,,,,,,`,`,`,,,,,,,,,,,,`,,`
,,,`,,`,,,,,,,,,,`,"{givename name=""left trap gate""}",`,`,`,"{givename name=""right trap gate""}",`,,,,,,,,,,`,,`
,,,`,,`,,`,,,,,,,,,,`,`,`,,,,,,,,,,,,`,,`
,,,`,,`,,`,,,,,,,,`,,,,,,`,,,,,,,,,,`,,`
,,,`,,`,`,`,`,`,`,`,,`,`,`,`,,`,,`,`,`,`,,`,`,`,`,`,`,`,,`
,,,`,,`,,,,,,,,,`,,,,,,,,`,,,,,,,,,`,,`
,,,`,,`,,,,,,,,,,,,,,,,,,,,,,,,,,`,,`
,,,`,,`,,,,,,,,,,,,,,,,,,,,,,,,,,`,,`
,,,`,,`,,,,,,,,,,,,,,,,,,,,,,,,,,`,,`
,,,`,,`,,,,,,,,,`,,,,,,,,`,,,,,,,,,`,,`
,,,`,,`,`,`,`,`,`,`,`,`,`,,,,,,,,`,`,`,`,`,`,`,`,`,`,,`
,,,`,,,,,,,,,,,,,,,,,,,,,,,,,,,,,,`
,,,`,`,`,`,`,`,`,`,`,`,`,`,,,,,,,,`,`,`,`,`,`,`,`,`,`,`,`



#notes label(farming_help)
"Sets up farming, food storage, and related industries. Also provides post-embark necessities that can later be disassembed."
""
Features:
- Pairs with the surface blueprints to provide miasma vents
- Farm plots (intended to be managed by DFHack autofarm)
- Plentiful food storage
- Refuse/corpse quantum stockpile
- Small dormitory and dining room for post-embark needs
- Small offices for your manager and bookkeeper
""
Workshops:
- Kitchen
- Brewery
- Butcher
- Fishery
- Tannery
- Farmer's Workshop
- Quern
- Screw Press
""
Manual steps you have to take:
- Assign the lower office to your manager and the upper office to your bookkeeper (if different from your manager)
- Assign a minecart to your refuse quantum stockpile hauling route
"- If the industry level is already built, configure the jugs, pots, and bags stockpiles to take from the ""Goods"" quantum stockpile on the industry level"
""
Farming Walkthough:
"1) Wait until you have channeled the miasma vents and cleared trees on the surface before digging out the farming level on the z-level below the surface, otherwise you will end up with extra ramps on the farming level and unprotected holes through the surface when you later chop down trees growing above empty space."
""
"2) Start digging with /farming1 and get started on manufacturing furniture by running ""quickfort orders"" on /farming2 and /farming3."
""
"3) Once the level is dug out, run /farming2 to build workshops, stockpiles, and the furniture we need to declare the rooms. Remember to assign a minecart to the newly-designated quantum refuse dump. There are also jugs, pots, and bags stockpiles on this level that should be configured to ""take"" from the industry level stockpiles once we get the industry level built."
""
"4) When the furniture is in place, run /farming3 to designate your starter dining room and dormitory and build the farm plots and remaining furniture. The blueprint also attempts to assign the lower office to your manager, but double-check this assignment in case your dwarves are in an unexpected order."
""
"5) Once your fort has enough free time to build the remaining doors, run /farming4. This will also enable seasonal fertilization for your farm plots. Run ""quickfort orders"" for /farming4."
""
"6) You can disassemble the dining room and dormitory once the services and apartments levels are up and running, if you like."
"#dig label(farming1) start(16; 18; central stairs) message(This would be a good time to queue up manager orders for /farming2. Once the area is dug out, continue with /farming2.)"
# this level is dug at priority 2 since it is dug in soil. it's worth the miner's time to stop digging the industry level and
# quickly dig out this one.
,,,,,,,,,2,2,2,,2,2,2,2,2,,2,2,2,2
,,,,,,,,,2,2,2,,2,2,2,2,2,,2,2,2,2
,,,,,,,,,2,2,2,,2,2,2,2,2,,2,2,2,2
,,,,,,,,,,,2,,2,2,2,2,2,,2,2,2,2
,,,,,,,2,2,2,,2,,2,2,2,2,2,,2,2,2,2
,,,,,,,2,2,2,2,2,,2,2,2,2,2,,2,2,2,2
,,,,,,,2,2,2,,2,,2,2,2,2,2,,2
,,,,,,,,,,,2,,2,2,2,2,2,,2,,2,2,2
,,,,,,2,2,2,2,,2,,2,2,2,2,2,,2,2,2,2,2
,,,,,,2,2,2,2,,2,,2,2,2,2,2,,2,,2,2,2
,,,2,2,,2,2,2,2,,2,,2,2,2,2,2,,2
,,2,2,2,,2,2,2,2,,2,,2,2,2,2,2,,2,,2,2,2,,2,2,2
,,2,2,2,2,2,z2,2,2,2,2,,,2,,2,,,2,2,2,z2,2,2,2,z2,2
,,,2,2,,2,2,2,2,,2,2,2,2,2,2,2,2,2,,2,2,2,,2,2,2
,,,,2,,,2,,,,,,2,`,`,`,2,,,,,2,,,,2
,,2,2,2,2,2,2,2,2,2,2,,2,`,~,`,2,,2,2,2,2,2,2,2,2,2,2
,,2,2,2,2,2,2,2,2,2,2,2,2,`,`,`,2,2,2,2,2,2,2,2,2,2,2,2
,,2,2,2,2,2,2,2,2,2,2,,2,2,2,2,2,,2,2,2,2,2,2,2,2,2,2
,,2,2,2,2,2,2,2,2,2,,,,2,,2,,,,2,2,2,2,2,2,2,2,2
,,2,2,2,2,2,2,2,2,,,z2,2,2,2,2,2,z2,,,2,2,2,2,2,2,2,2
,,2,2,2,2,2,2,2,2,,z2,z2,,,2,,,z2,z2,,2,2,2,2,2,2,2,2
,,2,2,2,2,2,2,2,,,z2,z2,,z2,z2,z2,,z2,z2,,,2,2,2,2,2,2,2
,,2,2,2,2,2,2,2,,2,2,2,,z2,z2,z2,,2,2,2,,2,2,2,2,2,2,2
,,2,2,2,2,2,2,2,,2,z2,2,,z2,z2,z2,,2,z2,2,,2,2,2,2,2,2,2
,,2,2,2,2,2,2,2,,2,2,2,,,2,,,2,2,2,,2,2,2,2,2,2,2
,,,,,,,,,,,,,,,z2


"#meta label(farming2) start(central stairs) message(Once furniture has been placed, continue with /farming3.) workshops, stockpiles, and important furniture"
build/farming_build
place/farming_place
query_stockpiles/farming_query_stockpiles
""
#meta label(farming3) start(central stairs) configure rooms and build farm plots and more furniture
query_rooms/farming_rooms
build2/farming_build2
""
#meta label(farming4) start(central stairs) configure farm plots and build remaining furniture
query_plots/farming_query_plots
build3/farming_build3
#build label(farming_build) start(16; 18) hidden() workshops and important furniture


,,,,,,,,,`,`,`,,`,`,`,`,`,,`,`,`,`
,,,,,,,,,c,t,`,,`,`,`,`,`,,`,`,`,`
,,,,,,,,,`,`,`,,`,`,`,`,`,,`,`,t,c
,,,,,,,,,,,`,,`,`,`,`,`,,`,`,`,`
,,,,,,,`,`,`,,`,,`,`,`,`,`,,`,`,`,`
,,,,,,,c,t,`,`,`,,`,`,`,`,`,,`,`,`,`
,,,,,,,`,`,`,,`,,`,`,`,`,`,,`
,,,,,,,,,,,`,,`,`,`,`,`,,`,,`,`,b
,,,,,,`,`,`,`,,`,,`,`,`,`,`,,`,`,`,`,`
,,,,,,`,wl,`,`,,`,,`,`,`,`,`,,`,,`,`,`
,,,`,`,,`,`,`,`,,`,,`,`,`,`,`,,`
,,wq,`,`,,`,`,`,`,,`,,`,`,`,`,`,,`,,`,`,`,,`,`,`
,,wp,`,`,`,`,ww,`,`,`,`,,,`,,`,,,`,`,`,wu,`,`,`,wz,`
,,,`,`,,`,`,`,`,,`,`,`,`,`,`,`,`,`,,`,`,`,,`,`,`
,,,,`,,,`,,,,,,`,`,`,`,`,,,,,`,,,,`
,,`,`,`,`,`,`,`,`,`,`,,`,`,~,`,`,,`,`,`,`,`,`,`,`,`,`
,,`,`,`,`,`,`,`,`,`,`,`,`,`,`,`,`,`,`,`,`,`,`,`,`,`,`,`
,,`,`,`,`,`,`,`,`,`,`,,`,`,`,`,`,,`,`,`,`,`,`,`,`,`,`
,,`,`,`,`,`,`,`,`,`,,,,`,,`,,,,`,`,`,`,`,`,`,`,`
,,`,`,`,`,`,`,`,`,,,`,`,`,`,`,`,`,,,`,`,`,`,`,`,`,`
,,`,`,`,`,`,`,`,`,,`,`,,,`,,,`,`,,`,`,`,`,`,`,`,`
,,`,`,`,`,`,`,`,,,`,`,,`,`,`,,`,`,,,`,`,`,`,`,`,`
,,`,`,`,`,`,`,`,,`,`,`,,`,`,`,,`,`,`,,`,`,`,`,`,`,`
,,`,`,`,`,`,`,`,,`,wh,`,,`,`,`,,`,wn,`,,`,`,`,`,`,`,`
,,`,`,`,`,`,`,`,,`,`,`,,,trackstopS,,,`,`,`,,`,`,`,`,`,`,`
,,,,,,,,,,,,,,,`


#place label(farming_place) start(16; 18) hidden() stockpiles


,,,,,,,,,`,`,`,,`,`,`,f10(1x9),b(1x12),,f(4x2),,,`
,,,,,,,,,`,`,`,,`,`,`,`,`,,`,`,`,`
,,,,,,,,,`,`,`,,`,`,`,`,`,,`,`,`,`
,,,,,,,,,,,`,,`,`,`,`,`,,`,`,`,`
,,,,,,,`,`,`,,`,,`,`,`,`,`,,`,f(3x2),,`
,,,,,,,`,`,`,`,`,,`,`,`,`,`,,`,`,`,`
,,,,,,,`,`,`,,`,,`,`,`,`,`,,`
,,,,,,,,,,,`,,`,`,`,`,`,,`,,`,`,`
,,,,,,`,`,`,u,,`,,`,`,`,`,`,,`,`,`,`,`
,,,,,,`,`,`,u,,`,,f(4x3),,,`,`,,`,,`,`,`
,,,u,u,,`,`,`,u,,`,,`,`,`,`,`,,`
,,`,u,u,,`,`,`,u,,`,,`,`,`,`,`,,`,,`,`,`,,`,`,`
,,`,g,g,`,`,`,`,u,`,`,,,`,,`,,,`,`,`,`,`,`,`,`,`
,,,g,g,,`,`,`,u,,`,`,`,`,`,`,`,`,`,,`,`,`,,`,`,`
,,,,`,,,`,,,,,,`,`,`,`,`,,,,,`,,,,`
,,f,f,f,f,f,f,f,f,f,f,,`,`,~,`,`,,f,f,f,f,f,f,f,f,f,f
,,f,f,f,f,f,f,f,f,f,f,`,`,`,`,`,`,`,f,f,f,f,f,f,f,f,f,f
,,f,f,f,f,f,f,f,f,f,f,,`,`,`,`,`,,f,f,f,f,f,f,f,f,f,f
,,f,f,f,f,f,f,f,f,f,,,,`,,`,,,,f,f,f,f,f,f,f,f,f
,,f,f,f,f,f,f,f,f,,,f,`,`,`,`,`,r,,,f,f,f,f,f,f,f,f
,,f,f,f,f,f,f,f,f,,f,f,,,`,,,r,r,,f,f,f,f,f,f,f,f
,,f,f,f,f,f,f,f,,,f,f,,r(2x3),,ry2(1x3),,r,r,,,f,f,f,f,f,f,f
,,f,f,f,f,f,f,f,,`,`,`,,`,`,`,,`,`,`,,f,f,f,f,f,f,f
,,f,f,f,f,f,f,f,,`,`,`,,`,`,`,,`,`,`,,f,f,f,f,f,f,f
,,f,f,f,f,f,f,f,,`,`,`,,,`,,,`,`,`,,f,f,f,f,f,f,f
,,,,,,,,,,,,,,,ry


"#query label(farming_query_stockpiles) start(16; 18) hidden() message(remember to:
- assign a minecart to the refuse quantum stockpile
- if the industry level is already built, configure the jugs, pots, and bags stockpiles to take from the ""Goods"" quantum stockpile on the industry level) config stockpiles"


,,,,,,,,,`,`,`,,`,`,`,seeds,potash,,booze,"{givename name=""booze""}"
,,,,,,,,,`,`,`,,`,`,`,linksonly,nocontainers,,`,`,`,`
,,,,,,,,,`,`,`,,`,`,`,"{givename name=""seeds""}","{givename name=""potash""}",,`,`,`,`
,,,,,,,,,,,`,,`,`,`,`,`,,`,`,`,`
,,,,,,,`,`,`,,`,,`,`,`,`,`,,`,preparedfood,"{givename name=""prepared food""}"
,,,,,,,`,`,`,`,`,,`,`,`,`,`,,`,`,`,`
,,,,,,,`,`,`,,`,,`,`,`,`,`,,`
,,,,,,,,,,,`,,`,`,`,`,`,,`,,`,`,`
,,,,,,`,`,`,pots,,`,,`,`,`,`,`,,`,`,`,`,`
,,,,,,`,`,`,"{givename name=""pots""}",,`,,seeds,nocontainers,"{givename name=""seeds feeder""}",give2up,`,,`,,`,`,`
,,,bags,"{givename name=""bags""}",,`,`,`,`,,`,,`,`,`,`,`,,`
,,`,nocontainers,`,,`,`,`,`,,`,,`,`,`,`,`,,`,,`,`,`,,`,`,`
,,`,jugs,"{givename name=""jugs""}",`,`,`,`,`,`,`,,,`,,`,,,`,`,`,`,`,`,`,`,`
,,,nocontainers,`,,`,`,`,`,,`,`,`,`,`,`,`,`,`,,`,`,`,,`,`,`
,,,,`,,,`,,,,,,`,`,`,`,`,,,,,`,,,,`
,,plants,`,`,`,`,`,`,`,`,`,,`,`,~,`,`,,`,`,`,"{givename name=""cookable food""}",`,`,`,`,`,`
,,"{givename name=""plants""}",`,`,`,`,`,`,`,`,`,`,`,`,`,`,`,`,`,`,`,forbidplants,`,`,`,`,`,`
,,`,`,`,`,`,`,`,`,`,`,,`,`,`,`,`,,`,`,`,forbidtallow,`,`,`,`,`,`
,,`,`,`,`,`,`,`,`,`,,,,`,,`,,,,`,`,forbiddye,`,`,`,`,`,`
,,`,`,`,`,`,`,`,`,,,unpreparedfish,`,`,`,`,`,rawhides,,,`,forbidunpreparedfish,`,`,`,`,`,`
,,`,`,`,`,`,`,`,`,,`,nocontainers,,,`,,,"{givename name=""rawhides""}",`,,`,forbidmiscliquid,`,`,`,`,`,`
,,`,`,`,`,`,`,`,,,`,"{givename name=""unprepared fish""}",,forbidcraftrefuse,"{givename name=""refuse feeder""}",corpses,,t{Left 3}{Down 4}&,`,,,forbidpreparedfood,`,`,`,`,`,`
,,`,`,`,`,`,`,`,,`,`,`,,forbidcorpses,"{give move=""{Right 3}{Up}""}","{givename name=""corpse feeder""}",,`,`,`,,forbidbooze,`,`,`,`,`,`
,,`,`,`,`,`,`,`,,`,`,`,,`,`,`,,`,`,`,,forbidseeds,`,`,`,`,`,`
,,`,`,`,`,`,`,`,,`,`,`,,,"{quantumstop name=""Refuse/Corpse quantum"" sp_links=""{sp_link move={Up} move_back={Down}}{sp_link move=""""{Right}{Up}"""" move_back=""""{Down}{Left}""""}""}{givename name=""refuse/corpse dumper""}",,,`,`,`,,`,`,`,`,`,`,`
,,,,,,,,,,,,,,,"{quantum name=""refuse/corpse quantum""}"


#query label(farming_rooms) start(16; 18) hidden() message(Check to ensure the lower office got assigned to your manager and assign the upper office to your bookkeeper (if different from your manager).) configure rooms


,,,,,,,,,`,`,`,,`,`,`,`,`,,`,`,`,`
,,,,,,,,,r&,`,`,,`,`,`,`,`,,`,`,`,`
,,,,,,,,,`,`,`,,`,`,`,`,`,,`,`,r+&h
,,,,,,,,,,,`,,`,`,`,`,`,,`,`,`,`
,,,,,,,`,`,`,,`,,`,`,`,`,`,,`,`,`,`
,,,,,,,r&a+&,,,`,`,,`,`,`,`,`,,`,`,`,`
,,,,,,,`,`,`,,`,,`,`,`,`,`,,`
,,,,,,,,,,,`,,`,`,`,`,`,,`,,`,`,r&d
,,,,,,`,`,`,`,,`,,`,`,`,`,`,,`,`,`,`,`
,,,,,,`,`,`,`,,`,,`,`,`,`,`,,`,,`,`,`
,,,`,`,,`,`,`,`,,`,,`,`,`,`,`,,`
,,`,`,`,,`,`,`,`,,`,,`,`,`,`,`,,`,,`,`,`,,`,`,`
,,`,`,`,`,`,`,`,`,`,`,,,`,,`,,,`,`,`,`,`,`,`,`,`
,,,`,`,,`,`,`,`,,`,`,`,`,`,`,`,`,`,,`,`,`,,`,`,`
,,,,`,,,`,,,,,,`,`,`,`,`,,,,,`,,,,`
,,`,`,`,`,`,`,`,`,`,`,,`,`,~,`,`,,`,`,`,`,`,`,`,`,`,`
,,`,`,`,`,`,`,`,`,`,`,`,`,`,`,`,`,`,`,`,`,`,`,`,`,`,`,`
,,`,`,`,`,`,`,`,`,`,`,,`,`,`,`,`,,`,`,`,`,`,`,`,`,`,`
,,`,`,`,`,`,`,`,`,`,,,,`,,`,,,,`,`,`,`,`,`,`,`,`
,,`,`,`,`,`,`,`,`,,,`,`,`,`,`,`,`,,,`,`,`,`,`,`,`,`
,,`,`,`,`,`,`,`,`,,`,`,,,`,,,`,`,,`,`,`,`,`,`,`,`
,,`,`,`,`,`,`,`,,,`,`,,`,`,`,,`,`,,,`,`,`,`,`,`,`
,,`,`,`,`,`,`,`,,`,`,`,,`,`,`,,`,`,`,,`,`,`,`,`,`,`
,,`,`,`,`,`,`,`,,`,`,`,,`,`,`,,`,`,`,,`,`,`,`,`,`,`
,,`,`,`,`,`,`,`,,`,`,`,,,`,,,`,`,`,,`,`,`,`,`,`,`
,,,,,,,,,,,,,,,`


"#build label(farming_build2) start(16; 18) hidden() farm plots, remaining furniture, and important doors"


,,,,,,,,,`,`,`,,p(3x1),,,`,`,,`,`,`,`
,,,,,,,,,`,`,`,,p(3x1),,,`,`,,`,`,`,`
,,,,,,,,,`,`,`,,p(3x1),,,`,`,,c,t,~,~
,,,,,,,,,,,`,,p(3x1),,,`,`,,c,t,t,c
,,,,,,,`,`,`,,`,,p(3x1),,,`,`,,`,`,`,`
,,,,,,,`,`,`,`,`,,p(3x1),,,`,`,,`,`,`,`
,,,,,,,`,`,`,,`,,p(3x1),,,`,`,,`
,,,,,,,,,,,`,,p(3x1),,,`,`,,`,,b,b,~
,,,,,,`,`,`,`,,`,,p(3x1),,,`,`,,`,`,`,`,h
,,,,,,`,`,`,`,,`,,`,`,`,`,`,,`,,b,b,b
,,,`,`,,`,`,`,`,,`,,`,`,`,`,`,,`
,,`,`,`,,`,`,`,`,,`,,`,`,`,`,`,,`,,`,`,`,,`,`,`
,,`,`,`,`,`,`,`,`,`,`,,,`,,`,,,`,`,`,`,`,`,`,`,`
,,,`,`,,`,`,`,`,,`,`,`,`,`,`,`,`,`,,`,`,`,,`,`,`
,,,,`,,,`,,,,,,`,`,`,`,`,,,,,`,,,,`
,,`,`,`,`,`,`,`,`,`,`,,`,`,~,`,`,,`,`,`,`,`,`,`,`,`,`
,,`,`,`,`,`,`,`,`,`,`,`,`,`,`,`,`,`,`,`,`,`,`,`,`,`,`,`
,,`,`,`,`,`,`,`,`,`,`,,`,`,`,`,`,,`,`,`,`,`,`,`,`,`,`
,,`,`,`,`,`,`,`,`,`,,,,`,,`,,,,`,`,`,`,`,`,`,`,`
,,`,`,`,`,`,`,`,`,,,`,d,`,`,`,d,`,,,`,`,`,`,`,`,`,`
,,`,`,`,`,`,`,`,`,,`,`,,,d,,,`,`,,`,`,`,`,`,`,`,`
,,`,`,`,`,`,`,`,,,`,`,,`,`,`,,`,`,,,`,`,`,`,`,`,`
,,`,`,`,`,`,`,`,,`,`,`,,`,`,`,,`,`,`,,`,`,`,`,`,`,`
,,`,`,`,`,`,`,`,,`,`,`,,`,`,`,,`,`,`,,`,`,`,`,`,`,`
,,`,`,`,`,`,`,`,,`,`,`,,,`,,,`,`,`,,`,`,`,`,`,`,`
,,,,,,,,,,,,,,,`


#query label(farming_query_plots) start(16; 18) hidden() configure farm plots for seasonal fertilization


,,,,,,,,,`,`,`,,s,`,`,`,`,,`,`,`,`
,,,,,,,,,`,`,`,,s,`,`,`,`,,`,`,`,`
,,,,,,,,,`,`,`,,s,`,`,`,`,,`,`,`,`
,,,,,,,,,,,`,,s,`,`,`,`,,`,`,`,`
,,,,,,,`,`,`,,`,,s,`,`,`,`,,`,`,`,`
,,,,,,,`,`,`,`,`,,s,`,`,`,`,,`,`,`,`
,,,,,,,`,`,`,,`,,s,`,`,`,`,,`
,,,,,,,,,,,`,,s,`,`,`,`,,`,,`,`,`
,,,,,,`,`,`,`,,`,,s,`,`,`,`,,`,`,`,`,`
,,,,,,`,`,`,`,,`,,`,`,`,`,`,,`,,`,`,`
,,,`,`,,`,`,`,`,,`,,`,`,`,`,`,,`
,,`,`,`,,`,`,`,`,,`,,`,`,`,`,`,,`,,`,`,`,,`,`,`
,,`,`,`,`,`,`,`,`,`,`,,,`,,`,,,`,`,`,`,`,`,`,`,`
,,,`,`,,`,`,`,`,,`,`,`,`,`,`,`,`,`,,`,`,`,,`,`,`
,,,,`,,,`,,,,,,`,`,`,`,`,,,,,`,,,,`
,,`,`,`,`,`,`,`,`,`,`,,`,`,~,`,`,,`,`,`,`,`,`,`,`,`,`
,,`,`,`,`,`,`,`,`,`,`,`,`,`,`,`,`,`,`,`,`,`,`,`,`,`,`,`
,,`,`,`,`,`,`,`,`,`,`,,`,`,`,`,`,,`,`,`,`,`,`,`,`,`,`
,,`,`,`,`,`,`,`,`,`,,,,`,,`,,,,`,`,`,`,`,`,`,`,`
,,`,`,`,`,`,`,`,`,,,`,`,`,`,`,`,`,,,`,`,`,`,`,`,`,`
,,`,`,`,`,`,`,`,`,,`,`,,,`,,,`,`,,`,`,`,`,`,`,`,`
,,`,`,`,`,`,`,`,,,`,`,,`,`,`,,`,`,,,`,`,`,`,`,`,`
,,`,`,`,`,`,`,`,,`,`,`,,`,`,`,,`,`,`,,`,`,`,`,`,`,`
,,`,`,`,`,`,`,`,,`,`,`,,`,`,`,,`,`,`,,`,`,`,`,`,`,`
,,`,`,`,`,`,`,`,,`,`,`,,,`,,,`,`,`,,`,`,`,`,`,`,`
,,,,,,,,,,,,,,,`


#build label(farming_build3) start(16; 18) hidden() remaining doors


,,,,,,,,,`,`,`,,`,`,`,`,`,,`,`,`,`
,,,,,,,,,`,`,`,,`,`,`,`,`,,`,`,`,`
,,,,,,,,,`,`,`,,`,`,`,`,`,,~,~,~,~
,,,,,,,,,,,d,,`,`,`,`,`,,~,~,~,~
,,,,,,,`,`,`,,`,,`,`,`,`,`,,`,`,`,`
,,,,,,,`,`,`,d,`,,`,`,`,`,`,,`,`,`,`
,,,,,,,`,`,`,,`,,`,`,`,`,`,,d
,,,,,,,,,,,`,,`,`,`,`,`,,`,,~,~,~
,,,,,,`,`,`,`,,`,,`,`,`,`,`,,`,d,`,`,~
,,,,,,`,`,`,`,,`,,`,`,`,`,`,,`,,~,~,~
,,,`,`,,`,`,`,`,,`,,`,`,`,`,`,,`
,,`,`,`,,`,`,`,`,,`,,`,`,`,`,`,,`,,`,`,`,,`,`,`
,,`,`,`,d,`,`,`,`,d,`,,,d,,d,,,`,d,`,`,`,d,`,`,`
,,,`,`,,`,`,`,`,,`,d,`,`,`,`,`,d,`,,`,`,`,,`,`,`
,,,,d,,,d,,,,,,`,`,`,`,`,,,,,d,,,,d
,,`,`,`,`,`,`,`,`,`,`,,`,`,~,`,`,,`,`,`,`,`,`,`,`,`,`
,,`,`,`,`,`,`,`,`,`,`,d,`,`,`,`,`,d,`,`,`,`,`,`,`,`,`,`
,,`,`,`,`,`,`,`,`,`,`,,`,`,`,`,`,,`,`,`,`,`,`,`,`,`,`
,,`,`,`,`,`,`,`,`,`,,,,d,,d,,,,`,`,`,`,`,`,`,`,`
,,`,`,`,`,`,`,`,`,,,`,~,`,`,`,~,`,,,`,`,`,`,`,`,`,`
,,`,`,`,`,`,`,`,`,,`,`,,,~,,,`,`,,`,`,`,`,`,`,`,`
,,`,`,`,`,`,`,`,,,`,`,,`,`,`,,`,`,,,`,`,`,`,`,`,`
,,`,`,`,`,`,`,`,,`,`,`,,`,`,`,,`,`,`,,`,`,`,`,`,`,`
,,`,`,`,`,`,`,`,,`,`,`,,`,`,`,,`,`,`,,`,`,`,`,`,`,`
,,`,`,`,`,`,`,`,,`,`,`,,,`,,,`,`,`,,`,`,`,`,`,`,`
,,,,,,,,,,,,,,,`


#notes label(industry_help)
Sets up workshops for all non-farming industries
""
Features:
- Quantum stockpiles for infinite storage
- Space-efficient layout for all workshops
with separate stockpiles for:
- A reserve of uncut gems for strange moods that the jeweler's workshop cannot take from
- Steel bars and coal so you can see at a glance if you're low on either
- Items that cannot be quantum stockpiled (e.g. lye and sand bags)
- Meltable weapons and armor
""
Workshops:
- 3x Mason
- 1x Craftsdwarf
- 1x Jeweler
- 1x Mechanic
- 4x Smelter
- 1x Forge
- 1x Glassmaker
- 1x Kiln
- 4x Wood furnace
- 1x Ashery
- 1x Soap maker
- 1x Carpenter
- 1x Siege workshop
- 1x Bowyer
- 1x Dyer
- 1x Loom
- 1x Clothier
""
""
Manual steps you have to take:
- Assign minecarts to your quantum stockpile hauling routes
"- Give from the ""Goods"" quantum stockpile to the jugs, pots, and bags stockpiles on the farming level"
"- If desired, set the stockpiles in the bottom right to auto-melt. This results in melting all weapons and armor that are not masterwork steel. This is great for upgrading your military, but it takes a *lot* of fuel. If you enable this, be sure you're in a heavily forested area, enable auto-chop, and keep your coal stocks high."
- Download automation.json from https://drive.google.com/file/d/17WcN5mK-rnADOm2B_JFpPnByYgkYjxhb/view and put it in your dfhack-config/orders/ directory.
""
Industry Walkthrough:
"1) You can start digging out /industry1 immediately after embark. It is best to choose a stone layer at least two layers underground so the boulders can be used by your starting workshops. Note that even if you dig the services level immediately below this one, there is space to route magma underneath your furnaces so you can replace the furnaces on this level with magma-powered equivalents."
""
"2) Queue up manufacturing by running ""quickfort orders"" on /industry2. If you brought an anvil, feel free to remove the anvil work order from the manager orders screen."
""
"3) Once the area is dug out, run /industry2. Remember to assign minecarts to to your quantum stockpile hauling routes, and if the farming level is already built, give from the ""Goods"" quantum stockpile to the jugs, pots, and bags stockpiles on the farming level."
""
"4) If you want to automatically melt goblinite and other low-quality weapons and armor, mark the south-east stockpiles for auto-melt."
""
"5) Run ""orders import automation"" to use the provided automation.json to take care of your fort's basic needs, such as food, booze, military supplies, and raw material processing. If you get job cancelation spam about not being able to make soap, manually queue up a few ""Make lye"" jobs at your ashery. That should get the soap-making jobs back on track."
""
"6) You'll need more than 2 Mason's Workshops to keep up with the orders. When you have more masons, make more Mason's Workshops as needed."
"#dig label(industry1) start(18; 18; central stairs) message(This would be a good time to queue manager orders for /industry2. Once the area is dug out, continue with /industry2.)"


,,,,,,,,,,,d,d,d,d,d,d,d,d,d,d,d,d,d
,,,,,,,,,,,d,d,d,d,d,d,d,d,d,d,d,d,d
,,,,d,d,d,d,d,d,d,d,d,d,d,d,d,d,d,d,d,d,d,d,d,d,d,d,d,d,d
,,,,d,d,d,d,d,d,d,d,d,d,d,d,d,d,d,d,d,d,d,d,d,d,d,d,d,d,d
,,,,d,d,d,d,d,d,d,d,d,d,d,d,d,d,d,d,d,d,d,d,d,d,d,d,d,d,d
,,,,d,d,d,d,d,d,d,d,d,d,d,d,d,d,d,d,d,d,d,d,d,d,d,d,d,d,d
,,,,d,d,d,d,d,d,d,d,d,d,d,d,d,d,d,d,d,d,d,d,d,d,d,d,d,d,d
,,,,d,d,d,d,d,d,d,d,d,d,d,d,d,d,d,d,d,d,d,d,d,d,d,d,d,d,d
,,,,d,d,d,d,d,d,d,d,d,d,d,d,d,d,d,d,d,d,d,d,d,d,d,d,d,d,d
,,d,d,d,d,d,d,d,d,d,d,d,d,d,d,d,d,d,d,d,d,d,d,d,d,d,d,d,d,d,d,d
,,d,d,d,d,d,d,d,d,d,d,d,d,d,d,d,d,d,d,d,d,d,d,d,d,d,d,d,d,d,d,d
,,d,d,d,d,d,d,d,d,d,d,d,d,d,d,d,d,d,d,d,d,d,d,d,d,d,d,d,d,d,d,d
,,d,d,d,d,d,d,d,d,d,d,d,d,,,d,,d,,,d,d,d,d,d,d,d,d,d,d,d,d
,,d,d,d,d,d,d,d,d,d,d,d,d,,d,d,d,d,d,,d,d,d,d,d,d,d,d,d,d,d,d
,,d,d,d,d,d,d,d,d,d,d,d,d,d,d,`,`,`,d,d,d,d,d,d,d,d,d,d,d,d,d,d
,,d,d,d,d,d,d,d,d,d,d,d,d,,d,`,`,`,d,,d,d,d,d,d,d,d,d,d,d,d,d
,,d,d,d,d,d,d,d,d,d,d,d,d,d,d,`,`,`,d,d,d,d,d,d,d,d,d,d,d,d,d,d
,,d,d,d,d,d,d,d,d,d,d,d,d,,d,d,d,d,d,,d,d,d,d,d,d,d,d,d,d,d,d
,,d,d,d,d,d,d,d,d,d,d,d,d,,,d,,d,,,d,d,d,d,d,d,d,d,d,d,d,d
,,d,d,d,d,d,d,d,d,d,d,d,d,d,d,d,d,d,d,d,d,d,d,d,d,d,d,d,d,d,d,d
,,d,d,d,d,d,d,d,d,d,d,d,d,d,d,d,d,d,d,d,d,d,d,d,d,d,d,d,d,d,d,d
,,d,d,d,d,d,d,d,d,d,d,d,d,d,d,d,d,d,d,d,d,d,d,d,d,d,d,d,d,d,d,d
,,,,d,d,d,d,d,d,d,d,d,d,d,d,d,d,d,d,d,d,d,d,d,d,d,d,d,d,d
,,,,d,d,d,d,d,d,d,d,d,d,d,d,d,d,d,d,d,d,d,d,d,d,d,d,d,d,d
,,,,d,d,d,d,d,d,d,d,d,d,d,d,d,d,d,d,d,d,d,d,d,d,d,d,d,d,d
,,,,d,d,d,d,d,d,d,d,d,d,d,d,d,d,d,d,d,d,d,d,d,d,d,d,d,d,d
,,,,d,d,d,d,d,d,d,d,d,d,d,d,d,d,d,d,d,d,d,d,d,d,d,d,d,d,d
,,,,d,d,d,d,d,d,d,d,d,d,d,d,d,d,d,d,d,d,d,d,d,d,d,d,d,d,d
,,,,d,d,d,d,d,d,d,d,d,d,d,d,d,d,d,d,d,d,d,d,d,d,d,d,d,d,d
,,,,,,,,,,,d,d,d,d,d,d,d,d,d,d,d,d,d
,,,,,,,,,,,d,d,d,d,d,d,d,d,d,d,d,d,d


"#meta label(industry2) start(central stairs) build workshops and stockpiles, configure stockpiles"
build/industry_build
place/industry_place
query/industry_query
#build label(industry_build) start(18; 18) hidden()


,,,,,,,,,,,`,`,`,`,`,`,`,`,`,`,`,`,`
,,,,,,,,,,,`,`,`,`,`,`,`,`,`,`,`,`,`
,,,,`,`,`,`,`,`,`,`,`,`,`,`,`,wj,`,`,`,`,`,`,`,`,`,`,`,`,`
,,,,`,`,`,`,`,`,`,`,`,`,`,`,`,`,`,`,`,`,`,`,`,`,`,`,`,`,`
,,,,`,`,`,`,`,`,`,`,`,`,`,`,`,`,`,`,`,`,`,`,`,`,`,`,`,`,`
,,,,`,`,`,`,`,`,`,`,`,wr,`,`,`,`,`,`,`,wt,`,`,`,`,`,`,`,`,`
,,,,`,`,`,`,ws,`,`,`,`,`,`,`,`,trackstopN,`,`,`,`,`,`,`,`,`,`,`,`,`
,,,,`,`,`,`,`,`,`,`,`,`,`,`,`,`,`,`,`,`,`,`,`,`,`,`,`,`,`
,,,,`,`,`,`,`,`,`,`,`,wm,`,`,`,`,`,`,`,wm,`,`,`,`,`,`,`,`,`
,,`,`,`,`,`,`,`,`,`,`,`,`,`,`,`,`,`,`,`,`,`,`,`,`,`,`,`,`,`,`,`
,,`,`,`,`,`,`,`,`,`,`,`,`,`,`,`,`,`,`,`,`,`,`,`,`,`,`,`,`,`,`,`
,,`,`,wy,`,`,ew,`,`,ew,`,`,`,`,`,`,`,`,`,`,`,`,`,wk,`,`,wo,`,`,`,`,`
,,`,`,`,`,`,`,`,`,`,`,`,`,,,d,,d,,,`,`,`,`,`,`,`,`,`,`,`,`
,,`,`,`,`,`,`,`,`,`,`,`,`,,`,`,`,`,`,,`,`,`,`,`,`,`,`,`,`,`,`
,,`,`,`,`,`,`,`,`,`,`,`,`,d,`,,,,`,d,`,`,`,`,`,`,`,`,`,`,`,`
,,`,`,wc,`,`,`,trackstopW,`,`,`,`,`,,`,,`,,`,,`,`,`,`,`,trackstopE,`,`,`,we,`,`
,,`,`,`,`,`,`,`,`,`,`,`,`,d,`,,,,`,d,`,`,`,`,`,`,`,`,`,`,`,`
,,`,`,`,`,`,`,`,`,`,`,`,`,,`,`,`,`,`,,`,`,`,`,`,`,`,`,`,`,`,`
,,`,`,`,`,`,`,`,`,`,`,`,`,,,d,,d,,,`,`,`,`,`,`,`,`,`,`,`,`
,,`,`,wS,`,`,ew,`,`,ew,`,`,`,`,`,`,`,`,`,`,`,`,`,wb,`,`,wd,`,`,`,`,`
,,`,`,`,`,`,`,`,`,`,`,`,`,`,`,`,`,`,`,`,`,`,`,`,`,`,`,`,`,`,`,`
,,`,`,`,`,`,`,`,`,`,`,`,`,`,`,`,`,`,`,`,`,`,`,`,`,`,`,`,`,`,`,`
,,,,`,`,`,`,`,`,`,`,`,es,`,`,`,`,`,`,`,es,`,`,`,`,`,`,`,`,`
,,,,`,`,`,`,`,`,`,`,`,`,`,`,`,`,`,`,`,`,`,`,`,`,`,`,`,`,`
,,,,`,`,`,`,`,`,`,`,`,`,`,`,`,trackstopS,`,`,`,`,`,`,`,`,`,`,`,`,`
,,,,`,`,`,`,`,`,`,`,`,es,`,`,`,`,`,`,`,es,`,`,`,`,`,`,`,`,`
,,,,`,`,`,`,`,`,`,`,`,`,`,`,`,`,`,`,`,`,`,`,`,`,`,`,`,`,`
,,,,`,`,`,`,`,`,`,`,`,`,`,`,`,`,`,`,`,`,`,`,`,`,`,`,`,`,`
,,,,`,`,`,`,`,`,`,`,`,eg,`,`,`,wf,`,`,`,ek,`,`,`,`,`,`,`,`,`
,,,,,,,,,,,`,`,`,`,`,`,`,`,`,`,`,`,`
,,,,,,,,,,,`,`,`,`,`,`,`,`,`,`,`,`,`


#place label(industry_place) start(18; 18) hidden()


,,,,,,,,,,,e,e,e,e,e,e,e,e,e,e,e,e,e
,,,,,,,,,,,`,`,`,`,`,`,`,`,`,`,`,`,`
,,,,`,`,`,`,`,`,`,`,`,`,`,`,`,`,`,`,`,`,`,`,`,`,`,`,`,`,`
,,,,`,`,`,`,`,`,`,`,`,`,`,`,`,`,`,`,`,`,`,`,`,`,`,`,`,`,`
,,,,`,`,`,`,`,`,`,`,`,`,`,`,`,`,`,`,`,`,`,`,`,`,`,`,`,`,`
,,,,`,`,`,`,`,`,`,`,`,`,`,`,`,c,`,`,`,`,`,`,`,`,`,`,`,`,`
,,,,`,`,`,`,`,`,`,`,`,`,`,`,`,`,`,`,`,`,`,`,`,`,`,`,`,`,`
,,,,`,`,`,`,`,`,`,`,`,`,`,s4(5x4),,,~,~,`,`,`,`,`,`,`,`,`,`,`
,,,,`,`,`,`,`,`,`,`,`,`,`,~,~,~,~,~,`,`,`,`,`,`,`,`,`,`,`
,,f,`,`,`,`,`,`,`,`,`,`,`,`,~,~,~,~,~,`,`,`,`,`,`,`,`,`,`,`,`,`
,,f,`,`,`,`,`,`,`,`,`,`,`,`,~,~,~,~,~,`,`,`,`,`,`,`,`,`,`,`,`,`
,,f,`,`,`,`,`,`,`,`,`,`,`,`,e(5x1),,,~,~,`,`,`,`,`,`,`,`,`,`,`,`,`
,,f,`,`,`,`,`,`,`,`,`,`,`,,,`,,`,,,`,`,`,`,`,`,`,`,`,`,`,`
,,f,`,`,`,`,`,`,w(2x5),,afnguS(3x5),,`,,`,`,`,`,`,,rhl(5x5),,,~,~,`,`,`,`,`,`,`
,,f,`,`,`,`,`,`,~,~,~,~,~,`,`,,,,`,`,~,~,~,~,~,`,`,`,`,`,`,`
,,f,`,`,`,`,c,`,~,~,~,~,~,,`,,`,,`,,~,~,~,~,~,`,r,`,`,`,`,`
,,f,`,`,`,`,`,`,~,~,~,~,~,`,`,,,,`,`,~,~,~,~,~,`,`,`,`,`,`,`
,,f,`,`,`,`,`,`,~,~,~,~,~,,`,`,`,`,`,,~,~,~,~,~,`,`,`,`,`,`,`
,,f,`,`,`,`,`,`,`,`,`,`,`,,,`,,`,,,`,`,`,`,`,`,`,`,`,`,`,`
,,f,`,`,`,`,`,`,`,`,`,`,`,`,bpdz(5x2),,,,~,`,`,`,`,`,`,`,`,`,`,`,`,`
,,f,`,`,`,`,`,`,`,`,`,`,`,`,~,~,~,~,~,`,`,`,`,`,`,`,`,`,`,`,`,`
,,f,`,`,`,`,`,`,`,`,`,`,`,`,s2(5x3),,,~,~,`,`,`,`,`,`,`,`,`,`,`,`,`
,,,,`,`,`,`,`,`,`,`,`,`,`,~,~,~,~,~,`,`,`,`,pd(7x3),,,~,~,~,~
,,,,`,`,`,`,`,`,`,`,`,`,`,~,~,~,~,~,`,`,`,`,~,~,~,~,~,~,~
,,,,`,`,`,`,`,`,`,`,`,`,`,`,`,`,`,`,`,`,`,`,~,~,~,~,~,~,~
,,,,`,`,`,`,`,`,`,`,`,`,`,b,`,c,`,b,`,`,`,`,`,`,`,`,`,`,`
,,,,`,`,`,`,`,`,`,`,`,`,`,b,b,b,b,b,`,`,`,`,pd(7x3),,,~,~,~,~
,,,,`,`,`,`,`,`,`,`,`,`,`,b,`,`,`,b,`,`,`,`,~,~,~,~,~,~,~
,,,,`,`,`,`,`,`,`,`,`,`,`,b,`,`,`,b,`,`,`,`,~,~,~,~,~,~,~
,,,,,,,,,,,`,`,`,`,`,`,`,`,`,`,`,`,`
,,,,,,,,,,,u(6x1),,,~,~,~,`,b(6x1),,,~,~,~


"#query label(industry_query) start(18; 18) hidden() message(remember to:
- assign minecarts to to your quantum stockpile hauling routes
- if the farming level is already built, give from the ""Goods"" quantum stockpile to the jugs, pots, and bags stockpiles on the farming level
- if you want to automatically melt goblinite and other low-quality weapons and armor, mark the south-east stockpiles for auto-melt
- now that your industry is set up, run ""orders import automation"" to automate your fort's basic needs (download automation.json from https://drive.google.com/file/d/17WcN5mK-rnADOm2B_JFpPnByYgkYjxhb/view?usp=sharing and put it in your dfhack-config/orders/ directory))"


,,,,,,,,,,,roughgems,,,,nocontainers,"{givename name=""rough gems for moods""}",t{Down 5}&,,,,,~,~
,,,,,,,,,,,`,`,`,`,`,`,`,`,`,`,`,`,`
,,,,`,`,`,`,`,`,`,`,`,`,`,`,`,~,`,`,`,`,`,`,`,`,`,`,`,`,`
,,,,`,`,`,`,`,`,`,`,`,`,`,`,`,`,`,`,`,`,`,`,`,`,`,`,`,`,`
,,,,`,`,`,`,`,`,`,`,`,`,`,`,`,`,`,`,`,`,`,`,`,`,`,`,`,`,`
,,,,`,`,`,`,`,`,`,`,`,~,`,`,`,"{quantum name=""stoneworker quantum""}g{Up 3}&",`,`,`,~,`,`,`,`,`,`,`,`,`
,,,,`,`,`,`,~,`,`,`,`,`,`,`,`,"{quantumstop name=""Stoneworker quantum"" sp_links=""{sp_link move={Down} move_back={Up}}{sp_link move=""""{Down 5}"""" move_back=""""{Up 5}""""}""}{givename name=""stoneworker dumper""}",`,`,`,`,`,`,`,`,`,`,`,`,`
,,,,`,`,`,`,`,`,`,`,`,`,`,otherstone,,,,~,`,`,`,`,`,`,`,`,`,`,`
,,,,`,`,`,`,`,`,`,`,`,~,`,"{givename name=""stone feeder""}",~,~,~,~,`,~,`,`,`,`,`,`,`,`,`
,,miscliquid,`,`,`,`,`,`,`,`,`,`,`,`,~,~,~,~,~,`,`,`,`,`,`,`,`,`,`,`,`,`
,,nocontainers,`,`,`,`,`,`,`,`,`,`,`,`,~,~,~,~,~,`,`,`,`,`,`,`,`,`,`,`,`,`
,,"{givename name=""non-quantum liquids""}",`,~,`,`,~,`,`,~,`,`,`,`,nocontainers,"{givename name=""gem feeder""}",~,~,~,`,`,`,`,~,`,`,~,`,`,`,`,`
,,~,`,`,`,`,`,`,`,`,`,`,`,,,`,,`,,,`,`,`,`,`,`,`,`,`,`,`,`
,,~,`,`,`,`,`,`,"{givename name=""wood feeder""}",~,"{givename name=""goods feeder""}",nocontainers,~,,`,`,`,`,`,,craftrefuse,,,,~,`,`,`,`,`,`,`
,,~,`,`,`,`,`,`,~,~,{cages}{permittraps},~,~,`,`,,,,`,`,"{givename name=""cloth/bones feeder""}",~,~,~,~,`,`,`,`,`,`,`
,,~,`,~,`,`,"{quantum name=""goods/wood quantum""}g{Up 13}{Right 10}&","{quantumstop name=""Goods/Wood quantum"" sp_links=""{sp_link move={Right} move_back={Left}}{sp_link move=""""{Right 5}"""" move_back=""""{Left 5}""""}""}{givename name=""goods/wood dumper""}",~,~,{tallow}{permitdye},~,~,,`,,`,,`,,nocontainers,~,~,~,~,"{quantumstopfromwest name=""Clothier/Bones quantum""}{givename name=""cloth/bones dumper""}","{quantum name=""cloth/bones quantum""}",`,`,~,`,`
,,~,`,`,`,`,`,`,~,~,forbidsand,~,~,`,`,,,,`,`,~,~,~,~,~,`,`,`,`,`,`,`
,,~,`,`,`,`,`,`,~,~,forbidcrafts,~,~,,`,`,`,`,`,,~,~,~,~,~,`,`,`,`,`,`,`
,,~,`,`,`,`,`,`,`,`,`,`,`,,,`,,`,,,`,`,`,`,`,`,`,`,`,`,`,`
,,~,`,~,`,`,~,`,`,~,`,`,`,`,forbidpotash,nocontainers,"{givename name=""bar/military feeder""}",~,~,`,`,`,`,~,`,`,~,`,`,`,`,`
,,~,`,`,`,`,`,`,`,`,`,`,`,`,~,~,~,~,~,`,`,`,`,`,`,`,`,`,`,`,`,`
,,~,`,`,`,`,`,`,`,`,`,`,`,`,forbidotherstone,,,,,`,`,`,`,`,`,`,`,`,`,`,`,`
,,,,`,`,`,`,`,`,`,`,`,~,`,"{givename name=""ore/clay feeder""}",~,~,~,~,`,~,`,`,nocontainers,t{Left 6}{Up 3}&,t{Left 9}{Down 3}&,"{givename name=""meltable steel/brnze""}"
,,,,`,`,`,`,`,`,`,`,`,`,`,~,~,~,~,~,`,`,`,`,{bronzeweapons}{permitsteelweapons}{forbidmasterworkweapons}{forbidartifactweapons}
,,,,`,`,`,`,`,`,`,`,`,`,`,`,`,"{quantumstop name=""Metalworker quantum"" sp_links=""{sp_link move={Up} move_back={Down}}{sp_link move=""""{Up 5}"""" move_back=""""{Down 5}""""}""}{givename name=""metalworker dumper""}",`,`,`,`,`,`,{bronzearmor}{permitsteelarmor}{forbidmasterworkarmor}{forbidartifactarmor}
,,,,`,`,`,`,`,`,`,`,`,~,`,`,`,"{quantum name=""metalworker quantum""}",`,`,`,~,`,`,`,`,`,`,`,`,`
,,,,`,`,`,`,`,`,`,`,`,`,`,coal,"{givename name=""coal""}",t{Up}&,nocontainers,`,`,`,`,`,nocontainers,t{Left 6}{Up 7}&,t{Left 9}{Up 1}&,"{givename name=""other meltables""}"
,,,,`,`,`,`,`,`,`,`,`,`,`,`,`,`,`,`,`,`,`,`,{metalweapons}{forbidbronzeweapons}{forbidsteelweapons}{forbidmasterworkweapons}{forbidartifactweapons}
,,,,`,`,`,`,`,`,`,`,`,~,`,`,`,~,`,`,`,~,`,`,{metalarmor}{forbidbronzearmor}{forbidsteelarmor}{forbidmasterworkarmor}{forbidartifactarmor}
,,,,,,,,,,,`,`,`,`,`,`,`,`,`,`,`,`,`
,,,,,,,,,,,sand,"{givename name=""sand bags""}",nocontainers,~,~,~,`,t{Up 5}{Left}&,,,nocontainers,steelbars,"{givename name=""steel""}"


#notes label(services_help)
"Sets up public services (dining, hospital, etc.)"
""
Features:
- Spacious dining room (also usable as a tavern)
- Prepared food and drink stockpiles
- Well cistern system (bring your own water)
- Four well-appointed jail cells
- Hospital with a well for washing
- Garbage dump
""
Manual steps you have to take:
"- If you want to declare the dining room as a tavern, the bedrooms at the top can be assigned to the tavern as rented rooms."
"- Fill the cisterns with water, either with a bucket brigade or by plumbing flowing water. Fill so that there are two z-levels of 7-depth water to prevent muddiness. If you want to fill with buckets, designate a pond zone on the level below the main floor. If you feel adventurous and are experienced with water pressure, you can instead route (depressurized!) water to the second-to-bottom level (the one above the up staircases)."
""
Services Walkthough:
1) Start this level before your fort grows beyond around 50 dwarves so everyone has a place to eat.
""
"2) Start digging with /services1. Note that this digs out the main level and three levels below for the well plumbing. Start manufacturing with ""quickfort orders"" on /services2."
""
"3) Once the area is dug out, set up important furniture, stockpiles, hospital zone and garbage dump zone with /services2."
""
"4) When the table and chair have been placed in the dining room and the weapon rack and archery targets have been constructed in the barracks, run /services3 to build the rest of the furniture and configure your dining room and barracks. Run ""quickfort orders"" for /services3."
""
5) Fill the wells with either bucket brigades or by carefully routing flowing water.
""
"6) When your fort is mature enough to need jail cells, run /services4 to set those up. You also get some decorative statues to increase the value of your dining hall. Run ""quickfort orders"" for /services4."
"#dig label(services1) start(23; 22; central stairs) message(This would be a good time to queue manager orders for /services2 and /services3. Once the area is dug out, continue with /services2.)"


,,,,d,d,d,,,d,d,d,,,d,d,d
,,,,d,d,d,,,d,d,d,,,d,d,d
,,,,d,d,d,,,d,d,d,,,d,d,d
,,,,,d,,,,,d,,,,,d
,,,,d,d,d,d,d,d,d,d,d,d,d,d,d,,d,h,d,,j,,d,h,d
,,,,d,d,d,d,d,d,d,d,d,d,d,d,d,,d,d,d,d,d,d,d,d,d
,,,,d,d,d,d,d,d,d,d,d,d,d,d,d,,d,d,d,,d,,d,d,d
,,,,d,d,d,d,d,d,d,d,d,d,d,d,d,,,,,,d
,,,,d,d,d,d,d,d,d,d,d,d,d,d,d,,d,h,d,,d,,d,h,d
,,,,d,d,d,d,d,d,d,d,d,d,d,d,d,,d,d,d,d,d,d,d,d,d
,,,,d,d,d,d,d,d,d,d,d,d,d,d,d,,d,d,d,,d,,d,d,d
,,,,d,d,d,d,d,d,d,d,d,d,d,d,d,,,,,,d
,,,,d,d,d,d,d,d,d,d,d,d,d,d,d,,d,d,d,d,d,d,d,d,d
,,,,d,d,d,d,d,d,d,d,d,d,d,d,d,,d,d,d,d,d,d,d,d,d
,,,,d,d,d,d,d,d,d,d,d,d,d,d,d,,d,d,d,d,d,d,d,d,d,,d,d,d,d,d,d,d,d,d
,,,,d,d,d,d,d,d,d,d,d,d,d,d,d,,d,d,d,d,d,d,d,d,d,,d,d,d,d,d,d,d,d,d
,,,,d,d,d,d,d,d,d,d,d,d,d,d,d,,,,,d,,d,,,,,d,d,d,d,d,d,d,d,d
,,,,d,d,d,d,d,d,d,d,d,d,d,d,d,,,,d,d,d,d,d,,,,d,d,d,d,d,d,d,d,d
,,,,d,d,d,d,d,d,d,d,d,d,d,d,d,d,d,d,d,`,`,`,d,d,d,d,d,d,d,d,d,d,d,d,d
,,,,d,d,d,d,d,d,d,d,d,d,d,d,d,,,,d,`,`,`,d,,,,d,d,d,d,h,d,d,d,d
,,,,d,d,d,d,d,d,d,d,d,d,d,d,d,d,d,d,d,`,`,`,d,d,d,d,d,d,d,d,d,d,d,d,d
,,,,d,d,d,d,d,d,d,d,d,d,d,d,d,,,,d,d,d,d,d,,,,d,d,d,d,d,d,d,d,d
,,,,d,d,d,d,d,d,d,d,d,d,d,d,d,,,,,,d,,,,,,d,d,d,d,d,d,d,d,d
,,,,,,,,d,d,,d,d,,,,,,,,,,,,,,,,d,d,d,d,d,d,d,d,d
,,,,d,d,d,d,d,d,,d,d,d,d,d,d,,,,,,,,,,,,d,d,d,d,d,d,d,d,d
,,,,d,d,d,d,d,d,,d,d,d,d,d,d
,,,,d,d,d,d,d,d,,d,d,d,d,d,d
,,,,d,d,d,d,d,d,,d,d,d,d,d,d
,,,,d,d,d,d,d,d,,d,d,d,d,d,d
#>






,,,,,,,,,,,,,,,,,,j6,h6,j,,u,,j,h6,j6
,,,,,,,,,,,,,,,,,,6,6,6,6,6,6,6,6,6
,,,,,,,,,,,,,,,,,,,,,,d
,,,,,,,,,,,,,,,,,,,,,,d
,,,,,,,,,,,,,,,,,,j6,h6,j,,d,,j,h6,j6
,,,,,,,,,,,,,,,,,,6,6,6,6,d,6,6,6,6
,,,,,,,,,,,,,,,,,,,,,,d
,,,,,,,,,,,,,,,,,,,,,,d
,,,,,,,,,,,,,,,,,,,,,,d
,,,,,,,,,,,,,,,,,,,,,,d
,,,,,,,,,,,,,,,,,,,,,,d
,,,,,,,,,,,,,,,,,,,,,,d
,,,,,,,,,,,,,,,,,,,,,,d
,,,,,,,,,,,,,,,,,,,,d,d,d,d,d
,,,,,,,,,,,,,,,,,,,,d,`,`,`,d
,,,,,,,,,,,,,,,,,,,,d,`,`,`,d,,,,,,,j,h6,j6
,,,,,,,,,,,,,,,,,,,,d,`,`,`,d,,,,,,,6,6,6
,,,,,,,,,,,,,,,,,,,,d,d,d,d,d,,,,,,,,d
,,,,,,,,,,,,,,,,,,,,,,d,,,,,,,,,,d
,,,,,,,,,,,,,,,,,,,,,,d,d,d,d,d,d,d,d,d,d,d
#>






,,,,,,,,,,,,,,,,,,u5,h5,i,,,,i,h5,u5



,,,,,,,,,,,,,,,,,,u5,h5,i,,,,i,h5,u5








,,,,,,,,,,,,,,,,,,,,d,d,d,d,d
,,,,,,,,,,,,,,,,,,,,d,`,`,`,d
,,,,,,,,,,,,,,,,,,,,d,`,`,`,d,,,,,,,i,h5,u5
,,,,,,,,,,,,,,,,,,,,d,`,`,`,d
,,,,,,,,,,,,,,,,,,,,d,d,d,d,d
#>






,,,,,,,,,,,,,,,,,,,d,u,,,,u,d



,,,,,,,,,,,,,,,,,,,d,u,,,,u,d








,,,,,,,,,,,,,,,,,,,,d,d,d,d,d
,,,,,,,,,,,,,,,,,,,,d,`,`,`,d
,,,,,,,,,,,,,,,,,,,,d,`,`,`,d,,,,,,,u,d
,,,,,,,,,,,,,,,,,,,,d,`,`,`,d
,,,,,,,,,,,,,,,,,,,,d,d,d,d,d


"#meta label(services2) start(central stairs) message(Once furniture has been placed, continue with /services3.) dining hall anchors, stockpiles, hospital, garbage dump"
build/services_build
place/services_place
zones/services_zones
name_zones/services_name_zones
query_stockpiles/services_query_stockpiles
""
"#meta label(services3) start(central stairs) configure dining room, build dining hall and hospital furniture"
query_dining/services_query_dining
build2/services_build2
""
#meta label(services4) start(central stairs) complete jail and build decorative furniture
build3/services_build3
place_jail/services_place_jail
query_jail/services_query_jail
#build label(services_build) start(23; 22) hidden() build basic hospital and dining room anchor


,,,,`,`,`,,,`,`,`,,,`,`,`
,,,,`,`,`,,,`,`,`,,,`,`,`
,,,,`,`,`,,,`,`,`,,,`,`,`
,,,,,d,,,,,d,,,,,d
,,,,`,`,`,`,`,`,`,`,`,`,`,`,`,,`,`,`,,,,`,`,`
,,,,`,`,`,`,`,`,`,`,`,`,`,`,`,,`,`,`,`,`,`,`,`,`
,,,,`,`,`,`,`,`,`,`,`,`,`,`,`,,`,`,`,,`,,`,`,`
,,,,`,`,`,`,`,`,`,`,`,`,`,`,`,,,,,,`
,,,,`,`,`,`,`,`,`,`,`,`,`,`,`,,`,`,`,,`,,`,`,`
,,,,`,`,`,`,`,`,`,`,`,`,`,`,`,,`,`,`,`,`,`,`,`,`
,,,,`,`,`,`,`,`,`,`,`,`,`,`,`,,`,`,`,,`,,`,`,`
,,,,`,`,`,`,`,`,`,`,`,`,`,`,`,,,,,,d
,,,,`,`,`,`,`,`,`,`,`,`,`,`,`,,`,A,A,A,`,A,A,A,`
,,,,`,`,`,`,`,`,`,`,`,`,`,`,`,,`,`,`,`,r,`,`,`,`
,,,,`,`,`,`,`,`,`,`,`,`,`,`,`,,`,`,`,`,`,`,`,`,`,,`,`,`,`,`,`,b,`,`
,,,,`,`,`,`,`,`,`,`,`,`,`,`,`,,`,`,`,`,`,`,`,`,`,,h,`,`,`,`,`,`,`,`
,,,,`,`,`,`,`,`,`,`,`,`,`,`,`,,,,,d,,d,,,,,`,`,`,`,`,`,t,`,`
,,,,`,`,`,`,t,c,`,`,`,`,`,`,`,,,,`,`,`,`,`,,,,`,`,`,`,`,`,`,`,`
,,,,`,`,`,`,`,`,`,`,`,`,`,`,`,d,`,`,`,`,`,`,`,`,`,`,`,`,`,`,`,`,`,`,R
,,,,`,`,`,`,`,`,`,`,`,`,`,`,`,,,,`,`,`,`,`,,,,`,`,`,`,`,`,`,`,R
,,,,`,`,`,`,`,`,`,`,`,`,`,`,`,d,`,`,`,`,`,`,`,`,`,`,`,`,`,`,`,`,`,`,R
,,,,`,`,`,`,`,`,`,`,`,`,`,`,`,,,,`,`,`,`,`,,,,`,`,`,`,`,`,`,`,`
,,,,`,`,`,h,`,`,`,`,`,`,`,`,`,,,,,,`,,,,,,`,`,`,`,`,`,`,`,`
,,,,,,,,`,`,,`,`,,,,,,,,,,,,,,,,`,`,`,`,`,`,`,`,`
,,,,`,`,`,`,`,`,,`,`,`,`,`,`,,,,,,,,,,,,`,`,`,`,`,`,`,`,`
,,,,`,`,`,`,`,`,,`,`,`,`,`,`
,,,,`,`,`,`,`,`,,`,`,`,`,`,`
,,,,`,`,`,`,`,`,,`,`,`,`,`,`
,,,,`,`,`,`,`,`,,`,`,`,`,`,`


#place label(services_place) start(23; 22) hidden()


,,,,`,`,`,,,`,`,`,,,`,`,`
,,,,`,`,`,,,`,`,`,,,`,`,`
,,,,`,`,`,,,`,`,`,,,`,`,`
,,,,,`,,,,,`,,,,,`
,,,,`,`,`,`,`,`,`,`,`,`,`,`,`,,`,`,`,,,,`,`,`
,,,,`,`,`,`,`,`,`,`,`,`,`,`,`,,`,`,`,`,`,`,`,`,`
,,,,`,`,`,`,`,`,`,`,`,`,`,`,`,,`,`,`,,`,,`,`,`
,,,,`,`,`,`,`,`,`,`,`,`,`,`,`,,,,,,`
,,,,`,`,`,`,`,`,`,`,`,`,`,`,`,,`,`,`,,`,,`,`,`
,,,,`,`,`,`,`,`,`,`,`,`,`,`,`,,`,`,`,`,`,`,`,`,`
,,,,`,`,`,`,`,`,`,`,`,`,`,`,`,,`,`,`,,`,,`,`,`
,,,,`,`,`,`,`,`,`,`,`,`,`,`,`,,,,,,`
,,,,`,`,`,`,`,`,`,`,`,`,`,`,`,,`,`,`,`,`,`,`,`,`
,,,,`,`,`,`,`,`,`,`,`,`,`,`,`,,`,`,`,`,`,`,`,`,`
,,,,`,`,`,`,`,`,`,`,`,`,`,`,`,,`,z(7x2),`,`,`,`,`,`,`,,`,`,`,`,`,`,`,`,`
,,,,`,`,`,`,`,`,`,`,`,`,`,`,`,,`,`,`,`,`,`,`,`,`,,`,`,`,`,`,`,`,`,`
,,,,`,`,`,`,`,`,`,`,`,`,`,`,`,,,,,`,,`,,,,,`,`,`,`,`,`,`,`,`
,,,,`,`,`,`,`,`,`,`,`,`,`,`,`,,,,`,`,`,`,`,,,,`,`,`,`,`,`,`,`,`
,,,,`,`,`,`,`,`,`,`,`,`,`,`,`,`,`,`,`,`,`,`,`,`,`,`,`,`,`,`,`,`,`,`,`
,,,,`,`,`,`,`,`,`,`,`,`,`,`,`,,,,`,`,`,`,`,,,,`,`,`,`,`,`,`,`,`
,,,,`,`,`,`,`,`,`,`,`,`,`,`,`,`,`,`,`,`,`,`,`,`,`,`,`,`,`,`,`,`,`,`,`
,,,,`,`,`,`,`,`,`,`,`,`,`,`,`,,,,`,`,`,`,`,,,,`,`,`,`,`,`,`,`,`
